Workbook
Name A_ALL_ANF: #REF!
Name E_ALL_ANF: #REF!
Name L_ALL_ANF: #REF!
Name V_ALL_ANF: #REF!

Sheet Cover
F3: Abercrombie & Fitch (ANF)
F4: COMPANY MODEL
B9: Sources: Company data, Goldman Sachs Global Investment Research
B11: Date: September 08, 2026
B13: Jon Keypour
B14: Vice President
B15: tel: 212-934-0334
B16: jon.keypour@gs.com
B18: Kareem Elbadrawi
B19: Analyst
B20: tel: 212-902-7320
B21: kareem.elbadrawi@gs.com

Sheet Rev Driver
A1: ANF Rev. Driver
A3: Period | B3: FY15 | C3: FY16 | D3: FY17 | E3: FY18 | F3: FY19 | G3: 1Q20 | H3: 2Q20 | I3: 3Q20 | J3: 4Q20 | K3: FY20 | L3: 1Q21 | M3: 2Q21 | N3: 3Q21 | O3: 4Q21 | P3: FY21 | Q3: 1Q22 | R3: 2Q22 | S3: 3Q22 | T3: 4Q22 | U3: FY22 | V3: 1Q23 | W3: 2Q23 | X3: 3Q23 | Y3: 4Q23 | Z3: FY23 | AA3: 1Q24 | AB3: 2Q24 | AC3: 3Q24 | AD3: 4Q24 | AE3: FY24 | AF3: 1Q25 | AG3: 2Q25 | AH3: 3Q25 | AI3: 4Q25 | AJ3: FY25 | AK3: 1Q26 | AL3: 2Q26 | AM3: 3Q26E | AN3: 4Q26E | AO3: FY26E | AP3: 1Q27E | AQ3: 2Q27E | AR3: 3Q27E | AS3: 4Q27E | AT3: FY27E | AU3: 1Q28E | AV3: 2Q28E | AW3: 3Q28E | AX3: 4Q28E | AY3: FY28E
A4: End Date | B4: 42399 | C4: 42763 | D4: 43134 | E4: 43498 | F4: 43862 | G4: 43953 | H4: 44044 | I4: 44135 | J4: 44226 | K4: =J4 -> 44226 | L4: 44317 | M4: 44408 | N4: 44500 | O4: 44590 | P4: =O4 -> 44590 | Q4: 44681 | R4: 44772 | S4: 44863 | T4: 44954 | U4: =T4 -> 44954 | V4: 45045 | W4: 45136 | X4: 45227 | Y4: 45325 | Z4: =Y4 -> 45325 | AA4: 45416 | AB4: 45507 | AC4: 45598 | AD4: 45689 | AE4: =AD4 -> 45689 | AF4: 45780 | AG4: =AF4+AG5*7 -> 45871 | AH4: =AH5*7+AG4 -> 45962 | AI4: =AI5*7+AH4 -> 46053 | AJ4: =AI4 -> 46053 | AK4: =AK5*7+AJ4 -> 46144 | AL4: =AL5*7+AK4 -> 46235 | AM4: =AM5*7+AL4 -> 46326 | AN4: =AN5*7+AM4 -> 46417 | AO4: =AN4 -> 46417 | AP4: =AP5*7+AO4 -> 46508 | AQ4: =AQ5*7+AP4 -> 46599 | AR4: =AR5*7+AQ4 -> 46690 | AS4: =AS5*7+AR4 -> 46781 | AT4: =AS4 -> 46781 | AU4: =AU5*7+AT4 -> 46872 | AV4: =AV5*7+AU4 -> 46963 | AW4: =AW5*7+AV4 -> 47054 | AX4: =AX5*7+AW4 -> 47145 | AY4: =AX4 -> 47145
A5: Wks. In Q | B5: 52 | C5: 52 | D5: 53 | E5: 52 | F5: 52 | G5: 13 | H5: 13 | I5: 13 | J5: 13 | K5: =SUM(G5:J5) -> 52 | L5: 13 | M5: 13 | N5: 13 | O5: 13 | P5: =SUM(L5:O5) -> 52 | Q5: 13 | R5: 13 | S5: 13 | T5: 13 | U5: =SUM(Q5:T5) -> 52 | V5: 13 | W5: 13 | X5: 13 | Y5: 14 | Z5: =SUM(V5:Y5) -> 53 | AA5: 13 | AB5: 13 | AC5: 13 | AD5: 13 | AE5: =SUM(AA5:AD5) -> 52 | AF5: 13 | AG5: 13 | AH5: 13 | AI5: 13 | AJ5: =SUM(AF5:AI5) -> 52 | AK5: 13 | AL5: 13 | AM5: 13 | AN5: 13 | AO5: =SUM(AK5:AN5) -> 52 | AP5: 13 | AQ5: 13 | AR5: 13 | AS5: 13 | AT5: =SUM(AP5:AS5) -> 52 | AU5: 13 | AV5: 13 | AW5: 13 | AX5: 13 | AY5: =SUM(AU5:AX5) -> 52
A6: Segments by Brand | AT6: x | AY6: x
A7: Abercrombie | B7: 1640992 | C7: 1487024 | D7: 1454092 | E7: 1437571 | F7: 1464559 | G7: 212347 | H7: 269080 | I7: 342988 | J7: 466620 | K7: =SUM(G7:J7) -> 1291035 | L7: 338997 | M7: 350367 | N7: 382849 | O7: 492576 | P7: =SUM(L7:O7) -> 1564789 | Q7: 383928 | R7: 368157 | S7: 422332 | T7: 560438 | U7: =SUM(Q7:T7) -> 1734855 | V7: 436044 | W7: 462711 | X7: 547728 | Y7: 755203 | Z7: =SUM(V7:Y7) -> 2201686 | AA7: 571513 | AB7: 582416 | AC7: 629835 | AD7: 772670 | AE7: =SUM(AA7:AD7) -> 2556434 | AF7: 547947 | AG7: 551868 | AH7: 617345 | AI7: 806502 | AJ7: =SUM(AF7:AI7) -> 2523662 | AK7: 564719 | AL7: 596808 | AM7: =AH7*(1+AM14) -> 666732.6 | AN7: =AI7*(1+AN14) -> 862957.14 | AO7: =SUM(AK7:AN7) -> 2691216.7 | AP7: =AK7*(1+AP14) -> 592954.95 | AQ7: =AL7*(1+AQ14) -> 620680.32 | AR7: =AM7*(1+AR14) -> 693401.9 | AS7: =AN7*(1+AS14) -> 897475.43 | AT7: =SUM(AP7:AS7) -> 2804512.6 | AU7: =AP7*(1+AU14) -> 607778.82 | AV7: =AQ7*(1+AV14) -> 636197.33 | AW7: =AR7*(1+AW14) -> 710736.95 | AX7: =AS7*(1+AX14) -> 919912.31 | AY7: =SUM(AU7:AX7) -> 2874625.4
A8: Hollister | B8: 1877688 | C8: 1839716 | D8: 2038598 | E8: 2152538 | F8: 2158514 | G8: 273012 | H8: 429248 | I8: 476665 | J8: 655424 | K8: =SUM(G8:J8) -> 1834349 | L8: 442408 | M8: 514483 | N8: 522311 | O8: 668777 | P8: =SUM(L8:O8) -> 2147979 | Q8: 428834 | R8: 436934 | S8: 457752 | T8: 639376 | U8: =SUM(Q8:T8) -> 1962896 | V8: 399950 | W8: 472634 | X8: 508703 | Y8: 697704 | Z8: =SUM(V8:Y8) -> 2078991 | AA8: 449217 | AB8: 551558 | AC8: 579131 | AD8: 812247 | AE8: =SUM(AA8:AD8) -> 2392153 | AF8: 549364 | AG8: 656692 | AH8: 673274 | AI8: 863300 | AJ8: =SUM(AF8:AI8) -> 2742630 | AK8: 549102 | AL8: 669881 | AM8: =AH8*(1+AM15) -> 700204.96 | AN8: =AI8*(1+AN15) -> 923731 | AO8: =SUM(AK8:AN8) -> 2842919 | AP8: =AK8*(1+AP15) -> 571066.08 | AQ8: =AL8*(1+AQ15) -> 696676.24 | AR8: =AM8*(1+AR15) -> 721211.11 | AS8: =AN8*(1+AS15) -> 951442.93 | AT8: =SUM(AP8:AS8) -> 2940396.4 | AU8: =AP8*(1+AU15) -> 588198.06 | AV8: =AQ8*(1+AV15) -> 717576.53 | AW8: =AR8*(1+AW15) -> 746453.5 | AX8: =AS8*(1+AX15) -> 984743.43 | AY8: =SUM(AU8:AX8) -> 3036971.5
A9: Total | B9: =SUM(B7:B8) -> 3518680 | C9: =SUM(C7:C8) -> 3326740 | D9: =SUM(D7:D8) -> 3492690 | E9: =SUM(E7:E8) -> 3590109 | F9: =SUM(F7:F8) -> 3623073 | G9: =SUM(G7:G8) -> 485359 | H9: =SUM(H7:H8) -> 698328 | I9: =SUM(I7:I8) -> 819653 | J9: =SUM(J7:J8) -> 1122044 | K9: =IF(SUM(K7:K8)=SUM(G9:J9),SUM(K7:K8),"ERR") -> 3125384 | L9: =SUM(L7:L8) -> 781405 | M9: =SUM(M7:M8) -> 864850 | N9: =SUM(N7:N8) -> 905160 | O9: =SUM(O7:O8) -> 1161353 | P9: =IF(SUM(P7:P8)=SUM(L9:O9),SUM(P7:P8),"ERR") -> 3712768 | Q9: =SUM(Q7:Q8) -> 812762 | R9: =SUM(R7:R8) -> 805091 | S9: =SUM(S7:S8) -> 880084 | T9: =SUM(T7:T8) -> 1199814 | U9: =IF(SUM(U7:U8)=SUM(Q9:T9),SUM(U7:U8),"ERR") -> 3697751 | V9: =SUM(V7:V8) -> 835994 | W9: =SUM(W7:W8) -> 935345 | X9: =SUM(X7:X8) -> 1056431 | Y9: =SUM(Y7:Y8) -> 1452907 | Z9: =IF(SUM(Z7:Z8)=SUM(V9:Y9),SUM(Z7:Z8),"ERR") -> 4280677 | AA9: =SUM(AA7:AA8) -> 1020730 | AB9: =SUM(AB7:AB8) -> 1133974 | AC9: =SUM(AC7:AC8) -> 1208966 | AD9: =SUM(AD7:AD8) -> 1584917 | AE9: =IF(SUM(AE7:AE8)=SUM(AA9:AD9),SUM(AE7:AE8),"ERR") -> 4948587 | AF9: =SUM(AF7:AF8) -> 1097311 | AG9: =SUM(AG7:AG8) -> 1208560 | AH9: =SUM(AH7:AH8) -> 1290619 | AI9: =SUM(AI7:AI8) -> 1669802 | AJ9: =IF(SUM(AJ7:AJ8)=SUM(AF9:AI9),SUM(AJ7:AJ8),"ERR") -> 5266292 | AK9: =SUM(AK7:AK8) -> 1113821 | AL9: =SUM(AL7:AL8) -> 1266689 | AM9: =SUM(AM7:AM8) -> 1366937.6 | AN9: =SUM(AN7:AN8) -> 1786688.1 | AO9: =IF(SUM(AO7:AO8)=SUM(AK9:AN9),SUM(AO7:AO8),"ERR") -> 5534135.7 | AP9: =SUM(AP7:AP8) -> 1164021 | AQ9: =SUM(AQ7:AQ8) -> 1317356.6 | AR9: =SUM(AR7:AR8) -> 1414613 | AS9: =SUM(AS7:AS8) -> 1848918.4 | AT9: =IF(SUM(AT7:AT8)=SUM(AP9:AS9),SUM(AT7:AT8),"ERR") -> 5744909 | AU9: =SUM(AU7:AU8) -> 1195976.9 | AV9: =SUM(AV7:AV8) -> 1353773.9 | AW9: =SUM(AW7:AW8) -> 1457190.4 | AX9: =SUM(AX7:AX8) -> 1904655.7 | AY9: =IF(SUM(AY7:AY8)=SUM(AU9:AX9),SUM(AY7:AY8),"ERR") -> 5911596.9
A10: Check | G10: =G9-G52 -> 0 | H10: =H9-H52 -> 0 | I10: =I9-I52 -> 0 | J10: =J9-J52 -> 0 | K10: =K9-K52 -> 0 | L10: =L9-L52 -> 0 | M10: =M9-M52 -> 0 | N10: =N9-N52 -> 0 | ... AH10: =AH9-AH52 -> 0
A12: Sales Drivers
A13: Net Sales
A14: Abercrombie | C14: =C7/B7-1 -> -0.093826173 | D14: =D7/C7-1 -> -0.022146246 | E14: =E7/D7-1 -> -0.01136173 | F14: =F7/E7-1 -> 0.018773334 | K14: =K7/F7-1 -> -0.11848208 | L14: =L7/G7-1 -> 0.59642943 | M14: =M7/H7-1 -> 0.30209231 | N14: =N7/I7-1 -> 0.11621689 | O14: =O7/J7-1 -> 0.055625563 | P14: =P7/K7-1 -> 0.21204228 | Q14: =Q7/L7-1 -> 0.132541 | R14: =R7/M7-1 -> 0.05077533 | ... AH14: =AH7/AC7-1 -> -0.019830591 | AI14: =AI19+AI29+AI34 -> 0.043522564 | AJ14: =AJ7/AE7-1 -> -0.01281942 | AK14: =AK7/AF7-1 -> 0.0306088 | AL14: =AL7/AG7-1 -> 0.081432516 | AM14: =AM19+AM29+AM34 -> 0.08 | AN14: =AN19+AN29+AN34 -> 0.07 | AO14: =AO7/AJ7-1 -> 0.066393495 | AP14: =AP19+AP29+AP34 -> 0.05 | AQ14: =AQ19+AQ29+AQ34 -> 0.04 | AR14: =AR19+AR29+AR34 -> 0.04 | AS14: =AS19+AS29+AS34 -> 0.04 | AT14: =AT7/AO7-1 -> 0.042098378 | AU14: =AU19+AU29+AU34 -> 0.025 | AV14: =AV19+AV29+AV34 -> 0.025 | AW14: =AW19+AW29+AW34 -> 0.025 | AX14: =AX19+AX29+AX34 -> 0.025 | AY14: =AY7/AT7-1 -> 0.025
A15: Hollister | C15: =C8/B8-1 -> -0.020222742 | D15: =D8/C8-1 -> 0.10810473 | E15: =E8/D8-1 -> 0.055891353 | F15: =F8/E8-1 -> 0.0027762576 | K15: =K8/F8-1 -> -0.15017971 | L15: =L8/G8-1 -> 0.6204709 | M15: =M8/H8-1 -> 0.19856819 | N15: =N8/I8-1 -> 0.095761174 | O15: =O8/J8-1 -> 0.020373071 | P15: =P8/K8-1 -> 0.17097619 | Q15: =Q8/L8-1 -> -0.030682085 | R15: =R8/M8-1 -> -0.1507319 | ... AH15: =AH8/AC8-1 -> 0.16255908 | AI15: =AI20+AI30+AI35 -> 0.062185869 | AJ15: =AJ8/AE8-1 -> 0.14651111 | AK15: =AK8/AF8-1 -> -0.00047691512 | AL15: =AL8/AG8-1 -> 0.020083997 | AM15: =AM20+AM30+AM35 -> 0.04 | AN15: =AN20+AN30+AN35 -> 0.07 | AO15: =AO8/AJ8-1 -> 0.036566712 | AP15: =AP20+AP30+AP35 -> 0.04 | AQ15: =AQ20+AQ30+AQ35 -> 0.04 | AR15: =AR20+AR30+AR35 -> 0.03 | AS15: =AS20+AS30+AS35 -> 0.03 | AT15: =AT8/AO8-1 -> 0.034287787 | AU15: =AU20+AU30+AU35 -> 0.03 | AV15: =AV20+AV30+AV35 -> 0.03 | AW15: =AW20+AW30+AW35 -> 0.035 | AX15: =AX20+AX30+AX35 -> 0.035 | AY15: =AY8/AT8-1 -> 0.032844266
A16: Total ANF | C16: =C9/B9-1 -> -0.054548865 | D16: =D9/C9-1 -> 0.04988367 | E16: =E9/D9-1 -> 0.027892255 | F16: =F9/E9-1 -> 0.0091818939 | K16: =K9/F9-1 -> -0.13736654 | L16: =L9/G9-1 -> 0.60995263 | M16: =M9/H9-1 -> 0.23845815 | N16: =N9/I9-1 -> 0.10432097 | O16: =O9/J9-1 -> 0.035033386 | P16: =P9/K9-1 -> 0.18793979 | Q16: =Q9/L9-1 -> 0.040128998 | R16: =R9/M9-1 -> -0.069097531 | ... AY16: =AY9/AT9-1 -> 0.029014903
A18: Comparable Sales
A19: Abercrombie | B19: -0.06 | C19: -0.11 | D19: 0.08 | E19: 0.01 | F19: 0.03 | V19: 0.14 | W19: 0.23 | X19: 0.26 | Y19: 0.28 | Z19: 0.23 | AA19: 0.29 | AB19: 0.21 | AC19: 0.11 | AD19: 0.05 | AE19: 0.15 | AF19: -0.1 | AG19: -0.11 | AH19: -0.07 | AI19: -0.01 | AJ19: -0.07 | AK19: 0 | AL19: 0.04 | AM19: 0.02 | AN19: 0.02 | AO19: =SUMPRODUCT(AK19:AN19,AF$43:AI$43) -> 0.020031074 | AP19: 0.02 | AQ19: 0.02 | AR19: 0.02 | AS19: 0.02 | AT19: =SUMPRODUCT(AP19:AS19,AK$43:AN$43) -> 0.02 | AU19: 0.015 | AV19: 0.015 | AW19: 0.015 | AX19: 0.015 | AY19: =SUMPRODUCT(AU19:AX19,AP$43:AS$43) -> 0.015
A20: Hollister | B20: 0 | C20: 0 | D20: -0.02 | E20: 0.05 | F20: -0.01 | V20: -0.06 | W20: 0.05 | X20: 0.07 | Y20: 0.06 | Z20: 0.04 | AA20: 0.13 | AB20: 0.15 | AC20: 0.21 | AD20: 0.24 | AE20: 0.19 | AF20: 0.23 | AG20: 0.19 | AH20: 0.15 | AI20: 0.03 | AJ20: 0.13 | AK20: -0.02 | AL20: -0.03 | AM20: -0.01 | AN20: 0.03 | AO20: =SUMPRODUCT(AK20:AN20,AF$44:AI$44) -> -0.0042009969 | AP20: 0.03 | AQ20: 0.03 | AR20: 0.02 | AS20: 0.02 | AT20: =SUMPRODUCT(AP20:AS20,AK$44:AN$44) -> 0.024287787 | AU20: 0.02 | AV20: 0.02 | AW20: 0.025 | AX20: 0.025 | AY20: =SUMPRODUCT(AU20:AX20,AP$44:AS$44) -> 0.022844266
A21: Total ANF | B21: -0.03 | C21: -0.05 | D21: 0.03 | E21: 0.03 | F21: 0.01 | V21: 0.03 | W21: 0.13 | X21: 0.16 | Y21: 0.16 | Z21: 0.13 | AA21: 0.21 | AB21: 0.18 | AC21: 0.16 | AD21: 0.14 | AE21: 0.17 | AF21: 0.04 | AG21: 0.03 | AH21: 0.03 | AI21: 0.01 | AJ21: 0.03 | AK21: -0.01 | AL21: 0 | AM21: =AM19*AH$39+AM20*AH$40 -> 0.0043499747 | AN21: =AN19*AI$39+AN20*AI$40 -> 0.025170074 | AO21: =SUMPRODUCT(AK21:AN21,AF$45:AI$45) -> 0.0069631707 | AP21: =AP19*AK$39+AP20*AK$40 -> 0.024929894 | AQ21: =AQ19*AL$39+AQ20*AL$40 -> 0.025288441 | AR21: =AR19*AM$39+AR20*AM$40 -> 0.02 | AS21: =AS19*AN$39+AS20*AN$40 -> 0.02 | AT21: =SUMPRODUCT(AP21:AS21,AK$45:AN$45) -> 0.022202662 | AU21: =AU19*AP$39+AU20*AP$40 -> 0.017452989 | AV21: =AV19*AQ$39+AV20*AQ$40 -> 0.01764422 | AW21: =AW19*AR$39+AW20*AR$40 -> 0.020098293 | AX21: =AX19*AS$39+AX20*AS$40 -> 0.020145943 | AY21: =SUMPRODUCT(AU21:AX21,AP$45:AS$45) -> 0.019014903
A23: FX $ Impact | AF23: Assumed | AG23: Assumed | AH23: Assumed | AI23: Assumed | AK23: Assumed | AL23: Assumed
A24: Abercrombie | S24: -8120 | T24: -7715 | U24: -24948 | V24: -3414 | W24: -71 | X24: 1393 | Y24: 843 | Z24: =SUM(V24:Y24) -> -1249 | AA24: -572 | AB24: -1125 | AC24: 1643 | AD24: -2370 | AE24: =SUM(AA24:AD24) -> -2424 | AF24: =1/3*AF26 -> -69.333333 | AG24: =AG26*1/3 -> 3569 | AH24: =AH26*1/3 -> 1944.6667 | AI24: =AI26*1/3 -> 5609.6667 | AJ24: =SUM(AF24:AI24) -> 11054 | AK24: =1/3*AK26 -> 3673 | AL24: =AL26*1/3 -> 74.333333 | AM24: =AM29*AH7 -> 0 | AN24: =AN29*AI7 -> 0 | AO24: =SUM(AK24:AN24) -> 3747.3333 | AP24: =AP29*AK7 -> 0 | AQ24: =AQ29*AL7 -> 0 | AR24: =AR29*AM7 -> 0 | AS24: =AS29*AN7 -> 0 | AT24: =SUM(AP24:AS24) -> 0 | AU24: =AU29*AP7 -> 0 | AV24: =AV29*AQ7 -> 0 | AW24: =AW29*AR7 -> 0 | AX24: =AX29*AS7 -> 0 | AY24: =SUM(AU24:AX24) -> 0
A25: Hollister | S25: -18740 | T25: -15575 | U25: -56855 | V25: -5183 | W25: 2944 | X25: 5544 | Y25: 4444 | Z25: =SUM(V25:Y25) -> 7749 | AA25: 21 | AB25: -1245 | AC25: 3646 | AD25: -3768 | AE25: =SUM(AA25:AD25) -> -1346 | AF25: =AF26-AF24 -> -138.66667 | AG25: =AG26-AG24 -> 7138 | AH25: =AH26-AH24 -> 3889.3333 | AI25: =AI26-AI24 -> 11219.333 | AJ25: =SUM(AF25:AI25) -> 22108 | AK25: =AK26-AK24 -> 7346 | AL25: =AL26-AL24 -> 148.66667 | AM25: =AM30*AH8 -> 0 | AN25: =AN30*AI8 -> 4316.5 | AO25: =SUM(AK25:AN25) -> 11811.167 | AP25: =AP30*AK8 -> 0 | AQ25: =AQ30*AL8 -> 0 | AR25: =AR30*AM8 -> 0 | AS25: =AS30*AN8 -> 0 | AT25: =SUM(AP25:AS25) -> 0 | AU25: =AU30*AP8 -> 0 | AV25: =AV30*AQ8 -> 0 | AW25: =AW30*AR8 -> 0 | AX25: =AX30*AS8 -> 0 | AY25: =SUM(AU25:AX25) -> 0
A26: Total ANF | C26: 20000 | E26: -37000 | R26: -23124 | S26: =SUM(S24:S25) -> -26860 | T26: =SUM(T24:T25) -> -23290 | U26: =SUM(U24:U25) -> -81803 | V26: =SUM(V24:V25) -> -8597 | W26: =SUM(W24:W25) -> 2873 | X26: =SUM(X24:X25) -> 6937 | Y26: =SUM(Y24:Y25) -> 5287 | Z26: =SUM(V26:Y26) -> 6500 | AA26: =SUM(AA24:AA25) -> -551 | AB26: =SUM(AB24:AB25) -> -2370 | AC26: =SUM(AC24:AC25) -> 5289 | AD26: =SUM(AD24:AD25) -> -6138 | AE26: =SUM(AA26:AD26) -> -3770 | AF26: -208 | AG26: 10707 | AH26: 5834 | AI26: 16829 | AJ26: =SUM(AF26:AI26) -> 33162 | AK26: 11019 | AL26: 223 | AM26: =SUM(AM24:AM25) -> 0 | AN26: =SUM(AN24:AN25) -> 4316.5 | AO26: =SUM(AK26:AN26) -> 15558.5 | AP26: =SUM(AP24:AP25) -> 0 | AQ26: =SUM(AQ24:AQ25) -> 0 | AR26: =SUM(AR24:AR25) -> 0 | AS26: =SUM(AS24:AS25) -> 0 | AT26: =SUM(AP26:AS26) -> 0 | AU26: =SUM(AU24:AU25) -> 0 | AV26: =SUM(AV24:AV25) -> 0 | AW26: =SUM(AW24:AW25) -> 0 | AX26: =SUM(AX24:AX25) -> 0 | AY26: =SUM(AU26:AX26) -> 0
A28: FX % Impact
A29: Abercrombie | S29: =S24/N7 -> -0.021209406 | T29: =T24/O7 -> -0.015662558 | U29: =U24/P7 -> -0.015943364 | V29: =V24/Q7 -> -0.0088922923 | W29: =W24/R7 -> -0.00019285251 | X29: =X24/S7 -> 0.003298353 | Y29: =Y24/T7 -> 0.0015041807 | Z29: =Z24/U7 -> -0.00071994489 | ... AL29: =AL24/AG7 -> 0.00013469405 | AM29: 0 | AN29: 0 | AO29: =SUMPRODUCT(AK29:AN29,AF$43:AI$43) -> 0.0014848792 | AP29: 0 | AQ29: 0 | AR29: 0 | AS29: 0 | AT29: =SUMPRODUCT(AP29:AS29,AK$43:AN$43) -> 0 | AU29: 0 | AV29: 0 | AW29: 0 | AX29: 0 | AY29: =SUMPRODUCT(AU29:AX29,AP$43:AS$43) -> 0
A30: Hollister | S30: =S25/N8 -> -0.035879007 | T30: =T25/O8 -> -0.023288779 | U30: =U25/P8 -> -0.026469067 | V30: =V25/Q8 -> -0.012086262 | W30: =W25/R8 -> 0.0067378597 | X30: =X25/S8 -> 0.012111362 | Y30: =Y25/T8 -> 0.0069505268 | Z30: =Z25/U8 -> 0.0039477384 | ... AL30: =AL25/AG8 -> 0.00022638721 | AM30: 0 | AN30: 0.005 | AO30: =SUMPRODUCT(AK30:AN30,AF$44:AI$44) -> 0.0043065111 | AP30: 0 | AQ30: 0 | AR30: 0 | AS30: 0 | AT30: =SUMPRODUCT(AP30:AS30,AK$44:AN$44) -> 0 | AU30: 0 | AV30: 0 | AW30: 0 | AX30: 0 | AY30: =SUMPRODUCT(AU30:AX30,AP$44:AS$44) -> 0
A31: Total ANF | C31: =B26/B9 -> 0 | D31: =C26/C9 -> 0.0060118915 | E31: =E26/D9 -> -0.010593554 | F31: =F26/E9 -> 0 | R31: =R26/M9 -> -0.026737585 | S31: =S26/N9 -> -0.029674312 | T31: =T26/O9 -> -0.020054195 | U31: =U26/P9 -> -0.022032888 | V31: =V26/Q9 -> -0.010577512 | W31: =W26/R9 -> 0.0035685407 | X31: =X26/S9 -> 0.0078822022 | Y31: =Y26/T9 -> 0.0044065163 | ... AH31: =AH26/AC9 -> 0.0048256113 | AI31: =AI29*AD$39+AI30*AD$40 -> 0.010618222 | AJ31: =AJ26/AE9 -> 0.0067013069 | AK31: =AK26/AF9 -> 0.01004182 | AL31: =AL26/AG9 -> 0.00018451711 | AM31: =AM29*AH$39+AM30*AH$40 -> 0 | AN31: =AN29*AI$39+AN30*AI$40 -> 0.002585037 | AO31: =SUMPRODUCT(AK31:AN31,AF$45:AI$45) -> 0.0029543557 | AP31: =AP29*AK$39+AP30*AK$40 -> 0 | AQ31: =AQ29*AL$39+AQ30*AL$40 -> 0 | AR31: =AR29*AM$39+AR30*AM$40 -> 0 | AS31: =AS29*AN$39+AS30*AN$40 -> 0 | AT31: =SUMPRODUCT(AP31:AS31,AK$45:AN$45) -> 0 | AU31: =AU29*AP$39+AU30*AP$40 -> 0 | AV31: =AV29*AQ$39+AV30*AQ$40 -> 0 | AW31: =AW29*AR$39+AW30*AR$40 -> 0 | AX31: =AX29*AS$39+AX30*AS$40 -> 0 | AY31: =SUMPRODUCT(AU31:AX31,AP$45:AS$45) -> 0
A33: Non-Comp/Other Impact
A34: Abercrombie | V34: =V7/(Q7+V24)-1-V19 -> 0.0059341838 | W34: =W7/(R7+W24)-1-W19 -> 0.027073075 | X34: =X7/(S7+X24)-1-X19 -> 0.032649714 | Y34: =Y7/(T7+Y24)-1-Y19 -> 0.065498957 | Z34: =Z7/(U7+Z24)-1-Z19 -> 0.04000368 | AA34: =AA7/(V7+AA24)-1-AA19 -> 0.02239896 | AB34: =AB7/(W7+AB24)-1-AB19 -> 0.051771371 | AC34: =AC7/(X7+AC24)-1-AC19 -> 0.036465685 | ... AL34: =AL7/(AG7+AL24)-1-AL19 -> 0.041286874 | AM34: 0.06 | AN34: 0.05 | AO34: =SUMPRODUCT(AK34:AN34,AF$43:AI$43) -> 0.044840586 | AP34: 0.03 | AQ34: 0.02 | AR34: 0.02 | AS34: 0.02 | AT34: =SUMPRODUCT(AP34:AS34,AK$43:AN$43) -> 0.022098378 | AU34: 0.01 | AV34: 0.01 | AW34: 0.01 | AX34: 0.01 | AY34: =SUMPRODUCT(AU34:AX34,AP$43:AS$43) -> 0.01
A35: Hollister | V35: =V8/(Q8+V25)-1-V20 -> 0.0040553663 | W35: =W8/(R8+W25)-1-W20 -> 0.024466102 | X35: =X8/(S8+X25)-1-X20 -> 0.028008617 | Y35: =Y8/(T8+Y25)-1-Y20 -> 0.0236942 | Z35: =Z8/(U8+Z25)-1-Z20 -> 0.014979968 | AA35: =AA8/(V8+AA25)-1-AA20 -> -0.0068760735 | AB35: =AB8/(W8+AB25)-1-AB20 -> 0.02006973 | AC35: =AC8/(X8+AC25)-1-AC20 -> -0.079655255 | ... AL35: =AL8/(AG8+AL25)-1-AL20 -> 0.049853115 | AM35: 0.05 | AN35: 0.035 | AO35: =SUMPRODUCT(AK35:AN35,AF$44:AI$44) -> 0.036496725 | AP35: 0.01 | AQ35: 0.01 | AR35: 0.01 | AS35: 0.01 | AT35: =SUMPRODUCT(AP35:AS35,AK$44:AN$44) -> 0.01 | AU35: 0.01 | AV35: 0.01 | AW35: 0.01 | AX35: 0.01 | AY35: =SUMPRODUCT(AU35:AX35,AP$44:AS$44) -> 0.01
A36: Total ANF | D36: =D9/(C9+C26)-1-D21 -> 0.013609602 | F36: =F9/(E9+F26)-1-F21 -> -0.00081810608 | V36: =V9/(Q9+V26)-1-V21 -> 0.0095801857 | W36: =W9/(R9+W26)-1-W21 -> 0.027656777 | X36: =X9/(S9+X26)-1-X21 -> 0.030987587 | Y36: =Y9/(T9+Y26)-1-Y21 -> 0.045630897 | Z36: =Z9/(U9+Z26)-1-Z21 -> 0.025612025 | AA36: =AA9/(V9+AA26)-1-AA21 -> 0.011782934 | AB36: =AB9/(W9+AB26)-1-AB21 -> 0.035438785 | AC36: =AC9/(X9+AC26)-1-AC21 -> -0.021313717 | ... AL36: =AL9/(AG9+AL26)-1-AL21 -> 0.04790438 | AM36: =AM34*AH$39+AM35*AH$40 -> 0.054783325 | AN36: =AN34*AI$39+AN35*AI$40 -> 0.042244889 | AO36: =SUMPRODUCT(AK36:AN36,AF$45:AI$45) -> 0.040930096 | AP36: =AP34*AK$39+AP35*AK$40 -> 0.020140211 | AQ36: =AQ34*AL$39+AQ35*AL$40 -> 0.014711559 | AR36: =AR34*AM$39+AR35*AM$40 -> 0.014877564 | AS36: =AS34*AN$39+AS35*AN$40 -> 0.014829926 | AT36: =SUMPRODUCT(AP36:AS36,AK$45:AN$45) -> 0.015883368 | AU36: =AU34*AP$39+AU35*AP$40 -> 0.01 | AV36: =AV34*AQ$39+AV35*AQ$40 -> 0.01 | AW36: =AW34*AR$39+AW35*AR$40 -> 0.01 | AX36: =AX34*AS$39+AX35*AS$40 -> 0.01 | AY36: =SUMPRODUCT(AU36:AX36,AP$45:AS$45) -> 0.01
A38: Sales Weights
A39: Abercrombie | B39: =B7/B$9 -> 0.4663658 | C39: =C7/C$9 -> 0.44699135 | D39: =D7/D$9 -> 0.41632438 | E39: =E7/E$9 -> 0.40042545 | F39: =F7/F$9 -> 0.40423116 | G39: =G7/G$9 -> 0.43750502 | H39: =H7/H$9 -> 0.38532037 | I39: =I7/I$9 -> 0.41845513 | ... AY39: =AY7/AY$9 -> 0.48626885
A40: Hollister | B40: =B8/B$9 -> 0.5336342 | C40: =C8/C$9 -> 0.55300865 | D40: =D8/D$9 -> 0.58367562 | E40: =E8/E$9 -> 0.59957455 | F40: =F8/F$9 -> 0.59576884 | G40: =G8/G$9 -> 0.56249498 | H40: =H8/H$9 -> 0.61467963 | I40: =I8/I$9 -> 0.58154487 | ... AY40: =AY8/AY$9 -> 0.51373115
A42: Seasonality
A43: Abercrombie | G43: =G7/K7 -> 0.16447811 | H43: =H7/K7 -> 0.20842193 | I43: =I7/K7 -> 0.26566902 | J43: =J7/K7 -> 0.36143094 | K43: =SUM(G43:J43) -> 1 | L43: =L7/P7 -> 0.21664071 | M43: =M7/P7 -> 0.22390687 | N43: =N7/P7 -> 0.24466494 | O43: =O7/P7 -> 0.31478749 | P43: =SUM(L43:O43) -> 1 | Q43: =Q7/U7 -> 0.22130264 | R43: =R7/U7 -> 0.21221197 | S43: =S7/U7 -> 0.24343937 | T43: =T7/U7 -> 0.32304602 | U43: =SUM(Q43:T43) -> 1 | V43: =V7/Z7 -> 0.19805004 | W43: =W7/Z7 -> 0.21016212 | X43: =X7/Z7 -> 0.24877662 | Y43: =Y7/Z7 -> 0.34301122 | Z43: =SUM(V43:Y43) -> 1 | AA43: =AA7/AE7 -> 0.22355868 | AB43: =AB7/AE7 -> 0.2278236 | AC43: =AC7/AE7 -> 0.24637249 | AD43: =AD7/AE7 -> 0.30224524 | AE43: =SUM(AA43:AD43) -> 1 | AF43: =AF7/AJ7 -> 0.21712377 | AG43: =AG7/AJ7 -> 0.21867746 | AH43: =AH7/AJ7 -> 0.2446227 | AI43: =AI7/AJ7 -> 0.31957608 | AJ43: =SUM(AF43:AI43) -> 1 | AK43: =AK7/$AO7 -> 0.2098378 | AL43: =AL7/$AO7 -> 0.2217614 | AM43: =AM7/$AO7 -> 0.24774393 | AN43: =AN7/$AO7 -> 0.32065687 | AO43: =SUM(AK43:AN43) -> 1 | AP43: =AP7/$AT7 -> 0.21142888 | AQ43: =AQ7/$AT7 -> 0.22131486 | AR43: =AR7/$AT7 -> 0.24724507 | AS43: =AS7/$AT7 -> 0.32001119 | AT43: =SUM(AP43:AS43) -> 1 | AU43: =AU7/$AT7 -> 0.2167146 | AV43: =AV7/$AT7 -> 0.22684773 | AW43: =AW7/$AT7 -> 0.25342619 | AX43: =AX7/$AT7 -> 0.32801147 | AY43: =SUM(AU43:AX43) -> 1.025
A44: Hollister | G44: =G8/K8 -> 0.14883318 | H44: =H8/K8 -> 0.23400563 | I44: =I8/K8 -> 0.25985513 | J44: =J8/K8 -> 0.35730605 | K44: =SUM(G44:J44) -> 1 | L44: =L8/P8 -> 0.20596477 | M44: =M8/P8 -> 0.23951957 | N44: =N8/P8 -> 0.24316392 | O44: =O8/P8 -> 0.31135174 | P44: =SUM(L44:O44) -> 1 | Q44: =Q8/U8 -> 0.21847006 | R44: =R8/U8 -> 0.22259661 | S44: =S8/U8 -> 0.23320237 | T44: =T8/U8 -> 0.32573096 | U44: =SUM(Q44:T44) -> 1 | V44: =V8/Z8 -> 0.19237698 | W44: =W8/Z8 -> 0.22733817 | X44: =X8/Z8 -> 0.24468745 | Y44: =Y8/Z8 -> 0.33559741 | Z44: =SUM(V44:Y44) -> 1 | AA44: =AA8/AE8 -> 0.18778774 | AB44: =AB8/AE8 -> 0.2305697 | AC44: =AC8/AE8 -> 0.24209614 | AD44: =AD8/AE8 -> 0.33954643 | AE44: =SUM(AA44:AD44) -> 1 | AF44: =AF8/AJ8 -> 0.20030555 | AG44: =AG8/AJ8 -> 0.23943879 | AH44: =AH8/AJ8 -> 0.24548481 | AI44: =AI8/AJ8 -> 0.31477086 | AJ44: =SUM(AF44:AI44) -> 1 | AK44: =AK8/$AO8 -> 0.19314726 | AL44: =AL8/$AO8 -> 0.23563141 | AM44: =AM8/$AO8 -> 0.2462979 | AN44: =AN8/$AO8 -> 0.32492344 | AO44: =SUM(AK44:AN44) -> 1 | AP44: =AP8/$AT8 -> 0.19421398 | AQ44: =AQ8/$AT8 -> 0.23693277 | AR44: =AR8/$AT8 -> 0.24527683 | AS44: =AS8/$AT8 -> 0.32357642 | AT44: =SUM(AP44:AS44) -> 1 | AU44: =AU8/$AT8 -> 0.2000404 | AV44: =AV8/$AT8 -> 0.24404075 | AW44: =AW8/$AT8 -> 0.25386152 | AX44: =AX8/$AT8 -> 0.3349016 | AY44: =SUM(AU44:AX44) -> 1.0328443
A45: Total | G45: =G9/K9 -> 0.1552958 | H45: =H9/K9 -> 0.2234375 | I45: =I9/K9 -> 0.26225673 | J45: =J9/K9 -> 0.35900996 | K45: =SUM(G45:J45) -> 1 | L45: =L9/P9 -> 0.21046427 | M45: =M9/P9 -> 0.23293941 | N45: =N9/P9 -> 0.24379654 | O45: =O9/P9 -> 0.31279978 | P45: =SUM(L45:O45) -> 1 | Q45: =Q9/U9 -> 0.21979901 | R45: =R9/U9 -> 0.2177245 | S45: =S9/U9 -> 0.23800521 | T45: =T9/U9 -> 0.32447128 | U45: =SUM(Q45:T45) -> 1 | V45: =V9/Z9 -> 0.19529481 | W45: =W9/Z9 -> 0.21850399 | X45: =X9/Z9 -> 0.24679064 | Y45: =Y9/Z9 -> 0.33941057 | Z45: =SUM(V45:Y45) -> 1 | AA45: =AA9/AE9 -> 0.20626696 | AB45: =AB9/AE9 -> 0.22915107 | AC45: =AC9/AE9 -> 0.24430529 | AD45: =AD9/AE9 -> 0.32027668 | AE45: =SUM(AA45:AD45) -> 1 | AF45: =AF9/AJ9 -> 0.20836501 | AG45: =AG9/AJ9 -> 0.22948974 | AH45: =AH9/AJ9 -> 0.24507167 | AI45: =AI9/AJ9 -> 0.31707357 | AJ45: =SUM(AF45:AI45) -> 1 | AK45: =AK9/$AO9 -> 0.20126377 | AL45: =AL9/$AO9 -> 0.22888651 | AM45: =AM9/$AO9 -> 0.24700109 | AN45: =AN9/$AO9 -> 0.32284863 | AO45: =SUM(AK45:AN45) -> 1 | AP45: =AP9/$AT9 -> 0.20261784 | AQ45: =AQ9/$AT9 -> 0.22930852 | AR45: =AR9/$AT9 -> 0.24623767 | AS45: =AS9/$AT9 -> 0.32183597 | AT45: =SUM(AP45:AS45) -> 1 | AU45: =AU9/$AT9 -> 0.2081803 | AV45: =AV9/$AT9 -> 0.23564757 | AW45: =AW9/$AT9 -> 0.25364901 | AX45: =AX9/$AT9 -> 0.33153802 | AY45: =SUM(AU45:AX45) -> 1.0290149
A48: Segments by Geography (NON-DRIVER)
A49: Americas | G49: =322862+17508 -> 340370 | H49: =458671+26546 -> 485217 | I49: =557814+28007 -> 585821 | J49: =788056+39834 -> 827890 | K49: =SUM(G49:J49) -> 2239298 | L49: =553846+22511 -> 576357 | M49: =601767+31015 -> 632782 | N49: =654858+32931 -> 687789 | O49: =841687+47380 -> 889067 | P49: =SUM(L49:O49) -> 2785995 | Q49: =585106+33790 -> 618896 | R49: 613244 | S49: 713860 | T49: 971091 | U49: =SUM(Q49:T49) -> 2917091 | V49: 665423 | W49: 731427 | X49: 867566 | Y49: 1191259 | Z49: =SUM(V49:Y49) -> 3455675 | AA49: 820121 | AB49: 901224 | AC49: 986449 | AD49: 1319720 | AE49: =SUM(AA49:AD49) -> 4027514 | AF49: 874804 | AG49: 974200 | AH49: 1057448 | AI49: 1383943 | AJ49: =SUM(AF49:AI49) -> 4290395 | AK49: 899944 | AL49: 1020537 | AM49: =(1+AM65)*AH49 -> 1119060.2 | AN49: =(1+AN65)*AI49 -> 1496734.4 | AO49: =SUM(AK49:AN49) -> 4536275.6 | AP49: =(1+AP65)*AK49 -> 936301.74 | AQ49: =(1+AQ65)*AL49 -> 1056562 | AR49: =(1+AR65)*AM49 -> 1158563 | AS49: =(1+AS65)*AN49 -> 1549569.1 | AT49: =SUM(AP49:AS49) -> 4700995.8 | AU49: =(1+AU65)*AP49 -> 964578.05 | AV49: =(1+AV65)*AQ49 -> 1088470.1 | AW49: =(1+AW65)*AR49 -> 1193551.6 | AX49: =(1+AX65)*AS49 -> 1596366.1 | AY49: =SUM(AU49:AX49) -> 4842965.9
A50: EMEA | G50: 112654 | H50: 171297 | I50: 190214 | J50: 235286 | K50: =SUM(G50:J50) -> 709451 | L50: 159002 | M50: 190840 | N50: 179156 | O50: 226074 | P50: =SUM(L50:O50) -> 755072 | Q50: 163969 | R50: 164827 | S50: 138840 | T50: 193400 | U50: =SUM(Q50:T50) -> 661036 | V50: 138106 | W50: 171962 | X50: 157976 | Y50: 219050 | Z50: =SUM(V50:Y50) -> 687094 | AA50: 164778 | AB50: 199682 | AC50: 181592 | AD50: 224467 | AE50: =SUM(AA50:AD50) -> 770519 | AF50: 185036 | AG50: 197210 | AH50: 194510 | AI50: 241384 | AJ50: =SUM(AF50:AI50) -> 818140 | AK50: 167373 | AL50: 201990 | AM50: =(1+AM71)*AH50 -> 199995.18 | AN50: =(1+AN71)*AI50 -> 231825.19 | AO50: =SUM(AK50:AN50) -> 801183.38 | AP50: =(1+AP71)*AK50 -> 177499.07 | AQ50: =(1+AQ71)*AL50 -> 214210.39 | AR50: =(1+AR71)*AM50 -> 204015.09 | AS50: =(1+AS71)*AN50 -> 236484.88 | AT50: =SUM(AP50:AS50) -> 832209.43 | AU50: =(1+AU71)*AP50 -> 181066.8 | AV50: =(1+AV71)*AQ50 -> 218516.02 | AW50: =(1+AW71)*AR50 -> 208115.79 | AX50: =(1+AX71)*AS50 -> 241238.23 | AY50: =SUM(AU50:AX50) -> 848936.84
...

Sheet IS
A1: ANF P&L | AE1: 0.44
U2: Old Opex <-| | V2: |-> New Opex
A3: Period | B3: ='Rev Driver'!B3 -> FY15 | C3: ='Rev Driver'!C3 -> FY16 | D3: ='Rev Driver'!D3 -> FY17 | E3: ='Rev Driver'!E3 -> FY18 | F3: ='Rev Driver'!F3 -> FY19 | G3: ='Rev Driver'!G3 -> 1Q20 | H3: ='Rev Driver'!H3 -> 2Q20 | I3: ='Rev Driver'!I3 -> 3Q20 | ... AY3: ='Rev Driver'!AY3 -> FY28E
A4: Date end | B4: ='Rev Driver'!B4 -> 42399 | C4: ='Rev Driver'!C4 -> 42763 | D4: ='Rev Driver'!D4 -> 43134 | E4: ='Rev Driver'!E4 -> 43498 | F4: ='Rev Driver'!F4 -> 43862 | G4: ='Rev Driver'!G4 -> 43953 | H4: ='Rev Driver'!H4 -> 44044 | I4: 44135 | J4: ='Rev Driver'!J4 -> 44226 | K4: ='Rev Driver'!K4 -> 44226 | L4: ='Rev Driver'!L4 -> 44317 | M4: ='Rev Driver'!M4 -> 44408 | N4: ='Rev Driver'!N4 -> 44500 | O4: ='Rev Driver'!O4 -> 44590 | P4: ='Rev Driver'!P4 -> 44590 | Q4: ='Rev Driver'!Q4 -> 44681 | ... AY4: ='Rev Driver'!AY4 -> 47145
A5: # Weeks | B5: ='Rev Driver'!B5 -> 52 | C5: ='Rev Driver'!C5 -> 52 | D5: ='Rev Driver'!D5 -> 53 | E5: ='Rev Driver'!E5 -> 52 | F5: ='Rev Driver'!F5 -> 52 | G5: ='Rev Driver'!G5 -> 13 | H5: ='Rev Driver'!H5 -> 13 | I5: ='Rev Driver'!I5 -> 13 | ... AY5: ='Rev Driver'!AY5 -> 52
A6: Net Sales | B6: ='Rev Driver'!B9 -> 3518680 | C6: ='Rev Driver'!C9 -> 3326740 | D6: ='Rev Driver'!D9 -> 3492690 | E6: ='Rev Driver'!E9 -> 3590109 | F6: ='Rev Driver'!F9 -> 3623073 | G6: ='Rev Driver'!G9 -> 485359 | H6: ='Rev Driver'!H9 -> 698328 | I6: ='Rev Driver'!I9 -> 819653 | ... AY6: ='Rev Driver'!AY9 -> 5911596.9
A7: COGS | B7: =1361137-20647 -> 1340490 | C7: 1298172 | D7: 1408848 | E7: 1430193 | F7: 1472155 | G7: 221214 | H7: 274720 | I7: 295220 | J7: 443025 | K7: =SUM(G7:J7) -> 1234179 | L7: 286271 | M7: 301365 | N7: 328916 | O7: 484221 | P7: =SUM(L7:O7) -> 1400773 | Q7: 363216 | R7: 339200 | S7: 359268 | T7: 531529 | U7: =SUM(Q7:T7) -> 1593213 | V7: 326200 | W7: 350965 | X7: 370762 | Y7: 539338 | Z7: =SUM(V7:Y7) -> 1587265 | AA7: 343273 | AB7: 397712 | AC7: 422034 | AD7: 610907 | AE7: =SUM(AA7:AD7) -> 1773926 | AF7: 417133 | AG7: =451590 -> 451590 | AH7: 483670 | AI7: 676491 | AJ7: =SUM(AF7:AI7) -> 2028884 | AK7: 413838 | AL7: =366109+100000 -> 466109 | AM7: =AM6-AM8 -> 494500.81 | AN7: =AN6-AN8 -> 693471.67 | AO7: =SUM(AK7:AN7) -> 2067919.5 | AP7: =AP6-AP8 -> 431325.7 | AQ7: =AQ6-AQ8 -> 483436 | AR7: =AR6-AR8 -> 510333.19 | AS7: =AS6-AS8 -> 715776.32 | AT7: =SUM(AP7:AS7) -> 2140871.2 | AU7: =AU6-AU8 -> 440774.93 | AV7: =AV6-AV8 -> 496800.21 | AW7: =AW6-AW8 -> 525693.34 | AX7: =AX6-AX8 -> 733544.76 | AY7: =SUM(AU7:AX7) -> 2196813.2
A8: Adj. Gross Profit | B8: =B6-B7 -> 2178190 | C8: =C6-C7 -> 2028568 | D8: =D6-D7 -> 2083842 | E8: =E6-E7 -> 2159916 | F8: =F6-F7 -> 2150918 | G8: =G6-G7 -> 264145 | H8: =H6-H7 -> 423608 | I8: =I6-I7 -> 524433 | ... AL8: =AL6-AL7 -> 800580 | AM8: =AM$6*AM26 -> 872436.75 | AN8: =AN$6*AN26 -> 1093216.5 | AO8: =AO6-AO7 -> 3466216.2 | AP8: =AP$6*AP26 -> 732695.33 | AQ8: =AQ$6*AQ26 -> 833920.56 | AR8: =AR$6*AR26 -> 904279.83 | AS8: =AS$6*AS26 -> 1133142 | AT8: =AT6-AT7 -> 3604037.7 | AU8: =AU$6*AU26 -> 755201.96 | AV8: =AV$6*AV26 -> 856973.64 | AW8: =AW$6*AW26 -> 931497.11 | AX8: =AX$6*AX26 -> 1171111 | AY8: =AY6-AY7 -> 3714783.7
A9: Selling Exp. | B9: =1604214-6665 -> 1597549 | C9: 1578460 | D9: 1542425 | E9: 1542022 | F9: 1551243 | G9: 322124 | H9: 310370 | I9: 346263 | J9: 412827 | K9: =SUM(G9:J9) -> 1391584 | L9: 316608 | M9: 325847 | N9: 351815 | O9: 435153 | P9: =SUM(L9:O9) -> 1429423 | Q9: 337543 | R9: 340791 | S9: 367333 | T9: 437264 | U9: =SUM(Q9:T9) -> 1482931 | V9: =324251-4436 -> 319815 | W9: 338296 | X9: 371969 | Y9: 498922 | Z9: =SUM(V9:Y9) -> 1529002 | AA9: 360018 | AB9: 382557 | AC9: 420990 | AD9: 526423 | AE9: =SUM(AA9:AD9) -> 1689988 | AF9: 399937 | AG9: =375356+42874 -> 418230 | AH9: 459548 | AI9: 574792 | AJ9: =SUM(AF9:AI9) -> 1852507 | AK9: 431195 | AL9: 444042 | AM9: =AM$6*AM29 -> 493557.28 | AN9: =AN$6*AN29 -> 609667.38 | AO9: =SUM(AK9:AN9) -> 1978461.7 | AP9: =AP$6*AP29 -> 442480.86 | AQ9: =AQ$6*AQ29 -> 464438.39 | AR9: =AR$6*AR29 -> 513600.58 | AS9: =AS$6*AS29 -> 634599.88 | AT9: =SUM(AP9:AS9) -> 2055119.7 | AU9: =AU$6*AU29 -> 455824.26 | AV9: =AV$6*AV29 -> 478631.2 | AW9: =AW$6*AW29 -> 530516.27 | AX9: =AX$6*AX29 -> 655635.15 | AY9: =SUM(AU9:AX9) -> 2120606.9
A10: G&A Exp. | B10: =470321-17523 -> 452798 | C10: =453202+6000 -> 459202 | D10: =471914-15070 -> 456844 | E10: =484863-2595 -> 482268 | F10: 464615 | G10: 108257 | H10: 97252 | I10: 121000 | J10: 137334 | K10: =SUM(G10:J10) -> 463843 | L10: 120947 | M10: 123913 | N10: 146269 | O10: 145686 | P10: =SUM(L10:O10) -> 536815 | Q10: 122149 | R10: 124168 | S10: 133201 | T10: 138084 | U10: =SUM(Q10:T10) -> 517602 | V10: =154429 -> 154429 | W10: 158936 | X10: 174424 | Y10: 193387 | Z10: =SUM(V10:Y10) -> 681176 | AA10: 189548 | AB10: 178147 | AC10: 188246 | AD10: 194544 | AE10: =SUM(AA10:AD10) -> 750485 | AF10: 174925 | AG10: =175325-4300 -> 171025 | AH10: 193402 | AI10: 181819 | AJ10: =SUM(AF10:AI10) -> 721171 | AK10: 182754 | AL10: 204784 | AM10: =AM$6*AM36 -> 210306.25 | AN10: =AN$6*AN36 -> 196333.02 | AO10: =SUM(AK10:AN10) -> 794177.27 | AP10: =AP$6*AP36 -> 187498.68 | AQ10: =AQ$6*AQ36 -> 209023.29 | AR10: =AR$6*AR36 -> 217641.22 | AS10: =AS$6*AS36 -> 203171.28 | AT10: =SUM(AP10:AS10) -> 817334.47 | AU10: =AU$6*AU36 -> 191450.1 | AV10: =AV$6*AV36 -> 213447.8 | AW10: =AW$6*AW36 -> 222734.66 | AX10: =AX$6*AX36 -> 207391.42 | AY10: =SUM(AU10:AX10) -> 835023.98
A11: Other Loss/(Inc.) | B11: =-6441-2211 -> -8652 | C11: =(-26212+12282)+1574 -> -12356 | D11: =-16938+(14391-13661) -> -16208 | E11: =-5915+(11580-8671) -> -3006 | F11: =-1400+(19135-12752)+47257 -> 52240 | G11: =-543+506 -> -37 | H11: =-3884-2356 -> -6240 | I11: =-8063+288 -> -7775 | J11: =854-3492 -> -2638 | K11: =SUM(G11:J11) -> -16690 | L11: =-1418-1100 -> -2518 | M11: -1848 | N11: -1320 | O11: -3741 | P11: =SUM(L11:O11) -> -9427 | Q11: -3842 | R11: 953 | S11: -1005 | T11: 1220 | U11: =SUM(Q11:T11) -> -2674 | V11: -2894 | W11: -2694 | X11: 1256 | Y11: -1541 | Z11: =SUM(V11:Y11) -> -5873 | AA11: -1958 | AB11: -67 | AC11: -1586 | AD11: -3021 | AE11: =SUM(AA11:AD11) -> -6632 | AF11: 3783 | AG11: =-369 -> -369 | AH11: -1022 | AI11: 769 | AJ11: =SUM(AF11:AI11) -> 3161 | AK11: -2763 | AL11: -946 | AM11: -750 | AN11: -750 | AO11: =SUM(AK11:AN11) -> -5209 | AP11: -1000 | AQ11: -1000 | AR11: -1000 | AS11: -1000 | AT11: =SUM(AP11:AS11) -> -4000 | AU11: -1000 | AV11: -1000 | AW11: -1000 | AX11: -1000 | AY11: =SUM(AU11:AX11) -> -4000
A12: Adj. Operating Income | B12: =B6-B7-B9-B10-B11 -> 136495 | C12: =C6-C7-C9-C10-C11 -> 3262 | D12: =D6-D7-D9-D10-D11 -> 100781 | E12: =E6-E7-E9-E10-E11 -> 138632 | F12: =F6-F7-F9-F10-F11 -> 82820 | G12: =G6-G7-G9-G10-G11 -> -166199 | H12: =H6-H7-H9-H10-H11 -> 22226 | I12: =I6-I7-I9-I10-I11 -> 64945 | ... AY12: =AY6-AY7-AY9-AY10-AY11 -> 763152.83
A13: Interest Exp. Net | B13: 18248 | C13: 18666 | D13: 16889 | E13: 10999 | F13: 7737 | G13: 3371 | H13: 7098 | I13: 8808 | J13: 8997 | K13: =SUM(G13:J13) -> 28274 | L13: 8606 | M13: 11275 | N13: 7270 | O13: 6959 | P13: =SUM(L13:O13) -> 34110 | Q13: 7307 | R13: 6917 | S13: 7295 | T13: 4113 | U13: =SUM(Q13:T13) -> 25632 | V13: =7458-4015 -> 3443 | W13: =7635-6538 -> 1097 | X13: =8568-7897 -> 671 | Y13: =6691-11530 -> -4839 | Z13: =SUM(V13:Y13) -> 372 | AA13: =-10803+5780 -> -5023 | AB13: =-10392+5189 -> -5203 | AC13: =-9302+569 -> -8733 | AD13: =-9437+539 -> -8898 | AE13: =SUM(AA13:AD13) -> -27857 | AF13: =-7444+661 -> -6783 | AG13: =620-3094 -> -2474 | AH13: =-6491+550 -> -5941 | AI13: =544-6975 -> -6431 | AJ13: =SUM(AF13:AI13) -> -21629 | AK13: =450-5737 -> -5287 | AL13: =561-8152+3084 -> -4507 | AM13: -4500 | AN13: -5500 | AO13: =SUM(AK13:AN13) -> -19794 | AP13: -4500 | AQ13: -4500 | AR13: -4500 | AS13: -5000 | AT13: =SUM(AP13:AS13) -> -18500 | AU13: -4500 | AV13: -4500 | AW13: -4500 | AX13: -5000 | AY13: =SUM(AU13:AX13) -> -18500
A14: Adj. Pre-Tax Income | B14: =B12-B13 -> 118247 | C14: =C12-C13 -> -15404 | D14: =D12-D13 -> 83892 | E14: =E12-E13 -> 127633 | F14: =F12-F13 -> 75083 | G14: =G12-G13 -> -169570 | H14: =H12-H13 -> 15128 | I14: =I12-I13 -> 56137 | ... AY14: =AY12-AY13 -> 781652.83
A15: Tax | B15: =16031+21186 -> 37217 | C15: =-11196-3900 -> -15096 | D15: =44636-9180 -> 35456 | E15: =37559+6018 -> 43577 | F15: =17371+4013 -> 21384 | G15: 35965 | H15: 87 | I15: 6148 | J15: 22310 | K15: =SUM(G15:J15) -> 64510 | L15: =6121+449 -> 6570 | M15: =-6944+224 -> -6720 | N15: 17758 | O15: 23721 | P15: =SUM(L15:O15) -> 41329 | Q15: =-2187--918 -> -1269 | R15: =4976-Q15 -> 6245 | S15: =-SUM(Q15:R15)+16918 -> 11942 | T15: 43515 | U15: =SUM(Q15:T15) -> 60433 | V15: 13905 | W15: =-V15+43939 -> 30034 | X15: =-SUM(V15:W15)+83556 -> 39617 | Y15: =-SUM(V15:X15)+150117 -> 66561 | Z15: =SUM(V15:Y15) -> 150117 | AA15: 19794 | AB15: 45449 | AC15: 54151 | AD15: 75267 | AE15: =SUM(AA15:AD15) -> 194661 | AF15: 26577 | AG15: =65744-9692 -> 56052 | AH15: 45862 | AI15: 67594 | AJ15: =SUM(AF15:AI15) -> 196085 | AK15: 25965 | AL15: =74752-(100000+3084-AL21) -> 48757.25 | AM15: =AM$14*AM45 -> 50408.734 | AN15: =AN$14*AN45 -> 82170.501 | AO15: =SUM(AK15:AN15) -> 207301.48 | AP15: =AP$14*AP45 -> 32464.738 | AQ15: =AQ$14*AQ45 -> 49787.662 | AR15: =AR$14*AR45 -> 53561.409 | AS15: =AS$14*AS45 -> 90411.261 | AT15: =SUM(AP15:AS15) -> 226225.07 | AU15: =AU$14*AU45 -> 34028.281 | AV15: =AV$14*AV45 -> 51118.39 | AW15: =AW$14*AW45 -> 55123.854 | AX15: =AX$14*AX45 -> 94225.325 | AY15: =SUM(AU15:AX15) -> 234495.85
A16: NCI | B16: 2983 | C16: 3762 | D16: 3431 | E16: 4267 | F16: 5602 | G16: 117 | H16: 328 | I16: 1758 | J16: 2864 | K16: =SUM(G16:J16) -> 5067 | L16: 938 | M16: 1956 | N16: 1845 | O16: 2317 | P16: =SUM(L16:O16) -> 7056 | Q16: 1623 | R16: 2092 | S16: 1496 | T16: 2358 | U16: =SUM(Q16:T16) -> 7569 | V16: 1276 | W16: =-V16+3113 -> 1837 | X16: 1521 | Y16: 2656 | Z16: =SUM(V16:Y16) -> 7290 | AA16: 1228 | AB16: 2211 | AC16: 1885 | AD16: 2469 | AE16: =SUM(AA16:AD16) -> 7793 | AF16: 1326 | AG16: =2005 -> 2005 | AH16: 2105 | AI16: 2638 | AJ16: =SUM(AF16:AI16) -> 8074 | AK16: 985 | AL16: 1819 | AM16: =AM$14*AM46 -> 1738.2322 | AN16: =AN$14*AN46 -> 2934.6607 | AO16: =SUM(AK16:AN16) -> 7476.8929 | AP16: =AP$14*AP46 -> 1082.1579 | AQ16: =AQ$14*AQ46 -> 1825.5476 | AR16: =AR$14*AR46 -> 1963.9183 | AS16: =AS$14*AS46 -> 3013.7087 | AT16: =SUM(AP16:AS16) -> 7885.3326 | AU16: =AU$14*AU46 -> 1247.7036 | AV16: =AV$14*AV46 -> 1874.341 | AW16: =AW$14*AW46 -> 2021.208 | AX16: =AX$14*AX46 -> 3140.8442 | AY16: =SUM(AU16:AX16) -> 8284.0967
A17: Adj. Net Income | B17: =B14-B15-B16 -> 78047 | C17: =C14-C15-C16 -> -4070 | D17: =D14-D15-D16 -> 45005 | E17: =E14-E15-E16 -> 79789 | F17: =F14-F15-F16 -> 48097 | G17: =G14-G15-G16 -> -205652 | H17: =H14-H15-H16 -> 14713 | I17: =I14-I15-I16 -> 48231 | ... AY17: =AY14-AY15-AY16 -> 538872.88
A18: Diluted EPS | B18: =B17/B19 -> 1.1243211 | C18: =C17/C19 -> -0.059960517 | D18: =D17/D19 -> 0.648459 | E18: =E17/E19 -> 1.1540709 | F18: =F17/F19 -> 0.73120192 | G18: =G17/G19 -> -3.2882749 | H18: =H17/H19 -> 0.23248428 | I18: =I17/I19 -> 0.75506051 | ... AY18: =AY17/AY19 -> 13.448709
A19: Diluted Shares Out | B19: 69417 | C19: 67878 | D19: 69403 | E19: 69137 | F19: 65778 | G19: 62541 | H19: 63286 | I19: 63877 | J19: 64788 | K19: 62636 | L19: 65305 | M19: 64136 | N19: 61465 | O19: 58700 | P19: 62636 | Q19: 52077 | R19: 50441 | S19: 49486 | T19: 51217 | U19: 52327 | V19: 51467 | W19: 51548 | X19: 52624 | Y19: 53399 | Z19: 52726 | AA19: 53276 | AB19: 53279 | AC19: 52869 | AD19: 52461 | AE19: 52971 | AF19: 50634 | AG19: 48551 | AH19: 47881 | AI19: 46837 | AJ19: 48476 | AK19: 45677 | AL19: 44051 | AM19: =SCF!AM61 -> 43434.333 | AN19: =SCF!AN61 -> 42826.743 | AO19: =AVERAGE(AK19:AN19) -> 43997.269 | AP19: =SCF!AP61 -> 42398.212 | AQ19: =SCF!AQ61 -> 41976.152 | AR19: =SCF!AR61 -> 41560.498 | AS19: =SCF!AS61 -> 41151.188 | AT19: =AVERAGE(AP19:AS19) -> 41771.512 | AU19: =SCF!AU61 -> 40712.409 | AV19: =SCF!AV61 -> 40279.461 | AW19: =SCF!AW61 -> 39852.284 | AX19: =SCF!AX61 -> 39430.821 | AY19: =AVERAGE(AU19:AX19) -> 40068.744
A21: Adj. to Net Income | B21: -42471 | C21: 8026 | D21: -37911 | E21: -5248 | F21: -8739 | G21: -38496 | H21: -9249 | I21: -5960 | J21: -14933 | K21: =SUM(G21:J21) -> -68638 | L21: -2215 | M21: -562 | N21: -5374 | O21: -1528 | P21: =SUM(L21:O21) -> -9679 | Q21: -2504 | R21: =-16834-R17 -> -1559 | S21: =-2214-S17 -> -2768 | T21: -3398 | U21: =SUM(Q21:T21) -> -10229 | V21: -3249 | W21: =-V21-3229 -> 20 | X21: =-SUM(V21:W21)-3229 -> 0 | Y21: =-SUM(V21:X21)-3205 -> 24 | Z21: =SUM(V21:Y21) -> -3205 | AA21: 0 | AB21: 0 | AC21: 0 | AD21: 0 | AE21: =SUM(AA21:AD21) -> 0 | AF21: 0 | AG21: 28882 | AH21: 0 | AI21: 0 | AJ21: =SUM(AF21:AI21) -> 28882 | AK21: 0 | AL21: =1.75*AL19 -> 77089.25 | AM21: =0.35*AM19 -> 15202.017 | AN21: 0 | AO21: =SUM(AK21:AN21) -> 92291.267 | AP21: 0 | AQ21: 0 | AR21: 0 | AS21: 0 | AT21: =SUM(AP21:AS21) -> 0 | AU21: 0 | AV21: 0 | AW21: 0 | AX21: 0 | AY21: =SUM(AU21:AX21) -> 0
A22: GAAP Net Income | B22: =B21+B17 -> 35576 | C22: =C21+C17 -> 3956 | D22: =D21+D17 -> 7094 | E22: =E21+E17 -> 74541 | F22: =F21+F17 -> 39358 | G22: =G21+G17 -> -244148 | H22: =H21+H17 -> 5464 | I22: =I21+I17 -> 42271 | ... AY22: =AY21+AY17 -> 538872.88
A23: GAAP EPS | B23: =B22/B19 -> 0.51249694 | C23: =C22/68284 -> 0.057934509 | D23: =D22/D19 -> 0.1022146 | E23: =E22/E19 -> 1.0781636 | F23: =F22/F19 -> 0.59834595 | G23: =G22/G19 -> -3.9038071 | H23: =H22/H19 -> 0.086338211 | I23: =I22/I19 -> 0.66175619 | J23: =J22/J19 -> 1.271717 | K23: =K22/K19 -> -1.8203749 | ... AY23: =AY22/AY19 -> 13.448709
A25: Margin Analysis
A26: Gross Margin | B26: =B7/B6 -> 0.38096388 | C26: =C7/C6 -> 0.39022346 | D26: =D7/D6 -> 0.40337047 | E26: =E7/E6 -> 0.39837036 | F26: =F7/F6 -> 0.40632772 | G26: =G7/G6 -> 0.45577397 | H26: =H7/H6 -> 0.3933968 | I26: =I7/I6 -> 0.36017681 | ... P26: =P7/P6 -> 0.37728536 | Q26: =Q8/Q$6 -> 0.55310903 | R26: =R8/R$6 -> 0.57868117 | S26: =S8/S$6 -> 0.59177988 | T26: =T8/T$6 -> 0.5569905 | U26: =U8/U$6 -> 0.56914 | V26: =V8/V$6 -> 0.60980581 | W26: =W8/W$6 -> 0.62477482 | X26: =X8/X$6 -> 0.64904286 | ... AL26: =AL8/AL$6 -> 0.6320257 | AM26: =AH26+AM27/10^4 -> 0.63824184 | AN26: =AI26+AN27/10^4 -> 0.61186754 | AO26: =AO8/AO$6 -> 0.62633379 | AP26: =AK26+AP27/10^4 -> 0.62945197 | AQ26: =AL26+AQ27/10^4 -> 0.6330257 | AR26: =AM26+AR27/10^4 -> 0.63924184 | AS26: =AN26+AS27/10^4 -> 0.61286754 | AT26: =AT8/AT$6 -> 0.62734462 | AU26: =AP26+AU27/10^4 -> 0.63145197 | AV26: =AQ26+AV27/10^4 -> 0.6330257 | AW26: =AR26+AW27/10^4 -> 0.63924184 | AX26: =AS26+AX27/10^4 -> 0.61486754 | AY26: =AY8/AY$6 -> 0.6283892
A27: YoY Chg. | C27: =(ROUND(C26,3)-ROUND(B26,3))*10^4 -> 90 | D27: =(ROUND(D26,3)-ROUND(C26,3))*10^4 -> 130 | E27: =(ROUND(E26,3)-ROUND(D26,3))*10^4 -> -50 | F27: =(ROUND(F26,3)-ROUND(E26,3))*10^4 -> 80 | K27: =(ROUND(K26,3)-ROUND(F26,3))*10^4 -> -110 | L27: =(ROUND(L26,3)-ROUND(G26,3))*10^4 -> -900 | M27: =(ROUND(M26,3)-ROUND(H26,3))*10^4 -> -450 | N27: =(ROUND(N26,3)-ROUND(I26,3))*10^4 -> 30 | O27: =(ROUND(O26,3)-ROUND(J26,3))*10^4 -> 220 | P27: =(ROUND(P26,3)-ROUND(K26,3))*10^4 -> -180 | Q27: =(ROUND(Q26,3)-ROUND(L26,3))*10^4 -> 1870 | R27: =(ROUND(R26,3)-ROUND(M26,3))*10^4 -> 2310 | ... AL27: =(ROUND(AL26,3)-ROUND(AG26,3))*10^4 -> 60 | AM27: 130 | AN27: 170 | AO27: =(ROUND(AO26,3)-ROUND(AJ26,3))*10^4 -> 110 | AP27: 10 | AQ27: 10 | AR27: 10 | AS27: 10 | AT27: =(ROUND(AT26,3)-ROUND(AO26,3))*10^4 -> 10 | AU27: 20 | AV27: 0 | AW27: 0 | AX27: 20 | AY27: =(ROUND(AY26,3)-ROUND(AT26,3))*10^4 -> 10
A29: Selling Margin | B29: =B9/B$6 -> 0.45401941 | C29: =C9/C$6 -> 0.47447651 | D29: =D9/D$6 -> 0.4416152 | E29: =E9/E$6 -> 0.42951955 | F29: =F9/F$6 -> 0.42815671 | G29: =G9/G$6 -> 0.66368193 | H29: =H9/H$6 -> 0.44444731 | I29: =I9/I$6 -> 0.42245072 | ... AL29: =AL9/AL$6 -> 0.35055329 | AM29: =AH29+AM34/10^4 -> 0.3610679 | AN29: =AI29+AN34/10^4 -> 0.34122764 | AO29: =AO9/AO$6 -> 0.35750147 | AP29: =AK29+AP34/10^4 -> 0.38013133 | AQ29: =AL29+AQ34/10^4 -> 0.35255329 | AR29: =AM29+AR34/10^4 -> 0.3630679 | AS29: =AN29+AS34/10^4 -> 0.34322764 | AT29: =AT9/AT$6 -> 0.35772886 | AU29: =AP29+AU34/10^4 -> 0.38113133 | AV29: =AQ29+AV34/10^4 -> 0.35355329 | AW29: =AR29+AW34/10^4 -> 0.3640679 | AX29: =AS29+AX34/10^4 -> 0.34422764 | AY29: =AY9/AY$6 -> 0.3587198
A30: Marketing | AF30: 50 | AG30: 0 | AH30: 100 | AK30: 50 | AL30: 0
A31: Store Expense | AF31: 40 | AG31: 90 | AH31: 40 | AK31: 40 | AL31: 0
A32: Fulfillment | AF32: 30 | AG32: 0 | AH32: -80 | AK32: 30 | AL32: 80
A33: Other | AF33: =AF34-SUM(AF30:AF32) -> -10 | AG33: =AG34-SUM(AG30:AG32) -> -4.6895821e-13 | AH33: =AH34-SUM(AH30:AH32) -> 20 | AK33: =AK34-SUM(AK30:AK32) -> 110 | AL33: =AL34-SUM(AL30:AL32) -> -30
A34: YoY Chg. | C34: =(ROUND(C29,3)-ROUND(B29,3))*10^4 -> 200 | D34: =(ROUND(D29,3)-ROUND(C29,3))*10^4 -> -320 | E34: =(ROUND(E29,3)-ROUND(D29,3))*10^4 -> -120 | F34: =(ROUND(F29,3)-ROUND(E29,3))*10^4 -> -20 | K34: =(ROUND(K29,3)-ROUND(F29,3))*10^4 -> 170 | L34: =(ROUND(L29,3)-ROUND(G29,3))*10^4 -> -2590 | M34: =(ROUND(M29,3)-ROUND(H29,3))*10^4 -> -670 | N34: =(ROUND(N29,3)-ROUND(I29,3))*10^4 -> -330 | O34: =(ROUND(O29,3)-ROUND(J29,3))*10^4 -> 70 | P34: =(ROUND(P29,3)-ROUND(K29,3))*10^4 -> -600 | Q34: =(ROUND(Q29,3)-ROUND(L29,3))*10^4 -> 100 | R34: =(ROUND(R29,3)-ROUND(M29,3))*10^4 -> 460 | ... U34: =(ROUND(U29,3)-ROUND(P29,3))*10^4 -> 160 | V34: N/A | W34: N/A | X34: N/A | Y34: N/A | Z34: N/A | AA34: =(ROUND(AA29,3)-ROUND(V29,3))*10^4 -> -300 | AB34: =(ROUND(AB29,3)-ROUND(W29,3))*10^4 -> -250 | AC34: =(ROUND(AC29,3)-ROUND(X29,3))*10^4 -> -40 | AD34: =(ROUND(AD29,3)-ROUND(Y29,3))*10^4 -> -110 | AE34: =(ROUND(AE29,3)-ROUND(Z29,3))*10^4 -> -150 | AF34: =(ROUND(AF29,3)-ROUND(AA29,3))*10^4 -> 110 | AG34: =(ROUND(AG29,3)-ROUND(AB29,3))*10^4 -> 90 | AH34: =(ROUND(AH29,3)-ROUND(AC29,3))*10^4 -> 80 | ... AL34: =(ROUND(AL29,3)-ROUND(AG29,3))*10^4 -> 50 | AM34: 50 | AN34: -30 | AO34: =(ROUND(AO29,3)-ROUND(AJ29,3))*10^4 -> 60 | AP34: -70 | AQ34: 20 | AR34: 20 | AS34: 20 | AT34: =(ROUND(AT29,3)-ROUND(AO29,3))*10^4 -> 0 | AU34: 10 | AV34: 10 | AW34: 10 | AX34: 10 | AY34: =(ROUND(AY29,3)-ROUND(AT29,3))*10^4 -> 10
A36: G&A Margin | B36: =B10/B$6 -> 0.12868405 | C36: =C10/C$6 -> 0.13803363 | D36: =D10/D$6 -> 0.13080004 | E36: =E10/E$6 -> 0.13433241 | F36: =F10/F$6 -> 0.12823782 | G36: =G10/G$6 -> 0.22304521 | H36: =H10/H$6 -> 0.13926407 | I36: =I10/I$6 -> 0.14762345 | ... AL36: =AL10/AL$6 -> 0.16166873 | AM36: =AH36+AM40/10^4 -> 0.15385213 | AN36: =AI36+AN40/10^4 -> 0.10988656 | AO36: =AO10/AO$6 -> 0.1435052 | AP36: =AK36+AP40/10^4 -> 0.16107843 | AQ36: =AL36+AQ40/10^4 -> 0.15866873 | AR36: =AM36+AR40/10^4 -> 0.15385213 | AS36: =AN36+AS40/10^4 -> 0.10988656 | AT36: =AT10/AT$6 -> 0.14227109 | AU36: =AP36+AU40/10^4 -> 0.16007843 | AV36: =AQ36+AV40/10^4 -> 0.15766873 | AW36: =AR36+AW40/10^4 -> 0.15285213 | AX36: =AS36+AX40/10^4 -> 0.10888656 | AY36: =AY10/AY$6 -> 0.14125185
A37: Employee comp | AF37: -210 | AG37: -150 | AH37: -110 | AK37: -210 | AL37: 120
A38: Outside services | AF38: -60 | AG38: 0 | AH38: 40 | AK38: -60 | AL38: 70
A39: Other | AF39: =AF40-SUM(AF37:AF38) -> 0 | AG39: =AG40-SUM(AG37:AG38) -> 0 | AH39: =AH40-SUM(AH37:AH38) -> 10 | AK39: =AK40-SUM(AK37:AK38) -> 320 | AL39: =AL40-SUM(AL37:AL38) -> 10
A40: YoY Chg. | C40: =(ROUND(C36,3)-ROUND(B36,3))*10^4 -> 90 | D40: =(ROUND(D36,3)-ROUND(C36,3))*10^4 -> -70 | E40: =(ROUND(E36,3)-ROUND(D36,3))*10^4 -> 30 | F40: =(ROUND(F36,3)-ROUND(E36,3))*10^4 -> -60 | K40: =(ROUND(K36,3)-ROUND(F36,3))*10^4 -> 200 | L40: =(ROUND(L36,3)-ROUND(G36,3))*10^4 -> -680 | M40: =(ROUND(M36,3)-ROUND(H36,3))*10^4 -> 40 | N40: =(ROUND(N36,3)-ROUND(I36,3))*10^4 -> 140 | O40: =(ROUND(O36,3)-ROUND(J36,3))*10^4 -> 30 | P40: =(ROUND(P36,3)-ROUND(K36,3))*10^4 -> -30 | Q40: =(ROUND(Q36,3)-ROUND(L36,3))*10^4 -> -50 | R40: =(ROUND(R36,3)-ROUND(M36,3))*10^4 -> 110 | ... U40: =(ROUND(U36,3)-ROUND(P36,3))*10^4 -> -50 | V40: N/A | W40: N/A | X40: N/A | Y40: N/A | Z40: N/A | AA40: =(ROUND(AA36,3)-ROUND(V36,3))*10^4 -> 10 | AB40: =(ROUND(AB36,3)-ROUND(W36,3))*10^4 -> -130 | AC40: =(ROUND(AC36,3)-ROUND(X36,3))*10^4 -> -90 | AD40: =(ROUND(AD36,3)-ROUND(Y36,3))*10^4 -> -100 | AE40: =(ROUND(AE36,3)-ROUND(Z36,3))*10^4 -> -70 | AF40: =(ROUND(AF36,3)-ROUND(AA36,3))*10^4 -> -270 | AG40: =(ROUND(AG36,3)-ROUND(AB36,3))*10^4 -> -150 | AH40: =(ROUND(AH36,3)-ROUND(AC36,3))*10^4 -> -60 | ... AL40: =(ROUND(AL36,3)-ROUND(AG36,3))*10^4 -> 200 | AM40: 40 | AN40: 10 | AO40: =(ROUND(AO36,3)-ROUND(AJ36,3))*10^4 -> 70 | AP40: -30 | AQ40: -30 | AR40: 0 | AS40: 0 | AT40: =(ROUND(AT36,3)-ROUND(AO36,3))*10^4 -> -20 | AU40: -10 | AV40: -10 | AW40: -10 | AX40: -10 | AY40: =(ROUND(AY36,3)-ROUND(AT36,3))*10^4 -> -10
A42: Operating Margin | B42: =B12/B$6 -> 0.038791535 | C42: =C12/C$6 -> 0.00098053951 | D42: =D12/D$6 -> 0.028854837 | E42: =E12/E$6 -> 0.038614984 | F42: =F12/F$6 -> 0.022859048 | G42: =G12/G$6 -> -0.34242489 | H42: =H12/H$6 -> 0.031827451 | I42: =I12/I$6 -> 0.079234749 | ... AY42: =AY12/AY$6 -> 0.12909419
A43: YoY Chg. | C43: =(ROUND(C42,3)-ROUND(B42,3))*10^4 -> -380 | D43: =(ROUND(D42,3)-ROUND(C42,3))*10^4 -> 280 | E43: =(ROUND(E42,3)-ROUND(D42,3))*10^4 -> 100 | F43: =(ROUND(F42,3)-ROUND(E42,3))*10^4 -> -160 | K43: =(ROUND(K42,3)-ROUND(J42,3))*10^4 -> -1000 | L43: =(ROUND(L42,3)-ROUND(G42,3))*10^4 -> 4190 | M43: =(ROUND(M42,3)-ROUND(H42,3))*10^4 -> 1020 | N43: =(ROUND(N42,3)-ROUND(I42,3))*10^4 -> 90 | O43: =(ROUND(O42,3)-ROUND(J42,3))*10^4 -> -310 | P43: =(ROUND(P42,3)-ROUND(O42,3))*10^4 -> 100 | Q43: =(ROUND(Q42,3)-ROUND(L42,3))*10^4 -> -850 | R43: =(ROUND(R42,3)-ROUND(M42,3))*10^4 -> -1340 | S43: =(ROUND(S42,3)-ROUND(N42,3))*10^4 -> -640 | T43: =(ROUND(T42,3)-ROUND(O42,3))*10^4 -> -100 | U43: =(ROUND(U42,3)-ROUND(P42,3))*10^4 -> -670 | V43: =(ROUND(V42,3)-ROUND(Q42,3))*10^4 -> 540 | W43: =(ROUND(W42,3)-ROUND(R42,3))*10^4 -> 960 | X43: =(ROUND(X42,3)-ROUND(S42,3))*10^4 -> 1070 | ... AY43: =(ROUND(AY42,3)-ROUND(AT42,3))*10^4 -> 10
A45: Tax Rate | B45: =B15/B$14 -> 0.31473949 | C45: =C15/C$14 -> 0.98000519 | D45: =D15/D$14 -> 0.42263863 | E45: =E15/E$14 -> 0.34142424 | F45: =F15/F$14 -> 0.28480482 | G45: =G15/G$14 -> -0.2120953 | H45: =H15/H$14 -> 0.0057509254 | I45: =I15/I$14 -> 0.10951779 | ... AL45: =AL15/AL$14 -> 0.31014681 | AM45: 0.29 | AN45: 0.28 | AO45: =AO15/AO$14 -> 0.28848757 | AP45: 0.3 | AQ45: 0.3 | AR45: 0.3 | AS45: 0.3 | AT45: =AT15/AT$14 -> 0.3 | AU45: 0.3 | AV45: 0.3 | AW45: 0.3 | AX45: 0.3 | AY45: =AY15/AY$14 -> 0.3
A46: NCI % of Pretax | B46: =B16/B$14 -> 0.025226856 | C46: =C16/C$14 -> -0.24422228 | D46: =D16/D$14 -> 0.040897821 | E46: =E16/E$14 -> 0.033431793 | F46: =F16/F$14 -> 0.074610764 | G46: =G16/G$14 -> -0.00068998054 | H46: =H16/H$14 -> 0.02168165 | I46: =I16/I$14 -> 0.031316244 | ... AL46: =AL16/AL$14 -> 0.011570732 | AM46: 0.01 | AN46: 0.01 | AO46: =AO16/AO$14 -> 0.01040509 | AP46: 0.01 | AQ46: 0.011 | AR46: 0.011 | AS46: 0.01 | AT46: =AT16/AT$14 -> 0.010456842 | AU46: 0.011 | AV46: 0.011 | AW46: 0.011 | AX46: 0.01 | AY46: =AY16/AY$14 -> 0.010598179
...

Sheet BS
A1: ANF Balance Sheet
A3: Period | B3: ='Rev Driver'!B3 -> FY15 | C3: ='Rev Driver'!C3 -> FY16 | D3: ='Rev Driver'!D3 -> FY17 | E3: ='Rev Driver'!E3 -> FY18 | F3: ='Rev Driver'!F3 -> FY19 | G3: ='Rev Driver'!G3 -> 1Q20 | H3: ='Rev Driver'!H3 -> 2Q20 | I3: ='Rev Driver'!I3 -> 3Q20 | ... AY3: ='Rev Driver'!AY3 -> FY28E
A4: Date end | B4: ='Rev Driver'!B4 -> 42399 | C4: ='Rev Driver'!C4 -> 42763 | D4: ='Rev Driver'!D4 -> 43134 | E4: ='Rev Driver'!E4 -> 43498 | F4: ='Rev Driver'!F4 -> 43862 | G4: ='Rev Driver'!G4 -> 43953 | H4: ='Rev Driver'!H4 -> 44044 | I4: ='Rev Driver'!I4 -> 44135 | ... AY4: ='Rev Driver'!AY4 -> 47145
A5: # Weeks | B5: ='Rev Driver'!B5 -> 52 | C5: ='Rev Driver'!C5 -> 52 | D5: ='Rev Driver'!D5 -> 53 | E5: ='Rev Driver'!E5 -> 52 | F5: ='Rev Driver'!F5 -> 52 | G5: ='Rev Driver'!G5 -> 13 | H5: ='Rev Driver'!H5 -> 13 | I5: ='Rev Driver'!I5 -> 13 | ... AY5: ='Rev Driver'!AY5 -> 52
A6: Cash & Equiv. | B6: =SCF!B36 -> 588578 | C6: =SCF!C36 -> 547189 | D6: =SCF!D36 -> 675558 | E6: =SCF!E36 -> 723135 | F6: =SCF!F36 -> 671267 | G6: =SCF!G36 -> 703989 | H6: =SCF!H36 -> 766721 | I6: =SCF!I36 -> 812881 | ... AI6: =SCF!AI36 -> 759540 | AJ6: 759540 | AK6: =SCF!AK36 -> 594080 | AL6: =SCF!AL36 -> 627716 | AM6: =SCF!AM36 -> 676349.14 | AN6: =SCF!AN36 -> 768594.75 | AO6: =SCF!AO36 -> 768594.75 | AP6: =SCF!AP36 -> 828807.84 | AQ6: =SCF!AQ36 -> 956277.54 | AR6: =SCF!AR36 -> 850766.04 | ... AY6: =SCF!AY36 -> 1107375.1
A7: Marketable Securities | G7: 0 | H7: 0 | I7: 0 | J7: 0 | K7: =J7 -> 0 | L7: 0 | M7: 0 | N7: 0 | O7: 0 | P7: =O7 -> 0 | Q7: 0 | R7: 0 | S7: 0 | T7: 0 | U7: =T7 -> 0 | V7: 0 | W7: 0 | X7: 0 | Y7: 0 | Z7: =Y7 -> 0 | AA7: 0 | AB7: 0 | AC7: 0 | AD7: 116221 | AE7: =AD7 -> 116221 | AF7: 97006 | AG7: 30795 | AH7: 25255 | AI7: 25036 | AJ7: =AI7 -> 25036 | AK7: 25144 | AL7: 10283 | AM7: =AL7 -> 10283 | AN7: =AM7 -> 10283 | AO7: =AN7 -> 10283 | AP7: =AO7 -> 10283 | AQ7: =AP7 -> 10283 | AR7: =AQ7 -> 10283 | AS7: =AR7 -> 10283 | AT7: =AS7 -> 10283 | ... AY7: =AX7 -> 10283
A8: Receivables | B8: 56868 | C8: 93384 | D8: 79724 | E8: 73112 | F8: 80251 | G8: 88639 | H8: 88323 | I8: 89074 | J8: 83857 | K8: =J8 -> 83857 | L8: 107821 | M8: 87151 | N8: 83447 | O8: 69102 | P8: =O8 -> 69102 | Q8: 88807 | R8: 79820 | S8: 108468 | T8: 104506 | U8: =T8 -> 104506 | V8: 106149 | W8: 112597 | X8: 96762 | Y8: 78346 | Z8: =Y8 -> 78346 | AA8: 93605 | AB8: 115077 | AC8: 111583 | AD8: 105324 | AE8: =AD8 -> 105324 | AF8: 113311 | AG8: 174000 | AH8: 131741 | AI8: 146757 | AJ8: =AI8 -> 146757 | AK8: 146042 | AL8: 190347 | AM8: =AM50*2-AH8 -> 119114.57 | AN8: =AN50*2-AI8 -> 160710.43 | AO8: =AN8 -> 160710.43 | AP8: =AP50*2-AK8 -> 108507.65 | AQ8: =AQ50*2-AL8 -> 119448.94 | AR8: =AR50*2-AM8 -> 162875.32 | AS8: =AS50*2-AN8 -> 153402.51 | AT8: =AS8 -> 153402.51 | AU8: =AU50*2-AP8 -> 158287.19 | AV8: =AV50*2-AQ8 -> 139404.52 | AW8: =AW50*2-AR8 -> 175000.71 | AX8: =AX50*2-AS8 -> 164737.79 | AY8: =AX8 -> 164737.79
A9: Inventories | B9: 436701 | C9: 399795 | D9: 424393 | E9: 437879 | F9: 434326 | G9: 426594 | H9: 453239 | I9: 545548 | J9: 404053 | K9: =J9 -> 404053 | L9: 388633 | M9: 415604 | N9: 543713 | O9: 525864 | P9: =O9 -> 525864 | Q9: 562510 | R9: 708024 | S9: 741963 | T9: 505621 | U9: =T9 -> 505621 | V9: 447806 | W9: 493479 | X9: 595067 | Y9: 469466 | Z9: =Y9 -> 469466 | AA9: 449267 | AB9: 539759 | AC9: 692596 | AD9: 575005 | AE9: =AD9 -> 575005 | AF9: 542059 | AG9: 592966 | AH9: 730453 | AI9: 601218 | AJ9: =AI9 -> 601218 | AK9: 532691 | AL9: 591662 | AM9: =AM44*2-AH9 -> 748702.18 | AN9: =AN44*2-AI9 -> 646268.95 | AO9: =AN9 -> 646268.95 | AP9: =AP44*2-AK9 -> 567900.51 | AQ9: =AQ44*2-AL9 -> 688115.29 | AR9: =AR44*2-AM9 -> 765473.2 | AS9: =AS44*2-AN9 -> 692468.74 | AT9: =AS9 -> 692468.74 | AU9: =AU44*2-AP9 -> 519990.13 | AV9: =AV44*2-AQ9 -> 694190.36 | AW9: =AW44*2-AR9 -> 758459.81 | AX9: =AX44*2-AS9 -> 760111.11 | AY9: =AX9 -> 760111.11
A10: Other CA | B10: 96833 | C10: 98932 | D10: 84863 | E10: 101824 | F10: 78905 | G10: 67412 | H10: 75160 | I10: 73776 | J10: 68857 | K10: =J10 -> 68857 | L10: 78727 | M10: 77392 | N10: 111423 | O10: 89654 | P10: =O10 -> 89654 | Q10: 93179 | R10: 104887 | S10: 112602 | T10: 100289 | U10: =T10 -> 100289 | V10: 107684 | W10: 87850 | X10: 100085 | Y10: 88569 | Z10: =Y10 -> 88569 | AA10: 102516 | AB10: 123415 | AC10: 168499 | AD10: 104154 | AE10: =AD10 -> 104154 | AF10: 111231 | AG10: 118624 | AH10: 116303 | AI10: 117913 | AJ10: =AI10 -> 117913 | AK10: 117202 | AL10: 125670 | AM10: =AL10+(SCF!AM35-SCF!AL35)-SCF!AM17 -> 125670 | AN10: =AM10+(SCF!AN35-SCF!AM35)-SCF!AN17 -> 125670 | AO10: =AN10 -> 125670 | AP10: =AO10+(SCF!AP35-SCF!AO35)-SCF!AP17 -> 125670 | AQ10: =AP10+(SCF!AQ35-SCF!AP35)-SCF!AQ17 -> 125670 | AR10: =AQ10+(SCF!AR35-SCF!AQ35)-SCF!AR17 -> 125670 | AS10: =AR10+(SCF!AS35-SCF!AR35)-SCF!AS17 -> 125670 | AT10: =AS10 -> 125670 | AU10: =AT10+(SCF!AU35-SCF!AT35)-SCF!AU17 -> 125670 | AV10: =AU10+(SCF!AV35-SCF!AU35)-SCF!AV17 -> 125670 | AW10: =AV10+(SCF!AW35-SCF!AV35)-SCF!AW17 -> 125670 | AX10: =AW10+(SCF!AX35-SCF!AW35)-SCF!AX17 -> 125670 | AY10: =AX10 -> 125670
A11: Total CA | B11: =SUM(B6:B10) -> 1178980 | C11: =SUM(C6:C10) -> 1139300 | D11: =SUM(D6:D10) -> 1264538 | E11: =SUM(E6:E10) -> 1335950 | F11: =SUM(F6:F10) -> 1264749 | G11: =SUM(G6:G10) -> 1286634 | H11: =SUM(H6:H10) -> 1383443 | I11: =SUM(I6:I10) -> 1521279 | J11: =SUM(J6:J10) -> 1661629 | K11: =J11 -> 1661629 | L11: =SUM(L6:L10) -> 1484189 | M11: =SUM(M6:M10) -> 1501651 | N11: =SUM(N6:N10) -> 1604205 | O11: =SUM(O6:O10) -> 1507759 | P11: =O11 -> 1507759 | Q11: =SUM(Q6:Q10) -> 1212874 | R11: =SUM(R6:R10) -> 1262688 | S11: =SUM(S6:S10) -> 1220365 | T11: =SUM(T6:T10) -> 1228018 | U11: =T11 -> 1228018 | V11: =SUM(V6:V10) -> 1108591 | W11: =SUM(W6:W10) -> 1311265 | X11: =SUM(X6:X10) -> 1441403 | Y11: =SUM(Y6:Y10) -> 1537265 | Z11: =Y11 -> 1537265 | AA11: =SUM(AA6:AA10) -> 1509583 | AB11: =SUM(AB6:AB10) -> 1516653 | AC11: =SUM(AC6:AC10) -> 1655767 | AD11: =SUM(AD6:AD10) -> 1673431 | AE11: =AD11 -> 1673431 | AF11: =SUM(AF6:AF10) -> 1374170 | AG11: =SUM(AG6:AG10) -> 1489115 | AH11: =SUM(AH6:AH10) -> 1609535 | AI11: =SUM(AI6:AI10) -> 1650464 | AJ11: =AI11 -> 1650464 | AK11: =SUM(AK6:AK10) -> 1415159 | AL11: =SUM(AL6:AL10) -> 1545678 | AM11: =SUM(AM6:AM10) -> 1680118.9 | AN11: =SUM(AN6:AN10) -> 1711527.1 | AO11: =AN11 -> 1711527.1 | AP11: =SUM(AP6:AP10) -> 1641169 | AQ11: =SUM(AQ6:AQ10) -> 1899794.8 | AR11: =SUM(AR6:AR10) -> 1915067.6 | AS11: =SUM(AS6:AS10) -> 1910909.4 | AT11: =AS11 -> 1910909.4 | AU11: =SUM(AU6:AU10) -> 1778760.8 | AV11: =SUM(AV6:AV10) -> 2020367.8 | AW11: =SUM(AW6:AW10) -> 2170336.9 | AX11: =SUM(AX6:AX10) -> 2168177 | AY11: =AX11 -> 2168177
A12: PP&E | B12: 894178 | C12: 824738 | D12: 738182 | E12: 694855 | F12: 665290 | G12: 654784 | H12: 635703 | I12: 593932 | J12: 550587 | K12: =J12 -> 550587 | L12: 533773 | M12: 532795 | N12: 516176 | O12: 508336 | P12: =O12 -> 508336 | Q12: 497976 | R12: 511181 | S12: 542138 | T12: 551585 | U12: =T12 -> 551585 | V12: 550810 | W12: 553680 | X12: 546935 | Y12: 538033 | Z12: =Y12 -> 538033 | AA12: 540697 | AB12: 552453 | AC12: 570440 | AD12: 575773 | AE12: =AD12 -> 575773 | AF12: 606060 | AG12: 638590 | AH12: 661646 | AI12: 674079 | AJ12: =AI12 -> 674079 | AK12: 686576 | AL12: 708576 | AM12: =AL12-SCF!AM23-SCF!AM7-SCF!AM8 -> 730245 | AN12: =AM12-SCF!AN23-SCF!AN7-SCF!AN8 -> 741313.27 | AO12: =AN12 -> 741313.27 | AP12: =AO12-SCF!AP23-SCF!AP7-SCF!AP8 -> 752481.94 | AQ12: =AP12-SCF!AQ23-SCF!AQ7-SCF!AQ8 -> 763751.95 | AR12: =AQ12-SCF!AR23-SCF!AR7-SCF!AR8 -> 775117.31 | AS12: =AR12-SCF!AS23-SCF!AS7-SCF!AS8 -> 786607.12 | AT12: =AS12 -> 786607.12 | AU12: =AT12-SCF!AU23-SCF!AU7-SCF!AU8 -> 798160.85 | AV12: =AU12-SCF!AV23-SCF!AV7-SCF!AV8 -> 809787.42 | AW12: =AV12-SCF!AW23-SCF!AW7-SCF!AW8 -> 821499.14 | AX12: =AW12-SCF!AX23-SCF!AX7-SCF!AX8 -> 833322.33 | AY12: =AX12 -> 833322.33
A13: Op. Lease ROU | F13: 1230954 | G13: 1133618 | H13: 1073464 | I13: 955781 | J13: 893989 | K13: =J13 -> 893989 | L13: 839003 | M13: 791036 | N13: 762641 | O13: 698231 | P13: =O13 -> 698231 | Q13: 671991 | R13: 740627 | S13: 713166 | T13: 723550 | U13: =T13 -> 723550 | V13: 692699 | W13: 714977 | X13: 682559 | Y13: 678256 | Z13: =Y13 -> 678256 | AA13: 699471 | AB13: 746788 | AC13: 798290 | AD13: 803121 | AE13: =AD13 -> 803121 | AF13: 868130 | AG13: 933559 | AH13: 965919 | AI13: 997399 | AJ13: =AI13 -> 997399 | AK13: 1115832 | AL13: 1107421 | AM13: =AL13*(1+AM65) -> 1162792.1 | AN13: =AM13*(1+AN65) -> 1220931.7 | AO13: =AN13 -> 1220931.7 | AP13: =AO13*(1+AP65) -> 1281978.2 | AQ13: =AP13*(1+AQ65) -> 1346077.1 | AR13: =AQ13*(1+AR65) -> 1413381 | AS13: =AR13*(1+AS65) -> 1484050.1 | AT13: =AS13 -> 1484050.1 | AU13: =AT13*(1+AU65) -> 1558252.6 | AV13: =AU13*(1+AV65) -> 1636165.2 | AW13: =AV13*(1+AW65) -> 1717973.4 | AX13: =AW13*(1+AX65) -> 1803872.1 | AY13: =AX13 -> 1803872.1
A14: Other NCA | B14: 359881 | C14: 331719 | D14: 322972 | E14: 354788 | F14: 388672 | G14: 216795 | H14: 216204 | I14: 205970 | J14: 208697 | K14: =J14 -> 208697 | L14: 213585 | M14: 229911 | N14: 229512 | O14: 225165 | P14: =O14 -> 225165 | Q14: 224462 | R14: 219598 | S14: 218325 | T14: 209947 | U14: =T14 -> 209947 | V14: 205978 | W14: 216792 | X14: 226749 | Y14: 220679 | Z14: =Y14 -> 220679 | AA14: 220334 | AB14: 233664 | AC14: 245375 | AD14: 247562 | AE14: =AD14 -> 247562 | AF14: 247816 | AG14: 240677 | AH14: 242818 | AI14: 219932 | AJ14: =AI14 -> 219932 | AK14: 235397 | AL14: 233181 | AM14: =AL14 -> 233181 | AN14: =AM14 -> 233181 | AO14: =AN14 -> 233181 | AP14: =AO14 -> 233181 | AQ14: =AP14 -> 233181 | AR14: =AQ14 -> 233181 | AS14: =AR14 -> 233181 | AT14: =AS14 -> 233181 | ... AY14: =AX14 -> 233181
