Workbook

Sheet 周涨跌
A1: 周涨跌幅
A2: Ticker | B2: 251201-1207 | C2: 251208-1214 | D2: 251215-1221 | E2: 251222-1228 | F2: 251229-0104 | G2: 260105-0111 | H2: 260112-0118 | I2: 260119-0125 | J2: 260126-0201 | K2: 260202-0208 | L2: 260209-0215 | M2: 260216-0222 | N2: 260223-0301 | O2: 260302-0308 | P2: 260309-0315 | Q2: 260316-0322 | R2: 260323-0329 | S2: 260330-0405 | T2: 260406-0412 | U2: 260413-0419 | V2: 260420-0426 | W2: 260427-0503 | X2: 260504-0510 | Y2: 260511-0517 | Z2: 260518-0524 | AA2: 260525-0531 | AB2: 260601-0607 | AC2: 260608-0614 | AD2: 260615-0621 | AE2: 260622-0628 | AF2: 260629-0705 | AG2: 260706-0712 | AH2: 260713-0719 | AI2: 260720-0726 | AJ2: 260727-0802 | AK2: 260803-0809 | AL2: 260810-0816 | AM2: 260817-0823 | AN2: 260824-0830 | AO2: 260831-0906 | AP2: 260907-0913 | AQ2: 260914-0920 | AR2: 260921-0927 | AS2: 260928-0930 | AT2: 261001-1004 | AU2: 261005-1011
A3: 运动服饰
A4: NKE.N | B4: 0.0072 | C4: 0.0244 | D4: -0.1298 | E4: 0.0378 | F4: 0.0386 | G4: 0.0417 | H4: -0.0234 | I4: 0.0103 | J4: -0.0497 | K4: 0.0341 | L4: -0.0124 | M4: 0.036 | N4: -0.0492 | O4: -0.0831 | P4: -0.0531 | Q4: -0.0298 | R4: -0.0191 | S4: -0.1398 | T4: -0.0355 | U4: 0.08 | V4: -0.0291 | W4: -0.0065 | X4: -0.0059 | Y4: -0.0512 | Z4: 0.0666 | AA4: 0.0349 | AB4: -0.0703 | AC4: 0.0454 | AD4: 0.006 | AE4: -0.0985 | AF4: 0.082 | AG4: 0.0064 | AH4: -0.0137 | AI4: -0.0471 | AJ4: 0.0002 | AK4: -0.0002 | AL4: -0.0233 | AM4: 0.0007 | AN4: -0.0285 | AO4: -0.0303 | AP4: -0.0417 | AQ4: -0.0351 | AR4: 0.0166 | AS4: -0.0151 | AT4: -0.0432 | AU4: 0.0248
A5: ADDY | B5: 0.0195 | C5: 0.0195 | D5: -0.0143 | E5: -0.0042 | F5: 0.0182 | G5: -0.0045 | H5: -0.0408 | I5: -0.1007 | J5: 0.0376 | K5: 0.0248 | L5: 0.0137 | M5: 0.0242 | N5: -0.0032 | O5: -0.098 | P5: -0.0266 | Q5: -0.0389 | R5: -0.0109 | S5: 0.0216 | T5: 0.0215 | U5: 0.0624 | V5: -0.0693 | W5: 0.0818 | X5: -0.0037 | Y5: -0.0078 | Z5: 0.0604 | AA5: 0.0783 | AB5: -0.0309 | AC5: 0.0923 | AD5: -0.0082 | AE5: 0.0389 | AF5: 0.0198 | AG5: -0.0186 | AH5: -0.0041 | AI5: -0.0414 | AJ5: -0.0818 | AK5: 0.0292 | AL5: -0.0396 | AM5: -0.0197 | AN5: -0.0016 | AO5: -0.0327 | AP5: -0.0429 | AQ5: -0.0035 | AR5: 0 | AS5: -0.0142 | AT5: -0.0086 | AU5: 0.0403
A6: WWW.N | B6: 0.0229 | C6: 0.0408 | D6: 0.0099 | E6: -0.0197 | F6: 0.0151 | G6: 0.045 | H6: 0.0142 | I6: -0.0663 | J6: -0.0166 | K6: 0.0491 | L6: -0.0527 | M6: 0.0312 | N6: -0.027 | O6: -0.0713 | P6: -0.0262 | Q6: -0.0056 | R6: -0.0069 | S6: 0.0108 | T6: 0.0652 | U6: 0.0624 | V6: -0.0172 | W6: -0.0231 | X6: -0.0364 | Y6: -0.0808 | Z6: 0.0691 | AA6: 0.0695 | AB6: -0.094 | AC6: 0.1333 | AD6: -0.0233 | AE6: -0.0261 | AF6: -0.0356 | AG6: 0.0714 | AH6: 0.0373 | AI6: 0.0229 | AJ6: 0.0474 | AK6: -0.0381 | AL6: 0.1109 | AM6: -0.0033 | AN6: -0.0296 | AO6: 0.0206 | AP6: -0.04 | AQ6: -0.0502 | AR6: 0.0291 | AS6: 0.0058 | AT6: 0.0047 | AU6: 0.012
A7: VSCO.N | B7: 0.1117 | C7: 0.1109 | D7: 0.0406 | E7: -0.051 | F7: -0.0084 | G7: 0.235 | H7: -0.0917 | I7: -0.0018 | J7: -0.0877 | K7: 0.1455 | L7: -0.0625 | M7: 0.0996 | N7: -0.0259 | O7: -0.2547 | P7: -0.04 | Q7: 0 | R7: -0.0533 | S7: 0.0831 | T7: 0.095 | U7: 0.0864 | V7: -0.0355 | W7: -0.008 | X7: -0.0825 | Y7: -0.0433 | Z7: 0.1412 | AA7: 0.0486 | AB7: 0.4556 | AC7: 0 | AD7: 0 | AE7: 0 | AF7: 0 | AG7: 0 | AH7: 0 | AI7: 0 | AJ7: 0 | AK7: 0 | AL7: 0 | AM7: 0 | AN7: 0 | AO7: 0 | AP7: 0 | AQ7: 0 | AR7: 0 | AS7: 0
A8: UAA.N | B8: -0.0066 | C8: -0.0484 | D8: 0.0462 | E8: 0.0265 | F8: 0.1376 | G8: 0.0662 | H8: 0.0248 | I8: 0.0986 | J8: -0.0283 | K8: 0.2253 | L8: -0.0489 | M8: 0.1321 | N8: -0.0885 | O8: -0.1119 | P8: -0.0152 | Q8: -0.0986 | R8: -0.0188 | S8: -0.0209 | T8: 0.089 | U8: 0.0605 | V8: -0.0447 | W8: 0.0145 | X8: 0.0223 | Y8: -0.2037 | Z8: 0.0742 | AA8: 0.0673 | AB8: -0.0528 | AC8: 0.0881 | AD8: 0.0017 | AE8: 0.0396 | AF8: 0.0524 | AG8: 0.0241 | AH8: 0.0943 | AI8: -0.0538 | AJ8: -0.0541 | AK8: -0.0812 | AL8: -0.1227 | AM8: 0.0056 | AN8: -0.0575 | AO8: 0.0335 | AP8: -0.0267 | AQ8: -0.045 | AR8: -0.0225 | AS8: -0.0023 | AT8: 0.0561 | AU8: 0.0467
A9: SKX.N
A10: SHOO.O | B10: 0.0221 | C10: -0.0062 | D10: -0.0128 | E10: -0.0002 | F10: -0.0195 | G10: 0.0675 | H10: 0.0122 | I10: -0.0024 | J10: -0.0354 | K10: -0.1862 | L10: 0.0975 | M10: 0.0179 | N10: -0.095 | O10: -0.0615 | P10: -0.0741 | Q10: 0.0147 | R10: 0.0402 | S10: 0.0266 | T10: 0.1168 | U10: 0.0485 | V10: -0.0307 | W10: -0.028 | X10: 0.0829 | Y10: -0.0448 | Z10: 0.0809 | AA10: 0.036 | AB10: 0.0136 | AC10: 0.0481 | AD10: -0.0425 | AE10: -0.022 | AF10: -0.0764 | AG10: 0.0524 | AH10: 0.0336 | AI10: -0.0154 | AJ10: 0.0779 | AK10: 0.0543 | AL10: -0.0296 | AM10: -0.0225 | AN10: -0.0399 | AO10: -0.0127 | AP10: -0.0172 | AQ10: -0.0191 | AR10: 0.0171 | AS10: 0.0053 | AT10: 0.0268 | AU10: -0.0363
A11: RL.N | B11: 0.0069 | C11: 0.0049 | D11: -0.0208 | E11: -0.0122 | F11: 0.0123 | G11: 0.0201 | H11: -0.0183 | I11: 0.0119 | J11: -0.038 | K11: -0.0298 | L11: 0.0767 | M11: 0.0429 | N11: -0.0583 | O11: -0.0669 | P11: -0.0225 | Q11: -0.0026 | R11: -0.0062 | S11: 0.0616 | T11: 0.0915 | U11: 0.0185 | V11: -0.0404 | W11: -0.0243 | X11: -0.0104 | Y11: -0.0883 | Z11: 0.156 | AA11: -0.0367 | AB11: 0.0073 | AC11: 0.1021 | AD11: 0.0224 | AE11: -0.0045 | AF11: -0.0315 | AG11: -0.0083 | AH11: -0.0366 | AI11: -0.0181 | AJ11: 0.0181 | AK11: 0.0399 | AL11: -0.0167 | AM11: -0.042 | AN11: -0.0498 | AO11: -0.008 | AP11: -0.0345 | AQ11: -0.0118 | AR11: 0.0141 | AS11: -0.0035 | AT11: 0.0234 | AU11: 0.0218
A12: PUM.DF | B12: 0.0183 | C12: 0.0313 | D12: 0.0308 | E12: -0.0388 | F12: 0.0394 | G12: 0.0692 | H12: -0.0852 | I12: -0.1556 | J12: 0.1697 | K12: 0.049 | L12: 0.033 | M12: -0.0085 | N12: 0.0219 | O12: -0.0572 | P12: -0.0353 | Q12: -0.0717 | R12: 0.0703 | S12: 0.027 | T12: 0.1224 | U12: 0.0428 | V12: -0.0314 | W12: 0.0392 | X12: -0.0312 | Y12: 0.0532 | Z12: 0.0856 | AA12: 0.0101 | AB12: -0.0802 | AC12: 0.049 | AD12: 0.0064 | AE12: -0.0507 | AF12: 0.0034 | AG12: 0.048 | AH12: 0.0177 | AI12: -0.0241 | AJ12: -0.0175 | AK12: -0.0142 | AL12: -0.0214 | AM12: -0.0569 | AN12: 0.0244 | AO12: -0.0702 | AP12: -0.0898 | AQ12: 0.0138 | AR12: 0 | AS12: -0.0149 | AT12: -0.0281 | AU12: 0.037
A13: ONON.N | B13: 0.0774 | C13: 0.0129 | D13: -0.0039 | E13: -0.0369 | F13: 0.0036 | G13: 0.0462 | H13: -0.0829 | I13: 0.0202 | J13: -0.0154 | K13: -0.0393 | L13: 0.0419 | M13: 0.0912 | N13: -0.0595 | O13: -0.108 | P13: -0.0837 | Q13: -0.0087 | R13: -0.1399 | S13: 0.0198 | T13: 0.0157 | U13: 0.1013 | V13: -0.0189 | W13: -0.0472 | X13: 0.0203 | Y13: 0.0573 | Z13: 0.0684 | AA13: 0.0254 | AB13: -0.0916 | AC13: 0.0405 | AD13: 0.0078 | AE13: -0.0466 | AF13: -0.0065 | AG13: 0.0464 | AH13: -0.0348 | AI13: -0.0371 | AJ13: 0.0117 | AK13: 0.0361 | AL13: -0.1419 | AM13: -0.0683 | AN13: -0.039 | AO13: -0.0298 | AP13: -0.0207 | AQ13: -0.0055 | AR13: 0.0022 | AS13: -0.015 | AT13: 0.0419 | AU13: 0.1374
A14: NWL.O | B14: -0.0236 | C14: 0.0242 | D14: -0.0236 | E14: 0.0188 | F14: -0.0185 | G14: 0.1317 | H14: 0.0024 | I14: 0.0237 | J14: -0.0162 | K14: 0.0894 | L14: 0.0151 | M14: 0.0383 | N14: -0.0676 | O14: -0.0681 | P14: -0.0472 | Q14: -0.1683 | R14: 0.0119 | S14: -0.0029 | T14: 0.1475 | U14: 0.1131 | V14: -0.0231 | W14: 0.0757 | X14: -0.0022 | Y14: -0.1542 | Z14: -0.0521 | AA14: -0.0659 | AB14: 0.0941 | AC14: 0.3226 | AD14: 0 | AE14: 0.1829 | AF14: 0.0017 | AG14: -0.1132 | AH14: 0.0116 | AI14: -0.0287 | AJ14: 0.1024 | AK14: 0.0732 | AL14: 0.0383 | AM14: -0.024 | AN14: 0.0131 | AO14: -0.0097 | AP14: -0.0426 | AQ14: -0.0632 | AR14: 0.0219 | AS14: -0.0221 | AT14: 0.0227 | AU14: 0.0444
A15: LULU.O | B15: 0.0417 | C15: 0.0787 | D15: 0.0219 | E15: -0.0023 | F15: 0.0088 | G15: -0.0328 | H15: -0.01 | I15: -0.0535 | J15: -0.0867 | K15: -0.0095 | L15: 0.0207 | M15: 0.0617 | N15: -0.0114 | O15: -0.0812 | P15: -0.0726 | Q15: 0.0319 | R15: -0.1042 | S15: 0.0677 | T15: 0.0523 | U15: 0.0209 | V15: -0.1404 | W15: -0.0711 | X15: -0.018 | Y15: -0.0918 | Z15: 0.0675 | AA15: 0.0315 | AB15: -0.1292 | AC15: 0.0397 | AD15: -0.0589 | AE15: 0.0519 | AF15: 0.0073 | AG15: 0.007 | AH15: -0.0246 | AI15: -0.0176 | AJ15: 0.0402 | AK15: 0.0817 | AL15: -0.0702 | AM15: 0.0127 | AN15: -0.0021 | AO15: -0.1672 | AP15: -0.0163 | AQ15: -0.0092 | AR15: 0.033 | AS15: -0.0369 | AT15: -0.018 | AU15: 0.0004
A16: LEVI.N | B16: -0.0009 | C16: -0.0346 | D16: 0.0098 | E16: -0.0276 | F16: -0.0137 | G16: 0.0447 | H16: 0.0005 | I16: -0.0239 | J16: -0.064 | K16: 0.0337 | L16: 0.0662 | M16: 0.0443 | N16: -0.0315 | O16: -0.1155 | P16: -0.0862 | Q16: 0.0011 | R16: 0.0184 | S16: 0.035 | T16: 0.2037 | U16: 0.0066 | V16: -0.0258 | W16: -0.0013 | X16: 0.0175 | Y16: -0.0745 | Z16: 0.0496 | AA16: 0.0536 | AB16: -0.0289 | AC16: 0.0657 | AD16: -0.0129 | AE16: 0.0354 | AF16: -0.0053 | AG16: -0.0041 | AH16: 0.0021 | AI16: 0.0074 | AJ16: -0.0008 | AK16: -0.0045 | AL16: -0.0762 | AM16: -0.047 | AN16: -0.0093 | AO16: -0.0108 | AP16: -0.0427 | AQ16: -0.0169 | AR16: 0 | AS16: -0.003 | AT16: 0.0086 | AU16: -0.0589
A17: KTB.N | B17: 0.0138 | C17: -0.1268 | D17: -0.0365 | E17: -0.0189 | F17: -0.0223 | G17: 0.0054 | H17: -0.039 | I17: -0.0268 | J17: 0.0329 | K17: 0.1222 | L17: 0.0064 | M17: 0.0334 | N17: -0.0646 | O17: 0.1696 | P17: -0.1151 | Q17: -0.0074 | R17: -0.0084 | S17: 0.0388 | T17: 0.0422 | U17: 0.0747 | V17: -0.0593 | W17: -0.007 | X17: 0.0201 | Y17: -0.1614 | Z17: 0.132 | AA17: 0.0266 | AB17: -0.0237 | AC17: 0.1276 | AD17: -0.0106 | AE17: 0.0655 | AF17: 0.0205 | AG17: 0.0078 | AH17: -0.0011 | AI17: -0.0237 | AJ17: 0.0024 | AK17: -0.0799 | AL17: 0.1019 | AM17: -0.034 | AN17: -0.0612 | AO17: -0.0442 | AP17: -0.0947 | AQ17: -0.0039 | AR17: 0.0008 | AS17: -0.0099 | AT17: 0.0267 | AU17: 0.0141
A18: HBI.N
A19: GIL.N | B19: 0.0207 | C19: 0.0294 | D19: 0.0474 | E19: 0.0025 | F19: -0.0098 | G19: 0.0083 | H19: -0.0036 | I19: 0.0584 | J19: -0.0288 | K19: 0.0962 | L19: 0.019 | M19: -0.0141 | N19: -0.0485 | O19: -0.0831 | P19: -0.0604 | Q19: -0.0455 | R19: -0.0279 | S19: 0.0004 | T19: 0.0623 | U19: 0.0353 | V19: -0.0219 | W19: 0.0502 | X19: -0.0366 | Y19: -0.0467 | Z19: 0.0299 | AA19: 0.0481 | AB19: -0.0553 | AC19: 0.055 | AD19: -0.1463 | AE19: 0.0179 | AF19: -0.025 | AG19: 0.0194 | AH19: 0.0301 | AI19: -0.0764 | AJ19: 0.1087 | AK19: 0.0383 | AL19: -0.0136 | AM19: -0.0097 | AN19: -0.0543 | AO19: 0.0053 | AP19: -0.0927 | AQ19: -0.0326 | AR19: -0.0151 | AS19: 0.004 | AT19: -0.0382 | AU19: 0.0237
A20: GAP.N | B20: -0.0342 | C20: -0.0083 | D20: 0.0638 | E20: -0.0657 | F20: -0.0378 | G20: 0.1243 | H20: -0.0561 | I20: 0.0138 | J20: 0.0325 | K20: 0.0411 | L20: -0.0501 | M20: 0.0398 | N20: -0.0254 | O20: -0.1698 | P20: -0.0017 | Q20: 0.0288 | R20: 0.0347 | S20: -0.0053 | T20: 0.0687 | U20: 0.0274 | V20: -0.0751 | W20: -0.0124 | X20: -0.0531 | Y20: -0.0993 | Z20: 0.1112 | AA20: -0.0958 | AB20: 0.0194 | AC20: 0.0153 | AD20: -0.0338 | AE20: -0.0444 | AF20: -0.0475 | AG20: 0.0109 | AH20: 0.0457 | AI20: -0.0658 | AJ20: 0.0568 | AK20: 0.0189 | AL20: 0.0064 | AM20: -0.0388 | AN20: 0.1859 | AO20: -0.0447 | AP20: -0.041 | AQ20: -0.0451 | AR20: 0.0346 | AS20: 0.0257 | AT20: -0.0144 | AU20: 0.032
A21: DECK.N | B21: 0.0835 | C21: 0.0148 | D21: -0.0169 | E21: 0.0364 | F21: 0.0359 | G21: -0.0284 | H21: -0.0296 | I21: -0.0071 | J21: 0.1936 | K21: -0.0326 | L21: 0.0024 | M21: 0.0256 | N21: -0.012 | O21: -0.111 | P21: -0.0333 | Q21: -0.0035 | R21: -0.0635 | S21: 0.0453 | T21: 0.0971 | U21: 0.043 | V21: -0.0353 | W21: -0.0705 | X21: -0.0046 | Y21: -0.0683 | Z21: 0.1401 | AA21: 0.0673 | AB21: -0.0502 | AC21: 0.0527 | AD21: -0.0415 | AE21: -0.0417 | AF21: 0.0012 | AG21: 0.0124 | AH21: 0.0047 | AI21: -0.0981 | AJ21: 0.0087 | AK21: 0.006 | AL21: -0.0448 | AM21: -0.0151 | AN21: -0.0428 | AO21: -0.0222 | AP21: -0.0529 | AQ21: -0.0349 | AR21: 0.023 | AS21: -0.0087 | AT21: 0.0125 | AU21: 0.0476
A22: CROX.O | B22: 0.0354 | C22: 0.0023 | D22: -0.0067 | E22: 0.026 | F22: -0.0511 | G22: -0.0101 | H22: -0.0349 | I22: 0.0332 | J22: -0.0223 | K22: 0.0225 | L22: 0.129 | M22: 0.0326 | N22: -0.0933 | O22: -0.0519 | P22: -0.0936 | Q22: -0.0278 | R22: 0.0496 | S22: 0.0518 | T22: 0.1924 | U22: 0.0612 | V22: -0.0335 | W22: 0.0152 | X22: -0.0024 | Y22: -0.0839 | Z22: 0.1633 | AA22: 0.0745 | AB22: 0.0057 | AC22: 0.0449 | AD22: 0.0027 | AE22: 0.0217 | AF22: -0.0194 | AG22: 0.0599 | AH22: 0.0328 | AI22: -0.0176 | AJ22: -0.0498 | AK22: 0.0673 | AL22: -0.0359 | AM22: -0.073 | AN22: 0.001 | AO22: -0.0385 | AP22: -0.043 | AQ22: 0.0868 | AR22: 0.0119 | AS22: 0.0022 | AT22: 0.0066 | AU22: -0.0263
A23: COLM.O | B23: -0.004 | C23: 0.0376 | D23: -0.0343 | E23: 0.0065 | F23: 0.0081 | G23: -0.0007 | H23: -0.0368 | I23: -0.0193 | J23: 0.0452 | K23: 0.1409 | L23: 0.0035 | M23: 0.0149 | N23: -0.0357 | O23: -0.0584 | P23: -0.0526 | Q23: -0.0004 | R23: -0.0112 | S23: -0.0029 | T23: 0.0516 | U23: 0.0616 | V23: -0.0087 | W23: 0.0347 | X23: 0.0111 | Y23: -0.0839 | Z23: 0.0977 | AA23: 0.044 | AB23: -0.0296 | AC23: 0.0431 | AD23: -0.0079 | AE23: -0.0293 | AF23: -0.0184 | AG23: -0.0055 | AH23: 0.0084 | AI23: -0.0186 | AJ23: -0.0472 | AK23: -0.034 | AL23: 0.001 | AM23: 0.0507 | AN23: -0.0385 | AO23: -0.005 | AP23: -0.0139 | AQ23: -0.0014 | AR23: -0.0019 | AS23: -0.006 | AT23: -0.0024 | AU23: -0.004
A24: BZUN.O | B24: 0.0554 | C24: -0.0951 | D24: -0.0109 | E24: -0.011 | F24: 0.0407 | G24: 0.0178 | H24: -0.0245 | I24: 0.0036 | J24: -0.0429 | K24: 0 | L24: 0 | M24: 0.0299 | N24: -0.0906 | O24: -0.0518 | P24: 0.0084 | Q24: -0.1 | R24: -0.0301 | S24: 0.2029 | T24: -0.0397 | U24: 0.2975 | V24: -0.1115 | W24: -0.0179 | X24: 0.0036 | Y24: -0.1055 | Z24: 0.0163 | AA24: 0.036 | AB24: 0.0232 | AC24: 0.0377 | AD24: 0.0145 | AE24: -0.0072 | AF24: 0.0036 | AG24: 0.0216 | AH24: -0.1162 | AI24: -0.012 | AJ24: 0.1573 | AK24: 0.0314 | AL24: -0.0439 | AM24: 0.0035 | AN24: 0.0634 | AO24: -0.0497 | AP24: -0.0488 | AQ24: 0.044 | AR24: 0.0298 | AS24: -0.0129 | AT24: 0.0327 | AU24: 0.0475
A25: AS.N | B25: -0.0329 | C25: 0.0712 | D25: -0.0039 | E25: 0.0042 | F25: -0.0227 | G25: 0.0275 | H25: -0.0389 | I25: 0.0186 | J25: -0.0289 | K25: 0.024 | L25: 0.0613 | M25: 0.054 | N25: -0.0949 | O25: -0.1053 | P25: -0.0483 | Q25: -0.0495 | R25: 0.0224 | S25: 0.0627 | T25: 0.0545 | U25: 0.0537 | V25: -0.0342 | W25: -0.0165 | X25: 0.0221 | Y25: -0.0885 | Z25: 0.0737 | AA25: 0.0091 | AB25: -0.0416 | AC25: 0.0399 | AD25: 0.0386 | AE25: -0.0722 | AF25: 0.0258 | AG25: -0.0071 | AH25: 0.0471 | AI25: -0.0692 | AJ25: 0.0469 | AK25: 0.0375 | AL25: -0.1078 | AM25: -0.0073 | AN25: -0.0484 | AO25: -0.049 | AP25: -0.0494 | AQ25: -0.0477 | AR25: 0.0269 | AS25: -0.0138 | AT25: -0.0044 | AU25: 0.0357
A26: ANF.N | B26: -0.069 | C26: 0.1815 | D26: 0.08 | E26: 0.0477 | F26: -0.0244 | G26: 0.0091 | H26: -0.1661 | I26: -0.0752 | J26: 0.0138 | K26: 0.0003 | L26: -0.0405 | M26: 0.0289 | N26: 0.0144 | O26: -0.1309 | P26: -0.0369 | Q26: 0.0748 | R26: 0.0131 | S26: 0.035 | T26: 0.0666 | U26: -0.041 | V26: -0.0769 | W26: -0.0294 | X26: -0.0775 | Y26: -0.0951 | Z26: 0.0948 | AA26: -0.0005 | AB26: -0.0243 | AC26: 0.2022 | AD26: -0.0368 | AE26: 0.0489 | AF26: 0.0099 | AG26: 0.007 | AH26: 0.0233 | AI26: -0.015 | AJ26: 0.0611 | AK26: 0.1314 | AL26: -0.0399 | AM26: 0.0081 | AN26: 0.3615 | AO26: 0.0084 | AP26: -0.0297 | AQ26: -0.0652 | AR26: 0.0074 | AS26: -0.0044 | AT26: 0.0091 | AU26: 0.0491
A27: 9983.T | B27: 0.0141 | C27: 0.0067 | D27: -0.0135 | E27: 0.0163 | F27: -0.0058 | G27: 0.102 | H27: -0.0016 | I27: -0.0343 | J27: -0.0281 | K27: 0.0799 | L27: 0.089 | M27: -0.0317 | N27: 0.0309 | O27: -0.0522 | P27: -0.0066 | Q27: -0.0242 | R27: -0.026 | S27: 0.0408 | T27: 0.1748 | U27: -0.0197 | V27: -0.0535 | W27: 0.0399 | X27: 0.0289 | Y27: -0.0449 | Z27: 0.0542 | AA27: 0.0903 | AB27: -0.0441 | AC27: 0.0233 | AD27: 0.0319 | AE27: 0.0117 | AF27: 0.0051 | AG27: -0.0283 | AH27: -0.0398 | AI27: -0.0332 | AJ27: 0.0258 | AK27: 0.0143 | AL27: -0.0276 | AM27: -0.0468 | AN27: -0.0306 | AO27: -0.0303 | AP27: -0.0379 | AQ27: 0.0181 | AR27: 0 | AS27: 0.0255 | AT27: 0.0128 | AU27: 0.0001
A28: 8111.T | B28: -0.0019 | C28: -0.0086 | D28: -0.0567 | E28: -0.054 | F28: -0.0226 | G28: 0.0367 | H28: 0.0161 | I28: -0.0216 | J28: -0.0037 | K28: -0.0444 | L28: -0.0071 | M28: -0.0102 | N28: 0.0194 | O28: -0.0436 | P28: -0.0125 | Q28: 0.0015 | R28: -0.0219 | S28: -0.0388 | T28: 0.0203 | U28: 0.0161 | V28: -0.0415 | W28: 0.0147 | X28: 0.0016 | Y28: -0.0079 | Z28: -0.0184 | AA28: -0.022 | AB28: -0.0088 | AC28: 0.038 | AD28: 0.0088 | AE28: -0.0199 | AF28: 0.0424 | AG28: 0.0018 | AH28: 0.0109 | AI28: 0.0154 | AJ28: -0.0041 | AK28: -0.0945 | AL28: 0.0282 | AM28: 0.0026 | AN28: 0.0238 | AO28: -0.0352 | AP28: -0.0109 | AQ28: 0.0175 | AR28: 0 | AS28: -0.0377 | AT28: -0.008 | AU28: 0.0309
A29: 7936.T | B29: 0.0016 | C29: 0.0528 | D29: -0.0205 | E29: 0.0146 | F29: -0.0327 | G29: 0.1031 | H29: 0.0036 | I29: -0.0404 | J29: -0.0687 | K29: 0.0086 | L29: 0.1732 | M29: 0.0942 | N29: -0.0033 | O29: -0.039 | P29: -0.0319 | Q29: -0.0126 | R29: -0.0223 | S29: 0 | T29: 0.0606 | U29: 0.0061 | V29: -0.0394 | W29: -0.0165 | X29: 0.0689 | Y29: -0.0289 | Z29: 0.0087 | AA29: 0.0656 | AB29: -0.0865 | AC29: 0.0059 | AD29: -0.0196 | AE29: 0.0213 | AF29: 0.0377 | AG29: -0.0097 | AH29: 0.069 | AI29: -0.0208 | AJ29: -0.0081 | AK29: 0.0469 | AL29: 0.0611 | AM29: -0.1121 | AN29: -0.0188 | AO29: -0.0728 | AP29: -0.0649 | AQ29: 0.0193 | AR29: 0 | AS29: 0.0024 | AT29: -0.0187 | AU29: 0.0804
A30: 3998.HK | B30: -0.014 | C30: -0.0344 | D30: -0.0356 | E30: 0 | F30: -0.0174 | G30: -0.0088 | H30: 0.0089 | I30: 0.0243 | J30: 0.0302 | K30: 0.0398 | L30: -0.0282 | M30: -0.0124 | N30: 0.021 | O30: -0.037 | P30: -0.1346 | Q30: 0.0123 | R30: -0.0244 | S30: 0.035 | T30: 0.0386 | U30: -0.0302 | V30: 0.036 | W30: -0.0139 | X30: 0.0305 | Y30: -0.0251 | Z30: -0.0257 | AA30: 0.0192 | AB30: 0.0024 | AC30: 0.0023 | AD30: -0.0913 | AE30: 0.018 | AF30: 0.1367 | AG30: 0.0579 | AH30: 0.0042 | AI30: -0.0042 | AJ30: 0.04 | AK30: -0.0425 | AL30: -0.0095 | AM30: -0.0075 | AN30: -0.0505 | AO30: -0.0159 | AP30: 0.0046 | AQ30: -0.0607 | AR30: -0.05 | AS30: -0.0309 | AT30: -0.01 | AU30: 0.1108
... A36: 002832.SZ | B36: -0.0146 | C36: -0.0078 | D36: -0.0065 | E36: -0.0072 | F36: -0.0119 | G36: 0.0167 | H36: 0 | I36: 0.0099 | J36: -0.0176 | K36: 0.0252 | L36: -0.0291 | M36: 0 | N36: 0.034 | O36: 0.065 | P36: 0.0193 | Q36: -0.0142 | R36: 0.0445 | S36: -0.0127 | T36: 0.0158 | U36: 0.0224 | V36: 0.0135 | W36: 0.122 | X36: -0.0321 | Y36: 0.0791 | Z36: -0.0459 | AA36: -0.0283 | AB36: 0.0194 | AC36: 0.0696 | AD36: -0.0267 | AE36: -0.0385 | AF36: 0.046 | AG36: -0.011 | AH36: 0.0155 | AI36: 0.0857 | AJ36: 0.1394 | AK36: -0.0527 | AL36: 0.0593 | AM36: -0.0686 | AN36: 0.0074 | AO36: 0.087 | AP36: -0.0579 | AQ36: 0.0227 | AR36: 0.0078 | AS36: 0.0244 | AT36: 0 | AU36: 0.0698
AG37: =AVERAGE(AG4:AG36) | AH37: =AVERAGE(AH4:AH36) | AI37: =AVERAGE(AI4:AI36) | AJ37: =AVERAGE(AJ4:AJ36) | AK37: =AVERAGE(AK4:AK36) | AL37: =AVERAGE(AL4:AL36) | AM37: =AVERAGE(AM4:AM36) | AN37: =AVERAGE(AN4:AN36) | ... AS37: =AVERAGE(AS4:AS36)
A38: 奢侈品
A39: VFC | B39: 0.0502 | C39: 0.032 | D39: -0.0529 | E39: -0.0064 | F39: -0.0184 | G39: 0.0936 | H39: -0.0524 | I39: 0.0489 | J39: -0.0076 | K39: 0.0383 | L39: -0.002 | M39: 0.0458 | N39: -0.0853 | O39: -0.1081 | P39: -0.0785 | Q39: 0.0201 | R39: 0.0074 | S39: 0.0287 | T39: 0.0806 | U39: 0.1519 | V39: -0.0576 | W39: -0.0394 | X39: -0.0016 | Y39: -0.1212 | Z39: 0.0012 | AA39: 0.0287 | AB39: -0.0343 | AC39: 0.0633 | AD39: -0.0176 | AE39: 0.0023 | AF39: -0.0616 | AG39: 0.0288 | AH39: 0.0125 | AI39: 0.0029 | AJ39: -0.1591 | AK39: 0.0468 | AL39: -0.008 | AM39: -0.0336 | AN39: -0.0487 | AO39: -0.0161 | AP39: -0.0208 | AQ39: -0.0289 | AR39: 0.0203 | AS39: 0.0055 | AT39: 0.0192 | AU39: 0.0468
A40: CFR | B40: -0.0009 | C40: -0.0409 | D40: 0.0117 | E40: 0.0104 | F40: 0.0118 | G40: 0.0256 | H40: -0.0856 | I40: -0.0421 | J40: -0.0324 | K40: 0.0395 | L40: 0.0206 | M40: 0.023 | N40: -0.0311 | O40: -0.0925 | P40: -0.0322 | Q40: -0.0558 | R40: 0.0587 | S40: 0.0351 | T40: 0.0731 | U40: 0.0434 | V40: -0.0606 | W40: -0.012 | X40: 0.0667 | Y40: -0.0177 | Z40: 0.001 | AA40: 0.0844 | AB40: -0.0252 | AC40: 0.0865 | AD40: 0.0266 | AE40: 0.0172 | AF40: -0.0139 | AG40: -0.0109 | AH40: 0.0659 | AI40: -0.0059 | AJ40: -0.0111 | AK40: 0.0238 | AL40: -0.0153 | AM40: -0.0348 | AN40: 0.0474 | AO40: -0.0468 | AP40: -0.0563 | AQ40: -0.0351 | AR40: 0 | AS40: 0.025 | AT40: -0.0349 | AU40: -0.0148
A41: 1913.HK | B41: -0.04 | C41: 0.0314 | D41: 0.0239 | E41: -0.0327 | F41: -0.0189 | G41: -0.0336 | H41: -0.0231 | I41: -0.0104 | J41: -0.0412 | K41: 0.011 | L41: 0.0346 | M41: 0.0076 | N41: 0.0545 | O41: -0.0813 | P41: -0.044 | Q41: -0.0573 | R41: 0.0071 | S41: -0.0016 | T41: 0.0508 | U41: -0.0504 | V41: 0.0152 | W41: -0.0752 | X41: 0.1084 | Y41: -0.0718 | Z41: 0.0275 | AA41: 0 | AB41: 0.0016 | AC41: 0.1045 | AD41: -0.0054 | AE41: -0.0525 | AF41: 0.0115 | AG41: 0.0222 | AH41: 0.041 | AI41: -0.0598 | AJ41: 0.1178 | AK41: 0.0194 | AL41: -0.0553 | AM41: -0.0134 | AN41: 0.0131 | AO41: -0.0552 | AP41: -0.0214 | AQ41: 0.0166 | AR41: -0.0445 | AS41: -0.0344 | AT41: -0.0229 | AU41: 0.0164
A42: MONC | B42: -0.0014 | C42: -0.0355 | D42: 0.0096 | E42: -0.0106 | F42: -0.0215 | G42: -0.011 | H42: -0.0576 | I42: -0.0271 | J42: -0.0123 | K42: -0.0133 | L42: 0.048 | M42: 0.1247 | N42: 0.0253 | O42: -0.0589 | P42: -0.0444 | Q42: -0.0088 | R42: -0.0376 | S42: 0.0602 | T42: 0.0229 | U42: 0.0445 | V42: -0.0475 | W42: -0.0529 | X42: 0.0636 | Y42: -0.0879 | Z42: 0.0364 | AA42: 0.0842 | AB42: -0.0301 | AC42: -0.0059 | AD42: -0.0189 | AE42: -0.0288 | AF42: -0.0035 | AG42: -0.0235 | AH42: 0.014 | AI42: -0.0533 | AJ42: 0.0242 | AK42: 0.0318 | AL42: -0.034 | AM42: -0.0376 | AN42: 0.0132 | AO42: -0.0394 | AP42: -0.0251 | AQ42: -0.0322 | AR42: 0 | AS42: -0.0045 | AT42: -0.0211 | AU42: -0.0041
A43: KER | B43: -0.0134 | C43: 0.0024 | D43: 0.0214 | E43: 0.0035 | F43: 0.0033 | G43: 0.042 | H43: -0.0904 | I43: -0.0476 | J43: -0.0393 | K43: -0.0231 | L43: 0.1019 | M43: -0.0223 | N43: 0.0284 | O43: -0.0997 | P43: -0.0338 | Q43: -0.0585 | R43: 0.0604 | S43: 0.0683 | T43: 0.0422 | U43: -0.0827 | V43: -0.0534 | W43: -0.0308 | X43: 0.057 | Y43: -0.0368 | Z43: 0.0217 | AA43: 0.0552 | AB43: -0.0231 | AC43: 0.0758 | AD43: 0.0134 | AE43: -0.018 | AF43: -0.0696 | AG43: 0.0002 | AH43: 0.0153 | AI43: -0.0396 | AJ43: 0.1729 | AK43: 0.0086 | AL43: -0.0631 | AM43: -0.0531 | AN43: -0.0004 | AO43: -0.0354 | AP43: -0.0269 | AQ43: -0.0235 | AR43: 0 | AS43: -0.0204 | AT43: -0.0586 | AU43: 0.0052
A44: SFER | B44: -0.0087 | C44: -0.0006 | D44: 0.0256 | E44: -0.0165 | F44: 0.0347 | G44: -0.0503 | H44: -0.0833 | I44: -0.0323 | J44: -0.059 | K44: 0.0113 | L44: 0.0045 | M44: 0.0372 | N44: -0.0316 | O44: -0.1007 | P44: 0.1252 | Q44: -0.0783 | R44: 0.0167 | S44: 0.0984 | T44: 0.0861 | U44: 0.0648 | V44: -0.0547 | W44: -0.0371 | X44: 0.1743 | Y44: -0.2394 | Z44: 0.1649 | AA44: 0.2273 | AB44: -0.0265 | AC44: 0.0359 | AD44: 0.0126 | AE44: 0.1202 | AF44: -0.0305 | AG44: -0.0363 | AH44: 0.0337 | AI44: -0.0421 | AJ44: 0.018 | AK44: -0.0079 | AL44: -0.049 | AM44: -0.0349 | AN44: 0.0243 | AO44: -0.0405 | AP44: -0.0582 | AQ44: -0.1136 | AR44: 0 | AS44: -0.0145 | AT44: -0.0409 | AU44: -0.0284
A45: RACE | B45: 0.0162 | C45: -0.0663 | D45: 0.0304 | E45: -0.0004 | F45: -0.0165 | G45: 0.0116 | H45: -0.0823 | I45: -0.0194 | J45: -0.0158 | K45: 0.0019 | L45: 0.1357 | M45: -0.032 | N45: 0.0353 | O45: -0.0785 | P45: -0.052 | Q45: -0.0519 | R45: 0.0088 | S45: 0.0712 | T45: 0.035 | U45: 0.0596 | V45: -0.0561 | W45: -0.0304 | X45: -0.0046 | Y45: -0.0544 | Z45: 0.0842 | AA45: -0.023 | AB45: 0.0199 | AC45: 0.0228 | AD45: 0.0203 | AE45: 0.0171 | AF45: 0.0451 | AG45: -0.0216 | AH45: 0.0005 | AI45: -0.0443 | AJ45: 0.0937 | AK45: 0.0467 | AL45: 0.0063 | AM45: 0.0523 | AN45: -0.0367 | AO45: -0.0252 | AP45: 0.0093 | AQ45: -0.0171 | AR45: 0.0232 | AS45: 0.0102 | AT45: -0.0115 | AU45: 0.0041
...

Sheet 日度收盘价
A1: 日度收盘价（本地货币）
A2: Date | B2: NKE.N | C2: ADDY | D2: ZGN.N | E2: WWW.N | F2: UAA.N | G2: SHOO.O | H2: RL.N | I2: PUM.DF | J2: ONON.N | K2: NWL.O | L2: LULU.O | M2: LEVI.N | N2: KTB.N | O2: GIL.N | P2: GAP.N | Q2: DECK.N | R2: CROX.O | S2: COLM.O | T2: BZUN.O | U2: AS.N | V2: ANF.N | W2: 9983.T | X2: 8111.T | Y2: 7936.T | Z2: 3998.HK | AA2: 2331.HK | AB2: 2020.HK | AC2: 1836.HK | AD2: 1368.HK | AE2: 1361.HK | AF2: 002832.SZ | AG2: | | AH2: VFC | AI2: CFR | AJ2: 1913.HK | AK2: MONC | AL2: KER | AM2: SFER | AN2: RACE | AO2: RMS | AP2: MC | AQ2: BRBY | AR2: CPRI | AS2: PVH | AT2: TPR | AU2: GOOS | AV2: ZGN
A3: 46295 | W3: 69580 | X3: 2091 | Y3: 4178 | Z3: 3.925 | AA3: 12.38 | AB3: 73.3 | AC3: 12.01 | AD3: 3.495 | AE3: 4.515 | AF3: 25.58 | AJ3: 37.56
A4: 46294 | B4: 35.84 | C4: 145.75 | D4: 12.62 | E4: 19.24 | F4: 4.27 | G4: 45.14 | H4: 355.92 | I4: 22.53 | J4: 29.55 | K4: 5.32 | L4: 96.87 | M4: 19.75 | N4: 64.29 | O4: 42.79 | P4: 23.54 | Q4: 77.68 | R4: 122.63 | S4: 58.34 | T4: 3.05 | U4: 27.24 | V4: 133.59 | W4: 68710 | X4: 2099 | Y4: 4101 | Z4: 4.01 | AA4: 12.53 | AB4: 73.5 | AC4: 12.1 | AD4: 3.48 | AE4: 4.53 | AF4: 25.28 | AH4: 14.5 | AI4: 176.55 | AJ4: 38.04 | AK4: 44.5 | AL4: 223.55 | AM4: 7.48 | AN4: 402.05 | AO4: 1352.5 | AP4: 394.6 | AQ4: 1028.5 | AR4: 14.66 | AS4: 75.74 | AT4: 114.12 | AU4: 10.92 | AV4: 12.62
A5: 46293 | B5: 36.39 | C5: 147.85 | D5: 12.64 | E5: 19.13 | F5: 4.28 | G5: 44.9 | H5: 357.16 | I5: 22.87 | J5: 30 | K5: 5.44 | L5: 100.58 | M5: 19.81 | N5: 64.93 | O5: 42.62 | P5: 22.95 | Q5: 78.36 | R5: 122.36 | S5: 58.69 | T5: 3.09 | U5: 27.62 | V5: 134.18 | W5: 67850 | X5: 2173 | Y5: 4168 | Z5: 4.05 | AA5: 12.45 | AB5: 72 | AC5: 12.03 | AD5: 3.48 | AE5: 4.49 | AF5: 24.97 | AH5: 14.42 | AI5: 172.25 | AJ5: 38.9 | AK5: 44.7 | AL5: 228.2 | AM5: 7.59 | AN5: 398 | AO5: 1381.5 | AP5: 398.8 | AQ5: 1023.5 | AR5: 14.79 | AS5: 75.73 | AT5: 113.45 | AU5: 10.87 | AV5: 12.64
A6: 46290 | B6: 35.75 | C6: 146.5 | D6: 12.73 | E6: 19.07 | F6: 4.43 | G6: 45.06 | H6: 357.1 | I6: 22.36 | J6: 29.96 | K6: 5.43 | L6: 101.3 | M6: 19.73 | N6: 65.37 | O6: 40.98 | P6: 21.82 | Q6: 78.67 | R6: 126.14 | S6: 57.6 | T6: 2.94 | U6: 27.77 | V6: 135.71 | W6: 68620 | X6: 2182 | Y6: 4144 | Z6: 3.97 | AA6: 12.24 | AB6: 71.2 | AC6: 11.85 | AD6: 3.41 | AE6: 4.42 | AH6: 14.15 | AI6: 171.4 | AJ6: 38.68 | AK6: 43.56 | AL6: 223.35 | AM6: 7.41 | AN6: 411.33 | AO6: 1347.5 | AP6: 396.85 | AQ6: 1017 | AR6: 15.1 | AS6: 75.99 | AT6: 113.88 | AU6: 10.75 | AV6: 12.73
A7: 46289 | B7: 35.99 | C7: 142.25 | D7: 12.47 | E7: 19.3 | F7: 4.5 | G7: 44.23 | H7: 351.86 | I7: 22.14 | J7: 30.46 | K7: 5.59 | L7: 101.64 | M7: 19.72 | N7: 64.41 | O7: 40.63 | P7: 21.69 | Q7: 78.68 | R7: 123.44 | S7: 56.97 | T7: 2.94 | U7: 26.77 | V7: 134.3 | W7: 67920 | X7: 2164 | Y7: 4110 | Z7: 4.01 | AA7: 12.3 | AB7: 71.95 | AC7: 11.77 | AD7: 3.46 | AE7: 4.45 | AF7: 25.15 | AH7: 13.69 | AI7: 170.6 | AJ7: 38.22 | AK7: 43.61 | AL7: 225.75 | AM7: 7.62 | AN7: 411.82 | AO7: 1354.5 | AP7: 397.1 | AQ7: 1024.5 | AR7: 15.19 | AS7: 75.79 | AT7: 112.12 | AU7: 10.72 | AV7: 12.47
A8: 46288 | B8: 36.05 | C8: 144.45 | D8: 12.44 | E8: 19.11 | F8: 4.53 | G8: 43.4 | H8: 337.47 | I8: 22.3 | J8: 30.16 | K8: 5.68 | L8: 102.28 | M8: 19.63 | N8: 65.69 | O8: 46.19 | P8: 21.28 | Q8: 78.59 | R8: 124.62 | S8: 56.78 | T8: 3 | U8: 26.9 | V8: 132.25 | Z8: 4.01 | AA8: 12.38 | AB8: 71.8 | AC8: 11.7 | AD8: 3.48 | AE8: 4.5 | AF8: 25.45 | AH8: 13.52 | AI8: 170.4 | AJ8: 38.14 | AK8: 44.32 | AL8: 227.3 | AM8: 7.7 | AN8: 413.05 | AO8: 1349.5 | AP8: 396.9 | AQ8: 1035.5 | AR8: 15.43 | AS8: 75.39 | AT8: 110.51 | AU8: 10.61 | AV8: 12.44
A9: 46287 | B9: 36.1 | C9: 146.85 | D9: 12.51 | E9: 19.87 | F9: 4.74 | G9: 44.45 | H9: 346.06 | I9: 22.75 | J9: 29.39 | K9: 5.77 | L9: 103.73 | M9: 20.06 | N9: 67.82 | O9: 47.01 | P9: 21.46 | Q9: 79.83 | R9: 124.58 | S9: 58.43 | T9: 2.99 | U9: 27.65 | V9: 136.21 | Z9: 3.94 | AA9: 12.36 | AB9: 71.9 | AC9: 11.62 | AD9: 3.52 | AE9: 4.46 | AF9: 25.65 | AH9: 13.55 | AI9: 169.75 | AJ9: 37.38 | AK9: 43.81 | AL9: 232 | AM9: 7.62 | AN9: 413.32 | AO9: 1355 | AP9: 401.95 | AQ9: 1024 | AR9: 15.19 | AS9: 75.89 | AT9: 112.59 | AU9: 10.71 | AV9: 12.51
A10: 46286 | B10: 36.1 | C10: 143.15 | D10: 12.42 | E10: 19.48 | F10: 4.77 | G10: 42.83 | H10: 339.82 | I10: 22.31 | J10: 27.32 | K10: 5.6 | L10: 101.3 | M10: 19.82 | N10: 66.41 | O10: 46.16 | P10: 21.25 | Q10: 80.23 | R10: 123.69 | S10: 56.73 | T10: 2.94 | U10: 27.45 | V10: 136.76 | Z10: 4.06 | AA10: 12.81 | AB10: 72 | AC10: 11.6 | AD10: 3.6 | AE10: 4.45 | AF10: 25.82 | AH10: 13.05 | AI10: 169.15 | AJ10: 37.34 | AK10: 43.48 | AL10: 228.65 | AM10: 7.46 | AN10: 416.13 | AO10: 1344 | AP10: 405.5 | AQ10: 1025.5 | AR10: 14.31 | AS10: 73.4 | AT10: 113.07 | AU10: 10.53 | AV10: 12.42
A11: 46283 | B11: 35.51 | C11: 142.25 | D11: 12.29 | E11: 18.93 | F11: 4.88 | G11: 42.11 | H11: 335.1 | I11: 21.99 | J11: 27.26 | K11: 5.48 | L11: 98.06 | M11: 19.82 | N11: 66.36 | O11: 46.87 | P11: 20.54 | Q11: 78.43 | R11: 122.24 | S11: 56.84 | T11: 2.85 | U11: 26.73 | V11: 135.76 | W11: 67680 | X11: 2126.5 | Y11: 4066 | Z11: 4.1 | AA11: 12.57 | AB11: 71.7 | AC11: 11.49 | AD11: 3.5 | AE11: 4.33 | AF11: 25.63 | AH11: 12.79 | AI11: 168.85 | AJ11: 39.14 | AK11: 43.25 | AL11: 233 | AM11: 7.61 | AN11: 406.69 | AO11: 1331.5 | AP11: 402.8 | AQ11: 996 | AR11: 14.75 | AS11: 73.35 | AT11: 115 | AU11: 10.43 | AV11: 12.29
A12: 46282 | B12: 36.36 | C12: 142.4 | D12: 12.36 | E12: 19.34 | F12: 4.97 | G12: 41.8 | H12: 333.08 | I12: 22 | J12: 27.33 | K12: 5.61 | L12: 99.39 | M12: 19.85 | N12: 65.53 | O12: 46.27 | P12: 20.87 | Q12: 79.71 | R12: 123 | S12: 57.05 | T12: 2.78 | U12: 26.27 | V12: 138.6 | W12: 67700 | X12: 2169.5 | Y12: 4097 | Z12: 4.08 | AA12: 12.58 | AB12: 72 | AC12: 11.3 | AD12: 3.5 | AE12: 4.39 | AF12: 25.36 | AH12: 12.93 | AI12: 171.55 | AJ12: 39.02 | AK12: 43.99 | AL12: 239.6 | AM12: 8 | AN12: 414 | AO12: 1375 | AP12: 412.3 | AQ12: 1013.5 | AR12: 14.95 | AS12: 73.54 | AT12: 116.04 | AU12: 10.44 | AV12: 12.36
A13: 46281 | B13: 35.78 | C13: 144.65 | D13: 11.8 | E13: 19.29 | F13: 5 | G13: 41.51 | H13: 338.36 | I13: 22.36 | J13: 27.15 | K13: 5.69 | L13: 95.98 | M13: 19.65 | N13: 68.37 | O13: 46.32 | P13: 20.17 | Q13: 77.96 | R13: 115.4 | S13: 57.09 | T13: 2.76 | U13: 27.13 | V13: 139.89 | W13: 67030 | X13: 2129.5 | Y13: 4013 | Z13: 4.22 | AA13: 12.65 | AB13: 72.35 | AC13: 11.44 | AD13: 3.53 | AE13: 4.43 | AF13: 25 | AH13: 12.73 | AI13: 170.75 | AJ13: 38.72 | AK13: 43.75 | AL13: 238 | AM13: 8.33 | AN13: 412.34 | AO13: 1383 | AP13: 410.95 | AQ13: 1009 | AR13: 14.73 | AS13: 71.7 | AT13: 117.94 | AU13: 10.39 | AV13: 11.8
A14: 46280 | B14: 36.22 | C14: 141.9 | D14: 11.6 | E14: 19.12 | F14: 4.96 | G14: 40.46 | H14: 335.23 | I14: 21.81 | J14: 26.76 | K14: 5.64 | L14: 98.37 | M14: 19.82 | N14: 67 | O14: 45.89 | P14: 20.43 | Q14: 77.51 | R14: 111.48 | S14: 56.49 | T14: 2.73 | U14: 26.62 | V14: 135.17 | W14: 66620 | X14: 2141 | Y14: 4115 | Z14: 4.31 | AA14: 12.8 | AB14: 73.25 | AC14: 11.28 | AD14: 3.5 | AE14: 4.38 | AF14: 25.55 | AH14: 12.71 | AI14: 169.85 | AJ14: 39.14 | AK14: 43.46 | AL14: 234.35 | AM14: 8.05 | AN14: 406.92 | AO14: 1375 | AP14: 406.45 | AQ14: 977.6 | AR14: 14.05 | AS14: 71.61 | AT14: 117.11 | AU14: 10.32 | AV14: 11.6
A15: 46279 | B15: 37.05 | C15: 143.9 | D15: 11.63 | E15: 19.53 | F15: 5.03 | G15: 42.34 | H15: 341.43 | I15: 21.71 | J15: 27.47 | K15: 5.77 | L15: 100.3 | M15: 20.23 | N15: 67.42 | O15: 47.44 | P15: 20.92 | Q15: 80.54 | R15: 111.49 | S15: 57.67 | T15: 2.72 | U15: 27.55 | V15: 140.62 | W15: 66760 | X15: 2139 | Y15: 4071 | Z15: 4.37 | AA15: 12.93 | AB15: 73.65 | AC15: 11.35 | AD15: 3.42 | AE15: 4.4 | AF15: 25.35 | AH15: 13.07 | AI15: 173.05 | AJ15: 39.08 | AK15: 44.34 | AL15: 238 | AM15: 8.42 | AN15: 409.08 | AO15: 1414 | AP15: 417.45 | AQ15: 997.6 | AR15: 14.16 | AS15: 73.01 | AT15: 117.91 | AU15: 10.89 | AV15: 11.63
A16: 46276 | B16: 36.8 | C16: 142.75 | D16: 11.61 | E16: 19.93 | F16: 5.11 | G16: 42.93 | H16: 339.09 | I16: 21.69 | J16: 27.41 | K16: 5.85 | L16: 98.97 | M16: 20.16 | N16: 66.62 | O16: 48.45 | P16: 21.51 | Q16: 81.27 | R16: 112.48 | S16: 56.92 | T16: 2.73 | U16: 28.07 | V16: 145.23 | W16: 66480 | X16: 2090 | Y16: 3989 | Z16: 4.37 | AA16: 13.01 | AB16: 72.45 | AC16: 11.59 | AD16: 3.29 | AE16: 4.38 | AF16: 25.06 | AH16: 13.17 | AI16: 175 | AJ16: 38.5 | AK16: 44.69 | AL16: 238.6 | AM16: 8.58 | AN16: 413.78 | AO16: 1399.5 | AP16: 415.3 | AQ16: 1018 | AR16: 13.89 | AS16: 70.64 | AT16: 118.49 | AU16: 10.99 | AV16: 11.61
A17: 46275 | B17: 36.62 | C17: 142.7 | D17: 11.63 | E17: 19.29 | F17: 4.97 | G17: 41.56 | H17: 336.67 | I17: 22.22 | J17: 26.85 | K17: 5.87 | L17: 96.88 | M17: 20.12 | N17: 66.16 | O17: 48.93 | P17: 20.91 | Q17: 79.88 | R17: 108.83 | S17: 56.42 | T17: 2.74 | U17: 27.41 | V17: 142.93 | W17: 66810 | X17: 2081.5 | Y17: 4020 | Z17: 4.36 | AA17: 13.06 | AB17: 72.05 | AC17: 11.7 | AD17: 3.37 | AE17: 4.43 | AF17: 25.67 | AH17: 12.62 | AI17: 172.9 | AJ17: 38.5 | AK17: 43.6 | AL17: 234.15 | AM17: 8.57 | AN17: 408.64 | AO17: 1409 | AP17: 406.5 | AQ17: 1029.5 | AR17: 12.88 | AS17: 69.35 | AT17: 115.87 | AU17: 10.54 | AV17: 11.63
A18: 46274 | B18: 37.35 | C18: 146.45 | D18: 11.7 | E18: 19.59 | F18: 4.9 | G18: 43.46 | H18: 335.61 | I18: 22.75 | J18: 26.84 | K18: 6 | L18: 99.72 | M18: 20.35 | N18: 67.16 | O18: 50.45 | P18: 21.36 | Q18: 80.23 | R18: 111.09 | S18: 56.06 | T18: 2.75 | U18: 27.77 | V18: 152.08 | W18: 66860 | X18: 2095 | Y18: 4100 | Z18: 4.31 | AA18: 13.37 | AB18: 73.5 | AC18: 11.77 | AD18: 3.47 | AE18: 4.5 | AF18: 26.09 | AH18: 12.91 | AI18: 175.1 | AJ18: 39.68 | AK18: 45.16 | AL18: 232.25 | AM18: 8.74 | AN18: 402.33 | AO18: 1409 | AP18: 411.25 | AQ18: 1035 | AR18: 12.71 | AS18: 68.51 | AT18: 113.71 | AU18: 10.51 | AV18: 11.7
A19: 46273 | B19: 38.1 | C19: 147.85 | D19: 12.03 | E19: 20.05 | F19: 5.06 | G19: 43.16 | H19: 347.23 | I19: 23.13 | J19: 27.27 | K19: 6.34 | L19: 103.19 | M19: 20.85 | N19: 70.73 | O19: 51.55 | P19: 22.38 | Q19: 82.6 | R19: 114.35 | S19: 57.71 | T19: 2.81 | U19: 28.69 | V19: 151.43 | W19: 68730 | X19: 2107.5 | Y19: 4049 | Z19: 4.48 | AA19: 14.23 | AB19: 75.95 | AC19: 11.7 | AD19: 3.53 | AE19: 4.55 | AF19: 26.56 | AH19: 13.2 | AI19: 183.65 | AJ19: 40.1 | AK19: 45.96 | AL19: 244.4 | AM19: 9.05 | AN19: 405.94 | AO19: 1442.5 | AP19: 426.55 | AQ19: 1078 | AR19: 13.1 | AS19: 71.26 | AT19: 117.58 | AU19: 10.66 | AV19: 12.03
A20: 46272 | C20: 147.6 | I20: 23.53 | W20: 69160 | X20: 2104 | Y20: 4164 | Z20: 4.39 | AA20: 13.75 | AB20: 75.85 | AC20: 11.8 | AD20: 3.5 | AE20: 4.51 | AF20: 26.21 | AI20: 185.4 | AJ20: 39.96 | AK20: 46.18 | AL20: 241.4 | AM20: 9.09 | AO20: 1475 | AP20: 431.2 | AQ20: 1102
A21: 46269 | B21: 38.4 | C21: 149.15 | D21: 12.56 | E21: 20.76 | F21: 5.25 | G21: 43.68 | H21: 351.2 | I21: 23.83 | J21: 27.99 | K21: 6.11 | L21: 100.61 | M21: 21.06 | N21: 73.59 | O21: 53.4 | P21: 22.43 | Q21: 85.81 | R21: 117.53 | S21: 57.72 | T21: 2.87 | U21: 29.53 | V21: 149.67 | W21: 69100 | X21: 2113 | Y21: 4266 | Z21: 4.35 | AA21: 13.53 | AB21: 76.1 | AC21: 11.84 | AD21: 3.43 | AE21: 4.45 | AF21: 26.6 | AH21: 13.45 | AI21: 185.45 | AJ21: 39.34 | AK21: 45.84 | AL21: 245.2 | AM21: 9.11 | AN21: 409.95 | AO21: 1457 | AP21: 429.1 | AQ21: 1103.5 | AR21: 13.56 | AS21: 74.33 | AT21: 122.14 | AU21: 11.28 | AV21: 12.56
A22: 46268 | B22: 38.77 | C22: 148.7 | D22: 12.65 | E22: 19.55 | F22: 5.19 | G22: 42.3 | H22: 344.2 | I22: 24.26 | J22: 28.36 | K22: 6.07 | L22: 121.77 | M22: 20.7 | N22: 73.67 | O22: 53.68 | P22: 22.32 | Q22: 84.5 | R22: 116.01 | S22: 57.79 | T22: 2.79 | U22: 28.51 | V22: 143.54 | W22: 68000 | X22: 2098.5 | Y22: 4195 | Z22: 4.3 | AA22: 13.24 | AB22: 75.85 | AC22: 11.73 | AD22: 3.62 | AE22: 4.41 | AF22: 25.94 | AH22: 13.14 | AI22: 183.65 | AJ22: 39.56 | AK22: 46.17 | AL22: 244.6 | AM22: 9.09 | AN22: 417.93 | AO22: 1481.5 | AP22: 431.05 | AQ22: 1097 | AR22: 13.24 | AS22: 72.46 | AT22: 122.6 | AU22: 11.25 | AV22: 12.65
A23: 46267 | B23: 38.24 | C23: 149.55 | D23: 12.56 | E23: 19.28 | F23: 5.15 | G23: 41.99 | H23: 336.5 | I23: 24.62 | J23: 27.8 | K23: 5.98 | L23: 120.07 | M23: 20.46 | N23: 72.49 | O23: 51.46 | P23: 22.06 | Q23: 83.76 | R23: 115.79 | S23: 56.86 | T23: 2.82 | U23: 28.56 | V23: 136.6 | W23: 70400 | X23: 2091.5 | Y23: 4213 | Z23: 4.25 | AA23: 13.24 | AB23: 76.4 | AC23: 11.69 | AD23: 3.67 | AE23: 4.42 | AF23: 25.3 | AH23: 13.22 | AI23: 189.55 | AJ23: 40 | AK23: 46.56 | AL23: 249.65 | AM23: 9.32 | AN23: 413.23 | AO23: 1532 | AP23: 439 | AQ23: 1075.5 | AR23: 12.71 | AS23: 72.29 | AT23: 123.14 | AU23: 11.26 | AV23: 12.56
A24: 46266 | B24: 38.12 | C24: 147.95 | D24: 13.04 | E24: 19.33 | F24: 4.92 | G24: 41.44 | H24: 340.82 | I24: 24.52 | J24: 27.73 | K24: 5.94 | L24: 118 | M24: 20.36 | N24: 74.64 | O24: 50.27 | P24: 22 | Q24: 84.58 | R24: 115.28 | S24: 56.81 | T24: 2.74 | U24: 29.46 | V24: 140.68 | W24: 71260 | X24: 2127 | Y24: 4371 | Z24: 4.3 | AA24: 13.39 | AB24: 78.35 | AC24: 12.31 | AD24: 3.76 | AE24: 4.5 | AF24: 25.11 | AH24: 13.09 | AI24: 188.75 | AJ24: 40.32 | AK24: 46.15 | AL24: 247.2 | AM24: 9.41 | AN24: 410.21 | AO24: 1542.5 | AP24: 445 | AQ24: 1070 | AR24: 12.79 | AS24: 72.87 | AT24: 122.14 | AU24: 11.25 | AV24: 13.04
A25: 46265 | B25: 39.06 | C25: 151.4 | D25: 13.58 | E25: 19.73 | F25: 5.04 | G25: 43.18 | H25: 346.9 | I25: 25.42 | J25: 28.5 | K25: 6.25 | L25: 120.26 | M25: 20.76 | N25: 75.41 | O25: 52.13 | P25: 22.31 | Q25: 87.08 | R25: 120.38 | S25: 57.4 | T25: 2.84 | U25: 30.55 | V25: 143.08 | W25: 72450 | X25: 2149 | Y25: 4500 | Z25: 4.27 | AA25: 13.63 | AB25: 77.7 | AC25: 12.39 | AD25: 3.67 | AE25: 4.51 | AF25: 25.38 | AH25: 13.44 | AI25: 192.15 | AJ25: 41.02 | AK25: 47.11 | AL25: 254.05 | AM25: 9.57 | AN25: 422.6 | AO25: 1581 | AP25: 453.3 | AR25: 13.25 | AS25: 74.16 | AT25: 123.39 | AU25: 11.45 | AV25: 13.58
A26: 46262 | B26: 39.6 | C26: 154.2 | D26: 13.73 | E26: 20.34 | F26: 5.08 | G26: 44.24 | H26: 354.04 | I26: 25.63 | J26: 28.85 | K26: 6.17 | L26: 120.81 | M26: 21.29 | N26: 76.99 | O26: 53.12 | P26: 23.48 | Q26: 87.76 | R26: 122.23 | S26: 58.01 | T26: 3.02 | U26: 31.05 | V26: 148.42 | W26: 71260 | X26: 2190 | Y26: 4601 | Z26: 4.42 | AA26: 13.65 | AB26: 77.4 | AC26: 12.48 | AD26: 3.78 | AE26: 4.57 | AF26: 24.47 | AH26: 13.67 | AI26: 194.55 | AJ26: 41.64 | AK26: 47.72 | AL26: 254.2 | AM26: 9.49 | AN26: 420.54 | AO26: 1598 | AP26: 458.15 | AQ26: 1084 | AR26: 13.5 | AS26: 75.79 | AT26: 125.49 | AU26: 11.46 | AV26: 13.73
A27: 46261 | B27: 38.44 | C27: 153.1 | D27: 13.64 | E27: 19.76 | F27: 5.07 | G27: 44.69 | H27: 351.9 | I27: 26.02 | J27: 28.95 | K27: 5.88 | L27: 115 | M27: 21.05 | N27: 76.48 | O27: 53.23 | P27: 20.79 | Q27: 86.33 | R27: 121.69 | S27: 56.84 | T27: 3.02 | U27: 30.52 | V27: 145.75 | W27: 71540 | X27: 2170 | Y27: 4467 | Z27: 4.42 | AA27: 13.68 | AB27: 77.8 | AC27: 12.49 | AD27: 3.66 | AE27: 4.73 | AF27: 24.03 | AH27: 13.64 | AI27: 191.05 | AJ27: 40.96 | AK27: 47.1 | AL27: 250.55 | AM27: 9.25 | AN27: 414.04 | AO27: 1563 | AP27: 447.4 | AQ27: 1072 | AR27: 13.18 | AS27: 76.16 | AT27: 123.24 | AU27: 11.23 | AV27: 13.64
A28: 46260 | B28: 38.59 | C28: 150.7 | D28: 13.73 | E28: 20.1 | F28: 5.15 | G28: 45.11 | H28: 362.32 | I28: 25 | J28: 29.23 | K28: 5.96 | L28: 116.35 | M28: 21.43 | N28: 77.18 | O28: 53.58 | P28: 21.15 | Q28: 89.47 | R28: 123.64 | S28: 58.16 | T28: 2.82 | U28: 31.08 | V28: 147.75 | W28: 72120 | X28: 2166.5 | Y28: 4536 | Z28: 4.46 | AA28: 13.57 | AB28: 78.75 | AC28: 12.64 | AD28: 3.75 | AE28: 4.76 | AF28: 24.14 | AH28: 13.89 | AI28: 191 | AJ28: 40.86 | AK28: 47.59 | AL28: 252.75 | AM28: 9.52 | AN28: 412.83 | AO28: 1547.5 | AP28: 453.8 | AQ28: 1088 | AR28: 13.6 | AS28: 78.51 | AT28: 130.25 | AU28: 11.28 | AV28: 13.73
A29: 46259 | B29: 39.48 | C29: 152.6 | D29: 13.65 | E29: 20.47 | F29: 5.12 | G29: 45.5 | H29: 362.6 | I29: 25 | J29: 28.83 | K29: 5.93 | L29: 118.33 | M29: 21.1 | N29: 80.01 | O29: 54.59 | P29: 20.15 | Q29: 88.74 | R29: 122.89 | S29: 58.94 | T29: 2.83 | U29: 31.59 | V29: 108.9 | W29: 72530 | X29: 2185 | Y29: 4695 | Z29: 4.48 | AA29: 13.57 | AB29: 71.9 | AC29: 12.77 | AD29: 3.79 | AE29: 4.76 | AF29: 24.03 | AH29: 13.85 | AI29: 187.05 | AJ29: 40.9 | AK29: 47.18 | AL29: 247.2 | AM29: 9.37 | AN29: 421.85 | AO29: 1556.5 | AP29: 450.7 | AQ29: 1080 | AR29: 13.3 | AS29: 74.52 | AT29: 130.12 | AU29: 11.37 | AV29: 13.65
A30: 46258 | B30: 40.75 | C30: 155.25 | D30: 13.86 | E30: 20.87 | F30: 5.37 | G30: 45.91 | H30: 370.82 | I30: 25.29 | J30: 29.51 | K30: 6.07 | L30: 122.78 | M30: 21.72 | N30: 83.23 | O30: 54.95 | P30: 20.36 | Q30: 92.08 | R30: 125.84 | S30: 60.08 | T30: 2.82 | U30: 31.24 | V30: 112.36 | W30: 72840 | X30: 2172 | Y30: 4766 | Z30: 4.44 | AA30: 13.66 | AB30: 72.7 | AC30: 12.71 | AD30: 3.57 | AE30: 4.74 | AF30: 24.17 | AH30: 14.31 | AI30: 188.2 | AJ30: 40.78 | AK30: 48.25 | AL30: 255.75 | AM30: 9.32 | AN30: 424.44 | AO30: 1580.5 | AP30: 459.35 | AQ30: 1078 | AR30: 13.68 | AS30: 77.03 | AT30: 132.16 | AU30: 11.4 | AV30: 13.86
A31: 46255 | B31: 40.76 | C31: 154.45 | D31: 13.9 | E31: 20.96 | F31: 5.39 | G31: 46.08 | H31: 372.59 | I31: 25.02 | J31: 30.02 | K31: 6.09 | L31: 121.07 | M31: 21.49 | N31: 82.01 | O31: 56.17 | P31: 19.8 | Q31: 91.68 | R31: 122.11 | S31: 60.33 | T31: 2.84 | U31: 32.63 | V31: 109.01 | W31: 73510 | X31: 2139 | Y31: 4689 | Z31: 4.65 | AA31: 14.25 | AB31: 74.1 | AC31: 13.15 | AD31: 3.51 | AE31: 4.91 | AF31: 24.29 | AH31: 14.37 | AI31: 185.75 | AJ31: 41.1 | AK31: 47.1 | AL31: 254.3 | AM31: 9.27 | AN31: 436.54 | AO31: 1573 | AP31: 452.5 | AQ31: 1069.5 | AR31: 13.65 | AS31: 78.5 | AT31: 130.17 | AU31: 12.02 | AV31: 13.9
A32: 46254 | B32: 40.21 | C32: 151 | D32: 13.63 | E32: 20.45 | F32: 5.3 | G32: 45.71 | H32: 372.52 | I32: 25.06 | J32: 29.9 | K32: 5.79 | L32: 115.69 | M32: 21.23 | N32: 78.99 | O32: 55.45 | P32: 19.65 | Q32: 88.86 | R32: 123.09 | S32: 59.44 | T32: 2.8 | U32: 32.53 | V32: 105.02 | W32: 76280 | X32: 2138.5 | Y32: 4917 | Z32: 4.64 | AA32: 14.46 | AB32: 74.9 | AC32: 14.15 | AD32: 3.57 | AE32: 4.83 | AF32: 24.97 | AH32: 13.95 | AI32: 182.95 | AJ32: 41.24 | AK32: 46.94 | AL32: 250.6 | AM32: 9.12 | AN32: 428.37 | AO32: 1549.5 | AP32: 443.1 | AQ32: 1056.5 | AR32: 13.77 | AS32: 76.09 | AT32: 129.82 | AU32: 11.78 | AV32: 13.63
A33: 46253 | B33: 41.05 | C33: 155.9 | D33: 13.77 | E33: 20.85 | F33: 5.25 | G33: 47.34 | H33: 377.96 | I33: 25.53 | J33: 31.26 | K33: 6.16 | L33: 119.45 | M33: 22 | N33: 82.17 | O33: 57.03 | P33: 20.1 | Q33: 91.57 | R33: 125.73 | S33: 60.32 | T33: 2.82 | U33: 34.02 | V33: 105.45 | W33: 74940 | X33: 2100 | Y33: 4853 | Z33: 4.69 | AA33: 14.21 | AB33: 73.65 | AC33: 14.15 | AD33: 3.52 | AE33: 4.93 | AF33: 25.2 | AH33: 14.37 | AI33: 185.45 | AJ33: 40.9 | AK33: 47.67 | AL33: 260.05 | AM33: 9.34 | AN33: 425.18 | AO33: 1582.5 | AP33: 456 | AQ33: 1083 | AR33: 14.4 | AS33: 78.99 | AT33: 131.72 | AU33: 12.08 | AV33: 13.77
A34: 46252 | B34: 40.06 | C34: 154.7 | D34: 13.47 | E34: 19.99 | F34: 5.07 | G34: 46.75 | H34: 378.25 | I34: 25.83 | J34: 31.03 | K34: 5.93 | L34: 119.01 | M34: 22.01 | N34: 82.3 | O34: 55.76 | P34: 20.08 | Q34: 89.51 | R34: 128.66 | S34: 57.89 | T34: 2.73 | U34: 33.62 | V34: 103.38 | W34: 75010 | X34: 2119 | Y34: 4897 | Z34: 4.61 | AA34: 14.25 | AB34: 72.1 | AC34: 14.1 | AD34: 3.52 | AE34: 4.81 | AF34: 26.37 | AH34: 14.31 | AI34: 187.05 | AJ34: 41.54 | AK34: 47.17 | AL34: 255.7 | AM34: 9.48 | AN34: 412.44 | AO34: 1560.5 | AP34: 447.75 | AQ34: 1074.5 | AR34: 14.42 | AS34: 78.73 | AT34: 132.26 | AU34: 11.82 | AV34: 13.47
A35: 46251 | B35: 39.09 | C35: 152.6 | D35: 13.37 | E35: 19.83 | F35: 5.29 | G35: 46.6 | H35: 379.31 | I35: 25.63 | J35: 31.31 | K35: 6.04 | L35: 115.74 | M35: 22.57 | N35: 81.77 | O35: 55.89 | P35: 20.18 | Q35: 90.11 | R35: 129.97 | S35: 57.09 | T35: 2.78 | U35: 32.57 | V35: 105.16 | W35: 76820 | X35: 2098 | Y35: 5148 | Z35: 4.59 | AA35: 14.45 | AB35: 72.15 | AC35: 14.26 | AD35: 3.58 | AE35: 4.67 | AF35: 26.42 | AH35: 14.48 | AI35: 186.4 | AJ35: 41.28 | AK35: 47.06 | AL35: 257.1 | AM35: 9.39 | AN35: 417.1 | AO35: 1550 | AP35: 446 | AQ35: 1050 | AR35: 14.67 | AS35: 78.18 | AT35: 129.02 | AU35: 11.77 | AV35: 13.37

Sheet 运动服饰 Prices
A1: 运动服饰 收盘价（本地货币）
A2: Date | B2: NKE.N | C2: ADDY | D2: ZGN.N | E2: WWW.N | F2: VSCO.N | G2: UAA.N | H2: SKX.N | I2: SHOO.O | J2: RL.N | K2: PUM.DF | L2: ONON.N | M2: NWL.O | N2: LULU.O | O2: LEVI.N | P2: KTB.N | Q2: HBI.N | R2: GIL.N | S2: GAP.N | T2: DECK.N | U2: CROX.O | V2: COLM.O | W2: BZUN.O | X2: AS.N | Y2: ANF.N | Z2: 9983.T | AA2: 8111.T | AB2: 7936.T | AC2: 3998.HK | AD2: 2331.HK | AE2: 2020.HK | AF2: 1836.HK | AG2: 1368.HK | AH2: 1361.HK | AI2: 002832.SZ
A3: 45257 | B3: 106.19985 | C3: 188.34645 | D3: 11.330142 | E3: 8.4159317 | G3: 8.6000004 | I3: 36.319511 | J3: 128.09523 | K3: 57.084995 | L3: 30.26 | M3: 7.0632625 | N3: 466.60999 | O3: 14.565889 | P3: 49.593102 | R3: 35.420803 | S3: 19.247845 | T3: 114.17667 | U3: 106.56 | V3: 75.909065 | W3: 2.8099999 | Y3: 77.879997 | Z3: 35938.934 | AA3: 3566.5745 | AB3: 1273.1725 | AC3: 2.6982057 | AD3: 19.263432 | AE3: 72.140068 | AF3: 7.1965842 | AG3: 3.5060871 | AH3: 2.8189254 | AI3: 29.6479
A4: 45264 | B4: 108.47395 | C4: 187.49316 | D4: 11.43612 | E4: 8.2770538 | G4: 8.46 | I4: 36.693356 | J4: 126.30268 | K4: 53.636909 | L4: 28.629999 | M4: 7.3332529 | N4: 489.64001 | O4: 13.93541 | P4: 50.027584 | R4: 34.82951 | S4: 19.852201 | T4: 115.89667 | U4: 103.74 | V4: 76.251625 | W4: 2.9300001 | Y4: 78.650002 | Z4: 34049.961 | AA4: 3444.2302 | AB4: 1153.5847 | AC4: 2.7886946 | AD4: 18.909163 | AE4: 67.111305 | AF4: 7.3169036 | AG4: 3.5688367 | AH4: 2.7863364 | AI4: 29.39883
A5: 45271 | B5: 113.75213 | C5: 186.67865 | D5: 11.2627 | E5: 8.3140879 | G5: 8.6000004 | I5: 39.663448 | J5: 135.2079 | K5: 50.62941 | L5: 30.879999 | M5: 7.6206603 | N5: 491.45999 | O5: 14.278464 | P5: 54.265808 | R5: 32.883938 | S5: 19.513395 | T5: 117.135 | U5: 107.11 | V5: 77.564842 | W5: 2.97 | Y5: 84.169998 | Z5: 34466.504 | AA5: 3458.1682 | AB5: 1100.5966 | AC5: 2.8304417 | AD5: 16.827827 | AE5: 68.482788 | AF5: 7.4146628 | AG5: 3.4747128 | AH5: 2.7456007 | AI5: 29.238714
A6: 45278 | B6: 101.10883 | C6: 178.5529 | D6: 11.147086 | E6: 8.4437056 | G6: 8.9700003 | I6: 40.518341 | J6: 139.44481 | K6: 47.794319 | L6: 28.030001 | M6: 7.4551821 | N6: 510 | O6: 15.233454 | P6: 57.802273 | R6: 31.195871 | S6: 19.385199 | T6: 115.615 | U6: 98.18 | V6: 76.308723 | W6: 2.8199999 | Y6: 92.580002 | Z6: 34495.562 | AA6: 3119.0107 | AB6: 1089.4156 | AC6: 2.8805377 | AD6: 17.536366 | AE6: 67.614182 | AF6: 7.098825 | AG6: 3.4668696 | AH6: 2.6559815 | AI6: 28.020067
A7: 45285 | B7: 101.60485 | C7: 178.5723 | D7: 11.147086 | E7: 8.322217 | G7: 8.79 | I7: 39.456768 | J7: 138.94298 | K7: 48.388157 | L7: 26.969999 | M7: 7.5596943 | N7: 511.29001 | O7: 15.335443 | P7: 57.63607 | R7: 31.529673 | S7: 19.14712 | T7: 111.405 | U7: 93.410004 | V7: 75.690186 | W7: 2.74 | Y7: 88.220001 | Z7: 33894.969 | AA7: 3139.1431 | AB7: 1083.4667 | AC7: 2.930634 | AD7: 18.510609 | AE7: 69.259949 | AF7: 6.9258666 | AG7: 3.4590259 | AH7: 2.8270724 | AI7: 28.197969
A8: 45292 | B8: 95.531204 | C8: 168.21634 | D8: 10.53048 | E8: 7.2363014 | G8: 7.9000001 | I8: 38.460957 | J8: 137.70964 | K8: 44.987961 | L8: 26.57 | M8: 7.324542 | N8: 491.10001 | O8: 14.918216 | P8: 52.816128 | R8: 30.33753 | S8: 19.174788 | T8: 108.715 | U8: 86.459999 | V8: 71.722023 | W8: 2.4000001 | Y8: 90.540001 | Z8: 33420.301 | AA8: 2937.8169 | AB8: 1032.4572 | AC8: 2.8972366 | AD8: 16.686117 | AE8: 64.13974 | AF8: 7.3093834 | AG8: 2.9648793 | AH8: 2.7863364 | AI8: 27.993378
A9: 45299 | B9: 98.320007 | C9: 172.15315 | D9: 10.453404 | E9: 8.3690224 | G9: 7.9200001 | I9: 39.419186 | J9: 132.98831 | K9: 45.409393 | L9: 28.02 | M9: 7.3942175 | N9: 479.94 | O9: 14.742052 | P9: 53.120842 | R9: 29.994198 | S9: 18.667517 | T9: 117.78 | U9: 103.39 | V9: 73.644249 | W9: 2.24 | Y9: 96.790001 | Z9: 37721.352 | AA9: 3194.8953 | AB9: 1092.5408 | AC9: 2.930634 | AD9: 15.942149 | AE9: 67.522743 | AF9: 7.5199423 | AG9: 3.4119642 | AH9: 2.9411333 | AI9: 26.899263
A10: 45306 | B10: 95.250443 | C10: 159.68333 | D10: 9.9235086 | E10: 7.7137284 | G10: 7.5100002 | I10: 38.987045 | J10: 133.05573 | K10: 40.275574 | L10: 27.959999 | M10: 7.0981011 | N10: 484.01999 | O10: 14.463901 | P10: 54.108833 | R10: 30.614107 | S10: 17.468517 | T10: 124.875 | U10: 101.35 | V10: 74.605362 | W10: 2.0699999 | Y10: 101.11 | Z10: 37624.477 | AA10: 3119.0107 | AB10: 1143.3052 | AC10: 2.8805377 | AD10: 14.330223 | AE10: 60.116734 | AF10: 7.7004204 | AG10: 3.1452825 | AH10: 2.9085445 | AI10: 27.593094
A11: 45313 | B11: 96.158211 | C11: 172.46346 | D11: 10.925494 | E11: 8.0413761 | G11: 7.6799998 | I11: 40.27409 | J11: 138.8466 | K11: 36.51141 | L11: 26.25 | M11: 7.5684037 | N11: 478.03 | O11: 14.788411 | P11: 55.872444 | R11: 31.815783 | S11: 18.206364 | T11: 127.965 | U11: 102.96 | V11: 76.57518 | W11: 2.3599999 | Y11: 103.8 | Z11: 37653.539 | AA11: 3066.356 | AB11: 1107.0099 | AC11: 3.014128 | AD11: 15.162757 | AE11: 64.002609 | AF11: 7.8808985 | AG11: 3.1217513 | AH11: 2.981869 | AI11: 26.552347
A12: 45320 | B12: 94.249084 | C12: 169.70961 | D12: 12.640429 | E12: 8.0226526 | G12: 7.75 | I12: 39.823151 | J12: 142.38286 | K12: 36.837063 | L12: 27.700001 | M12: 7.2461596 | N12: 462.39999 | O12: 15.038747 | P12: 53.868767 | R12: 32.130512 | S12: 18.270924 | T12: 147.00999 | U12: 98.18 | V12: 77.422096 | W12: 2.1400001 | X12: 14.95 | Y12: 109.47 | Z12: 37605.105 | AA12: 3027.3296 | AB12: 1126.629 | AC12: 2.9723809 | AD12: 15.69416 | AE12: 60.893898 | AF12: 7.5124216 | AG12: 3.0433154 | AH12: 2.8270724 | AI12: 25.3248
A13: 45327 | B13: 97.795944 | C13: 166.52913 | D13: 12.052727 | E13: 8.2286034 | G13: 8.0900002 | I13: 39.221912 | J13: 168.62975 | K13: 38.838867 | L13: 29.5 | M13: 5.965889 | N13: 470.23999 | O13: 16.597235 | P13: 57.368294 | R13: 32.645512 | S13: 18.501505 | T13: 140.87 | U13: 107.54 | V13: 76.175499 | W13: 2.3499999 | X13: 14.94 | Y13: 110.11 | Z13: 38467.25 | AA13: 2808.6582 | AB13: 1172.2434 | AC13: 3.0809231 | AD13: 16.508982 | AE13: 64.596909 | AF13: 7.6703405 | AG13: 3.0433154 | AH13: 2.9981635 | AI13: 29.105288
A14: 45334 | B14: 96.869461 | C14: 170.89262 | D14: 12.495914 | E14: 8.6592236 | G14: 8.0699997 | I14: 41.20414 | J14: 174.25687 | K14: 40.428818 | L14: 31.74 | M14: 6.6800532 | N14: 449.60001 | O14: 16.681295 | P14: 58.199314 | R14: 32.941162 | S14: 18.224812 | T14: 143.83 | U14: 118.98 | V14: 77.165161 | W14: 2.5 | X14: 15.97 | Y14: 120.9 | Z14: 40763.082 | AA14: 2767.4636 | AB14: 1447.6471 | AC14: 3.2228625 | AD14: 18.820597 | AE14: 71.68293 | AF14: 8.0914574 | AG14: 3.3805897 | AH14: 3.1040766
A15: 45341 | B15: 98.853455 | C15: 183.05212 | D15: 13.680953 | E15: 9.2489882 | G15: 8.4300003 | I15: 41.711437 | J15: 181.57016 | K15: 40.524601 | L15: 32.200001 | M15: 6.3142619 | N15: 457.89001 | O15: 16.980177 | P15: 58.587132 | R15: 33.818573 | S15: 17.938894 | T15: 146.74667 | U15: 118.31 | V15: 78.725792 | W15: 2.4100001 | X15: 15.54 | Y15: 122.82 | Z15: 41915.84 | AA15: 2724.7205 | AB15: 1539.1213 | AC15: 3.2562604 | AD15: 18.510609 | AE15: 72.551514 | AF15: 7.8808985 | AG15: 3.3727465 | AH15: 3.3810813 | AI15: 27.2017
A16: 45348 | B16: 95.684669 | C16: 181.32613 | D16: 14.01816 | E16: 9.5017405 | G16: 8.8900003 | I16: 40.123768 | J16: 178.24593 | K16: 40.084011 | L16: 34.650002 | M16: 6.6386814 | N16: 458.5 | O16: 17.036215 | P16: 54.552048 | R16: 33.007919 | S16: 17.579193 | T16: 150.54834 | U16: 124.81 | V16: 77.269844 | W16: 2.3599999 | X16: 17.66 | Y16: 131.37 | Z16: 43154.984 | AA16: 2757.2424 | AB16: 1567.5691 | AC16: 3.3147056 | AD16: 17.757786 | AE16: 69.625687 | AF16: 8.0463381 | AG16: 3.4511824 | AH16: 3.4462581 | AI16: 27.441874
A17: 45355 | B17: 93.130089 | C17: 183.40118 | D17: 13.921815 | E17: 9.3613214 | G17: 8.4399996 | I17: 39.645504 | J17: 169.61255 | K17: 39.720047 | L17: 33.09 | M17: 6.9112625 | N17: 460.39001 | O17: 17.017536 | P17: 57.144482 | R17: 32.492916 | S17: 19.294689 | T17: 152.03334 | U17: 125.04 | V17: 77.072098 | W17: 2.4400001 | X17: 15.49 | Y17: 118.64 | Z17: 42240.727 | AA17: 2999.144 | AB17: 1560.7024 | AC17: 3.3481035 | AD17: 17.022673 | AE17: 68.437065 | AF17: 8.1816969 | AG17: 3.2786233 | AH17: 3.4951415 | AI17: 27.397398
A18: 45362 | B18: 93.580879 | C18: 198.77997 | D18: 14.201214 | E18: 9.5017405 | G18: 7.1500001 | I18: 39.305607 | J18: 174.97951 | K18: 40.026543 | L18: 33.23 | M18: 7.1926374 | N18: 464.94 | O18: 16.989517 | P18: 54.938023 | R18: 32.786671 | S18: 21.75725 | T18: 151.63333 | U18: 128.17 | V18: 76.155106 | W18: 2.8299999 | X18: 15.13 | Y18: 125.89 | Z18: 42814.57 | AA18: 3031.9758 | AB18: 1585.7167 | AC18: 3.4232476 | AD18: 18.333473 | AE18: 71.591476 | AF18: 8.9186506 | AG18: 3.710021 | AH18: 3.6417906 | AI18: 27.851055
A19: 45369 | B19: 88.152359 | C19: 194.1741 | D19: 14.085601 | E19: 9.8387489 | G19: 7.1500001 | I19: 38.842964 | J19: 180.76077 | K19: 37.545837 | L19: 34.709999 | M19: 6.7354035 | N19: 403.19 | O19: 17.428497 | P19: 53.383259 | R19: 35.9147 | S19: 25.898415 | T19: 153.74001 | U19: 141.62 | V19: 74.053741 | W19: 2.3 | X19: 16.27 | Y19: 134.97 | Z19: 46111.742 | AA19: 3097.3293 | AB19: 1712.5055 | AC19: 3.3731515 | AD19: 18.112053 | AE19: 72.688667 | AF19: 9.324728 | AG19: 3.8198311 | AH19: 3.6580846 | AI19: 26.481186
A20: 45376 | B20: 88.265076 | C20: 200.7193 | D20: 14.114504 | E20: 10.587907 | G20: 7.3800001 | I20: 39.919312 | J20: 181.6599 | K20: 40.246838 | L20: 35.380001 | M20: 7.0607419 | N20: 390.64999 | O20: 18.670719 | P20: 56.092449 | R20: 35.626846 | S20: 25.40959 | T20: 156.87666 | U20: 143.8 | V20: 77.540108 | W20: 2.3 | X20: 16.299999 | Y20: 125.33 | Z20: 45654.609 | AA20: 3103.0408 | AB20: 1790.2463 | AC20: 3.2646096 | AD20: 18.422041 | AE20: 76.071663 | AF20: 9.3848877 | AG20: 3.8041441 | AH20: 3.7477038 | AI20: 25.965261
A21: 45383 | B21: 83.437645 | C21: 195.48314 | D21: 11.522831 | E21: 9.152257 | G21: 6.8200002 | I21: 38.673012 | J21: 166.36353 | K21: 40.361774 | L21: 31.98 | M21: 6.357306 | N21: 356.87 | O21: 19.193766 | P21: 52.48951 | R21: 34.715305 | S21: 22.365973 | T21: 146.64833 | U21: 134.09 | V21: 72.086143 | W21: 2.3299999 | X21: 15.34 | Y21: 120.79 | Z21: 42950.738 | AA21: 3020.4646 | AB21: 1719.8625 | AC21: 3.3481035 | AD21: 18.377758 | AE21: 81.191879 | AF21: 9.8210449 | AG21: 3.764926 | AH21: 3.7395573 | AI21: 26.498976
A22: 45390 | B22: 86.405495 | C22: 190.44092 | D22: 10.89659 | E22: 8.6138887 | G22: 6.5599999 | I22: 36.907425 | J22: 155.08237 | K22: 38.685619 | L22: 32.869999 | M22: 6.2605834 | N22: 336.13 | O22: 17.96088 | P22: 50.236496 | R22: 34.149193 | S22: 20.885359 | T22: 135.72833 | U22: 125.54 | V22: 71.446167 | W22: 2.3699999 | X22: 14.19 | Y22: 111.83 | Z22: 41005.504 | AA22: 2935.6907 | AB22: 1757.8748 | AC22: 3.2980072 | AD22: 16.827827 | AE22: 77.854591 | AF22: 10.24216 | AG22: 3.7257082 | AH22: 3.7802927 | AI22: 25.867413
A23: 45397 | B23: 88.781624 | C23: 217.78528 | D23: 11.089279 | E23: 9.2372646 | G23: 6.73 | I23: 36.935745 | J23: 153.31183 | K23: 40.764053 | L23: 31.58 | M23: 6.0495524 | N23: 352.47 | O23: 19.193766 | P23: 52.554676 | R23: 33.774975 | S23: 19.270224 | T23: 133.39667 | U23: 120.54 | V23: 73.117699 | W23: 2.3199999 | X23: 13.77 | Y23: 110.36 | Z23: 39410.418 | AA23: 2822.6587 | AB23: 1626.917 | AC23: 3.6069348 | AD23: 14.8262 | AE23: 76.620262 | AF23: 10.512878 | AG23: 3.5688367 | AH23: 3.6336436 | AI23: 26.383337
A24: 45404 | B24: 88.396568 | C24: 223.89412 | D24: 11.590271 | E24: 10.295111 | G24: 6.8000002 | I24: 38.219814 | J24: 161.07127 | K24: 41.86552 | L24: 32.790001 | M24: 6.8497114 | N24: 364.70001 | O24: 19.735485 | P24: 57.907898 | R24: 33.870926 | S24: 19.817886 | T24: 138.91 | U24: 125.4 | V24: 76.413017 | W24: 2.75 | X24: 15.04 | Y24: 122.08 | Z24: 40256.586 | AA24: 2985.927 | AB24: 1645.3098 | AC24: 3.7906206 | AD24: 18.687746 | AE24: 82.289047 | AF24: 10.42264 | AG24: 3.9688594 | AH24: 3.8699117 | AI24: 26.418921
A25: 45411 | B25: 86.546364 | C25: 218.17316 | D25: 12.245417 | E25: 10.153434 | G25: 6.7399998 | I25: 37.379509 | J25: 161.22604 | K25: 42.880795 | L25: 33.27 | M25: 6.7354035 | N25: 355.14999 | O25: 20.548067 | P25: 61.119831 | R25: 31.759993 | S25: 20.040663 | T25: 140.39 | U25: 124.28 | V25: 77.377724 | W25: 2.75 | X25: 14.48 | Y25: 128.75999 | Z25: 39702.199 | AA25: 2936.0046 | AB25: 1658.0623 | AC25: 3.8741145 | AD25: 19.440567 | AE25: 85.534904 | AF25: 10.693357 | AG25: 4.133575 | AH25: 3.9781785 | AI25: 26.552347
A26: 45418 | B26: 85.409943 | C26: 217.59135 | D26: 11.869672 | E26: 12.741379 | G26: 6.71 | I26: 39.060123 | J26: 161.71944 | K26: 48.675495 | L26: 30.4 | M26: 7.1135006 | N26: 352.95999 | O26: 21.241714 | P26: 63.484554 | R26: 32.230156 | S26: 21.126701 | T26: 143.66499 | U26: 143.27 | V26: 80.300522 | W26: 2.74 | X26: 14.81 | Y26: 129.71001 | Z26: 39604.938 | AA26: 2923.7598 | AB26: 1777.9841 | AC26: 3.8240182 | AD26: 19.750553 | AE26: 84.300575 | AF26: 11.129514 | AG26: 4.3264098 | AH26: 3.9949646 | AI26: 26.410023
... A55: 45621 | B55: 74.60038 | C55: 216.99034 | D55: 7.8824754 | E55: 22.193701 | G55: 9.71 | I55: 43.445805 | J55: 225.88026 | K55: 43.141705 | L55: 58.330002 | M55: 8.6587152 | N55: 320.66 | O55: 16.638758 | P55: 86.633171 | R55: 48.317692 | S55: 22.82135 | T55: 195.96001 | U55: 105.6 | V55: 84.247803 | W55: 2.55 | X55: 26.33 | Y55: 149.69 | Z55: 49953.699 | AA55: 2805.0349 | AB55: 2957.7275 | AC55: 3.5580809 | AD55: 14.717245 | AE55: 72.329933 | AF55: 11.66186 | AG55: 4.7529244 | AH55: 3.500314 | AI55: 18.133163
A56: 45628 | B56: 79.09 | C56: 230.2 | D56: 8.2 | E56: 23.53 | F56: 41.92 | G56: 10.16 | I56: 46.18 | J56: 233.41 | K56: 43.16 | L56: 58.53 | M56: 9.76 | N56: 334.4 | O56: 18.18 | P56: 94.19 | R56: 50.11 | S56: 25.81 | T56: 201.9 | U56: 109.68 | V56: 88.1 | W56: 2.77 | X56: 26.13 | Y56: 157.31 | Z56: 50430 | AA56: 2945 | AB56: 3134 | AC56: 4.13 | AD56: 16.32 | AE56: 78.2 | AF56: 14.02 | AG56: 5.32 | AH56: 3.94 | AI56: 19.61
A57: 45635 | B57: 77.64 | C57: 238.6 | D57: 8.49 | E57: 22.59 | F57: 47.2 | G57: 10.18 | I57: 43.84 | J57: 228.13 | K57: 46.29 | L57: 55.02 | M57: 11.51 | N57: 404.79 | O57: 17.55 | P57: 87.87 | R57: 47.84 | S57: 25.41 | T57: 201.55 | U57: 110.59 | V57: 90.65 | W57: 2.9 | X57: 25.79 | Y57: 140.07 | Z57: 53670 | AA57: 2866.33 | AB57: 3053 | AC57: 4.02 | AD57: 17.44 | AE57: 83.75 | AF57: 14.8 | AG57: 5.59 | AH57: 4.26 | AI57: 19.15
A58: 45642 | B58: 77.2 | C58: 243 | D58: 8.87 | E58: 23.36 | F58: 45.89 | G58: 8.32 | I58: 43.82 | J58: 231.66 | K58: 45.14 | L58: 57.88 | M58: 10.84 | N58: 389.74 | O58: 17.11 | P58: 89.95 | R58: 48.64 | S58: 24.84 | T58: 211.12 | U58: 108.96 | V58: 89.85 | W58: 3.7 | X58: 27.65 | Y58: 146.85 | Z58: 52780 | AA58: 2749.33 | AB58: 3029 | AC58: 4 | AD58: 16.72 | AE58: 81.35 | AF58: 14.7 | AG58: 5.83 | AH58: 4.25 | AI58: 22.41
A59: 45649 | B59: 76.76 | C59: 234.9 | D59: 8.51 | E59: 22.72 | F59: 42.18 | G59: 8.43 | I59: 42.47 | J59: 230.41 | K59: 45.13 | L59: 56.65 | M59: 10.05 | N59: 383.49 | O59: 17.32 | P59: 86.57 | R59: 46.75 | S59: 24.01 | T59: 207.65 | U59: 113.27 | V59: 87.23 | W59: 3.06 | X59: 28.56 | Y59: 152.96 | Z59: 53180 | AA59: 2839 | AB59: 3100 | AC59: 4.13 | AD59: 16.56 | AE59: 80 | AF59: 15.96 | AG59: 5.69 | AH59: 4.23 | AI59: 20.55
A60: 45656 | B60: 74.65 | C60: 236.8 | D60: 8.25 | E60: 22.05 | F60: 41.89 | G60: 8.21 | I60: 42.23 | J60: 232.22 | K60: 44.36 | L60: 55.19 | M60: 10 | N60: 384.05 | O60: 17.34 | P60: 85.21 | R60: 46.28 | S60: 23.55 | T60: 205.76 | U60: 108.71 | V60: 83.47 | W60: 2.76 | X60: 28.4 | Y60: 154.65 | Z60: 53820 | AA60: 2948.33 | AB60: 3110 | AC60: 4.03 | AD60: 16.3 | AE60: 78 | AF60: 16.3 | AG60: 5.76 | AH60: 4.22 | AI60: 20.56
A61: 45663 | B61: 72 | C61: 239.5 | D61: 8 | E61: 22.35 | F61: 39.72 | G61: 8.47 | I61: 42.15 | J61: 242.96 | K61: 44.71 | L61: 54.62 | M61: 10.17 | N61: 395.31 | O61: 17.84 | P61: 86.8 | R61: 47.1 | S61: 24.08 | T61: 208.47 | U61: 112.07 | V61: 83.1 | W61: 2.97 | X61: 29.86 | Y61: 156.22 | Z61: 51550 | AA61: 2874.67 | AB61: 3059 | AC61: 3.64 | AD61: 15.8 | AE61: 75.15 | AF61: 16.08 | AG61: 5.49 | AH61: 4.08 | AI61: 19.58
A62: 45670 | B62: 72.08 | C62: 238.8 | D62: 7.63 | E62: 22.67 | F62: 35.82 | G62: 8.3 | I62: 40.26 | J62: 236.5 | K62: 41.52 | L62: 55.38 | M62: 9.71 | N62: 398.86 | O62: 17.42 | P62: 84.3 | R62: 47.97 | S62: 23.06 | T62: 204.59 | U62: 105.77 | V62: 83.2 | W62: 2.71 | X62: 29.1 | Y62: 135.72 | Z62: 48700 | AA62: 2845 | AB62: 3251 | AC62: 3.58 | AD62: 14.66 | AE62: 78 | AF62: 17.42 | AG62: 5.51 | AH62: 3.87 | AI62: 18.33
