Workbook
Name ___OR2: #REF!
Name ___OR3: #REF!
Name ___OR4: #REF!
Name __ANI01: #REF!
Name __ANI02: #REF!
Name __ANI03: #REF!
Name __ANI04: #REF!
Name __ANI05: #REF!
Name __ANI06: #REF!
Name __ANI07: #REF!
Name __ANI87: #REF!
Name __ANI88: #REF!
Name __ANI89: #REF!
Name __ANI90: #REF!
Name __ANI91: #REF!
Name __ANI92: #REF!
Name __ANI93: #REF!
Name __ANI94: #REF!
Name __ANI95: #REF!
Name __ANI96: #REF!
Name __ANI97: #REF!
Name __ANI98: #REF!
Name __ANI99: #REF!
Name __DPS01: #REF!
Name __DPS04: #REF!
Name __DPS98: #REF!
Name __DPS99: #REF!
Name __FEE01: #REF!
Name __FEE02: #REF!
Name __FEE03: #REF!
Name __FEE04: #REF!
Name __FEE05: #REF!
Name __FEE06: #REF!
Name __FEE07: #REF!
Name __FEE87: #REF!
Name __FEE88: #REF!
Name __FEE89: #REF!
Name __FEE90: #REF!
Name __FEE91: #REF!
Name __FEE92: #REF!
Name __FEE93: #REF!
Name __FEE94: #REF!
Name __FEE95: #REF!
Name __FEE96: #REF!
Name __FEE97: #REF!
Name __FEE98: #REF!
Name __FEE99: #REF!
Name __GBP01: #REF!
Name __GBP98: #REF!
Name __GBP99: #REF!
Name __GOI01: #REF!
Name __GOI02: #REF!
Name __GOI03: #REF!
Name __GOI04: #REF!
Name __GOI05: #REF!
Name __GOI06: #REF!
Name __GOI07: #REF!
Name __GOI87: #REF!
Name __GOI88: #REF!
Name __GOI89: #REF!

Sheet 1. Cover
F3: Amer Sports, Inc.
F4: COMPANY MODEL
B9: Sources: Company data, Goldman Sachs Global Investment Research
B11: Date: September 21st, 2026
B13: Brooke Roach, CFA
B14: Managing Director
B15: tel: 212-357-2421
B16: brooke.roach@gs.com
B18: Mentesnot Adamu
B19: Analyst
B20: tel: 801-744-0630
B21: mentesnot.adamu@gs.com
B23: Carly Chasen
B24: Analyst
... B26: carly.chasen@gs.com

Sheet 2. Consolidated
B1: Amer Sports, Inc.
B2: Annual Consolidated Financial Statements
B3: $ millions, FY ending Saturday closest to December 31
C5: 44196 | D5: 44286 | E5: 44377 | F5: 44469 | G5: 44561 | H5: 44561 | I5: =DATE(YEAR(D5)+1,MONTH(D5),DAY(D5)) -> 44651 | J5: =DATE(YEAR(E5)+1,MONTH(E5),DAY(E5)) -> 44742 | K5: =DATE(YEAR(F5)+1,MONTH(F5),DAY(F5)) -> 44834 | L5: =DATE(YEAR(G5)+1,MONTH(G5),DAY(G5)) -> 44926 | M5: =DATE(YEAR(H5)+1,MONTH(H5),DAY(H5)) -> 44926 | N5: =DATE(YEAR(I5)+1,MONTH(I5),DAY(I5)) -> 45016 | O5: =DATE(YEAR(J5)+1,MONTH(J5),DAY(J5)) -> 45107 | P5: =DATE(YEAR(K5)+1,MONTH(K5),DAY(K5)) -> 45199 | ... R5: =DATE(YEAR(M5)+1,MONTH(M5),DAY(M5)) -> 45291 | S5: =H5 -> 44561 | T5: =M5 -> 44926 | U5: =N5 -> 45016 | V5: =O5 -> 45107 | W5: =P5 -> 45199 | X5: =Q5 -> 45291 | Y5: =R5 -> 45291 | Z5: =DATE(YEAR(N5)+1,MONTH(N5),DAY(N5)) -> 45382 | AA5: =DATE(YEAR(O5)+1,MONTH(O5),DAY(O5)) -> 45473 | AB5: =DATE(YEAR(P5)+1,MONTH(P5),DAY(P5)) -> 45565 | AC5: =DATE(YEAR(Q5)+1,MONTH(Q5),DAY(Q5)) -> 45657 | AD5: =DATE(YEAR(R5)+1,MONTH(R5),DAY(R5)) -> 45657 | AE5: =DATE(YEAR(Z5)+1,MONTH(Z5),DAY(Z5)) -> 45747 | AF5: =DATE(YEAR(AA5)+1,MONTH(AA5),DAY(AA5)) -> 45838 | AG5: =DATE(YEAR(AB5)+1,MONTH(AB5),DAY(AB5)) -> 45930 | AH5: =DATE(YEAR(AC5)+1,MONTH(AC5),DAY(AC5)) -> 46022 | AI5: =DATE(YEAR(AD5)+1,MONTH(AD5),DAY(AD5)) -> 46022 | AJ5: =DATE(YEAR(AE5)+1,MONTH(AE5),DAY(AE5)) -> 46112 | AK5: =DATE(YEAR(AF5)+1,MONTH(AF5),DAY(AF5)) -> 46203 | AL5: =DATE(YEAR(AG5)+1,MONTH(AG5),DAY(AG5)) -> 46295 | ... AX5: =DATE(YEAR(AS5)+1,MONTH(AS5),DAY(AS5)) -> 47118
C6: FY20 | D6: Q1'21 | E6: Q2'21 | F6: Q3'21 | G6: Q4'21 | H6: FY21 | I6: Q1'22 | J6: Q2'22 | K6: Q3'22 | L6: Q4'22 | M6: FY22 | N6: Q1'23 | O6: Q2'23 | P6: Q3'23 | Q6: Q4'23 | R6: FY23 | S6: =H6&"R" -> FY21R | T6: =M6&"R" -> FY22R | U6: =N6&"R" -> Q1'23R | V6: =O6&"R" -> Q2'23R | W6: =P6&"R" -> Q3'23R | X6: =Q6&"R" -> Q4'23R | Y6: =R6&"R" -> FY23R | Z6: Q1'24 | AA6: Q2'24 | AB6: Q3'24 | AC6: Q4'24 | AD6: FY24 | AE6: Q1'25 | AF6: Q2'25 | AG6: Q3'25 | AH6: Q4'25 | AI6: FY25 | AJ6: Q1'26 | AK6: Q2'26 | AL6: Q3'26E | AM6: Q4'26E | AN6: FY26E | AO6: Q1'27E | AP6: Q2'27E | AQ6: Q3'27E | AR6: Q4'27E | AS6: FY27E | AT6: Q1'28E | AU6: Q2'28E | AV6: Q3'28E | AW6: Q4'28E | AX6: FY28E
B7: Income Statement ($M, except where noted)
B8: Net Sales | C8: ='3. Segment Build'!C12 -> 2446.2 | D8: ='3. Segment Build'!D12 -> 663.49 | E8: ='3. Segment Build'!E12 -> 597.81 | F8: ='3. Segment Build'!F12 -> 806.13 | G8: ='3. Segment Build'!G12 -> 999 | H8: =D8+E8+F8+G8 -> 3066.43 | I8: ='3. Segment Build'!I12 -> 809.15761 | J8: ='3. Segment Build'!J12 -> 693.42159 | K8: ='3. Segment Build'!K12 -> 847.18302 | L8: ='3. Segment Build'!L12 -> 1198.7114 | M8: =I8+J8+K8+L8 -> 3548.4736 | N8: ='3. Segment Build'!N12 -> 1050.3 | O8: ='3. Segment Build'!O12 -> 856.8 | P8: ='3. Segment Build'!P12 -> 1146.3 | Q8: 1315 | R8: =N8+O8+P8+Q8 -> 4368.4 | S8: =H8+19.3 -> 3085.73 | T8: =M8+22.4 -> 3570.8736 | U8: =N8+6.7 -> 1057 | V8: =O8+6 -> 862.8 | W8: =P8+6.8 -> 1153.1 | X8: =Q8+12.5 -> 1327.5 | Y8: =U8+V8+W8+X8 -> 4400.4 | Z8: =1182.9+9.5 -> 1192.4 | AA8: =993.8+7.6 -> 1001.4 | AB8: 1353.8 | AC8: 1635.5 | AD8: =Z8+AA8+AB8+AC8 -> 5183.1 | AE8: 1472.5 | AF8: 1236.3 | AG8: 1756.3 | AH8: 2101.1 | AI8: =AE8+AF8+AG8+AH8 -> 6566.2 | AJ8: 1945.5 | AK8: 1632.6 | AL8: ='3. Segment Build'!AL12 -> 2145.3634 | AM8: ='3. Segment Build'!AM12 -> 2480.2939 | AN8: =AJ8+AK8+AL8+AM8 -> 8203.7573 | AO8: ='3. Segment Build'!AO12 -> 2257.3358 | AP8: ='3. Segment Build'!AP12 -> 1893.2688 | AQ8: ='3. Segment Build'!AQ12 -> 2451.3328 | AR8: ='3. Segment Build'!AR12 -> 2853.541 | AS8: =AO8+AP8+AQ8+AR8 -> 9455.4784 | AT8: ='3. Segment Build'!AT12 -> 2564.9111 | AU8: ='3. Segment Build'!AU12 -> 2152.926 | AV8: ='3. Segment Build'!AV12 -> 2774.1745 | AW8: ='3. Segment Build'!AW12 -> 3255.7219 | AX8: =AT8+AU8+AV8+AW8 -> 10747.734
B9: % chg. y/y | C9: -- | D9: -- | E9: -- | F9: -- | G9: -- | H9: =H8/C8-1 -> 0.25354836 | I9: =I8/D8-1 -> 0.21954756 | J9: =J8/E8-1 -> 0.15993641 | K9: =K8/F8-1 -> 0.05092606 | L9: =L8/G8-1 -> 0.19991127 | M9: =M8/H8-1 -> 0.15720026 | N9: =N8/I8-1 -> 0.29801658 | O9: =O8/J8-1 -> 0.23561195 | ... R9: =R8/M8-1 -> 0.23106454 | S9: -- | T9: =T8/S8-1 -> 0.15722166 | U9: -- | V9: -- | W9: -- | X9: -- | Y9: =Y8/T8-1 -> 0.2323035 | Z9: =Z8/U8-1 -> 0.12809839 | AA9: =AA8/V8-1 -> 0.16063978 | AB9: =AB8/W8-1 -> 0.17405255 | AC9: =AC8/X8-1 -> 0.23201507 | AD9: =AD8/Y8-1 -> 0.17787019 | AE9: =AE8/Z8-1 -> 0.23490439 | AF9: =AF8/AA8-1 -> 0.2345716 | ... AX9: =AX8/AS8-1 -> 0.13666734
B11: COGS | C11: -1297.4 | D11: -336.34878 | E11: -323.56518 | F11: -404.04946 | G11: -496.93783 | H11: =D11+E11+F11+G11 -> -1560.9012 | I11: -408.6 | J11: -364.7 | K11: -415.25413 | L11: -596.68189 | M11: =I11+J11+K11+L11 -> -1785.236 | N11: -495.4 | O11: -400.2 | P11: -564.9 | Q11: =-631.8 -> -631.8 | R11: =N11+O11+P11+Q11 -> -2092.3 | S11: =H11 -> -1560.9012 | T11: =M11 -> -1785.236 | U11: =N11 -> -495.4 | V11: =O11 -> -400.2 | W11: =P11 -> -564.9 | X11: =Q11 -> -631.8 | Y11: =U11+V11+W11+X11 -> -2092.3 | Z11: =-544.4 -> -544.4 | AA11: -442.5 | AB11: -606.5 | AC11: -718 | AD11: =Z11+AA11+AB11+AC11 -> -2311.4 | AE11: -621.4 | AF11: -513.4 | AG11: -758.1 | AH11: =-889 -> -889 | AI11: =AE11+AF11+AG11+AH11 -> -2781.9 | AJ11: -780.1 | AK11: -561 | AL11: =AL12-AL8 -> -883.90696 | AM11: =AM12-AM8 -> -994.02944 | AN11: =AJ11+AK11+AL11+AM11 -> -3219.0364 | AO11: =AO12-AO8 -> -888.66006 | AP11: =AP12-AP8 -> -702.25912 | AQ11: =AQ12-AQ8 -> -991.05612 | AR11: =AR12-AR8 -> -1124.5112 | AS11: =AO11+AP11+AQ11+AR11 -> -3706.4865 | AT11: =AT12-AT8 -> -990.00425 | AU11: =AU12-AU8 -> -781.91786 | AV11: =AV12-AV8 -> -1100.2851 | AW11: =AW12-AW8 -> -1261.3172 | AX11: =AT11+AU11+AV11+AW11 -> -4133.5244
B12: Gross Profit | C12: =C8+C11 -> 1148.8 | D12: =D8+D11 -> 327.14122 | E12: =E8+E11 -> 274.24482 | F12: =F8+F11 -> 402.08054 | G12: =G8+G11 -> 502.06217 | H12: =H8+H11 -> 1505.5288 | I12: =I8+I11 -> 400.55761 | J12: =J8+J11 -> 328.72159 | ... AK12: =AK8+AK11 -> 1071.6 | AL12: =AL17-AL16 -> 1261.4565 | AM12: =AM17-AM16 -> 1486.2645 | AN12: =AN8+AN11 -> 4984.7209 | AO12: =AO17-AO16 -> 1368.6758 | AP12: =AP17-AP16 -> 1191.0096 | AQ12: =AQ17-AQ16 -> 1460.2767 | AR12: =AR17-AR16 -> 1729.0298 | AS12: =AS8+AS11 -> 5748.992 | AT12: =AT17-AT16 -> 1574.9069 | AU12: =AU17-AU16 -> 1371.0081 | AV12: =AV17-AV16 -> 1673.8894 | AW12: =AW17-AW16 -> 1994.4047 | AX12: =AX8+AX11 -> 6614.2091
B13: % margin | C13: =C12/C8 -> 0.46962636 | D13: =D12/D8 -> 0.49306127 | E13: =E12/E8 -> 0.45874914 | F13: =F12/F8 -> 0.49877879 | G13: =G12/G8 -> 0.50256473 | H13: =H12/H8 -> 0.49097118 | I13: =I12/I8 -> 0.49503039 | J13: =J12/J8 -> 0.47405733 | ... AX13: =AX12/AX8 -> 0.61540502
B14: bps chg. y/y | C14: -- | D14: -- | E14: -- | F14: -- | G14: -- | H14: =(H13-C13)*100*100 -> 213.44821 | I14: =(I13-D13)*100*100 -> 19.691244 | J14: =(J13-E13)*100*100 -> 153.0819 | K14: =(K13-F13)*100*100 -> 110.62514 | L14: =(L13-G13)*100*100 -> -3.3418044 | M14: =(M13-H13)*100*100 -> 59.291121 | N14: =(N13-I13)*100*100 -> 332.94846 | O14: =(O13-J13)*100*100 -> 588.55835 | ... R14: =(R13-M13)*100*100 -> 241.37158 | S14: -- | T14: =(T13-S13)*100*100 -> 59.012733 | U14: -- | V14: -- | W14: -- | X14: -- | Y14: =(Y13-T13)*100*100 -> 244.64274 | Z14: =(Z13-U13)*100*100 -> 121.26755 | AA14: =(AA13-V13)*100*100 -> 219.57299 | AB14: =(AB13-W13)*100*100 -> 418.98573 | AC14: =(AC13-X13)*100*100 -> 369.22726 | AD14: =(AD13-Y13)*100*100 -> 295.30167 | AE14: =(AE13-Z13)*100*100 -> 345.54806 | AF14: =(AF13-AA13)*100*100 -> 266.09992 | ... AX14: =(AX13-AS13)*100*100 -> 73.985572
B16: PPA and Other Adjustments | I16: 3.5 | J16: 3.75 | K16: 3.75 | L16: 3 | M16: =I16+J16+K16+L16 -> 14 | N16: 3.8 | O16: 4.4 | P16: =3.7+1 -> 4.7 | Q16: 3.7 | R16: =N16+O16+P16+Q16 -> 16.6 | T16: =M16 -> 14 | U16: =N16 -> 3.8 | V16: =O16 -> 4.4 | W16: =P16 -> 4.7 | X16: =Q16 -> 3.7 | Y16: =U16+V16+W16+X16 -> 16.6 | Z16: 3.7 | AA16: 3.7 | AB16: 3.7 | AC16: =3.7+1.8 -> 5.5 | AD16: =Z16+AA16+AB16+AC16 -> 16.6 | AE16: =3.6-0.8 -> 2.8 | AF16: =-1.3+3.8 -> 2.5 | AG16: =17.5+0.7 -> 18.2 | AH16: 2.8 | AI16: =AE16+AF16+AG16+AH16 -> 26.3 | AJ16: 2.8 | AK16: 2.7 | AL16: 3.7 | AM16: 3.7 | AN16: =AJ16+AK16+AL16+AM16 -> 12.9 | AO16: 3.7 | AP16: 3.7 | AQ16: 3.7 | AR16: 3.7 | AS16: =AO16+AP16+AQ16+AR16 -> 14.8 | AT16: 3.7 | AU16: 3.7 | AV16: 3.7 | AW16: 3.7 | AX16: =AT16+AU16+AV16+AW16 -> 14.8
B17: Adj. Gross Profit | I17: =I12+I16 -> 404.05761 | J17: =J12+J16 -> 332.47159 | K17: =K12+K16 -> 435.67889 | L17: =L12+L16 -> 605.02947 | M17: =I17+J17+K17+L17 -> 1777.2376 | N17: =N12+N16 -> 558.7 | O17: =O12+O16 -> 461 | P17: =P12+P16 -> 586.1 | Q17: =Q12+Q16 -> 686.9 | R17: =N17+O17+P17+Q17 -> 2292.7 | T17: =T12+T16 -> 1799.6376 | U17: =U12+U16 -> 565.4 | V17: =V12+V16 -> 467 | W17: =W12+W16 -> 592.9 | X17: =X12+X16 -> 699.4 | Y17: =Y12+Y16 -> 2324.7 | Z17: =Z12+Z16 -> 651.7 | AA17: =AA12+AA16 -> 562.6 | ... AC17: =AC12+AC16 -> 923 | AD17: =Z17+AA17+AB17+AC17 -> 2888.3 | AE17: =AE12+AE16 -> 853.9 | AF17: =AF12+AF16 -> 725.4 | AG17: =AG12+AG16 -> 1016.4 | AH17: =AH12+AH16 -> 1214.9 | AI17: =AE17+AF17+AG17+AH17 -> 3810.6 | AJ17: =AJ12+AJ16 -> 1168.2 | AK17: =AK12+AK16 -> 1074.3 | AL17: =(AG18+AL19/100/100)*AL8 -> 1265.1565 | AM17: =(AH18+AM19/100/100)*AM8 -> 1489.9645 | AN17: =AJ17+AK17+AL17+AM17 -> 4997.6209 | AO17: =(AJ18+AO19/100/100)*AO8 -> 1372.3758 | AP17: =(AK18+AP19/100/100)*AP8 -> 1194.7096 | AQ17: =(AL18+AQ19/100/100)*AQ8 -> 1463.9767 | AR17: =(AM18+AR19/100/100)*AR8 -> 1732.7298 | AS17: =AO17+AP17+AQ17+AR17 -> 5763.792 | AT17: =(AO18+AT19/100/100)*AT8 -> 1578.6069 | AU17: =(AP18+AU19/100/100)*AU8 -> 1374.7081 | AV17: =(AQ18+AV19/100/100)*AV8 -> 1677.5894 | AW17: =(AR18+AW19/100/100)*AW8 -> 1998.1047 | AX17: =AT17+AU17+AV17+AW17 -> 6629.0091
B18: % margin | I18: =I17/I8 -> 0.49935588 | J18: =J17/J8 -> 0.4794653 | K18: =K17/K8 -> 0.51426773 | L18: =L17/L8 -> 0.50473324 | M18: =M17/M8 -> 0.50084565 | N18: =N17/N8 -> 0.53194325 | O18: =O17/O8 -> 0.53804855 | P18: =P17/P8 -> 0.51129722 | ... R18: =R17/R8 -> 0.52483747 | T18: =T17/T8 -> 0.50397683 | U18: =U17/U8 -> 0.53491012 | V18: =V17/V8 -> 0.54126101 | W18: =W17/W8 -> 0.51417917 | X18: =X17/X8 -> 0.52685499 | Y18: =Y17/Y8 -> 0.52829288 | Z18: =Z17/Z8 -> 0.54654478 | AA18: =AA17/AA8 -> 0.56181346 | ... AX18: =AX17/AX8 -> 0.61678205
B19: bps chg. y/y | I19: -- | J19: -- | K19: -- | L19: -- | M19: -- | N19: =(N18-I18)*100*100 -> 325.87374 | O19: =(O18-J18)*100*100 -> 585.83257 | P19: =(P18-K18)*100*100 -> -29.705172 | Q19: =(Q18-L18)*100*100 -> 176.24175 | R19: =(R18-M18)*100*100 -> 239.91818 | T19: -- | U19: -- | V19: -- | W19: -- | X19: -- | Y19: =(Y18-T18)*100*100 -> 243.16049 | Z19: =(Z18-U18)*100*100 -> 116.34661 | AA19: =(AA18-V18)*100*100 -> 205.5245 | AB19: =(AB18-W18)*100*100 -> 405.55651 | AC19: =(AC18-X18)*100*100 -> 374.98418 | AD19: =(AD18-Y18)*100*100 -> 289.60499 | AE19: =(AE18-Z18)*100*100 -> 333.53349 | AF19: =(AF18-AA18)*100*100 -> 249.37327 | ... AK19: =(AK18-AF18)*100*100 -> 712.79347 | AL19: =75-20+30+45-20 -> 110 | AM19: 225 | AN19: =(AN18-AI18)*100*100 -> 288.51173 | AO19: =65+10 -> 75 | AP19: =65+10-345 -> -270 | AQ19: =65+10 -> 75 | AR19: =65 -> 65 | AS19: =(AS18-AN18)*100*100 -> 3.8485743 | AT19: =65+10 -> 75 | AU19: =65+10 -> 75 | AV19: =65+10 -> 75 | AW19: =65 -> 65 | AX19: =(AX18-AS18)*100*100 -> 72.103616
B21: Selling and marketing expenses | C21: -733.2 | D21: -210.69895 | E21: -222.11811 | F21: -231.97091 | G21: -297.75899 | H21: =D21+E21+F21+G21 -> -962.54696 | I21: -249.1 | J21: -241.6 | K21: -263.6581 | L21: -353.46842 | M21: =I21+J21+K21+L21 -> -1107.8265 | N21: -303.8 | O21: -318.8 | P21: -334.2 | Q21: -424.9 | R21: =N21+O21+P21+Q21 -> -1381.7
B22: % chg. y/y | C22: -- | D22: -- | E22: -- | F22: -- | G22: -- | H22: =H21/C21-1 -> 0.31280273 | I22: =I21/D21-1 -> 0.18225552 | J22: =J21/E21-1 -> 0.08770961 | K22: =K21/F21-1 -> 0.13659984 | L22: =L21/G21-1 -> 0.18709571 | M22: =M21/H21-1 -> 0.15093244 | N22: =N21/I21-1 -> 0.21959053 | O22: =O21/J21-1 -> 0.31953642 | ... R22: =R21/M21-1 -> 0.24721694
B23: % of sales | C23: =-C21/C8 -> 0.29973019 | D23: =-D21/D8 -> 0.31756161 | E23: =-E21/E8 -> 0.37155301 | F23: =-F21/F8 -> 0.28775869 | G23: =-G21/G8 -> 0.29805704 | H23: =-H21/H8 -> 0.31389823 | I23: =-I21/I8 -> 0.30785102 | J23: =-J21/J8 -> 0.34841719 | ... R23: =-R21/R8 -> 0.3162943
B24: bps chg. y/y | C24: -- | D24: -- | E24: -- | F24: -- | G24: -- | H24: =(H23-C23)*100*100 -> 141.6804 | I24: =(I23-D23)*100*100 -> -97.105857 | J24: =(J23-E23)*100*100 -> -231.35825 | K24: =(K23-F23)*100*100 -> 234.58715 | L24: =(L23-G23)*100*100 -> -31.833751 | M24: =(M23-H23)*100*100 -> -17.001873 | N24: =(N23-I23)*100*100 -> -186.00334 | O24: =(O23-J23)*100*100 -> 236.64977 | ... R24: =(R23-M23)*100*100 -> 40.962487
B26: Administrative and other expenses | C26: =C30-C94-C96-C97-C98-'3. Segment Build'!C95 -> -277.11276 | D26: =D30-D94-D96-D97-D98-'3. Segment Build'!D95 -> -80.620206 | E26: =E30-E94-E96-E97-E98-'3. Segment Build'!E95 -> -96.846539 | F26: =F30-F94-F96-F97-F98-'3. Segment Build'!F95 -> -73.023541 | G26: =G30-G94-G96-G97-G98-'3. Segment Build'!G95 -> -113.7455 | H26: =D26+E26+F26+G26 -> -364.23579 | I26: =I30-I94-I96-I97-I98-'3. Segment Build'!I95+I16 -> -99.660163 | J26: =J30-J94-J96-J97-J98-'3. Segment Build'!J95+J16 -> -99.04881 | K26: =K30-K94-K96-K97-K98-'3. Segment Build'!K95+K16 -> -100.09062 | L26: =L30-L94-L96-L97-L98-'3. Segment Build'!L95+L16 -> -115.12819 | M26: =I26+J26+K26+L26 -> -413.92779 | N26: =N30-N94-N96-N97-N98-'3. Segment Build'!N95+N16 -> -118.6 | O26: =O30-O94-O96-O97-O98-'3. Segment Build'!O95+O16 -> -126.54467 | P26: =P30-P94-P96-P97-P98-'3. Segment Build'!P95+P16 -> -147.14467 | Q26: =Q30-Q94-Q96-Q97-Q98-'3. Segment Build'!Q95+Q16 -> -208.31067 | R26: =N26+O26+P26+Q26 -> -600.6
B27: % chg. y/y | C27: -- | D27: -- | E27: -- | F27: -- | G27: -- | H27: =H26/C26-1 -> 0.31439558 | I27: =I26/D26-1 -> 0.23616855 | J27: =J26/E26-1 -> 0.022739804 | L27: =L26/G26-1 -> 0.012156018 | M27: =M26/H26-1 -> 0.13642812 | N27: =N26/I26-1 -> 0.19004421 | O27: =O26/J26-1 -> 0.27759906 | P27: =P26/K26-1 -> 0.4701144 | Q27: =Q26/L26-1 -> 0.80938014 | R27: =R26/M26-1 -> 0.45097772
B28: % of sales | C28: =-C26/C8 -> 0.11328295 | D28: =-D26/D8 -> 0.1215093 | E28: =-E26/E8 -> 0.16200221 | F28: =-F26/F8 -> 0.090585316 | G28: =-G26/G8 -> 0.11385936 | H28: =-H26/H8 -> 0.11878171 | I28: =-I26/I8 -> 0.12316533 | J28: =-J26/J8 -> 0.14284068 | ... R28: =-R26/R8 -> 0.13748741
B29: bps chg. y/y | C29: -- | D29: -- | E29: -- | F29: -- | G29: -- | H29: =(H28-C28)*100*100 -> 54.987532 | I29: =(I28-D28)*100*100 -> 16.560279 | J29: =(J28-E28)*100*100 -> -191.61527 | K29: =(K28-F28)*100*100 -> 275.59902 | L29: =(L28-G28)*100*100 -> -178.16061 | M29: =(M28-H28)*100*100 -> -21.321718 | N29: =(N28-I28)*100*100 -> -102.45211 | O29: =(O28-J28)*100*100 -> 48.538432 | ... R29: =(R28-M28)*100*100 -> 208.37875
B30: Adjusted administrative and other expenses | C30: =C55-C12-C21-C46-C48 -> -222.7 | D30: =D55-D12-D21-D46-D48 -> -66.670405 | E30: =E55-E12-E21-E46-E48 -> -51.596871 | F30: =F55-F12-F21-F46-F48 -> -59.078287 | G30: =G55-G12-G21-G46-G48 -> -103.27301 | H30: =D30+E30+F30+G30 -> -280.61857 | I30: =I55-I17-I21-I46-I48 -> -85.519038 | J30: =J55-J17-J21-J46-J48 -> -88.823434 | K30: =K55-K17-K21-K46-K48 -> -93.840442 | L30: =L55-L17-L21-L46-L48 -> -107.49647 | M30: =I30+J30+K30+L30 -> -375.67938 | N30: =N55-N17-N21-N46-N48 -> -111.6 | O30: =O55-O17-O21-O46-O48 -> -117.5 | P30: =P55-P17-P21-P46-P48 -> -123 | Q30: =Q55-Q17-Q21-Q46-Q48 -> -135.1 | R30: =N30+O30+P30+Q30 -> -487.2
B31: % chg. y/y | C31: -- | D31: -- | E31: -- | F31: -- | G31: -- | H31: =H30/C30-1 -> 0.26007442 | I31: =I30/D30-1 -> 0.28271363 | J31: =J30/E30-1 -> 0.72148878 | K31: =K30/F30-1 -> 0.58840831 | L31: =L30/G30-1 -> 0.040896069 | M31: =M30/H30-1 -> 0.33875452 | N31: =N30/I30-1 -> 0.30497259 | O31: =O30/J30-1 -> 0.32284911 | ... R31: =R30/M30-1 -> 0.29685051
B32: % of sales | C32: =-C30/C8 -> 0.091039163 | D32: =-D30/D8 -> 0.10048442 | E32: =-E30/E8 -> 0.086309815 | F32: =-F30/F8 -> 0.073286302 | G32: =-G30/G8 -> 0.10337639 | H32: =-H30/H8 -> 0.091513119 | I32: =-I30/I8 -> 0.10568897 | J32: =-J30/J8 -> 0.12809442 | ... R32: =-R30/R8 -> 0.11152825
B33: bps chg. y/y | C33: -- | D33: -- | E33: -- | F33: -- | G33: -- | H33: =(H32-C32)*100*100 -> 4.7395632 | I33: =(I32-D32)*100*100 -> 52.045579 | J33: =(J32-E32)*100*100 -> 417.84602 | K33: =(K32-F32)*100*100 -> 374.81311 | L33: =(L32-G32)*100*100 -> -136.99694 | M33: =(M32-H32)*100*100 -> 143.57582 | N33: =(N32-I32)*100*100 -> 5.663818 | O33: =(O32-J32)*100*100 -> 90.437714 | ... R33: =(R32-M32)*100*100 -> 56.575475
B35: Total SG&A (IFRS) | C35: =C21+C26 -> -1010.3128 | D35: =D21+D26 -> -291.31916 | E35: =E21+E26 -> -318.96465 | F35: =F21+F26 -> -304.99445 | G35: =G21+G26 -> -411.50449 | H35: =D35+E35+F35+G35 -> -1326.7827 | I35: =I21+I26 -> -348.76016 | J35: =J21+J26 -> -340.64881 | K35: =K21+K26 -> -363.74873 | L35: =L21+L26 -> -468.59661 | M35: =I35+J35+K35+L35 -> -1521.7543 | N35: =N21+N26 -> -422.4 | O35: =O21+O26 -> -445.34467 | P35: =P21+P26 -> -481.34467 | Q35: =Q21+Q26 -> -633.21067 | R35: =N35+O35+P35+Q35 -> -1982.3 | S35: =H35-19.3 -> -1346.0827 | T35: =M35-22.4 -> -1544.1543 | U35: =N35-6.7 -> -429.1 | V35: =O35-6 -> -451.34467 | W35: =P35-6.8 -> -488.14467 | X35: =Q35-12.5 -> -645.71067 | Y35: =U35+V35+W35+X35 -> -2014.3 | Z35: =-534.2-9.5 -> -543.7 | AA35: =-560.2-7.6 -> -567.8 | AB35: -586.5 | AC35: -732.3 | AD35: =Z35+AA35+AB35+AC35 -> -2430.3 | AE35: -641.9 | AF35: -697.8 | AG35: -776.6 | AH35: =-988.3 -> -988.3 | AI35: =AE35+AF35+AG35+AH35 -> -3104.6 | AJ35: -856.2 | AK35: =-909.2 -> -909.2 | AL35: =AL40-AL96-AL97-AL98-AL94-'3. Segment Build'!AL95+AL16 -> -971.63478 | AM35: =AM40-AM96-AM97-AM98-AM94-'3. Segment Build'!AM95+AM16 -> -1158.5977 | AN35: =AJ35+AK35+AL35+AM35 -> -3895.6324 | AO35: =AO40-AO96-AO97-AO98-AO94-'3. Segment Build'!AO95+AO16 -> -982.64528 | AP35: =AP40-AP96-AP97-AP98-AP94-'3. Segment Build'!AP95+AP16 -> -1030.8629 | AQ35: =AQ40-AQ96-AQ97-AQ98-AQ94-'3. Segment Build'!AQ95+AQ16 -> -1106.7345 | AR35: =AR40-AR96-AR97-AR98-AR94-'3. Segment Build'!AR95+AR16 -> -1330.0011 | AS35: =AO35+AP35+AQ35+AR35 -> -4450.2437 | AT35: =AT40-AT96-AT97-AT98-AT94-'3. Segment Build'!AT95+AT16 -> -1116.8501 | AU35: =AU40-AU96-AU97-AU98-AU94-'3. Segment Build'!AU95+AU16 -> -1171.9096 | AV35: =AV40-AV96-AV97-AV98-AV94-'3. Segment Build'!AV95+AV16 -> -1255.946 | AW35: =AW40-AW96-AW97-AW98-AW94-'3. Segment Build'!AW95+AW16 -> -1516.7376 | AX35: =AT35+AU35+AV35+AW35 -> -5061.4433
B36: % chg. y/y | C36: -- | D36: -- | E36: -- | F36: -- | G36: -- | H36: =H35/C35-1 -> 0.31323962 | I36: =I35/D35-1 -> 0.19717551 | J36: =J35/E35-1 -> 0.06798297 | K36: =K35/F35-1 -> 0.19264046 | L36: =L35/G35-1 -> 0.13873997 | M36: =M35/H35-1 -> 0.14695063 | N36: =N35/I35-1 -> 0.2111475 | O36: =O35/J35-1 -> 0.3073425 | ... R36: =R35/M35-1 -> 0.30264129 | S36: -- | T36: =T35/S35-1 -> 0.14714665 | U36: -- | V36: -- | W36: -- | X36: -- | Y36: =Y35/T35-1 -> 0.30446808 | Z36: =Z35/U35-1 -> 0.26707061 | AA36: =AA35/V35-1 -> 0.25801863 | AB36: =AB35/W35-1 -> 0.20148808 | AC36: =AC35/X35-1 -> 0.13409928 | AD36: =AD35/Y35-1 -> 0.20652336 | AE36: =AE35/Z35-1 -> 0.18061431 | AF36: =AF35/AA35-1 -> 0.22895386 | ... AX36: =AX35/AS35-1 -> 0.1373407
B37: % of sales | C37: =-C35/C8 -> 0.41301315 | D37: =-D35/D8 -> 0.43907091 | E37: =-E35/E8 -> 0.53355522 | F37: =-F35/F8 -> 0.37834401 | G37: =-G35/G8 -> 0.4119164 | H37: =-H35/H8 -> 0.43267994 | I37: =-I35/I8 -> 0.43101635 | J37: =-J35/J8 -> 0.49125787 | ... AX37: =-AX35/AX8 -> 0.47093123
B38: bps chg. y/y | C38: -- | D38: -- | E38: -- | F38: -- | G38: -- | H38: =(H37-C37)*100*100 -> 196.66793 | I38: =(I37-D37)*100*100 -> -80.545578 | J38: =(J37-E37)*100*100 -> -422.97352 | K38: =(K37-F37)*100*100 -> 510.18617 | L38: =(L37-G37)*100*100 -> -209.99436 | M38: =(M37-H37)*100*100 -> -38.323591 | N38: =(N37-I37)*100*100 -> -288.45545 | O38: =(O37-J37)*100*100 -> 285.1882 | ... R38: =(R37-M37)*100*100 -> 249.34124 | S38: -- | T38: =(T37-S37)*100*100 -> -37.978932 | U38: -- | V38: -- | W38: -- | X38: -- | Y38: =(Y37-T37)*100*100 -> 253.23435 | Z38: =(Z37-U37)*100*100 -> 500.10886 | AA38: =(AA37-V37)*100*100 -> 438.89981 | AB38: =(AB37-W37)*100*100 -> 98.925302 | AC38: =(AC37-X37)*100*100 -> -386.58068 | AD38: =(AD37-Y37)*100*100 -> 111.35434 | AE38: =(AE37-Z37)*100*100 -> -200.45854 | AF38: =(AF37-AA37)*100*100 -> -25.800812 | ... AX38: =(AX37-AS37)*100*100 -> 2.7881241
B40: Total Adj. SG&A | C40: =C21+C30 -> -955.9 | D40: =D21+D30 -> -277.36936 | E40: =E21+E30 -> -273.71498 | F40: =F21+F30 -> -291.0492 | G40: =G21+G30 -> -401.032 | H40: =D40+E40+F40+G40 -> -1243.1655 | I40: =I21+I30 -> -334.61904 | J40: =J21+J30 -> -330.42343 | K40: =K21+K30 -> -357.49855 | L40: =L21+L30 -> -460.96489 | M40: =I40+J40+K40+L40 -> -1483.5059 | N40: =N21+N30 -> -415.4 | O40: =O21+O30 -> -436.3 | P40: =P21+P30 -> -457.2 | Q40: =Q21+Q30 -> -560 | R40: =N40+O40+P40+Q40 -> -1868.9 | S40: =H40-19.3 -> -1262.4655 | T40: =M40-22.4 -> -1505.9059 | U40: =N40-6.7 -> -422.1 | V40: =O40-6 -> -442.3 | W40: =P40-6.8 -> -464 | X40: =Q40-12.5 -> -572.5 | Y40: =U40+V40+W40+X40 -> -1900.9 | Z40: =-534.2+0.9+5.8+3.4+7-9.5 -> -526.6 | AA40: =-560.2+8.8+7+12.2+6.1-7.6 -> -533.7 | AB40: =-586.5+6.5+2.5+2.3+1.4+1.3 -> -572.5 | AC40: =-732.3+6.9+10.2+1.8+0.4+4.5 -> -708.5 | AD40: =Z40+AA40+AB40+AC40 -> -2341.3 | AE40: =-641.9+6.9+2.9+0.3+5 -> -626.8 | AF40: =-697.8+7.2+6+2+0.1+5.9 -> -676.6 | AG40: =-776.6+23+5.4+3.9+0.1+1.7 -> -742.5 | AH40: =-988.3+6.3+9.3+9.7+4.6+2.4 -> -956 | AI40: =AE40+AF40+AG40+AH40 -> -3001.9 | AJ40: =-856.2+6.4+4.2-0.1+4.6 -> -841.1 | AK40: =-909.2+6.3+6.8+0.6+0.2-1.7 -> -897 | AL40: =AL55-AL17-AL48-AL46 -> -962.33478 | AM40: =AM55-AM17-AM48-AM46 -> -1149.2977 | AN40: =AJ40+AK40+AL40+AM40 -> -3849.7324 | AO40: =AO55-AO17-AO48-AO46 -> -973.34528 | AP40: =AP55-AP17-AP48-AP46 -> -1021.5629 | AQ40: =AQ55-AQ17-AQ48-AQ46 -> -1097.4345 | AR40: =AR55-AR17-AR48-AR46 -> -1320.7011 | AS40: =AO40+AP40+AQ40+AR40 -> -4413.0437 | AT40: =AT55-AT17-AT48-AT46 -> -1107.5501 | AU40: =AU55-AU17-AU48-AU46 -> -1162.6096 | AV40: =AV55-AV17-AV48-AV46 -> -1246.646 | AW40: =AW55-AW17-AW48-AW46 -> -1507.4376 | AX40: =AT40+AU40+AV40+AW40 -> -5024.2433
B41: % chg. y/y | C41: -- | D41: -- | E41: -- | F41: -- | G41: -- | H41: =H40/C40-1 -> 0.3005184 | I41: =I40/D40-1 -> 0.20640232 | J41: =J40/E40-1 -> 0.20718068 | K41: =K40/F40-1 -> 0.22830966 | L41: =L40/G40-1 -> 0.14944665 | M41: =M40/H40-1 -> 0.19332934 | N41: =N40/I40-1 -> 0.24141173 | O41: =O40/J40-1 -> 0.32042693 | ... R41: =R40/M40-1 -> 0.25978602 | S41: -- | T41: =T40/S40-1 -> 0.19282932 | U41: -- | V41: -- | W41: -- | X41: -- | Y41: =Y40/T40-1 -> 0.26229666 | Z41: =Z40/U40-1 -> 0.24757167 | AA41: =AA40/V40-1 -> 0.20664707 | AB41: =AB40/W40-1 -> 0.23383621 | AC41: =AC40/X40-1 -> 0.23755459 | AD41: =AD40/Y40-1 -> 0.23167973 | AE41: =AE40/Z40-1 -> 0.19027725 | AF41: =AF40/AA40-1 -> 0.26775342 | ... AX41: =AX40/AS40-1 -> 0.13849842
B42: % of sales | C42: =-C40/C8 -> 0.39076936 | D42: =-D40/D8 -> 0.41804603 | E42: =-E40/E8 -> 0.45786283 | F42: =-F40/F8 -> 0.36104499 | G42: =-G40/G8 -> 0.40143343 | H42: =-H40/H8 -> 0.40541135 | I42: =-I40/I8 -> 0.41354 | J42: =-J40/J8 -> 0.47651161 | ... AX42: =-AX40/AX8 -> 0.46747003
B43: bps chg. y/y | C43: -- | D43: -- | E43: -- | F43: -- | G43: -- | H43: =(H42-C42)*100*100 -> 146.41997 | I43: =(I42-D42)*100*100 -> -45.060278 | J43: =(J42-E42)*100*100 -> 186.48777 | K43: =(K42-F42)*100*100 -> 609.40026 | L43: =(L42-G42)*100*100 -> -168.83069 | M43: =(M42-H42)*100*100 -> 126.57394 | N43: =(N42-I42)*100*100 -> -180.33953 | O43: =(O42-J42)*100*100 -> 327.08748 | ... R43: =(R42-M42)*100*100 -> 97.537962 | S43: -- | T43: =(T42-S42)*100*100 -> 125.88922 | U43: -- | V43: -- | W43: -- | X43: -- | Y43: =(Y42-T42)*100*100 -> 102.64268 | Z43: =(Z42-U42)*100*100 -> 422.92577 | AA43: =(AA42-V42)*100*100 -> 203.20578 | AB43: =(AB42-W42)*100*100 -> 204.90187 | AC43: =(AC42-X42)*100*100 -> 19.390858 | AD43: =(AD42-Y42)*100*100 -> 197.34628 | AE43: =(AE42-Z42)*100*100 -> -159.59697 | AF43: =(AF42-AA42)*100*100 -> 143.24304 | ... AX43: =(AX42-AS42)*100*100 -> 7.518447
B45: Impairment losses | C45: -20.5 | D45: 7.2024204 | E45: -6.7777385 | F45: 5.0349079 | G45: -6.2019981 | H45: =D45+E45+F45+G45 -> -0.74240835 | I45: -2.8 | J45: -1.2 | K45: 2.641505 | L45: -200.78907 | M45: =I45+J45+K45+L45 -> -202.14757 | N45: -2.8 | O45: -4.7 | P45: 2.9 | Q45: 2.2 | R45: =N45+O45+P45+Q45 -> -2.4 | S45: =H45 -> -0.74240835 | T45: =M45 -> -202.14757 | U45: =N45 -> -2.8 | V45: =O45 -> -4.7 | W45: =P45 -> 2.9 | X45: =Q45 -> 2.2 | Y45: =U45+V45+W45+X45 -> -2.4 | Z45: -1.3 | AA45: -1.2 | AB45: 0 | AC45: 0.6 | AD45: =Z45+AA45+AB45+AC45 -> -1.9 | AE45: -0.3 | AF45: -2.6 | AG45: -10.2 | AH45: -0.9 | AI45: =AE45+AF45+AG45+AH45 -> -14 | AJ45: -0.7 | AK45: -2.3 | AL45: 0 | AM45: 0 | AN45: =AJ45+AK45+AL45+AM45 -> -3 | AO45: 0 | AP45: 0 | AQ45: 0 | AR45: 0 | AS45: =AO45+AP45+AQ45+AR45 -> 0 | AT45: 0 | AU45: 0 | AV45: 0 | AW45: 0 | AX45: =AT45+AU45+AV45+AW45 -> 0
B46: Adjusted impairment losses | C46: =C45+C95 -> -20.5 | D46: =D45+D95 -> 7.2024204 | E46: =E45+E95 -> -6.7777385 | F46: =F45+F95 -> 5.0349079 | G46: =G45+G95 -> -6.2019981 | H46: =D46+E46+F46+G46 -> -0.74240835 | I46: =I45+I95 -> -2.8 | J46: =J45+J95 -> -1.2 | K46: =K45+K95 -> 2.641505 | L46: =L45+L95 -> -2.689075 | M46: =I46+J46+K46+L46 -> -4.04757 | N46: =N45+N95 -> -2.8 | O46: =O45+O95 -> -4.7 | P46: =P45+P95 -> 2.9 | Q46: =Q45+Q95 -> 2.2 | R46: =N46+O46+P46+Q46 -> -2.4 | S46: =H46 -> -0.74240835 | T46: =M46 -> -4.04757 | U46: =N46 -> -2.8 | V46: =O46 -> -4.7 | W46: =P46 -> 2.9 | X46: =Q46 -> 2.2 | Y46: =U46+V46+W46+X46 -> -2.4 | Z46: =Z45+Z95 -> -1.3 | AA46: =AA45+AA95 -> -1.2 | AB46: =AB45+AB95 -> 0 | AC46: =AC45+AC95 -> 0.6 | AD46: =Z46+AA46+AB46+AC46 -> -1.9 | AE46: =AE45+AE95 -> -0.3 | AF46: =AF45+AF95 -> -2.6 | AG46: =AG45+AG95 -> -3.5 | AH46: =AH45+AH95 -> -0.9 | AI46: =AE46+AF46+AG46+AH46 -> -7.3 | AJ46: =AJ45+AJ95 -> -0.7 | AK46: =AK45+AK95 -> -0.5 | AL46: =AL45+AL95 -> 0 | AM46: =AM45+AM95 -> 0 | AN46: =AJ46+AK46+AL46+AM46 -> -1.2 | AO46: =AO45+AO95 -> 0 | AP46: =AP45+AP95 -> 0 | AQ46: =AQ45+AQ95 -> 0 | AR46: =AR45+AR95 -> 0 | AS46: =AO46+AP46+AQ46+AR46 -> 0 | AT46: =AT45+AT95 -> 0 | AU46: =AU45+AU95 -> 0 | AV46: =AV45+AV95 -> 0 | AW46: =AW45+AW95 -> 0 | AX46: =AT46+AU46+AV46+AW46 -> 0
B48: Other operating income | C48: 7.2 | D48: 0.81671535 | E48: 0.8258933 | F48: 0.44675039 | G48: 6.8978288 | H48: =D48+E48+F48+G48 -> 8.9871878 | I48: 0.5 | J48: 2.2 | K48: -0.621854 | L48: 9.224496 | M48: =I48+J48+K48+L48 -> 11.302642 | N48: 0.7 | O48: 0.9 | P48: 1.7 | Q48: 7.9 | R48: =N48+O48+P48+Q48 -> 11.2 | S48: =H48 -> 8.9871878 | T48: =M48 -> 11.302642 | U48: =N48 -> 0.7 | V48: =O48 -> 0.9 | W48: =P48 -> 1.7 | X48: =Q48 -> 7.9 | Y48: =U48+V48+W48+X48 -> 11.2 | Z48: 6 | AA48: 1.6 | AB48: 15.9 | AC48: 7.8 | AD48: =Z48+AA48+AB48+AC48 -> 31.3 | AE48: 5.3 | AF48: 21.2 | AG48: 4.5 | AH48: 5.1 | AI48: =AE48+AF48+AG48+AH48 -> 36.1 | AJ48: 12.6 | AK48: 31.6 | AL48: 0 | AM48: 0 | AN48: =AJ48+AK48+AL48+AM48 -> 44.2 | AO48: =AJ48 -> 12.6 | AP48: =AK48 -> 31.6 | AQ48: =AL48 -> 0 | AR48: =AM48 -> 0 | AS48: =AO48+AP48+AQ48+AR48 -> 44.2 | AT48: =AO48 -> 12.6 | AU48: =AP48 -> 31.6 | AV48: =AQ48 -> 0 | AW48: =AR48 -> 0 | AX48: =AT48+AU48+AV48+AW48 -> 44.2
B50: Operating profit (IFRS) | C50: =C12+C21+C26+C45+C48 -> 125.18724 | D50: =D12+D21+D26+D45+D48 -> 43.841199 | E50: =E12+E21+E26+E45+E48 -> -50.671668 | F50: =F12+F21+F26+F45+F48 -> 102.56775 | G50: =G12+G21+G26+G45+G48 -> 91.25351 | H50: =H12+H21+H26+H45+H48 -> 186.99079 | I50: =I12+I21+I26+I45+I48 -> 49.497449 | J50: =J12+J21+J26+J45+J48 -> -10.927225 | ... R50: =R12+R21+R26+R45+R48 -> 302.6 | S50: =S12+S35+S45+S48 -> 186.99079 | T50: =T12+T35+T45+T48 -> 50.638321 | U50: =U12+U35+U45+U48 -> 130.4 | V50: =V12+V35+V45+V48 -> 7.4553333 | W50: =W12+W35+W45+W48 -> 104.65533 | X50: =X12+X35+X45+X48 -> 60.089333 | Y50: =Y12+Y35+Y45+Y48 -> 302.6 | Z50: =Z12+Z35+Z45+Z48 -> 109 | ... AX50: =AX12+AX35+AX45+AX48 -> 1596.9658
...

Sheet 3. Segment Build
B1: Amer Sports, Inc.
B2: Segment earnings build
B3: $ millions, FY ending Saturday closest to December 31
C5: 44196 | D5: 44286 | E5: 44377 | F5: 44469 | G5: 44561 | H5: 44561 | I5: =DATE(YEAR(D5)+1,MONTH(D5),DAY(D5)) -> 44651 | J5: =DATE(YEAR(E5)+1,MONTH(E5),DAY(E5)) -> 44742 | K5: =DATE(YEAR(F5)+1,MONTH(F5),DAY(F5)) -> 44834 | L5: =DATE(YEAR(G5)+1,MONTH(G5),DAY(G5)) -> 44926 | M5: =DATE(YEAR(H5)+1,MONTH(H5),DAY(H5)) -> 44926 | N5: =DATE(YEAR(I5)+1,MONTH(I5),DAY(I5)) -> 45016 | O5: =DATE(YEAR(J5)+1,MONTH(J5),DAY(J5)) -> 45107 | P5: =DATE(YEAR(K5)+1,MONTH(K5),DAY(K5)) -> 45199 | ... R5: =DATE(YEAR(M5)+1,MONTH(M5),DAY(M5)) -> 45291 | S5: ='2. Consolidated'!S5 -> 44561 | T5: ='2. Consolidated'!T5 -> 44926 | U5: ='2. Consolidated'!U5 -> 45016 | V5: ='2. Consolidated'!V5 -> 45107 | W5: ='2. Consolidated'!W5 -> 45199 | X5: ='2. Consolidated'!X5 -> 45291 | Y5: ='2. Consolidated'!Y5 -> 45291 | Z5: =DATE(YEAR(N5)+1,MONTH(N5),DAY(N5)) -> 45382 | AA5: =DATE(YEAR(O5)+1,MONTH(O5),DAY(O5)) -> 45473 | AB5: =DATE(YEAR(P5)+1,MONTH(P5),DAY(P5)) -> 45565 | AC5: =DATE(YEAR(Q5)+1,MONTH(Q5),DAY(Q5)) -> 45657 | AD5: =DATE(YEAR(R5)+1,MONTH(R5),DAY(R5)) -> 45657 | AE5: =DATE(YEAR(Z5)+1,MONTH(Z5),DAY(Z5)) -> 45747 | AF5: =DATE(YEAR(AA5)+1,MONTH(AA5),DAY(AA5)) -> 45838 | AG5: =DATE(YEAR(AB5)+1,MONTH(AB5),DAY(AB5)) -> 45930 | AH5: =DATE(YEAR(AC5)+1,MONTH(AC5),DAY(AC5)) -> 46022 | AI5: =DATE(YEAR(AD5)+1,MONTH(AD5),DAY(AD5)) -> 46022 | AJ5: =DATE(YEAR(AE5)+1,MONTH(AE5),DAY(AE5)) -> 46112 | AK5: =DATE(YEAR(AF5)+1,MONTH(AF5),DAY(AF5)) -> 46203 | AL5: =DATE(YEAR(AG5)+1,MONTH(AG5),DAY(AG5)) -> 46295 | ... AX5: =DATE(YEAR(AS5)+1,MONTH(AS5),DAY(AS5)) -> 47118
C6: ='2. Consolidated'!C6 -> FY20 | D6: ='2. Consolidated'!D6 -> Q1'21 | E6: ='2. Consolidated'!E6 -> Q2'21 | F6: ='2. Consolidated'!F6 -> Q3'21 | G6: ='2. Consolidated'!G6 -> Q4'21 | H6: ='2. Consolidated'!H6 -> FY21 | I6: ='2. Consolidated'!I6 -> Q1'22 | J6: ='2. Consolidated'!J6 -> Q2'22 | ... AX6: ='2. Consolidated'!AX6 -> FY28E
B7: Revenue Summary
B9: Technical Apparel | C9: =C107 -> 685.4 | D9: =D107 -> 203.17 | E9: =E107 -> 147.84 | F9: =F107 -> 238.58 | G9: =G107 -> 361.12 | H9: =D9+E9+F9+G9 -> 950.71 | I9: =I107 -> 261.32972 | J9: =J107 -> 169.81807 | K9: =K107 -> 227.67329 | L9: =L107 -> 436.69865 | M9: =I9+J9+K9+L9 -> 1095.5197 | N9: =N107 -> 355.2 | O9: =O107 -> 303 | P9: =P107 -> 384.6 | Q9: =Q107 -> 550 | R9: =N9+O9+P9+Q9 -> 1592.8 | S9: =S107 -> 961.51 | T9: =T107 -> 1108.1197 | U9: =U107 -> 359.4 | V9: =V107 -> 306.8 | W9: =W107 -> 388.8 | X9: =X107 -> 559.2 | Y9: =U9+V9+W9+X9 -> 1614.2 | Z9: =Z107 -> 517 | AA9: =AA107 -> 412.1 | AB9: =AB107 -> 520 | AC9: =AC107 -> 745.2 | AD9: =Z9+AA9+AB9+AC9 -> 2194.3 | AE9: =AE107 -> 663.8 | AF9: =AF107 -> 508.9 | AG9: =AG107 -> 683.3 | AH9: =AH107 -> 999.8 | AI9: =AE9+AF9+AG9+AH9 -> 2855.8 | AJ9: =AJ107 -> 885 | AK9: =AK107 -> 674.2 | AL9: =AL107 -> 845.13423 | AM9: =AM107 -> 1203.7695 | AN9: =AJ9+AK9+AL9+AM9 -> 3608.1037 | AO9: =AO107 -> 1033.9418 | AP9: =AP107 -> 786.57171 | AQ9: =AQ107 -> 968.92629 | AR9: =AR107 -> 1396.5097 | AS9: =AO9+AP9+AQ9+AR9 -> 4185.9496 | AT9: =AT107 -> 1180.8667 | AU9: =AU107 -> 900.59705 | AV9: =AV107 -> 1098.7355 | AW9: =AW107 -> 1602.3149 | AX9: =AT9+AU9+AV9+AW9 -> 4782.5141
B10: Outdoor Performance | C10: =C213 -> 1091.6 | D10: =D213 -> 261.81 | E10: =E213 -> 211.6 | F10: =F213 -> 347.5 | G10: =G213 -> 414.7 | H10: =D10+E10+F10+G10 -> 1235.61 | I10: =I213 -> 263.36717 | J10: =J213 -> 246.39547 | K10: =K213 -> 392.71821 | L10: =L213 -> 513.72745 | M10: =I10+J10+K10+L10 -> 1416.2083 | N10: =N213 -> 377.5 | O10: =O213 -> 273.6 | P10: =P213 -> 493.2 | Q10: =Q213 -> 523.4 | R10: =N10+O10+P10+Q10 -> 1667.7 | S10: =S213 -> 1240.61 | T10: =T213 -> 1422.0083 | U10: =U213 -> 379 | V10: =V213 -> 274.9 | W10: =W213 -> 494.5 | X10: =X213 -> 525.6 | Y10: =U10+V10+W10+X10 -> 1674 | Z10: =Z213 -> 401.8 | AA10: =AA213 -> 305.7 | AB10: =AB213 -> 533.6 | AC10: =AC213 -> 594.4 | AD10: =Z10+AA10+AB10+AC10 -> 1835.5 | AE10: =AE213 -> 502.4 | AF10: =AF213 -> 413.7 | AG10: =AG213 -> 723.5 | AH10: =AH213 -> 764.1 | AI10: =AE10+AF10+AG10+AH10 -> 2403.7 | AJ10: =AJ213 -> 713.6 | AK10: =AK213 -> 568.5 | AL10: =AL213 -> 914.1418 | AM10: =AM213 -> 908.42474 | AN10: =AJ10+AK10+AL10+AM10 -> 3104.6665 | AO10: =AO213 -> 844.5097 | AP10: =AP213 -> 680.82402 | AQ10: =AQ213 -> 1061.1429 | AR10: =AR213 -> 1056.0349 | AS10: =AO10+AP10+AQ10+AR10 -> 3642.5115 | AT10: =AT213 -> 980.41311 | AU10: =AU213 -> 798.44732 | AV10: =AV213 -> 1226.3805 | AW10: =AW213 -> 1226.2139 | AX10: =AT10+AU10+AV10+AW10 -> 4231.4549
B11: Ball & Racquet Sports | C11: =C316 -> 669.2 | D11: =D316 -> 198.51 | E11: =E316 -> 238.37 | F11: =F316 -> 220.05 | G11: =G316 -> 223.18 | H11: =D11+E11+F11+G11 -> 880.11 | I11: =I316 -> 284.46072 | J11: =J316 -> 277.20805 | K11: =K316 -> 226.79153 | L11: =L316 -> 248.28526 | M11: =I11+J11+K11+L11 -> 1036.7455 | N11: =N316 -> 317.6 | O11: =O316 -> 280.2 | P11: =P316 -> 268.5 | Q11: =Q316 -> 241.5 | R11: =N11+O11+P11+Q11 -> 1107.8 | S11: =S316 -> 883.61 | T11: =T316 -> 1040.7455 | U11: =U316 -> 318.6 | V11: =V316 -> 281.1 | W11: =W316 -> 269.8 | X11: =X316 -> 242.6 | Y11: =U11+V11+W11+X11 -> 1112.1 | Z11: =Z316 -> 273.6 | AA11: =AA316 -> 283.5 | AB11: =AB316 -> 300.2 | AC11: =AC316 -> 296.2 | AD11: =Z11+AA11+AB11+AC11 -> 1153.5 | AE11: =AE316 -> 306.3 | AF11: =AF316 -> 313.7 | AG11: =AG316 -> 349.5 | AH11: =AH316 -> 337.2 | AI11: =AE11+AF11+AG11+AH11 -> 1306.7 | AJ11: =AJ316 -> 346.9 | AK11: =AK316 -> 389.9 | AL11: =AL316 -> 386.08739 | AM11: =AM316 -> 368.09967 | AN11: =AJ11+AK11+AL11+AM11 -> 1490.9871 | AO11: =AO316 -> 378.88433 | AP11: =AP316 -> 425.87303 | AQ11: =AQ316 -> 421.26367 | AR11: =AR316 -> 400.99638 | AS11: =AO11+AP11+AQ11+AR11 -> 1627.0174 | AT11: =AT316 -> 403.63131 | AU11: =AU316 -> 453.88159 | AV11: =AV316 -> 449.05854 | AW11: =AW316 -> 427.19308 | AX11: =AT11+AU11+AV11+AW11 -> 1733.7645
B12: Total | C12: =SUM(C9:C11) -> 2446.2 | D12: =SUM(D9:D11) -> 663.49 | E12: =SUM(E9:E11) -> 597.81 | F12: =SUM(F9:F11) -> 806.13 | G12: =SUM(G9:G11) -> 999 | H12: =SUM(H9:H11) -> 3066.43 | I12: =SUM(I9:I11) -> 809.15761 | J12: =SUM(J9:J11) -> 693.42159 | ... AX12: =SUM(AX9:AX11) -> 10747.734
B13: % chg. y/y | C13: -- | D13: -- | E13: -- | F13: -- | G13: -- | H13: =H12/C12-1 -> 0.25354836 | I13: =I12/D12-1 -> 0.21954756 | J13: =J12/E12-1 -> 0.15993641 | K13: =K12/F12-1 -> 0.05092606 | L13: =L12/G12-1 -> 0.19991127 | M13: =M12/H12-1 -> 0.15720026 | N13: =N12/I12-1 -> 0.29801658 | O13: =O12/J12-1 -> 0.23561195 | ... R13: =R12/M12-1 -> 0.23103636 | S13: -- | T13: =T12/S12-1 -> 0.15722166 | U13: -- | V13: -- | W13: -- | X13: -- | Y13: =Y12/T12-1 -> 0.23227549 | Z13: =Z12/U12-1 -> 0.12809839 | AA13: =AA12/V12-1 -> 0.16052388 | AB13: =AB12/W12-1 -> 0.17405255 | AC13: =AC12/X12-1 -> 0.23233389 | AD13: =AD12/Y12-1 -> 0.17794241 | AE13: =AE12/Z12-1 -> 0.23490439 | AF13: =AF12/AA12-1 -> 0.2346949 | ... AX13: =AX12/AS12-1 -> 0.13666734
B14: % chg. y/y ex-FX | Z14: =(Z109*U107+Z215*U213+Z318*U316)/U12 -> 0.14293832 | AA14: =(AA109*V107+AA215*V213+AA318*V316)/V12 -> 0.18413363 | AB14: =(AB109*W107+AB215*W213+AB318*W316)/W12 -> 0.16731003 | AC14: =(AC109*X107+AC215*X213+AC318*X316)/X12 -> 0.24044757 | AD14: =SUMPRODUCT(Z14:AC14,U12:X12)/Y12 -> 0.18681717 | AE14: =(AE109*Z107+AE215*Z213+AE318*Z316)/Z12 -> 0.2647682 | AF14: =(AF109*AA107+AF215*AA213+AF318*AA316)/AA12 -> 0.21980725 | AG14: =(AG109*AB107+AG215*AB213+AG318*AB316)/AB12 -> 0.28460437 | AH14: =(AH109*AC107+AH215*AC213+AH318*AC316)/AC12 -> 0.26639186 | AI14: =SUMPRODUCT(AE14:AH14,Z12:AC12)/AD12 -> 0.26177605 | AJ14: =(AJ109*AE107+AJ215*AE213+AJ318*AE316)/AE12 -> 0.26155334 | AK14: =(AK109*AF107+AK215*AF213+AK318*AF316)/AF12 -> 0.29794678
B15: FX impact | Z15: =Z13-Z14 -> -0.014839924 | AA15: =AA13-AA14 -> -0.023609759 | AB15: =AB13-AB14 -> 0.0067425202 | AC15: =AC13-AC14 -> -0.0081136809 | AD15: =SUMPRODUCT(Z15:AC15,U12:X12)/Y12 -> -0.0088747585 | AE15: =AE13-AE14 -> -0.029863804 | AF15: =AF13-AF14 -> 0.014887646 | AG15: =AG13-AG14 -> 0.012706899 | AH15: =AH13-AH14 -> 0.018056119 | AI15: =SUMPRODUCT(AE15:AH15,Z12:AC12)/AD12 -> 0.0050230934 | AJ15: =AJ13-AJ14 -> 0.059669066 | AK15: =AK13-AK14 -> 0.022606487
B17: Technical Apparel % chg. y/y | C17: -- | D17: -- | E17: -- | F17: -- | G17: -- | H17: =H9/C9-1 -> 0.38708783 | I17: =I9/D9-1 -> 0.28626137 | J17: =J9/E9-1 -> 0.14866118 | K17: =K9/F9-1 -> -0.045715096 | L17: =L9/G9-1 -> 0.20928957 | M17: =M9/H9-1 -> 0.15231746 | N17: =N9/I9-1 -> 0.35920245 | O17: =O9/J9-1 -> 0.78426243 | ... R17: =R9/M9-1 -> 0.45392178 | S17: -- | T17: =T9/S9-1 -> 0.15247863 | U17: -- | V17: -- | W17: -- | X17: -- | Y17: =Y9/T9-1 -> 0.45670179 | Z17: =Z9/U9-1 -> 0.43850863 | AA17: =AA9/V9-1 -> 0.34322034 | AB17: =AB9/W9-1 -> 0.33744856 | AC17: =AC9/X9-1 -> 0.33261803 | AD17: =AD9/Y9-1 -> 0.35937306 | AE17: =AE9/Z9-1 -> 0.28394584 | AF17: =AF9/AA9-1 -> 0.23489444 | ... AX17: =AX9/AS9-1 -> 0.14251595
B18: Outdoor Performance % chg. y/y | C18: -- | D18: -- | E18: -- | F18: -- | G18: -- | H18: =H10/C10-1 -> 0.13192561 | I18: =I10/D10-1 -> 0.0059477216 | J18: =J10/E10-1 -> 0.16443983 | K18: =K10/F10-1 -> 0.13012434 | L18: =L10/G10-1 -> 0.23879298 | M18: =M10/H10-1 -> 0.14616125 | N18: =N10/I10-1 -> 0.43336011 | O18: =O10/J10-1 -> 0.11041004 | ... R18: =R10/M10-1 -> 0.17758101 | S18: -- | T18: =T10/S10-1 -> 0.14621702 | U18: -- | V18: -- | W18: -- | X18: -- | Y18: =Y10/T10-1 -> 0.17720832 | Z18: =Z10/U10-1 -> 0.060158311 | AA18: =AA10/V10-1 -> 0.11204074 | AB18: =AB10/W10-1 -> 0.079069767 | AC18: =AC10/X10-1 -> 0.13089802 | AD18: =AD10/Y10-1 -> 0.096475508 | AE18: =AE10/Z10-1 -> 0.25037332 | AF18: =AF10/AA10-1 -> 0.35328754 | ... AX18: =AX10/AS10-1 -> 0.16168608
B19: Ball & Racquet Sports % chg. y/y | C19: -- | D19: -- | E19: -- | F19: -- | G19: -- | H19: =H11/C11-1 -> 0.31516736 | I19: =I11/D11-1 -> 0.43297928 | J19: =J11/E11-1 -> 0.16293179 | K19: =K11/F11-1 -> 0.030636333 | L19: =L11/G11-1 -> 0.11248884 | M19: =M11/H11-1 -> 0.1779727 | N19: =N11/I11-1 -> 0.11649863 | O19: =O11/J11-1 -> 0.010793158 | ... R19: =R11/M11-1 -> 0.068536055 | S19: -- | T19: =T11/S11-1 -> 0.1778336 | U19: -- | V19: -- | W19: -- | X19: -- | Y19: =Y11/T11-1 -> 0.068560898 | Z19: =Z11/U11-1 -> -0.14124294 | AA19: =AA11/V11-1 -> 0.0085378869 | AB19: =AB11/W11-1 -> 0.11267606 | AC19: =AC11/X11-1 -> 0.22093982 | AD19: =AD11/Y11-1 -> 0.037226868 | AE19: =AE11/Z11-1 -> 0.11951754 | AF19: =AF11/AA11-1 -> 0.10652557 | ... AX19: =AX11/AS11-1 -> 0.065609073
B21: Technical Apparel % of total | C21: =C9/C12 -> 0.28018968 | D21: =D9/D12 -> 0.30621411 | E21: =E9/E12 -> 0.24730265 | F21: =F9/F12 -> 0.29595723 | G21: =G9/G12 -> 0.36148148 | H21: =H9/H12 -> 0.31003806 | I21: =I9/I12 -> 0.32296517 | J21: =J9/J12 -> 0.24489873 | ... AX21: =AX9/AX12 -> 0.44497885
B22: Outdoor Performance % of total | C22: =C10/C12 -> 0.44624315 | D22: =D10/D12 -> 0.39459525 | E22: =E10/E12 -> 0.35395862 | F22: =F10/F12 -> 0.43107191 | G22: =G10/G12 -> 0.41511512 | H22: =H10/H12 -> 0.4029474 | I22: =I10/I12 -> 0.32548316 | J22: =J10/J12 -> 0.35533285 | ... AX22: =AX10/AX12 -> 0.39370672
B23: Ball & Racquet Sports % of total | C23: =C11/C12 -> 0.27356717 | D23: =D11/D12 -> 0.29919064 | E23: =E11/E12 -> 0.39873873 | F23: =F11/F12 -> 0.27297086 | G23: =G11/G12 -> 0.2234034 | H23: =H11/H12 -> 0.28701454 | I23: =I11/I12 -> 0.35155168 | J23: =J11/J12 -> 0.39976842 | ... AX23: =AX11/AX12 -> 0.16131443
B25: Americas | C25: 984 | D25: =D143+D244+D341 -> 250.54613 | E25: =E143+E244+E341 -> 256.33191 | F25: =F143+F244+F341 -> 323.40969 | G25: =G143+G244+G341 -> 422.71765 | H25: =D25+E25+F25+G25 -> 1253.0054 | I25: =I143+I244+I341 -> 350.53477 | J25: =J143+J244+J341 -> 321.1189 | K25: =K143+K244+K341 -> 356.04838 | L25: =L143+L244+L341 -> 476.64035 | M25: =I25+J25+K25+L25 -> 1504.3424 | N25: 409.6 | O25: 365.9 | P25: =P143+P244+P341 -> 450.8 | Q25: =1726.8-N25-O25-P25 -> 500.5 | R25: =N25+O25+P25+Q25 -> 1726.8 | W25: 455 | X25: 507.9 | Y25: 1745.6 | Z25: 414.9 | AA25: 371.9 | AB25: 487.8 | AC25: 584.4 | AD25: =Z25+AA25+AB25+AC25 -> 1859 | AE25: 464.7 | AF25: 395.4 | AG25: 574.2 | AH25: 691.3 | AI25: =AE25+AF25+AG25+AH25 -> 2125.6 | AJ25: 548.8 | AK25: 496.7 | AL25: =AG25*(1+AL30) -> 677.556 | AM25: =AH25*(1+AM30) -> 788.082 | AN25: =AJ25+AK25+AL25+AM25 -> 2511.138 | AO25: =AJ25*(1+AO30) -> 620.144 | AP25: =AK25*(1+AP30) -> 561.271 | AQ25: =AL25*(1+AQ30) -> 765.63828 | AR25: =AM25*(1+AR30) -> 890.53266 | AS25: =AO25+AP25+AQ25+AR25 -> 2837.5859 | AT25: =AO25*(1+AT30) -> 688.35984 | AU25: =AP25*(1+AU30) -> 623.01081 | AV25: =AQ25*(1+AV30) -> 849.85849 | AW25: =AR25*(1+AW30) -> 988.49125 | AX25: =AT25+AU25+AV25+AW25 -> 3149.7204
B26: EMEA | C26: 1080.4 | D26: =D145+D246+D343 -> 283.35581 | E26: =E145+E246+E343 -> 224.34001 | F26: =F145+F246+F343 -> 329.44857 | G26: =G145+G246+G343 -> 388.48056 | H26: =D26+E26+F26+G26 -> 1225.6249 | I26: =I145+I246+I343 -> 278.11113 | J26: =J145+J246+J343 -> 239.6025 | K26: =K145+K246+K343 -> 296.69924 | L26: =L145+L246+L343 -> 456.38479 | M26: =I26+J26+K26+L26 -> 1270.7977 | N26: 356.9 | O26: 230.1 | P26: =P145+P246+P343 -> 411.6 | Q26: =1450.3-N26-O26-P26 -> 451.7 | R26: =N26+O26+P26+Q26 -> 1450.3 | W26: 413 | X26: 454.6 | Y26: 1457.6 | Z26: 360.6 | AA26: 233.1 | AB26: 428.5 | AC26: 491.2 | AD26: =Z26+AA26+AB26+AC26 -> 1513.4 | AE26: 404.9 | AF26: 276.2 | AG26: 528.5 | AH26: 596.2 | AI26: =AE26+AF26+AG26+AH26 -> 1805.8 | AJ26: 512.8 | AK26: 332.3 | AL26: =AG26*(1+AL31) -> 602.49 | AM26: =AH26*(1+AM31) -> 667.744 | AN26: =AJ26+AK26+AL26+AM26 -> 2115.334 | AO26: =AJ26*(1+AO31) -> 579.464 | AP26: =AK26*(1+AP31) -> 375.499 | AQ26: =AL26*(1+AQ31) -> 680.8137 | AR26: =AM26*(1+AR31) -> 754.55072 | AS26: =AO26+AP26+AQ26+AR26 -> 2390.3274 | AT26: =AO26*(1+AT31) -> 643.20504 | AU26: =AP26*(1+AU31) -> 416.80389 | AV26: =AQ26*(1+AV31) -> 755.70321 | AW26: =AR26*(1+AW31) -> 837.5513 | AX26: =AT26+AU26+AV26+AW26 -> 2653.2634
B27: Greater China | C27: 202.3 | D27: =D147+D248+D345 -> 81.710141 | E27: =E147+E248+E345 -> 71.554778 | F27: =F147+F248+F345 -> 100.43374 | G27: =G147+G248+G345 -> 119.16376 | H27: =D27+E27+F27+G27 -> 372.86241 | I27: =I147+I248+I345 -> 130.59833 | J27: =J147+J248+J345 -> 83.33387 | K27: =K147+K248+K345 -> 139.85286 | L27: =L147+L248+L345 -> 169.99065 | M27: =I27+J27+K27+L27 -> 523.77571 | N27: 205.6 | O27: 187.6 | P27: =P147+P248+P345 -> 199.9 | Q27: =841.4-N27-O27-P27 -> 248.3 | R27: =N27+O27+P27+Q27 -> 841.4 | W27: 200.5 | X27: 249.5 | Y27: 844.8 | Z27: 311.6 | AA27: 289.6 | AB27: 312.9 | AC27: 383.9 | AD27: =Z27+AA27+AB27+AC27 -> 1298 | AE27: 446 | AF27: 410.2 | AG27: 461.5 | AH27: 544.2 | AI27: =AE27+AF27+AG27+AH27 -> 1861.9 | AJ27: 644.5 | AK27: 556 | AL27: =AG27*(1+AL32) -> 553.8 | AM27: =AH27*(1+AM32) -> 669.366 | AN27: =AJ27+AK27+AL27+AM27 -> 2423.666 | AO27: =AJ27*(1+AO32) -> 754.065 | AP27: =AK27*(1+AP32) -> 650.52 | AQ27: =AL27*(1+AQ32) -> 647.946 | AR27: =AM27*(1+AR32) -> 783.15822 | AS27: =AO27+AP27+AQ27+AR27 -> 2835.6892 | AT27: =AO27*(1+AT32) -> 874.7154 | AU27: =AP27*(1+AU32) -> 754.6032 | AV27: =AQ27*(1+AV32) -> 751.61736 | AW27: =AR27*(1+AW32) -> 908.46354 | AX27: =AT27+AU27+AV27+AW27 -> 3289.3995
B28: APAC | C28: 179.6 | D28: =D149+D250+D347 -> 47.932674 | E28: =E149+E250+E347 -> 45.636748 | F28: =F149+F250+F347 -> 52.881846 | G28: =G149+G250+G347 -> 68.564066 | H28: =D28+E28+F28+G28 -> 215.01533 | I28: =I149+I250+I347 -> 50.625918 | J28: =J149+J250+J347 -> 48.69249 | K28: =K149+K250+K347 -> 54.766539 | L28: =L149+L250+L347 -> 95.794137 | M28: =I28+J28+K28+L28 -> 249.87908 | N28: 78.2 | O28: 73.2 | P28: =P149+P250+P347 -> 84 | Q28: =350-N28-O28-P28 -> 114.6 | R28: =N28+O28+P28+Q28 -> 350 | W28: 84.6 | X28: 115.5 | Y28: 352.4 | Z28: 105.4 | AA28: 106.8 | AB28: 124.6 | AC28: 176 | AD28: =Z28+AA28+AB28+AC28 -> 512.8 | AE28: 156.9 | AF28: 154.5 | AG28: 192.1 | AH28: 269.4 | AI28: =AE28+AF28+AG28+AH28 -> 772.9 | AJ28: 239.4 | AK28: 247.6 | AL28: =AL12-AL25-AL26-AL27 -> 311.51742 | AM28: =AM12-AM25-AM26-AM27 -> 355.10192 | AN28: =AJ28+AK28+AL28+AM28 -> 1153.6193 | AO28: =AO12-AO25-AO26-AO27 -> 303.66284 | AP28: =AP12-AP25-AP26-AP27 -> 305.97876 | AQ28: =AQ12-AQ25-AQ26-AQ27 -> 356.93484 | AR28: =AR12-AR25-AR26-AR27 -> 425.29941 | AS28: =AO28+AP28+AQ28+AR28 -> 1391.8758 | AT28: =AT12-AT25-AT26-AT27 -> 358.63086 | AU28: =AU12-AU25-AU26-AU27 -> 358.50806 | AV28: =AV12-AV25-AV26-AV27 -> 416.99546 | AW28: =AW12-AW25-AW26-AW27 -> 521.21581 | AX28: =AT28+AU28+AV28+AW28 -> 1655.3502
B30: Americas % chg. y/y | C30: -- | D30: -- | E30: -- | F30: -- | G30: -- | H30: =H25/C25-1 -> 0.27337945 | I30: =I25/D25-1 -> 0.39908277 | J30: =J25/E25-1 -> 0.25274649 | K30: =K25/F25-1 -> 0.10092056 | L30: =L25/G25-1 -> 0.12756197 | M30: =M25/H25-1 -> 0.20058734 | N30: =N25/I25-1 -> 0.16850033 | O30: =O25/J25-1 -> 0.13945334 | ... R30: =R25/M25-1 -> 0.14787697 | Z30: =Z25/N25-1 -> 0.012939453 | AA30: =AA25/O25-1 -> 0.016397923 | AB30: =AB25/W25-1 -> 0.072087912 | AC30: =AC25/X25-1 -> 0.1506202 | AD30: =AD25/Y25-1 -> 0.064963336 | AE30: =AE25/Z25-1 -> 0.12002892 | AF30: =AF25/AA25-1 -> 0.063189029 | AG30: =AG25/AB25-1 -> 0.17712177 | AH30: =AH25/AC25-1 -> 0.18292266 | AI30: =AI25/AD25-1 -> 0.14341044 | ... AK30: =AK25/AF25-1 -> 0.25619626 | AL30: 0.18 | AM30: 0.14 | AN30: =AN25/AI25-1 -> 0.18137843 | AO30: 0.13 | AP30: 0.13 | AQ30: 0.13 | AR30: 0.13 | AS30: =AS25/AN25-1 -> 0.13 | AT30: 0.11 | AU30: 0.11 | AV30: 0.11 | AW30: 0.11 | AX30: =AX25/AS25-1 -> 0.11
B31: EMEA % chg. y/y | C31: -- | D31: -- | E31: -- | F31: -- | G31: -- | H31: =H26/C26-1 -> 0.13441776 | I31: =I26/D26-1 -> -0.018509166 | J31: =J26/E26-1 -> 0.068032847 | K31: =K26/F26-1 -> -0.099406509 | L31: =L26/G26-1 -> 0.17479441 | M31: =M26/H26-1 -> 0.036856876 | N31: =N26/I26-1 -> 0.28329997 | O31: =O26/J26-1 -> -0.03965945 | ... R31: =R26/M26-1 -> 0.14125171 | Z31: =Z26/N26-1 -> 0.01036705 | AA31: =AA26/O26-1 -> 0.01303781 | AB31: =AB26/W26-1 -> 0.037530266 | AC31: =AC26/X26-1 -> 0.080510339 | AD31: =AD26/Y26-1 -> 0.038282108 | AE31: =AE26/Z26-1 -> 0.1228508 | AF31: =AF26/AA26-1 -> 0.18489918 | AG31: =AG26/AB26-1 -> 0.23337223 | AH31: =AH26/AC26-1 -> 0.21376221 | AI31: =AI26/AD26-1 -> 0.19320735 | ... AK31: =AK26/AF26-1 -> 0.20311369 | AL31: 0.14 | AM31: 0.12 | AN31: =AN26/AI26-1 -> 0.17141101 | AO31: 0.13 | AP31: 0.13 | AQ31: 0.13 | AR31: 0.13 | AS31: =AS26/AN26-1 -> 0.13 | AT31: 0.11 | AU31: 0.11 | AV31: 0.11 | AW31: 0.11 | AX31: =AX26/AS26-1 -> 0.11
B32: Greater China % chg. y/y | C32: -- | D32: -- | E32: -- | F32: -- | G32: -- | H32: =H27/C27-1 -> 0.84311622 | I32: =I27/D27-1 -> 0.59831241 | J32: =J27/E27-1 -> 0.16461642 | K32: =K27/F27-1 -> 0.39248884 | L32: =L27/G27-1 -> 0.42652979 | M32: =M27/H27-1 -> 0.40474258 | N32: =N27/I27-1 -> 0.5742927 | O32: =O27/J27-1 -> 1.2511855 | ... R32: =R27/M27-1 -> 0.6064128 | Z32: =Z27/N27-1 -> 0.5155642 | AA32: =AA27/O27-1 -> 0.54371002 | AB32: =AB27/W27-1 -> 0.5605985 | AC32: =AC27/X27-1 -> 0.53867735 | AD32: =AD27/Y27-1 -> 0.53645833 | AE32: =AE27/Z27-1 -> 0.43132221 | AF32: =AF27/AA27-1 -> 0.41643646 | AG32: =AG27/AB27-1 -> 0.47491211 | AH32: =AH27/AC27-1 -> 0.41755666 | AI32: =AI27/AD27-1 -> 0.4344376 | ... AK32: =AK27/AF27-1 -> 0.35543637 | AL32: 0.2 | AM32: 0.23 | AN32: =AN27/AI27-1 -> 0.30171653 | AO32: 0.17 | AP32: 0.17 | AQ32: 0.17 | AR32: 0.17 | AS32: =AS27/AN27-1 -> 0.17 | AT32: 0.16 | AU32: 0.16 | AV32: 0.16 | AW32: 0.16 | AX32: =AX27/AS27-1 -> 0.16
B33: APAC (excl. China) % chg. y/y | C33: -- | D33: -- | E33: -- | F33: -- | G33: -- | H33: =H28/C28-1 -> 0.19719006 | I33: =I28/D28-1 -> 0.056188046 | J33: =J28/E28-1 -> 0.066957916 | K33: =K28/F28-1 -> 0.035639696 | L33: =L28/G28-1 -> 0.39714785 | M33: =M28/H28-1 -> 0.16214541 | N33: =N28/I28-1 -> 0.54466335 | O33: =O28/J28-1 -> 0.50331191 | ... R33: =R28/M28-1 -> 0.40067746 | Z33: =Z28/N28-1 -> 0.34782609 | AA33: =AA28/O28-1 -> 0.45901639 | AB33: =AB28/W28-1 -> 0.47281324 | AC33: =AC28/X28-1 -> 0.52380952 | AD33: =AD28/Y28-1 -> 0.45516459 | AE33: =AE28/Z28-1 -> 0.4886148 | AF33: =AF28/AA28-1 -> 0.44662921 | AG33: =AG28/AB28-1 -> 0.54173355 | AH33: =AH28/AC28-1 -> 0.53068182 | AI33: =AI28/AD28-1 -> 0.50721529 | ... AX33: =AX28/AS28-1 -> 0.18929443
B35: Americas % of total | C35: =C25/C$12 -> 0.40225656 | D35: =D25/D$12 -> 0.37761855 | E35: =E25/E$12 -> 0.42878491 | F35: =F25/F$12 -> 0.40118801 | G35: =G25/G$12 -> 0.42314079 | H35: =H25/H$12 -> 0.40862025 | I35: =I25/I$12 -> 0.43320951 | J35: =J25/J$12 -> 0.46309331 | ... R35: =R25/R$12 -> 0.39530252 | Z35: =Z25/Z$12 -> 0.34795371 | AA35: =AA25/AA$12 -> 0.37141716 | AB35: =AB25/AB$12 -> 0.3603191 | AC35: =AC25/AC$12 -> 0.35725639 | AD35: =AD25/AD$12 -> 0.35865182 | AE35: =AE25/AE$12 -> 0.31558574 | AF35: =AF25/AF$12 -> 0.31982529 | AG35: =AG25/AG$12 -> 0.32693731 | ... AX35: =AX25/AX$12 -> 0.29305903
B36: EMEA % of total | C36: =C26/C$12 -> 0.44166462 | D36: =D26/D$12 -> 0.42706869 | E36: =E26/E$12 -> 0.37526976 | F36: =F26/F$12 -> 0.40867921 | G36: =G26/G$12 -> 0.38886943 | H36: =H26/H$12 -> 0.39969116 | I36: =I26/I$12 -> 0.34370452 | J36: =J26/J$12 -> 0.34553655 | ... R36: =R26/R$12 -> 0.33200559 | Z36: =Z26/Z$12 -> 0.3024153 | AA36: =AA26/AA$12 -> 0.23279736 | AB36: =AB26/AB$12 -> 0.31651647 | AC36: =AC26/AC$12 -> 0.30028121 | AD36: =AD26/AD$12 -> 0.29197615 | AE36: =AE26/AE$12 -> 0.27497453 | AF36: =AF26/AF$12 -> 0.22340856 | AG36: =AG26/AG$12 -> 0.3009167 | ... AX36: =AX26/AX$12 -> 0.24686725
B37: Greater China % of total | C37: =C27/C$12 -> 0.082699697 | D37: =D27/D$12 -> 0.12315203 | E37: =E27/E$12 -> 0.11969485 | F37: =F27/F$12 -> 0.12458752 | G37: =G27/G$12 -> 0.11928304 | H37: =H27/H$12 -> 0.12159495 | I37: =I27/I$12 -> 0.16140036 | J37: =J27/J$12 -> 0.12017778 | ... R37: =R27/R$12 -> 0.19261498 | Z37: =Z27/Z$12 -> 0.2613217 | AA37: =AA27/AA$12 -> 0.28922401 | AB37: =AB27/AB$12 -> 0.2311272 | AC37: =AC27/AC$12 -> 0.23468639 | AD37: =AD27/AD$12 -> 0.25041962 | AE37: =AE27/AE$12 -> 0.30288625 | AF37: =AF27/AF$12 -> 0.33179649 | AG37: =AG27/AG$12 -> 0.26276832 | ... AX37: =AX27/AX$12 -> 0.30605518
B38: APAC (excl. China) % of total | C38: =C28/C$12 -> 0.073419998 | D38: =D28/D$12 -> 0.072243251 | E38: =E28/E$12 -> 0.076339888 | F38: =F28/F$12 -> 0.06559965 | G38: =G28/G$12 -> 0.068632698 | H38: =H28/H$12 -> 0.070119107 | I38: =I28/I$12 -> 0.062566201 | J38: =J28/J$12 -> 0.070220614 | ... R38: =R28/R$12 -> 0.080122702 | Z38: =Z28/Z$12 -> 0.088393157 | AA38: =AA28/AA$12 -> 0.10666134 | AB38: =AB28/AB$12 -> 0.092037229 | AC38: =AC28/AC$12 -> 0.10759262 | AD38: =AD28/AD$12 -> 0.098933112 | AE38: =AE28/AE$12 -> 0.10655348 | AF38: =AF28/AF$12 -> 0.12496967 | AG38: =AG28/AG$12 -> 0.10937767 | ... AX38: =AX28/AX$12 -> 0.15401854
B40: Wholesale | C40: =C101+C207+C310 -> 1916.2 | D40: =D101+D207+D310 -> 498.54 | E40: =E101+E207+E310 -> 433.54 | F40: =F101+F207+F310 -> 634.21 | G40: =G101+G207+G310 -> 669.93 | H40: =D40+E40+F40+G40 -> 2236.22 | I40: =I101+I207+I310 -> 566.72195 | J40: =J101+J207+J310 -> 504.54427 | K40: =K101+K207+K310 -> 638.84542 | L40: =L101+L207+L310 -> 792.27256 | M40: =I40+J40+K40+L40 -> 2502.3842 | N40: =N101+N207+N310 -> 702.7 | O40: =O101+O207+O310 -> 535.9 | P40: =P101+P207+P310 -> 812.5 | Q40: =Q101+Q207+Q310 -> 758.5 | R40: =N40+O40+P40+Q40 -> 2809.6 | S40: =S101+S207+S310 -> 2236.22 | T40: =T101+T207+T310 -> 2502.3842 | U40: =U101+U207+U310 -> 702.7 | V40: =V101+V207+V310 -> 535.9 | W40: =W101+W207+W310 -> 812.5 | X40: =X101+X207+X310 -> 758.5 | Y40: =U40+V40+W40+X40 -> 2809.6 | Z40: =Z101+Z207+Z310 -> 694.5 | AA40: =AA101+AA207+AA310 -> 544.5 | AB40: =AB101+AB207+AB310 -> 874 | AC40: =AC101+AC207+AC310 -> 803.3 | AD40: =Z40+AA40+AB40+AC40 -> 2916.3 | AE40: 779.9 | AF40: 595.4 | AG40: 1033.8 | AH40: 948.4 | AI40: =AE40+AF40+AG40+AH40 -> 3357.5 | AJ40: 944 | AK40: 735.8 | AL40: =AL101+AL207+AL310 -> 1165.458 | AM40: =AM101+AM207+AM310 -> 1042.915 | AN40: =AJ40+AK40+AL40+AM40 -> 3888.173 | AO40: =AO101+AO207+AO310 -> 1034.271 | AP40: =AP101+AP207+AP310 -> 804.158 | AQ40: =AQ101+AQ207+AQ310 -> 1280.1745 | AR40: =AR101+AR207+AR310 -> 1146.6177 | AS40: =AO40+AP40+AQ40+AR40 -> 4265.2212 | AT40: =AT101+AT207+AT310 -> 1125.0821 | AU40: =AU101+AU207+AU310 -> 870.9614 | AV40: =AV101+AV207+AV310 -> 1397.606 | AW40: =AW101+AW207+AW310 -> 1252.9057 | AX40: =AT40+AU40+AV40+AW40 -> 4646.5552
B41: DTC | C41: =C104+C210+C313 -> 530 | D41: =D104+D210+D313 -> 164.95 | E41: =E104+E210+E313 -> 164.27 | F41: =F104+F210+F313 -> 171.92 | G41: =G104+G210+G313 -> 329.07 | H41: =D41+E41+F41+G41 -> 830.21 | I41: =I104+I210+I313 -> 242.43566 | J41: =J104+J210+J313 -> 188.87732 | K41: =K104+K210+K313 -> 208.3376 | L41: =L104+L210+L313 -> 406.43879 | M41: =I41+J41+K41+L41 -> 1046.0894 | N41: =N104+N210+N313 -> 347.6 | O41: =O104+O210+O313 -> 320.9 | P41: =P104+P210+P313 -> 333.8 | Q41: =Q104+Q210+Q313 -> 556.4 | R41: =N41+O41+P41+Q41 -> 1558.7 | S41: =S104+S210+S313 -> 849.51 | T41: =T104+T210+T313 -> 1068.4894 | U41: =U104+U210+U313 -> 354.3 | V41: =V104+V210+V313 -> 326.9 | W41: =W104+W210+W313 -> 340.6 | X41: =X104+X210+X313 -> 568.9 | Y41: =U41+V41+W41+X41 -> 1590.7 | Z41: =Z104+Z210+Z313 -> 497.9 | AA41: =AA104+AA210+AA313 -> 456.8 | AB41: =AB104+AB210+AB313 -> 479.8 | AC41: =AC104+AC210+AC313 -> 832.5 | AD41: =Z41+AA41+AB41+AC41 -> 2267 | AE41: 692.6 | AF41: 640.9 | AG41: 722.5 | AH41: 1152.7 | AI41: =AE41+AF41+AG41+AH41 -> 3208.7 | AJ41: 1001.5 | AK41: 896.8 | AL41: =AL104+AL210+AL313 -> 979.90542 | AM41: =AM104+AM210+AM313 -> 1437.3789 | AN41: =AJ41+AK41+AL41+AM41 -> 4315.5843 | AO41: =AO104+AO210+AO313 -> 1223.0648 | AP41: =AP104+AP210+AP313 -> 1089.1108 | AQ41: =AQ104+AQ210+AQ313 -> 1171.1584 | AR41: =AR104+AR210+AR313 -> 1706.9233 | AS41: =AO41+AP41+AQ41+AR41 -> 5190.2572 | AT41: =AT104+AT210+AT313 -> 1439.829 | AU41: =AU104+AU210+AU313 -> 1281.9646 | AV41: =AV104+AV210+AV313 -> 1376.5685 | AW41: =AW104+AW210+AW313 -> 2002.8162 | AX41: =AT41+AU41+AV41+AW41 -> 6101.1783
B42: Ecommerce | C42: 274 | D42: 83.42209 | E42: 83.51704 | F42: 77.091911 | G42: 160.38432 | H42: =D42+E42+F42+G42 -> 404.41536 | I42: 113.2049 | J42: 97.541879 | K42: 92.693385 | L42: 210.31628 | M42: =I42+J42+K42+L42 -> 513.75645 | N42: 154.52854 | O42: 140.47242 | P42: 150.4 | Q42: =718.4-N42-O42-P42 -> 272.99904 | R42: =N42+O42+P42+Q42 -> 718.4
B43: Retail | C43: 257 | D43: 81.535481 | E43: 80.737995 | F43: 94.826903 | G43: 168.68469 | H43: =D43+E43+F43+G43 -> 425.78506 | I43: 129.23075 | J43: 91.335439 | K43: 115.64422 | L43: 196.12251 | M43: =I43+J43+K43+L43 -> 532.33292 | N43: 192.97448 | O43: 180.5436 | P43: 183.4 | Q43: =840.4-N43-O43-P43 -> 283.48193 | R43: =N43+O43+P43+Q43 -> 840.4
B44: Total | C44: =C40+C41 -> 2446.2 | D44: =D40+D41 -> 663.49 | E44: =E40+E41 -> 597.81 | F44: =F40+F41 -> 806.13 | G44: =G40+G41 -> 999 | H44: =H40+H41 -> 3066.43 | I44: =I40+I41 -> 809.15761 | J44: =J40+J41 -> 693.42159 | ... AX44: =AX40+AX41 -> 10747.734
B45: % chg. y/y | C45: -- | D45: -- | E45: -- | F45: -- | G45: -- | H45: =H44/C44-1 -> 0.25354836 | I45: =I44/D44-1 -> 0.21954756 | J45: =J44/E44-1 -> 0.15993641 | K45: =K44/F44-1 -> 0.05092606 | L45: =L44/G44-1 -> 0.19991127 | M45: =M44/H44-1 -> 0.15720026 | N45: =N44/I44-1 -> 0.29801658 | O45: =O44/J44-1 -> 0.23561195 | ... R45: =R44/M44-1 -> 0.23103636 | S45: -- | T45: =T44/S44-1 -> 0.15722166 | U45: -- | V45: -- | W45: -- | X45: -- | Y45: =Y44/T44-1 -> 0.23227549 | Z45: =Z44/U44-1 -> 0.12809839 | AA45: =AA44/V44-1 -> 0.16052388 | AB45: =AB44/W44-1 -> 0.17405255 | AC45: =AC44/X44-1 -> 0.23233389 | AD45: =AD44/Y44-1 -> 0.17794241 | AE45: =AE44/Z44-1 -> 0.23490439 | AF45: =AF44/AA44-1 -> 0.2346949 | ... AX45: =AX44/AS44-1 -> 0.13666734
B47: Wholesale % chg. y/y | C47: -- | D47: -- | E47: -- | F47: -- | G47: -- | H47: =H40/C40-1 -> 0.16700762 | I47: =I40/D40-1 -> 0.13676325 | J47: =J40/E40-1 -> 0.16377789 | K47: =K40/F40-1 -> 0.0073089671 | L47: =L40/G40-1 -> 0.18261992 | M47: =M40/H40-1 -> 0.11902416 | N47: =N40/I40-1 -> 0.23993785 | O47: =O40/J40-1 -> 0.062146644 | ... R47: =R40/M40-1 -> 0.12276924 | S47: -- | T47: =T40/S40-1 -> 0.11902416 | U47: -- | V47: -- | W47: -- | X47: -- | Y47: =Y40/T40-1 -> 0.12276924 | Z47: =Z40/U40-1 -> -0.011669276 | AA47: =AA40/V40-1 -> 0.01604777 | AB47: =AB40/W40-1 -> 0.075692308 | AC47: =AC40/X40-1 -> 0.059063942 | AD47: =AD40/Y40-1 -> 0.037976936 | AE47: =AE40/Z40-1 -> 0.12296616 | AF47: =AF40/AA40-1 -> 0.093480257 | ... AX47: =AX40/AS40-1 -> 0.089405447
B48: DTC % chg. y/y | C48: -- | D48: -- | E48: -- | F48: -- | G48: -- | H48: =H41/C41-1 -> 0.56643396 | I48: =I41/D41-1 -> 0.4697524 | J48: =J41/E41-1 -> 0.149798 | K48: =K41/F41-1 -> 0.21182878 | L48: =L41/G41-1 -> 0.23511348 | M48: =M41/H41-1 -> 0.26002984 | N48: =N41/I41-1 -> 0.43378248 | O48: =O41/J41-1 -> 0.69898643 | ... R48: =R41/M41-1 -> 0.49002565 | S48: -- | T48: =T41/S41-1 -> 0.25777139 | U48: -- | V48: -- | W48: -- | X48: -- | Y48: =Y41/T41-1 -> 0.48873731 | Z48: =Z41/U41-1 -> 0.40530624 | AA48: =AA41/V41-1 -> 0.39736923 | AB48: =AB41/W41-1 -> 0.40869055 | AC48: =AC41/X41-1 -> 0.46335033 | AD48: =AD41/Y41-1 -> 0.42515874 | AE48: =AE41/Z41-1 -> 0.39104238 | AF48: =AF41/AA41-1 -> 0.40302102 | ... AX48: =AX41/AS41-1 -> 0.17550596
B49: Ecommerce % chg. y/y | C49: -- | D49: -- | E49: -- | F49: -- | G49: -- | H49: =H42/C42-1 -> 0.47596847 | I49: =I42/D42-1 -> 0.35701352 | J49: =J42/E42-1 -> 0.16792787 | K49: =K42/F42-1 -> 0.20237499 | L49: =L42/G42-1 -> 0.31132695 | M49: =M42/H42-1 -> 0.27036829 | N49: =N42/I42-1 -> 0.365034 | O49: =O42/J42-1 -> 0.44012419 | ... R49: =R42/M42-1 -> 0.39832794
...

Sheet 4. Summary Model
B1: Amer Sports, Inc.
B2: Summary Model
B3: $ millions except per share data, FY ending Dec
C5: ='2. Consolidated'!C5 -> 44196 | D5: ='2. Consolidated'!D5 -> 44286 | E5: ='2. Consolidated'!E5 -> 44377 | F5: ='2. Consolidated'!F5 -> 44469 | G5: ='2. Consolidated'!G5 -> 44561 | H5: ='2. Consolidated'!H5 -> 44561 | I5: ='2. Consolidated'!I5 -> 44651 | J5: ='2. Consolidated'!J5 -> 44742 | ... AX5: ='2. Consolidated'!AX5 -> 47118
C6: ='2. Consolidated'!C6 -> FY20 | D6: ='2. Consolidated'!D6 -> Q1'21 | E6: ='2. Consolidated'!E6 -> Q2'21 | F6: ='2. Consolidated'!F6 -> Q3'21 | G6: ='2. Consolidated'!G6 -> Q4'21 | H6: ='2. Consolidated'!H6 -> FY21 | I6: ='2. Consolidated'!I6 -> Q1'22 | J6: ='2. Consolidated'!J6 -> Q2'22 | ... AX6: ='2. Consolidated'!AX6 -> FY28E
B7: Segment Summary:
B8: Technical Apparel
