Workbook
Name \A: #REF!
Name \B: #REF!
Name \C: #REF!
Name \L: #REF!
Name \M: #REF!
Name \O: #REF!
Name \P: #REF!
Name \q: #REF!
Name \R: #REF!
Name \S: #REF!
Name \T: #REF!
Name \X: #REF!
Name \Z: #REF!
Name _: #REF!
Name __DAT1: #REF!
Name __DAT2: #REF!
Name __DAT3: #REF!
Name __DAT4: #REF!
Name __DAT5: #REF!
Name __DAT6: #REF!
Name __DAT7: #REF!
Name __DAT8: #REF!
Name _10_0pf1: #REF!
Name _107_._0Restructuring_char: #REF!
Name _108_._0Restructuring_char: #REF!
Name _116_._0SGA_gro: #REF!
Name _117_._0SGA_gro: #REF!
Name _125_._0Shares_repurchase_liabil: #REF!
Name _126_._0Shares_repurchase_liabil: #REF!
Name _134_0FAMERangeSheet: #REF!
Name _135_0FAMERangeSheet: #REF!
Name _143_0FAMERangeSheet: #REF!
Name _144_0FAMERangeSheet: #REF!
Name _152_0FAMERangeSheet: #REF!
Name _153_0FAMERangeSheet: #REF!
Name _161_0FAMERangeSheet: #REF!
Name _162_0FAMERangeSheet: #REF!
Name _17_0UniqueRang: #REF!
Name _170_0FAMERangeSheet: #REF!
Name _171_0FAMERangeSheet: #REF!
Name _179_0FAMERangeSheet: #REF!
Name _18_0UniqueRang: #REF!
Name _180_0FAMERangeSheet: #REF!
Name _188_0FAMERangeSheet: #REF!
Name _189_0FAMERangeSheet: #REF!
Name _197_0FAMERangeSheet: #REF!
Name _198_0FAMERangeSheet: #REF!
Name _1997BB: #REF!
Name _1997PL: #REF!
Name _1997PLQ: #REF!
Name _1998BB: #REF!
Name _1998PL: #REF!
Name _1998PLQ: #REF!
Name _1999BB: #REF!
Name _1999PL: #REF!
Name _1999PLQ: #REF!
Name _2: #REF!
Name _20_0_0TWX_Annual_Segments_Cha: #REF!
Name _2000BB: #REF!
Name _2000PL: #REF!

Sheet 1. Cover
F3: Lululemon Athetica Inc. (LULU)
F4: COMPANY MODEL
B9: Sources: Company data, Goldman Sachs Global Investment Research
B11: Date: September 4th, 2026
B13: Brooke Roach, CFA
B14: Managing Director
B15: tel: 212-357-2421
B16: brooke.roach@gs.com
B18: Mentesnot Adamu
B19: Analyst
B20: tel: 801-744-0630
B21: mentesnot.adamu@gs.com
B23: Carly Chasen
B24: Analyst
... B26: carly.chasen@gs.com

Sheet 2. Consolidated
B1: Lululemon Athletica Inc. (LULU)
B2: Consolidated
B3: $ millions except per-share data, fiscal year ending January
C5: 38383 | D5: 38472 | E5: 38564 | F5: 38656 | G5: 38748 | H5: =G5 -> 38748 | I5: =DATE(YEAR(D5)+1,MONTH(D5),DAY(D5)) -> 38837 | J5: =DATE(YEAR(E5)+1,MONTH(E5),DAY(E5)) -> 38929 | K5: =DATE(YEAR(F5)+1,MONTH(F5),DAY(F5)) -> 39021 | L5: =DATE(YEAR(G5)+1,MONTH(G5),DAY(G5)) -> 39113 | M5: =DATE(YEAR(H5)+1,MONTH(H5),DAY(H5)) -> 39113 | N5: =DATE(YEAR(I5)+1,MONTH(I5),DAY(I5)) -> 39202 | O5: =DATE(YEAR(J5)+1,MONTH(J5),DAY(J5)) -> 39294 | P5: =DATE(YEAR(K5)+1,MONTH(K5),DAY(K5)) -> 39386 | ... DS5: =DATE(YEAR(DN5)+1,MONTH(DN5),DAY(DN5)) -> 47149
C6: FY04 | D6: 1Q | E6: 2Q | F6: 3Q | G6: 4Q | H6: FY05 | I6: 1Q | J6: 2Q | K6: 3Q | L6: 4Q | M6: FY06 | N6: 1Q | O6: 2Q | P6: 3Q | Q6: 4Q | R6: FY07 | S6: 1Q | T6: 2Q | U6: 3Q | V6: 4Q | W6: FY08* | X6: 1Q | Y6: 2Q | Z6: 3Q | AA6: 4Q | AB6: FY09 | AC6: 1Q | AD6: 2Q | AE6: 3Q | AF6: 4Q | AG6: FY10 | AH6: 1Q | AI6: 2Q | AJ6: 3Q | AK6: 4Q | AL6: FY11 | AM6: 1Q | AN6: 2Q | AO6: 3Q | AP6: 4Q | AQ6: FY12* | AR6: 1Q | AS6: 2Q | AT6: 3Q | AU6: 4Q | AV6: FY13* | AW6: 1Q | AX6: 2Q | AY6: 3Q | AZ6: 4Q | BA6: FY14 | BB6: 1Q | BC6: 2Q | BD6: 3Q | BE6: 4Q | BF6: FY15 | BG6: 1Q | BH6: 2Q | BI6: 3Q | BJ6: 4Q | BK6: FY16 | BL6: 1Q | BM6: 2Q | BN6: 3Q | BO6: 4Q | BP6: FY17 | BQ6: 1Q | BR6: 2Q | BS6: 3Q | BT6: 4Q | BU6: FY18* | BV6: 1Q | BW6: 2Q | BX6: 3Q | BY6: 4Q | BZ6: FY19 | CA6: 1Q | CB6: 2Q | CC6: 3Q | CD6: 4Q | CE6: FY20 | CF6: 1Q | CG6: 2Q | CH6: 3Q | CI6: 4Q | CJ6: FY21 | CK6: 1Q | CL6: 2Q | CM6: 3QE | CN6: 4Q | CO6: FY22 | CP6: 1Q | CQ6: 2Q | CR6: 3Q | CS6: 4Q | CT6: FY23 | CU6: 1Q | CV6: 2Q | CW6: 3Q | CX6: 4Q | CY6: FY24 | CZ6: 1Q | DA6: 2Q | DB6: 3Q | DC6: 4Q | DD6: FY25 | DE6: 1Q | DF6: 2Q | DG6: 3QE | DH6: 4QE | DI6: FY26E | DJ6: 1QE | DK6: 2QE | DL6: 3QE | DM6: 4QE | DN6: FY27E | DO6: 1QE | DP6: 2QE | DQ6: 3QE | DR6: 4QE | DS6: FY28E
B7: DIVISIONAL SUMMARY
B8: Net Sales
B9: Stores | C9: ='3. Earnings Build'!C28 -> 29.906 | D9: ='3. Earnings Build'!D28 -> 11.052 | E9: ='3. Earnings Build'!E28 -> 13.455 | F9: ='3. Earnings Build'!F28 -> 15.62 | G9: ='3. Earnings Build'!G28 -> 25.45 | H9: =SUM(D9:G9) -> 65.577 | I9: ='3. Earnings Build'!I28 -> 22.146 | J9: ='3. Earnings Build'!J28 -> 26.831 | K9: ='3. Earnings Build'!K28 -> 29.145 | L9: ='3. Earnings Build'!L28 -> 42.612 | M9: =SUM(I9:L9) -> 120.734 | N9: ='3. Earnings Build'!N28 -> 38.008 | O9: ='3. Earnings Build'!O28 -> 53.1 | P9: ='3. Earnings Build'!P28 -> 59.9 | Q9: ='3. Earnings Build'!Q28 -> 92.5 | R9: =SUM(N9:Q9) -> 243.508 | S9: ='3. Earnings Build'!S28 -> 70.6 | T9: ='3. Earnings Build'!T28 -> 78.3 | U9: ='3. Earnings Build'!U28 -> 77.6 | V9: ='3. Earnings Build'!V28 -> 89.047803 | W9: =SUM(S9:V9) -> 315.5478 | X9: ='3. Earnings Build'!X28 -> 72.031 | Y9: ='3. Earnings Build'!Y28 -> 85.1 | Z9: ='3. Earnings Build'!Z28 -> 98.1 | AA9: ='3. Earnings Build'!AA28 -> 138.3 | AB9: =SUM(X9:AA9) -> 393.531 | AC9: ='3. Earnings Build'!AC28 -> 115.597 | AD9: ='3. Earnings Build'!AD28 -> 129.4 | AE9: ='3. Earnings Build'!AE28 -> 143.2 | AF9: ='3. Earnings Build'!AF28 -> 202.8 | AG9: =SUM(AC9:AF9) -> 590.997 | AH9: ='3. Earnings Build'!AH28 -> 156.5 | AI9: ='3. Earnings Build'!AI28 -> 178.223 | AJ9: ='3. Earnings Build'!AJ28 -> 190.016 | AK9: ='3. Earnings Build'!AK28 -> 292.47028 | AL9: =SUM(AH9:AK9) -> 817.20928 | AM9: ='3. Earnings Build'!AM28 -> 228.789 | AN9: ='3. Earnings Build'!AN28 -> 231.314 | AO9: ='3. Earnings Build'!AO28 -> 252.046 | AP9: ='3. Earnings Build'!AP28 -> 378.032 | AQ9: =SUM(AM9:AP9) -> 1090.181 | AR9: ='3. Earnings Build'!AR28 -> 269.357 | AS9: ='3. Earnings Build'!AS28 -> 273.768 | AT9: ='3. Earnings Build'!AT28 -> 290.666 | AU9: ='3. Earnings Build'!AU28 -> 395.208 | AV9: =SUM(AR9:AU9) -> 1228.999 | AW9: ='3. Earnings Build'!AW28 -> 288.101 | AX9: ='3. Earnings Build'!AX28 -> 294.04 | AY9: ='3. Earnings Build'!AY28 -> 310.014 | AZ9: ='3. Earnings Build'!AZ28 -> 456.07 | BA9: =SUM(AW9:AZ9) -> 1348.225 | BB9: ='3. Earnings Build'!BB28 -> 314.094 | BC9: ='3. Earnings Build'!BC28 -> 339.779 | BD9: ='3. Earnings Build'!BD28 -> 353.399 | BE9: ='3. Earnings Build'!BE28 -> 509.051 | BF9: =SUM(BB9:BE9) -> 1516.323 | BG9: ='3. Earnings Build'!BG28 -> 358.704 | BH9: ='3. Earnings Build'!BH28 -> 381.389 | BI9: ='3. Earnings Build'!BI28 -> 393.506 | BJ9: ='3. Earnings Build'!BJ28 -> 570.758 | BK9: =SUM(BG9:BJ9) -> 1704.357 | BL9: ='3. Earnings Build'!BL28 -> 379.099 | BM9: ='3. Earnings Build'!BM28 -> 413.944 | BN9: ='3. Earnings Build'!BN28 -> 425.1 | BO9: ='3. Earnings Build'!BO28 -> 618.9 | BP9: =SUM(BL9:BO9) -> 1837.043 | BQ9: ='3. Earnings Build'!BQ28 -> 433.12 | BR9: ='3. Earnings Build'!BR28 -> 486.4 | BS9: ='3. Earnings Build'!BS28 -> 476.877 | BT9: ='3. Earnings Build'!BT28 -> 729.966 | BU9: =SUM(BQ9:BT9) -> 2126.363 | BV9: ='3. Earnings Build'!BV28 -> 506.422 | BW9: ='3. Earnings Build'!BW28 -> 583.756 | BX9: ='3. Earnings Build'!BX28 -> 579.5 | BY9: ='3. Earnings Build'!BY28 -> 831.4 | BZ9: =SUM(BV9:BY9) -> 2501.078 | CA9: ='3. Earnings Build'!CA28 -> 259.97 | CB9: ='3. Earnings Build'!CB28 -> 287.2 | CC9: ='3. Earnings Build'!CC28 -> 511.756 | CD9: ='3. Earnings Build'!CD28 -> 599.881 | CE9: =SUM(CA9:CD9) -> 1658.807 | CF9: ='3. Earnings Build'!CF28 -> 536.584 | CG9: ='3. Earnings Build'!CG28 -> 695.12 | CH9: ='3. Earnings Build'!CH28 -> 707.16 | CI9: ='3. Earnings Build'!CI28 -> 882.633 | CJ9: =SUM(CF9:CI9) -> 2821.497 | CK9: ='3. Earnings Build'!CK28 -> 731.604 | CL9: ='3. Earnings Build'!CL28 -> 903.077 | CM9: ='3. Earnings Build'!CM28 -> 903.06 | CN9: ='3. Earnings Build'!CN28 -> 1110.386 | CO9: =SUM(CK9:CN9) -> 3648.127 | CP9: ='3. Earnings Build'!CP28 -> 958.087 | CQ9: ='3. Earnings Build'!CQ28 -> 1096.939 | CR9: ='3. Earnings Build'!CR28 -> 1073.973 | CS9: ='3. Earnings Build'!CS28 -> 1281.957 | CT9: =SUM(CP9:CS9) -> 4410.956 | CU9: ='3. Earnings Build'!CU28 -> 1070.525 | CV9: ='3. Earnings Build'!CV28 -> 1215.613 | CW9: ='3. Earnings Build'!CW28 -> 1210.523 | CX9: ='3. Earnings Build'!CX28 -> 1511.211 | CY9: =SUM(CU9:CX9) -> 5007.872 | CZ9: ='3. Earnings Build'!CZ28 -> 1153.107 | DA9: ='3. Earnings Build'!DA28 -> 1254.952 | DB9: ='3. Earnings Build'!DB28 -> 1206.558 | DC9: ='3. Earnings Build'!DC28 -> 1435.127 | DD9: =SUM(CZ9:DC9) -> 5049.744 | DE9: ='3. Earnings Build'!DE28 -> 1192.84 | DF9: ='3. Earnings Build'!DF28 -> 1173.747
B10: Direct | C10: ='3. Earnings Build'!C30 -> 0 | D10: ='3. Earnings Build'!D30 -> 0 | E10: ='3. Earnings Build'!E30 -> 0 | F10: ='3. Earnings Build'!F30 -> 0 | G10: ='3. Earnings Build'!G30 -> 0 | H10: =SUM(D10:G10) -> 0 | I10: ='3. Earnings Build'!I30 -> 0 | J10: ='3. Earnings Build'!J30 -> 0 | K10: ='3. Earnings Build'!K30 -> 0 | L10: ='3. Earnings Build'!L30 -> 0 | M10: =SUM(I10:L10) -> 0 | N10: ='3. Earnings Build'!N30 -> 0 | O10: ='3. Earnings Build'!O30 -> 0 | P10: ='3. Earnings Build'!P30 -> 0 | Q10: ='3. Earnings Build'!Q30 -> 0 | R10: =SUM(N10:Q10) -> 0 | S10: ='3. Earnings Build'!S30 -> 0 | T10: ='3. Earnings Build'!T30 -> 0 | U10: ='3. Earnings Build'!U30 -> 0 | V10: ='3. Earnings Build'!V30 -> 0 | W10: =SUM(S10:V10) -> 0 | X10: ='3. Earnings Build'!X30 -> 0.869 | Y10: ='3. Earnings Build'!Y30 -> 2.8 | Z10: ='3. Earnings Build'!Z30 -> 4.2 | AA10: ='3. Earnings Build'!AA30 -> 8.4 | AB10: =SUM(X10:AA10) -> 16.269 | AC10: ='3. Earnings Build'!AC30 -> 9.1278 | AD10: ='3. Earnings Build'!AD30 -> 9.6 | AE10: ='3. Earnings Build'!AE30 -> 13.4 | AF10: ='3. Earnings Build'!AF30 -> 24.6 | AG10: =SUM(AC10:AF10) -> 56.7278 | AH10: ='3. Earnings Build'!AH30 -> 13.82172 | AI10: ='3. Earnings Build'!AI30 -> 18.6 | AJ10: ='3. Earnings Build'!AJ30 -> 23.9 | AK10: ='3. Earnings Build'!AK30 -> 50.1 | AL10: =SUM(AH10:AK10) -> 106.42172 | AM10: ='3. Earnings Build'!AM30 -> 38.447 | AN10: ='3. Earnings Build'!AN30 -> 35.422 | AO10: ='3. Earnings Build'!AO30 -> 45.122 | AP10: ='3. Earnings Build'!AP30 -> 78.3 | AQ10: =SUM(AM10:AP10) -> 197.291 | AR10: ='3. Earnings Build'!AR30 -> 53.967 | AS10: ='3. Earnings Build'!AS30 -> 49.384 | AT10: ='3. Earnings Build'!AT30 -> 61.954 | AU10: ='3. Earnings Build'!AU30 -> 97.778 | AV10: =SUM(AR10:AU10) -> 263.083 | AW10: ='3. Earnings Build'!AW30 -> 65.974 | AX10: ='3. Earnings Build'!AX30 -> 63.5 | AY10: ='3. Earnings Build'!AY30 -> 77.203 | AZ10: ='3. Earnings Build'!AZ30 -> 114.5 | BA10: =SUM(AW10:AZ10) -> 321.177 | BB10: ='3. Earnings Build'!BB30 -> 83.636 | BC10: ='3. Earnings Build'!BC30 -> 82.239 | BD10: ='3. Earnings Build'!BD30 -> 89.33 | BE10: ='3. Earnings Build'!BE30 -> 146.32 | BF10: =SUM(BB10:BE10) -> 401.525 | BG10: ='3. Earnings Build'!BG30 -> 97.566 | BH10: ='3. Earnings Build'!BH30 -> 87.399 | BI10: ='3. Earnings Build'!BI30 -> 104.013 | BJ10: ='3. Earnings Build'!BJ30 -> 164.309 | BK10: =SUM(BG10:BJ10) -> 453.287 | BL10: ='3. Earnings Build'!BL30 -> 97.223 | BM10: ='3. Earnings Build'!BM30 -> 113.049 | BN10: ='3. Earnings Build'!BN30 -> 131.181 | BO10: ='3. Earnings Build'!BO30 -> 236.14 | BP10: =SUM(BL10:BO10) -> 577.593 | BQ10: ='3. Earnings Build'!BQ30 -> 157.82 | BR10: ='3. Earnings Build'!BR30 -> 167.4 | BS10: ='3. Earnings Build'!BS30 -> 189.375 | BT10: ='3. Earnings Build'!BT30 -> 344.261 | BU10: =SUM(BQ10:BT10) -> 858.856 | BV10: ='3. Earnings Build'!BV30 -> 209.844 | BW10: ='3. Earnings Build'!BW30 -> 217.636 | BX10: ='3. Earnings Build'!BX30 -> 246.7 | BY10: ='3. Earnings Build'!BY30 -> 463.6 | BZ10: =SUM(BV10:BY10) -> 1137.78 | CA10: ='3. Earnings Build'!CA30 -> 352.039 | CB10: ='3. Earnings Build'!CB30 -> 554.3 | CC10: ='3. Earnings Build'!CC30 -> 478.263 | CD10: ='3. Earnings Build'!CD30 -> 899.466 | CE10: =SUM(CA10:CD10) -> 2284.068 | CF10: ='3. Earnings Build'!CF30 -> 545.1 | CG10: ='3. Earnings Build'!CG30 -> 597.426 | CH10: ='3. Earnings Build'!CH30 -> 586.525 | CI10: ='3. Earnings Build'!CI30 -> 1048.893 | CJ10: =SUM(CF10:CI10) -> 2777.944 | CK10: ='3. Earnings Build'!CK30 -> 721.253 | CL10: ='3. Earnings Build'!CL30 -> 775.425 | CM10: ='3. Earnings Build'!CM30 -> 767.351 | CN10: ='3. Earnings Build'!CN30 -> 1435.762 | CO10: =SUM(CK10:CN10) -> 3699.791 | CP10: ='3. Earnings Build'!CP30 -> 834.942 | CQ10: ='3. Earnings Build'!CQ30 -> 893.673 | CR10: ='3. Earnings Build'!CR30 -> 908.127 | CS10: ='3. Earnings Build'!CS30 -> 1674.368 | CT10: =SUM(CP10:CS10) -> 4311.11 | CU10: ='3. Earnings Build'!CU30 -> 905.787 | CV10: ='3. Earnings Build'!CV30 -> 910.637 | CW10: ='3. Earnings Build'!CW30 -> 944.777 | CX10: ='3. Earnings Build'!CX30 -> 1809.245 | CY10: =SUM(CU10:CX10) -> 4570.446 | CZ10: ='3. Earnings Build'!CZ30 -> 960.89 | DA10: ='3. Earnings Build'!DA30 -> 993.093 | DB10: ='3. Earnings Build'!DB30 -> 1066.75 | DC10: ='3. Earnings Build'!DC30 -> 1897.964 | DD10: =SUM(CZ10:DC10) -> 4918.697 | DE10: ='3. Earnings Build'!DE30 -> 997.442 | DF10: ='3. Earnings Build'!DF30 -> 934.63
B11: Other | C11: ='3. Earnings Build'!C32 -> 10.843 | D11: ='3. Earnings Build'!D32 -> 4.578 | E11: ='3. Earnings Build'!E32 -> 3.671 | F11: ='3. Earnings Build'!F32 -> 4.364 | G11: ='3. Earnings Build'!G32 -> 5.939093 | H11: =SUM(D11:G11) -> 18.552093 | I11: ='3. Earnings Build'!I32 -> 6.038 | J11: ='3. Earnings Build'!J32 -> 5.686437 | K11: ='3. Earnings Build'!K32 -> 6.822615 | L11: ='3. Earnings Build'!L32 -> 9.603782 | M11: =SUM(I11:L11) -> 28.150834 | N11: ='3. Earnings Build'!N32 -> 6.781456 | O11: ='3. Earnings Build'!O32 -> 5.580944 | P11: ='3. Earnings Build'!P32 -> 6.25028 | Q11: ='3. Earnings Build'!Q32 -> 12.592648 | R11: =SUM(N11:Q11) -> 31.205328 | S11: ='3. Earnings Build'!S32 -> 7.567494 | T11: ='3. Earnings Build'!T32 -> 7.184223 | U11: ='3. Earnings Build'!U32 -> 9.447135 | V11: ='3. Earnings Build'!V32 -> 14.873197 | W11: =SUM(S11:V11) -> 39.072049 | X11: ='3. Earnings Build'!X32 -> 8.78 | Y11: ='3. Earnings Build'!Y32 -> 9.821 | Z11: ='3. Earnings Build'!Z32 -> 10.591 | AA11: ='3. Earnings Build'!AA32 -> 13.906 | AB11: =SUM(X11:AA11) -> 43.098 | AC11: ='3. Earnings Build'!AC32 -> 13.5722 | AD11: ='3. Earnings Build'!AD32 -> 13.208 | AE11: ='3. Earnings Build'!AE32 -> 19.2 | AF11: ='3. Earnings Build'!AF32 -> 17.999 | AG11: =SUM(AC11:AF11) -> 63.9792 | AH11: ='3. Earnings Build'!AH32 -> 16.45828 | AI11: ='3. Earnings Build'!AI32 -> 15.5 | AJ11: ='3. Earnings Build'!AJ32 -> 16.3 | AK11: ='3. Earnings Build'!AK32 -> 28.94972 | AL11: =SUM(AH11:AK11) -> 77.208 | AM11: ='3. Earnings Build'!AM32 -> 18.462 | AN11: ='3. Earnings Build'!AN32 -> 15.898 | AO11: ='3. Earnings Build'!AO32 -> 19.369 | AP11: ='3. Earnings Build'!AP32 -> 29.193 | AQ11: =SUM(AM11:AP11) -> 82.922 | AR11: ='3. Earnings Build'!AR32 -> 22.458 | AS11: ='3. Earnings Build'!AS32 -> 21.361 | AT11: ='3. Earnings Build'!AT32 -> 27.28 | AU11: ='3. Earnings Build'!AU32 -> 28.007 | AV11: =SUM(AR11:AU11) -> 99.106 | AW11: ='3. Earnings Build'!AW32 -> 30.543 | AX11: ='3. Earnings Build'!AX32 -> 33.187 | AY11: ='3. Earnings Build'!AY32 -> 32.179 | AZ11: ='3. Earnings Build'!AZ32 -> 31.899 | BA11: =SUM(AW11:AZ11) -> 127.808 | BB11: ='3. Earnings Build'!BB32 -> 25.814 | BC11: ='3. Earnings Build'!BC32 -> 30.992 | BD11: ='3. Earnings Build'!BD32 -> 36.964 | BE11: ='3. Earnings Build'!BE32 -> 48.905 | BF11: =SUM(BB11:BE11) -> 142.675 | BG11: ='3. Earnings Build'!BG32 -> 39.246 | BH11: ='3. Earnings Build'!BH32 -> 45.732 | BI11: ='3. Earnings Build'!BI32 -> 46.897 | BJ11: ='3. Earnings Build'!BJ32 -> 54.873 | BK11: =SUM(BG11:BJ11) -> 186.748 | BL11: ='3. Earnings Build'!BL32 -> 43.985 | BM11: ='3. Earnings Build'!BM32 -> 54.061 | BN11: ='3. Earnings Build'!BN32 -> 62.753 | BO11: ='3. Earnings Build'!BO32 -> 73.74 | BP11: =SUM(BL11:BO11) -> 234.539 | BQ11: ='3. Earnings Build'!BQ32 -> 58.72 | BR11: ='3. Earnings Build'!BR32 -> 69.7 | BS11: ='3. Earnings Build'!BS32 -> 81.403 | BT11: ='3. Earnings Build'!BT32 -> 93.277 | BU11: =SUM(BQ11:BT11) -> 303.1 | BV11: ='3. Earnings Build'!BV32 -> 66.049 | BW11: ='3. Earnings Build'!BW32 -> 81.96 | BX11: ='3. Earnings Build'!BX32 -> 89.9 | BY11: ='3. Earnings Build'!BY32 -> 102.5 | BZ11: =SUM(BV11:BY11) -> 340.409 | CA11: ='3. Earnings Build'!CA32 -> 39.953 | CB11: ='3. Earnings Build'!CB32 -> 61.439 | CC11: ='3. Earnings Build'!CC32 -> 127.407 | CD11: ='3. Earnings Build'!CD32 -> 230.205 | CE11: =SUM(CA11:CD11) -> 459.004 | CF11: ='3. Earnings Build'!CF32 -> 144.792 | CG11: ='3. Earnings Build'!CG32 -> 158.072 | CH11: ='3. Earnings Build'!CH32 -> 156.736 | CI11: ='3. Earnings Build'!CI32 -> 197.576 | CJ11: =SUM(CF11:CI11) -> 657.176 | CK11: ='3. Earnings Build'!CK32 -> 160.606 | CL11: ='3. Earnings Build'!CL32 -> 189.826 | CM11: ='3. Earnings Build'!CM32 -> 186.478 | CN11: ='3. Earnings Build'!CN32 -> 225.69 | CO11: =SUM(CK11:CN11) -> 762.6 | CP11: ='3. Earnings Build'!CP32 -> 207.763 | CQ11: ='3. Earnings Build'!CQ32 -> 218.553 | CR11: ='3. Earnings Build'!CR32 -> 222.118 | CS11: ='3. Earnings Build'!CS32 -> 248.778 | CT11: =SUM(CP11:CS11) -> 897.212 | CU11: ='3. Earnings Build'!CU32 -> 232.579 | CV11: ='3. Earnings Build'!CV32 -> 244.828 | CW11: ='3. Earnings Build'!CW32 -> 241.36 | CX11: ='3. Earnings Build'!CX32 -> 291.041 | CY11: =SUM(CU11:CX11) -> 1009.808 | CZ11: ='3. Earnings Build'!CZ32 -> 256.663 | DA11: ='3. Earnings Build'!DA32 -> 277.174 | DB11: ='3. Earnings Build'!DB32 -> 292.612 | DC11: ='3. Earnings Build'!DC32 -> 307.71 | DD11: =SUM(CZ11:DC11) -> 1134.159 | DE11: ='3. Earnings Build'!DE32 -> 281.321 | DF11: ='3. Earnings Build'!DF32 -> 307.254
B12: Total | C12: =SUM(C9:C11) -> 40.749 | D12: =SUM(D9:D11) -> 15.63 | E12: =SUM(E9:E11) -> 17.126 | F12: =SUM(F9:F11) -> 19.984 | G12: =SUM(G9:G11) -> 31.389093 | H12: =SUM(H9:H11) -> 84.129093 | I12: =SUM(I9:I11) -> 28.184 | J12: =SUM(J9:J11) -> 32.517437 | ... DF12: =SUM(DF9:DF11) -> 2415.631
B14: Americas | CO14: ='3. Earnings Build'!CO10 -> 6817.454 | CP14: ='3. Earnings Build'!CP10 -> 1567.738 | CQ14: ='3. Earnings Build'!CQ10 -> 1719.773 | CR14: ='3. Earnings Build'!CR10 -> 1732.398 | CS14: ='3. Earnings Build'!CS10 -> 2611.738 | CT14: ='3. Earnings Build'!CT10 -> 7631.647 | CU14: ='3. Earnings Build'!CU10 -> 1622.264 | CV14: ='3. Earnings Build'!CV10 -> 1741.433 | ... DS14: ='3. Earnings Build'!DS10 -> 6312.3848
B15: Mainland China | CO15: ='3. Earnings Build'!CO11 -> 576.503 | CP15: ='3. Earnings Build'!CP11 -> 210.068 | CQ15: ='3. Earnings Build'!CQ11 -> 234.445 | CR15: ='3. Earnings Build'!CR11 -> 228.595 | CS15: ='3. Earnings Build'!CS11 -> 290.652 | CT15: ='3. Earnings Build'!CT11 -> 963.76 | CU15: ='3. Earnings Build'!CU11 -> 303.786 | CV15: ='3. Earnings Build'!CV11 -> 314.189 | ... DS15: ='3. Earnings Build'!DS11 -> 2185.8684
B16: Rest of World | CO16: ='3. Earnings Build'!CO12 -> 716.561 | CP16: ='3. Earnings Build'!CP12 -> 222.986 | CQ16: ='3. Earnings Build'!CQ12 -> 254.947 | CR16: ='3. Earnings Build'!CR12 -> 243.225 | CS16: ='3. Earnings Build'!CS12 -> 302.713 | CT16: ='3. Earnings Build'!CT12 -> 1023.871 | CU16: ='3. Earnings Build'!CU12 -> 282.841 | CV16: ='3. Earnings Build'!CV12 -> 315.456 | ... DS16: ='3. Earnings Build'!DS12 -> 1832.7337
B17: Total | CO17: =CO14+CO15+CO16 -> 8110.518 | CP17: =CP14+CP15+CP16 -> 2000.792 | CQ17: =CQ14+CQ15+CQ16 -> 2209.165 | CR17: =CR14+CR15+CR16 -> 2204.218 | CS17: =CS14+CS15+CS16 -> 3205.103 | CT17: =CT14+CT15+CT16 -> 9619.278 | CU17: =CU14+CU15+CU16 -> 2208.891 | CV17: =CV14+CV15+CV16 -> 2371.078 | ... DS17: =DS14+DS15+DS16 -> 10330.987
B19: Operating Income
B20: Stores | N20: ='3. Earnings Build'!N149 -> 11.891 | O20: ='3. Earnings Build'!O149 -> 16.943 | P20: ='3. Earnings Build'!P149 -> 19.278 | Q20: ='3. Earnings Build'!Q149 -> 31.688 | R20: =SUM(N20:Q20) -> 79.8 | S20: ='3. Earnings Build'!S149 -> 23.217 | T20: ='3. Earnings Build'!T149 -> 23.758 | U20: ='3. Earnings Build'!U149 -> 21.401 | V20: ='3. Earnings Build'!V149 -> 26.524 | W20: =SUM(S20:V20) -> 94.9 | X20: ='3. Earnings Build'!X149 -> 21.687 | Y20: ='3. Earnings Build'!Y149 -> 23.548 | Z20: ='3. Earnings Build'!Z149 -> 30.76 | AA20: ='3. Earnings Build'!AA149 -> 45.619 | AB20: =SUM(X20:AA20) -> 121.614 | AC20: ='3. Earnings Build'!AC149 -> 45.955 | AD20: ='3. Earnings Build'!AD149 -> 44.353 | AE20: ='3. Earnings Build'!AE149 -> 50.787 | AF20: ='3. Earnings Build'!AF149 -> 74.059 | AG20: =SUM(AC20:AF20) -> 215.154 | AH20: ='3. Earnings Build'!AH149 -> 59.137 | AI20: ='3. Earnings Build'!AI149 -> 64.073 | AJ20: ='3. Earnings Build'!AJ149 -> 66.331 | AK20: ='3. Earnings Build'!AK149 -> 109.433 | AL20: =SUM(AH20:AK20) -> 298.974 | AM20: ='3. Earnings Build'!AM149 -> 77.252 | AN20: ='3. Earnings Build'!AN149 -> 77.04 | AO20: ='3. Earnings Build'!AO149 -> 84.699 | AP20: ='3. Earnings Build'!AP149 -> 140.679 | AQ20: =SUM(AM20:AP20) -> 379.67 | AR20: ='3. Earnings Build'!AR149 -> 69.559 | AS20: ='3. Earnings Build'!AS149 -> 83.53 | AT20: ='3. Earnings Build'!AT149 -> 89.676 | AU20: ='3. Earnings Build'!AU149 -> 129.866 | AV20: =SUM(AR20:AU20) -> 372.631 | AW20: ='3. Earnings Build'!AW149 -> 75.697 | AX20: ='3. Earnings Build'!AX149 -> 74.891 | AY20: ='3. Earnings Build'!AY149 -> 73.99 | AZ20: ='3. Earnings Build'!AZ149 -> 132.011 | BA20: =SUM(AW20:AZ20) -> 356.589 | BB20: ='3. Earnings Build'!BB149 -> 69.223 | BC20: ='3. Earnings Build'!BC149 -> 67.441 | BD20: ='3. Earnings Build'!BD149 -> 70.729 | BE20: ='3. Earnings Build'!BE149 -> 139.409 | BF20: =SUM(BB20:BE20) -> 346.802 | BG20: ='3. Earnings Build'!BG149 -> 73.259 | BH20: ='3. Earnings Build'!BH149 -> 80.277 | BI20: ='3. Earnings Build'!BI149 -> 91.497 | BJ20: ='3. Earnings Build'!BJ149 -> 170.602 | BK20: =SUM(BG20:BJ20) -> 415.635 | BL20: ='3. Earnings Build'!BL149 -> 77.499 | BM20: ='3. Earnings Build'!BM149 -> 92.609 | BN20: ='3. Earnings Build'!BN149 -> 97.015 | BO20: ='3. Earnings Build'!BO149 -> 197.198 | BP20: =SUM(BL20:BO20) -> 464.321 | BQ20: ='3. Earnings Build'!BQ149 -> 99.287 | BR20: ='3. Earnings Build'!BR149 -> 125.868 | BS20: ='3. Earnings Build'!BS149 -> 117.804 | BT20: ='3. Earnings Build'!BT149 -> 232.577 | BU20: =SUM(BQ20:BT20) -> 575.536 | BV20: ='3. Earnings Build'!BV149 -> 120.907 | BW20: ='3. Earnings Build'!BW149 -> 154.332 | BX20: ='3. Earnings Build'!BX149 -> 147.734 | BY20: ='3. Earnings Build'!BY149 -> 266.366 | BZ20: =SUM(BV20:BY20) -> 689.339 | CA20: ='3. Earnings Build'!CA149 -> -30.154 | CB20: ='3. Earnings Build'!CB149 -> -5.293 | CC20: ='3. Earnings Build'!CC149 -> 111.78 | CD20: ='3. Earnings Build'!CD149 -> 136.259 | CE20: =SUM(CA20:CD20) -> 212.592 | CF20: ='3. Earnings Build'!CF149 -> 99.148 | CG20: ='3. Earnings Build'!CG149 -> 184.996 | CH20: ='3. Earnings Build'!CH149 -> 180.7 | CI20: ='3. Earnings Build'!CI149 -> 262.891 | CJ20: =SUM(CF20:CI20) -> 727.735 | CK20: ='3. Earnings Build'!CK149 -> 160.706 | CL20: ='3. Earnings Build'!CL149 -> 256.807 | CM20: ='3. Earnings Build'!CM149 -> 242.733 | CN20: ='3. Earnings Build'!CN149 -> 330.821 | CO20: =SUM(CK20:CN20) -> 991.067 | CP20: ='3. Earnings Build'!CP149 -> 259.819 | CQ20: ='3. Earnings Build'!CQ149 -> 339.692 | CR20: ='3. Earnings Build'!CR149 -> 310.51 | CS20: ='3. Earnings Build'!CS149 -> 400 | CT20: =SUM(CP20:CS20) -> 1310.021
B21: Direct | N21: ='3. Earnings Build'!N150 -> 0 | O21: ='3. Earnings Build'!O150 -> 0 | P21: ='3. Earnings Build'!P150 -> 0 | Q21: ='3. Earnings Build'!Q150 -> 0 | R21: =SUM(N21:Q21) -> 0 | S21: ='3. Earnings Build'!S150 -> 0 | T21: ='3. Earnings Build'!T150 -> 0 | U21: ='3. Earnings Build'!U150 -> 0 | V21: ='3. Earnings Build'!V150 -> 0 | W21: =SUM(S21:V21) -> 0 | X21: ='3. Earnings Build'!X150 -> 0.365 | Y21: ='3. Earnings Build'!Y150 -> 1.199 | Z21: ='3. Earnings Build'!Z150 -> 1.811 | AA21: ='3. Earnings Build'!AA150 -> 2.913 | AB21: =SUM(X21:AA21) -> 6.288 | AC21: ='3. Earnings Build'!AC150 -> 3.242 | AD21: ='3. Earnings Build'!AD150 -> 2.817 | AE21: ='3. Earnings Build'!AE150 -> 3.901 | AF21: ='3. Earnings Build'!AF150 -> 6.404 | AG21: =SUM(AC21:AF21) -> 16.364 | AH21: ='3. Earnings Build'!AH150 -> 4.291 | AI21: ='3. Earnings Build'!AI150 -> 8.178 | AJ21: ='3. Earnings Build'!AJ150 -> 9.098 | AK21: ='3. Earnings Build'!AK150 -> 22.601 | AL21: =SUM(AH21:AK21) -> 44.168 | AM21: ='3. Earnings Build'!AM150 -> 17.057 | AN21: ='3. Earnings Build'!AN150 -> 14.085 | AO21: ='3. Earnings Build'!AO150 -> 18.373 | AP21: ='3. Earnings Build'!AP150 -> 33.432 | AQ21: =SUM(AM21:AP21) -> 82.947 | AR21: ='3. Earnings Build'!AR150 -> 21.216 | AS21: ='3. Earnings Build'!AS150 -> 20.633 | AT21: ='3. Earnings Build'!AT150 -> 27.98 | AU21: ='3. Earnings Build'!AU150 -> 39.74 | AV21: =SUM(AR21:AU21) -> 109.569 | AW21: ='3. Earnings Build'!AW150 -> 27.117 | AX21: ='3. Earnings Build'!AX150 -> 24.087 | AY21: ='3. Earnings Build'!AY150 -> 32.292 | AZ21: ='3. Earnings Build'!AZ150 -> 49.381 | BA21: =SUM(AW21:AZ21) -> 132.877 | BB21: ='3. Earnings Build'!BB150 -> 34.871 | BC21: ='3. Earnings Build'!BC150 -> 32.25 | BD21: ='3. Earnings Build'!BD150 -> 37.985 | BE21: ='3. Earnings Build'!BE150 -> 61.312 | BF21: =SUM(BB21:BE21) -> 166.418 | BG21: ='3. Earnings Build'!BG150 -> 38.551 | BH21: ='3. Earnings Build'!BH150 -> 32.644 | BI21: ='3. Earnings Build'!BI150 -> 43.588 | BJ21: ='3. Earnings Build'!BJ150 -> 71.395 | BK21: =SUM(BG21:BJ21) -> 186.178 | BL21: ='3. Earnings Build'!BL150 -> 35.442 | BM21: ='3. Earnings Build'!BM150 -> 40.139 | BN21: ='3. Earnings Build'!BN150 -> 52.201 | BO21: ='3. Earnings Build'!BO150 -> 103.513 | BP21: =SUM(BL21:BO21) -> 231.295 | BQ21: ='3. Earnings Build'!BQ150 -> 62.267 | BR21: ='3. Earnings Build'!BR150 -> 67.033 | BS21: ='3. Earnings Build'!BS150 -> 76.435 | BT21: ='3. Earnings Build'!BT150 -> 148.372 | BU21: =SUM(BQ21:BT21) -> 354.107 | BV21: ='3. Earnings Build'!BV150 -> 78.675 | BW21: ='3. Earnings Build'!BW150 -> 86.081 | BX21: ='3. Earnings Build'!BX150 -> 103.282 | BY21: ='3. Earnings Build'!BY150 -> 214.33 | BZ21: =SUM(BV21:BY21) -> 482.368 | CA21: ='3. Earnings Build'!CA150 -> 156.947 | CB21: ='3. Earnings Build'!CB150 -> 237.595 | CC21: ='3. Earnings Build'!CC150 -> 209.61 | CD21: ='3. Earnings Build'!CD150 -> 424.95 | CE21: =SUM(CA21:CD21) -> 1029.102 | CF21: ='3. Earnings Build'!CF150 -> 236.933 | CG21: ='3. Earnings Build'!CG150 -> 260.248 | CH21: ='3. Earnings Build'!CH150 -> 257.05 | CI21: ='3. Earnings Build'!CI150 -> 462.265 | CJ21: =SUM(CF21:CI21) -> 1216.496 | CK21: ='3. Earnings Build'!CK150 -> 285.107 | CL21: ='3. Earnings Build'!CL150 -> 326.423 | CM21: ='3. Earnings Build'!CM150 -> 321.742 | CN21: ='3. Earnings Build'!CN150 -> 629.266 | CO21: =SUM(CK21:CN21) -> 1562.538 | CP21: ='3. Earnings Build'!CP150 -> 369.453 | CQ21: ='3. Earnings Build'!CQ150 -> 383.87 | CR21: ='3. Earnings Build'!CR150 -> 384.393 | CS21: ='3. Earnings Build'!CS150 -> 750 | CT21: =SUM(CP21:CS21) -> 1887.716
B22: Other | N22: ='3. Earnings Build'!N151 -> 3.157 | O22: ='3. Earnings Build'!O151 -> 2.061 | P22: ='3. Earnings Build'!P151 -> 2.03 | Q22: ='3. Earnings Build'!Q151 -> 7.152 | R22: =SUM(N22:Q22) -> 14.4 | S22: ='3. Earnings Build'!S151 -> 3.875 | T22: ='3. Earnings Build'!T151 -> 2.963 | U22: ='3. Earnings Build'!U151 -> 2.58 | V22: ='3. Earnings Build'!V151 -> 9.982 | W22: =SUM(S22:V22) -> 19.4 | X22: ='3. Earnings Build'!X151 -> 2.198 | Y22: ='3. Earnings Build'!Y151 -> 2.818 | Z22: ='3. Earnings Build'!Z151 -> 2.776 | AA22: ='3. Earnings Build'!AA151 -> 3.053 | AB22: =SUM(X22:AA22) -> 10.845 | AC22: ='3. Earnings Build'!AC151 -> 4.632 | AD22: ='3. Earnings Build'!AD151 -> 3.31 | AE22: ='3. Earnings Build'!AE151 -> 5.543 | AF22: ='3. Earnings Build'!AF151 -> 4.519 | AG22: =SUM(AC22:AF22) -> 18.004 | AH22: ='3. Earnings Build'!AH151 -> 4.993 | AI22: ='3. Earnings Build'!AI151 -> 4.704 | AJ22: ='3. Earnings Build'!AJ151 -> 3.663 | AK22: ='3. Earnings Build'!AK151 -> 7.865 | AL22: =SUM(AH22:AK22) -> 21.225 | AM22: ='3. Earnings Build'!AM151 -> 3.856 | AN22: ='3. Earnings Build'!AN151 -> 3.008 | AO22: ='3. Earnings Build'!AO151 -> 4.049 | AP22: ='3. Earnings Build'!AP151 -> 6.457 | AQ22: =SUM(AM22:AP22) -> 17.37 | AR22: ='3. Earnings Build'!AR151 -> 4.404 | AS22: ='3. Earnings Build'!AS151 -> 3.325 | AT22: ='3. Earnings Build'!AT151 -> 4.597 | AU22: ='3. Earnings Build'!AU151 -> 3.781 | AV22: =SUM(AR22:AU22) -> 16.107 | AW22: ='3. Earnings Build'!AW151 -> 3.276 | AX22: ='3. Earnings Build'!AX151 -> 3.496 | AY22: ='3. Earnings Build'!AY151 -> 3.279 | AZ22: ='3. Earnings Build'!AZ151 -> -0.552 | BA22: =SUM(AW22:AZ22) -> 9.499 | BB22: ='3. Earnings Build'!BB151 -> 0.981 | BC22: ='3. Earnings Build'!BC151 -> 1.82 | BD22: ='3. Earnings Build'!BD151 -> 1.569 | BE22: ='3. Earnings Build'!BE151 -> 1.456 | BF22: =SUM(BB22:BE22) -> 5.826 | BG22: ='3. Earnings Build'!BG151 -> 2.069 | BH22: ='3. Earnings Build'!BH151 -> 4.636 | BI22: ='3. Earnings Build'!BI151 -> 5.709 | BJ22: ='3. Earnings Build'!BJ151 -> 9.898 | BK22: =SUM(BG22:BJ22) -> 22.312 | BL22: ='3. Earnings Build'!BL151 -> 2.836 | BM22: ='3. Earnings Build'!BM151 -> 6.952 | BN22: ='3. Earnings Build'!BN151 -> 9.319 | BO22: ='3. Earnings Build'!BO151 -> 16.473 | BP22: =SUM(BL22:BO22) -> 35.58 | BQ22: ='3. Earnings Build'!BQ151 -> 11.223 | BR22: ='3. Earnings Build'!BR151 -> 13.094 | BS22: ='3. Earnings Build'!BS151 -> 15.019 | BT22: ='3. Earnings Build'!BT151 -> 23.252 | BU22: =SUM(BQ22:BT22) -> 62.588 | BV22: ='3. Earnings Build'!BV151 -> 12.633 | BW22: ='3. Earnings Build'!BW151 -> 16.619 | BX22: ='3. Earnings Build'!BX151 -> 16.944 | BY22: ='3. Earnings Build'!BY151 -> 26.363 | BZ22: =SUM(BV22:BY22) -> 72.559 | CA22: ='3. Earnings Build'!CA151 -> -0.269 | CB22: ='3. Earnings Build'!CB151 -> 2.587 | CC22: ='3. Earnings Build'!CC151 -> 1.304 | CD22: ='3. Earnings Build'!CD151 -> 6.88 | CE22: =SUM(CA22:CD22) -> 10.502 | CF22: ='3. Earnings Build'!CF151 -> 14.506 | CG22: ='3. Earnings Build'!CG151 -> 22.24 | CH22: ='3. Earnings Build'!CH151 -> 27.45 | CI22: ='3. Earnings Build'!CI151 -> 13.087 | CJ22: =SUM(CF22:CI22) -> 77.283 | CK22: ='3. Earnings Build'!CK151 -> 19.527 | CL22: ='3. Earnings Build'!CL151 -> 29.626 | CM22: ='3. Earnings Build'!CM151 -> 24.911 | CN22: ='3. Earnings Build'!CN151 -> 33.019 | CO22: =SUM(CK22:CN22) -> 107.083 | CP22: ='3. Earnings Build'!CP151 -> 44.083 | CQ22: ='3. Earnings Build'!CQ151 -> 48.683 | CR22: ='3. Earnings Build'!CR151 -> 53.527 | CS22: ='3. Earnings Build'!CS151 -> 36.3 | CT22: =SUM(CP22:CS22) -> 182.593
B23: Segment Operating Profit | N23: =SUM(N20:N22) -> 15.048 | O23: =SUM(O20:O22) -> 19.004 | P23: =SUM(P20:P22) -> 21.308 | Q23: =SUM(Q20:Q22) -> 38.84 | R23: =SUM(R20:R22) -> 94.2 | S23: =SUM(S20:S22) -> 27.092 | T23: =SUM(T20:T22) -> 26.721 | U23: =SUM(U20:U22) -> 23.981 | ... CT23: =SUM(CT20:CT22) -> 3380.33
B24: Corporate Expense | N24: ='3. Earnings Build'!N156 -> -8.201 | O24: ='3. Earnings Build'!O156 -> -9.26 | P24: ='3. Earnings Build'!P156 -> -9.461 | Q24: ='3. Earnings Build'!Q156 -> -17.178 | R24: =SUM(N24:Q24) -> -44.1 | S24: ='3. Earnings Build'!S156 -> -15.371 | T24: ='3. Earnings Build'!T156 -> -11.179 | U24: ='3. Earnings Build'!U156 -> -10.926 | V24: ='3. Earnings Build'!V156 -> -16.024 | W24: =SUM(S24:V24) -> -53.5 | X24: ='3. Earnings Build'!X156 -> -14.397 | Y24: ='3. Earnings Build'!Y156 -> -13.233 | Z24: ='3. Earnings Build'!Z156 -> -14.421 | AA24: ='3. Earnings Build'!AA156 -> -9.949 | AB24: =SUM(X24:AA24) -> -52 | AC24: ='3. Earnings Build'!AC156 -> -21.355 | AD24: ='3. Earnings Build'!AD156 -> -16.237 | AE24: ='3. Earnings Build'!AE156 -> -17.855 | AF24: ='3. Earnings Build'!AF156 -> -13.653 | AG24: =SUM(AC24:AF24) -> -69.1 | AH24: ='3. Earnings Build'!AH156 -> -16.734 | AI24: ='3. Earnings Build'!AI156 -> -17.472 | AJ24: ='3. Earnings Build'!AJ156 -> -19.371 | AK24: ='3. Earnings Build'!AK156 -> -23.823 | AL24: =SUM(AH24:AK24) -> -77.4 | AM24: ='3. Earnings Build'!AM156 -> -25.1 | AN24: ='3. Earnings Build'!AN156 -> -23.945 | AO24: ='3. Earnings Build'!AO156 -> -26.51 | AP24: ='3. Earnings Build'!AP156 -> -27.993 | AQ24: =SUM(AM24:AP24) -> -103.548 | AR24: ='3. Earnings Build'!AR156 -> -29.29 | AS24: ='3. Earnings Build'!AS156 -> -28.502 | AT24: ='3. Earnings Build'!AT156 -> -29.917 | AU24: ='3. Earnings Build'!AU156 -> -19.24 | AV24: =SUM(AR24:AU24) -> -106.949 | AW24: ='3. Earnings Build'!AW156 -> -36.289 | AX24: ='3. Earnings Build'!AX156 -> -34.586 | AY24: ='3. Earnings Build'!AY156 -> -28.405 | AZ24: ='3. Earnings Build'!AZ156 -> -23.652 | BA24: =SUM(AW24:AZ24) -> -122.932 | BB24: ='3. Earnings Build'!BB156 -> -37.039 | BC24: ='3. Earnings Build'!BC156 -> -34.932 | BD24: ='3. Earnings Build'!BD156 -> -42.105 | BE24: ='3. Earnings Build'!BE156 -> -35.894 | BF24: =SUM(BB24:BE24) -> -149.97 | BG24: ='3. Earnings Build'!BG156 -> -56.29 | BH24: ='3. Earnings Build'!BH156 -> -43.598 | BI24: ='3. Earnings Build'!BI156 -> -47.819 | BJ24: ='3. Earnings Build'!BJ156 -> -55.266 | BK24: =SUM(BG24:BJ24) -> -202.973 | BL24: ='3. Earnings Build'!BL156 -> -52.604 | BM24: ='3. Earnings Build'!BM156 -> -65.558 | BN24: ='3. Earnings Build'!BN156 -> -50.762 | BO24: ='3. Earnings Build'!BO156 -> -59.048 | BP24: =SUM(BL24:BO24) -> -227.972 | BQ24: ='3. Earnings Build'!BQ156 -> -68.472 | BR24: ='3. Earnings Build'!BR156 -> -71.787 | BS24: ='3. Earnings Build'!BS156 -> -73.355 | BT24: ='3. Earnings Build'!BT156 -> -72.751 | BU24: =SUM(BQ24:BT24) -> -286.365 | BV24: ='3. Earnings Build'!BV156 -> -83.403 | BW24: ='3. Earnings Build'!BW156 -> -89.05 | BX24: ='3. Earnings Build'!BX156 -> -92.131 | BY24: ='3. Earnings Build'!BY156 -> -90.572 | BZ24: =SUM(BV24:BY24) -> -355.156 | CA24: ='3. Earnings Build'!CA156 -> -93.773 | CB24: ='3. Earnings Build'!CB156 -> -99.016 | CC24: ='3. Earnings Build'!CC156 -> -107.002 | CD24: ='3. Earnings Build'!CD156 -> -100.186 | CE24: =SUM(CA24:CD24) -> -399.977 | CF24: ='3. Earnings Build'!CF156 -> -146.907 | CG24: ='3. Earnings Build'!CG156 -> -166.115 | CH24: ='3. Earnings Build'!CH156 -> -180.931 | CI24: ='3. Earnings Build'!CI156 -> -144.03 | CJ24: =SUM(CF24:CI24) -> -637.983 | CK24: ='3. Earnings Build'!CK156 -> -202.798 | CL24: ='3. Earnings Build'!CL156 -> -219.633 | CM24: ='3. Earnings Build'!CM156 -> -234.77 | CN24: ='3. Earnings Build'!CN156 -> -205.666 | CO24: =SUM(CK24:CN24) -> -862.867 | CP24: ='3. Earnings Build'!CP156 -> -270.063 | CQ24: ='3. Earnings Build'!CQ156 -> -291.109 | CR24: ='3. Earnings Build'!CR156 -> -310.852 | CS24: ='3. Earnings Build'!CS156 -> -272.41 | CT24: =SUM(CP24:CS24) -> -1144.434
B25: Amortization of Intangible Assets & Other | BV25: ='3. Earnings Build'!BV157 -> 0 | BW25: ='3. Earnings Build'!BW157 -> 0 | BX25: ='3. Earnings Build'!BX157 -> -0.007 | BY25: ='3. Earnings Build'!BY157 -> 0 | BZ25: =SUM(BV25:BY25) -> -0.007 | CA25: ='3. Earnings Build'!CA157 -> 0 | CB25: ='3. Earnings Build'!CB157 -> 0 | CC25: ='3. Earnings Build'!CC157 -> -2.241 | CD25: ='3. Earnings Build'!CD157 -> -2.195 | CE25: =SUM(CA25:CD25) -> -4.436 | CF25: ='3. Earnings Build'!CF157 -> -2.195 | CG25: ='3. Earnings Build'!CG157 -> -2.195 | CH25: ='3. Earnings Build'!CH157 -> -2.195 | CI25: ='3. Earnings Build'!CI157 -> -2.197 | CJ25: =SUM(CF25:CI25) -> -8.782 | CK25: ='3. Earnings Build'!CK157 -> -2.195 | CL25: ='3. Earnings Build'!CL157 -> -2.195 | CM25: ='3. Earnings Build'!CM157 -> -2.189 | CN25: ='3. Earnings Build'!CN157 -> -2.173 | CO25: =SUM(CK25:CN25) -> -8.752 | CP25: ='3. Earnings Build'!CP157 -> -1.878 | CQ25: ='3. Earnings Build'!CQ157 -> -1.879 | CR25: ='3. Earnings Build'!CR157 -> -1.253 | CS25: ='3. Earnings Build'!CS157 -> 0 | CT25: =SUM(CP25:CS25) -> -5.01
B26: Total | C26: ='3. Earnings Build'!C158 -> 10.46 | H26: ='3. Earnings Build'!H158 -> 16.534374 | M26: ='3. Earnings Build'!M158 -> 23.441724 | N26: =N23+N24 -> 6.847 | O26: =O23+O24 -> 9.744 | P26: =P23+P24 -> 11.847 | Q26: =Q23+Q24 -> 21.662 | R26: =R23+R24 -> 50.1 | S26: =S23+S24 -> 11.721 | T26: =T23+T24 -> 15.542 | U26: =U23+U24 -> 13.055 | ... BU26: =BU23+BU24 -> 705.866 | BV26: =BV23+BV24+BV25 -> 128.812 | BW26: =BW23+BW24+BW25 -> 167.982 | BX26: =BX23+BX24+BX25 -> 175.822 | BY26: =BY23+BY24+BY25 -> 416.487 | BZ26: =BZ23+BZ24+BZ25 -> 889.103 | CA26: =CA23+CA24+CA25 -> 32.751 | CB26: =CB23+CB24+CB25 -> 135.873 | CC26: =CC23+CC24+CC25 -> 213.451 | ... CT26: =CT23+CT24+CT25 -> 2230.886
B28: Americas | CO28: ='3. Earnings Build'!CO213 -> 2503.74 | CP28: ='3. Earnings Build'!CP213 -> 581.222 | CQ28: ='3. Earnings Build'!CQ213 -> 660.57 | CR28: ='3. Earnings Build'!CR213 -> 636.714 | CS28: ='3. Earnings Build'!CS213 -> 1058.678 | CT28: ='3. Earnings Build'!CT213 -> 2937.184 | CU28: ='3. Earnings Build'!CU213 -> 564.84 | CV28: ='3. Earnings Build'!CV213 -> 669.427 | ... DF28: ='3. Earnings Build'!DF213 -> 594.413
B29: Mainland China | CO29: ='3. Earnings Build'!CO272 -> 196.865 | CP29: ='3. Earnings Build'!CP272 -> 73.885 | CQ29: ='3. Earnings Build'!CQ272 -> 83.481 | CR29: ='3. Earnings Build'!CR272 -> 76.792 | CS29: ='3. Earnings Build'!CS272 -> 103.158 | CT29: ='3. Earnings Build'!CT272 -> 337.316 | CU29: ='3. Earnings Build'!CU272 -> 119.778 | CV29: ='3. Earnings Build'!CV272 -> 119.085 | ... DF29: ='3. Earnings Build'!DF272 -> 151.27
B30: Rest of World | CO30: ='3. Earnings Build'!CO351 -> 103.204 | CP30: ='3. Earnings Build'!CP351 -> 43.794 | CQ30: ='3. Earnings Build'!CQ351 -> 51.292 | CR30: ='3. Earnings Build'!CR351 -> 45.552 | CS30: ='3. Earnings Build'!CS351 -> 61.194 | CT30: ='3. Earnings Build'!CT351 -> 201.832 | CU30: ='3. Earnings Build'!CU351 -> 66.681 | CV30: ='3. Earnings Build'!CV351 -> 74 | ... DF30: ='3. Earnings Build'!DF351 -> 74.973
B31: Segment EBIT | CO31: =CO28+CO29+CO30 -> 2803.809 | CP31: =CP28+CP29+CP30 -> 698.901 | CQ31: =CQ28+CQ29+CQ30 -> 795.343 | CR31: =CR28+CR29+CR30 -> 759.058 | CS31: =CS28+CS29+CS30 -> 1223.03 | CT31: =CT28+CT29+CT30 -> 3476.332 | CU31: =CU28+CU29+CU30 -> 751.299 | CV31: =CV28+CV29+CV30 -> 862.512 | ... DF31: =DF28+DF29+DF30 -> 820.656
B32: Corporate | CO32: ='3. Earnings Build'!CO373 -> -1014.74 | CP32: ='3. Earnings Build'!CP373 -> -297.487 | CQ32: ='3. Earnings Build'!CQ373 -> -316.086 | CR32: ='3. Earnings Build'!CR373 -> -322.733 | CS32: ='3. Earnings Build'!CS373 -> -309.14 | CT32: ='3. Earnings Build'!CT373 -> -1245.446 | CU32: ='3. Earnings Build'!CU373 -> -318.657 | CV32: ='3. Earnings Build'!CV373 -> -322.286 | ... DF32: ='3. Earnings Build'!DF373 -> -367.003
B33: Total EBIT | CO33: =CO31+CO32 -> 1789.069 | CP33: =CP31+CP32 -> 401.414 | CQ33: =CQ31+CQ32 -> 479.257 | CR33: =CR31+CR32 -> 436.325 | CS33: =CS31+CS32 -> 913.89 | CT33: =CT31+CT32 -> 2230.886 | CU33: =CU31+CU32 -> 432.642 | CV33: =CV31+CV32 -> 540.226 | ... DF33: =DF31+DF32 -> 453.653
B35: CONSOLIDATED INCOME STATEMENT
B37: Net Sales | C37: =C12 -> 40.749 | D37: =D12 -> 15.63 | E37: =E12 -> 17.126 | F37: =F12 -> 19.984 | G37: =G12 -> 31.389093 | H37: =SUM(D37:G37) -> 84.129093 | I37: =I12 -> 28.184 | J37: =J12 -> 32.517437 | K37: =K12 -> 35.967615 | L37: =L12 -> 52.215782 | M37: =SUM(I37:L37) -> 148.88483 | N37: =N12 -> 44.789456 | O37: =O12 -> 58.680944 | P37: =P12 -> 66.15028 | Q37: =Q12 -> 105.09265 | R37: =SUM(N37:Q37) -> 274.71333 | S37: =S12 -> 78.167494 | T37: =T12 -> 85.484223 | U37: =U12 -> 87.047135 | V37: =V12 -> 103.921 | W37: =SUM(S37:V37) -> 354.61985 | X37: =X12 -> 81.68 | Y37: =Y12 -> 97.721 | Z37: =Z12 -> 112.891 | AA37: =AA12 -> 160.606 | AB37: =SUM(X37:AA37) -> 452.898 | AC37: =AC12 -> 138.297 | AD37: =AD12 -> 152.208 | AE37: =AE12 -> 175.8 | AF37: =AF12 -> 245.399 | AG37: =SUM(AC37:AF37) -> 711.704 | AH37: =AH12 -> 186.78 | AI37: =AI12 -> 212.323 | AJ37: =AJ12 -> 230.216 | AK37: =AK12 -> 371.52 | AL37: =SUM(AH37:AK37) -> 1000.839 | AM37: =AM12 -> 285.698 | AN37: =AN12 -> 282.634 | AO37: =AO12 -> 316.537 | AP37: 485.489 | AQ37: 1370.358 | AR37: =AR12 -> 345.782 | AS37: =AS12 -> 344.513 | AT37: =AT12 -> 379.9 | AU37: =AU12 -> 520.993 | AV37: =SUM(AR37:AU37) -> 1591.188 | AW37: =AW12 -> 384.618 | AX37: =AX12 -> 390.727 | AY37: =AY12 -> 419.396 | AZ37: 602.491 | BA37: 1797.213 | BB37: =BB12 -> 423.544 | BC37: =BC12 -> 453.01 | BD37: =BD12 -> 479.693 | BE37: =BE12 -> 704.276 | BF37: =SUM(BB37:BE37) -> 2060.523 | BG37: =BG12 -> 495.516 | BH37: =BH12 -> 514.52 | BI37: =BI12 -> 544.416 | BJ37: =BJ12 -> 789.94 | BK37: =SUM(BG37:BJ37) -> 2344.392 | BL37: =BL12 -> 520.307 | BM37: =BM12 -> 581.054 | BN37: =BN12 -> 619.034 | BO37: 928.802 | BP37: 2649.181 | BQ37: 649.706 | BR37: 723.5 | BS37: 747.655 | BT37: 1167.458 | BU37: =SUM(BQ37:BT37) -> 3288.319 | BV37: 782.315 | BW37: 883.352 | BX37: 916.138 | BY37: 1397.491 | BZ37: =SUM(BV37:BY37) -> 3979.296 | CA37: 651.962 | CB37: 902.942 | CC37: 1117.426 | CD37: 1729.55 | CE37: =SUM(CA37:CD37) -> 4401.88 | CF37: 1226.465 | CG37: 1450.618 | CH37: 1450.421 | CI37: 2129.113 | CJ37: =SUM(CF37:CI37) -> 6256.617 | CK37: 1613.463 | CL37: 1868.328 | CM37: 1856.889 | CN37: 2771.838 | CO37: =SUM(CK37:CN37) -> 8110.518 | CP37: 2000.792 | CQ37: 2209.165 | CR37: 2204.218 | CS37: 3205.103 | CT37: =SUM(CP37:CS37) -> 9619.278 | CU37: 2208.891 | CV37: 2371.078 | CW37: 2396.66 | CX37: 3611.497 | CY37: =SUM(CU37:CX37) -> 10588.126 | CZ37: 2370.66 | DA37: 2525.219 | DB37: 2565.92 | DC37: 3640.801 | DD37: ='3. Earnings Build'!DD13 -> 11102.6 | DE37: 2471.603 | DF37: 2415.631 | DG37: ='3. Earnings Build'!DG13 -> 2315.5913 | DH37: ='3. Earnings Build'!DH13 -> 3263.7773 | DI37: ='3. Earnings Build'!DI13 -> 10466.603 | DJ37: ='3. Earnings Build'!DJ13 -> 2361.0562 | DK37: ='3. Earnings Build'!DK13 -> 2329.698 | DL37: ='3. Earnings Build'!DL13 -> 2305.1486 | DM37: ='3. Earnings Build'!DM13 -> 3221.0211 | DN37: ='3. Earnings Build'!DN13 -> 10216.924 | ... DS37: ='3. Earnings Build'!DS13 -> 10330.987
B38: % chg. Y/Y | H38: =H37/C37-1 -> 1.0645683 | I38: =I37/D37-1 -> 0.80319898 | J38: =J37/E37-1 -> 0.89871756 | K38: =K37/F37-1 -> 0.79982061 | L38: =L37/G37-1 -> 0.66350082 | M38: =M37/H37-1 -> 0.76971876 | N38: =N37/I37-1 -> 0.58918024 | O38: =O37/J37-1 -> 0.8045993 | ... DS38: =DS37/DN37-1 -> 0.011164122
B40: Total COGS | C40: ='3. Earnings Build'!C134 -> -19.448 | D40: ='3. Earnings Build'!D134 -> -8.207 | E40: ='3. Earnings Build'!E134 -> -7.94 | F40: ='3. Earnings Build'!F134 -> -9.613 | G40: ='3. Earnings Build'!G134 -> -15.416981 | H40: =SUM(D40:G40) -> -41.176981 | I40: ='3. Earnings Build'!I134 -> -13.664 | J40: ='3. Earnings Build'!J134 -> -16.614142 | K40: ='3. Earnings Build'!K134 -> -17.227413 | L40: ='3. Earnings Build'!L134 -> -25.397557 | M40: =SUM(I40:L40) -> -72.903112 | N40: ='3. Earnings Build'!N134 -> -22.178568 | O40: ='3. Earnings Build'!O134 -> -27.434066 | P40: ='3. Earnings Build'!P134 -> -30.26986 | Q40: ='3. Earnings Build'!Q134 -> -48.528681 | R40: =SUM(N40:Q40) -> -128.41117 | S40: ='3. Earnings Build'!S134 -> -36.645025 | T40: ='3. Earnings Build'!T134 -> -41.107858 | U40: ='3. Earnings Build'!U134 -> -45.153576 | V40: ='3. Earnings Build'!V134 -> -52.261 | W40: =SUM(S40:V40) -> -175.16746 | X40: ='3. Earnings Build'!X134 -> -46.731 | Y40: ='3. Earnings Build'!Y134 -> -52.557 | Z40: ='3. Earnings Build'!Z134 -> -56.553 | AA40: ='3. Earnings Build'!AA134 -> -74.046 | AB40: =SUM(X40:AA40) -> -229.887 | AC40: ='3. Earnings Build'!AC134 -> -63.94 | AD40: ='3. Earnings Build'!AD134 -> -71.91 | AE40: ='3. Earnings Build'!AE134 -> -78.968 | AF40: ='3. Earnings Build'!AF134 -> -101.939 | AG40: =SUM(AC40:AF40) -> -316.757 | AH40: ='3. Earnings Build'!AH134 -> -77.053 | AI40: ='3. Earnings Build'!AI134 -> -90.256 | AJ40: ='3. Earnings Build'!AJ134 -> -101.703 | AK40: ='3. Earnings Build'!AK134 -> -162.502 | AL40: =SUM(AH40:AK40) -> -431.514 | AM40: ='3. Earnings Build'!AM134 -> -128.434 | AN40: ='3. Earnings Build'!AN134 -> -126.879 | AO40: ='3. Earnings Build'!AO134 -> -141.237 | AP40: ='3. Earnings Build'!AP134 -> -210.982 | AQ40: =SUM(AM40:AP40) -> -607.532 | AR40: ='3. Earnings Build'!AR134 -> -175.057 | AS40: ='3. Earnings Build'!AS134 -> -158.558 | AT40: ='3. Earnings Build'!AT134 -> -175.294 | AU40: ='3. Earnings Build'!AU134 -> -242.203 | AV40: =SUM(AR40:AU40) -> -751.112 | AW40: ='3. Earnings Build'!AW134 -> -188.874 | AX40: ='3. Earnings Build'!AX134 -> -193.401 | AY40: ='3. Earnings Build'!AY134 -> -208.308 | AZ40: ='3. Earnings Build'!AZ134 -> -292.45 | BA40: =SUM(AW40:AZ40) -> -883.033 | BB40: ='3. Earnings Build'!BB134 -> -217.667 | BC40: ='3. Earnings Build'!BC134 -> -240.985 | BD40: ='3. Earnings Build'!BD134 -> -254.896 | BE40: ='3. Earnings Build'!BE134 -> -349.809 | BF40: =SUM(BB40:BE40) -> -1063.357 | BG40: ='3. Earnings Build'!BG134 -> -256.385 | BH40: ='3. Earnings Build'!BH134 -> -260.359 | BI40: ='3. Earnings Build'!BI134 -> -265.99 | BJ40: ='3. Earnings Build'!BJ134 -> -362.041 | BK40: =SUM(BG40:BJ40) -> -1144.775 | BL40: ='3. Earnings Build'!BL134 -> -257.993 | BM40: ='3. Earnings Build'!BM134 -> -281.388 | BN40: ='3. Earnings Build'!BN134 -> -295.878 | BO40: ='3. Earnings Build'!BO134 -> -406.434 | BP40: =SUM(BL40:BO40) -> -1241.693 | BQ40: -304.973 | BR40: -327.306 | BS40: -340.878 | BT40: -498.875 | BU40: =SUM(BQ40:BT40) -> -1472.032 | BV40: -360.595 | BW40: =-397.556 -> -397.556 | BX40: -411.094 | BY40: -586.665 | BZ40: =SUM(BV40:BY40) -> -1755.91 | CA40: -317.56 | CB40: -413.441 | CC40: -490.072 | CD40: -716.816 | CE40: =SUM(CA40:CD40) -> -1937.889 | CF40: -526.151 | CG40: -607.932 | CH40: -621.028 | CI40: -892.941 | CJ40: =SUM(CF40:CI40) -> -2648.052 | CK40: -743.07 | CL40: -812.852 | CM40: -818.037 | CN40: =-1244.219+62.928 -> -1181.291 | CO40: =SUM(CK40:CN40) -> -3555.25 | CP40: -849.987 | CQ40: -910.654 | CR40: =-947.554+23.709 -> -923.845 | CS40: =-1301.678 -> -1301.678 | CT40: =SUM(CP40:CS40) -> -3986.164 | CU40: -933.823 | CV40: -958.893 | CW40: -995.054 | CX40: -1429.545 | CY40: =SUM(CU40:CX40) -> -4317.315 | CZ40: -987.534 | DA40: -1048.017 | DB40: -1140.004 | DC40: =-1642.913 -> -1642.913 | DD40: =SUM(CZ40:DC40) -> -4818.468 | DE40: -1132.785 | DF40: =-953.753 -> -953.753 | DG40: =DG42-DG37 -> -1086.6761 | DH40: =DH42-DH37 -> -1472.7809 | DI40: =SUM(DE40:DH40) -> -4645.995 | DJ40: =DJ42-DJ37 -> -1075.036 | DK40: =DK42-DK37 -> -1040.9688 | DL40: =DL42-DL37 -> -1085.2332 | DM40: =DM42-DM37 -> -1458.3187 | DN40: =SUM(DJ40:DM40) -> -4659.5566 | DO40: =DO42-DO37 -> -1091.5165 | DP40: =DP42-DP37 -> -1055.1835 | DQ40: =DQ42-DQ37 -> -1104.7285 | DR40: =DR42-DR37 -> -1470.6806 | DS40: =SUM(DO40:DR40) -> -4722.1091
B42: Gross Profit | C42: =C37+C40 -> 21.301 | D42: =D37+D40 -> 7.423 | E42: =E37+E40 -> 9.186 | F42: =F37+F40 -> 10.371 | G42: =G37+G40 -> 15.972112 | H42: =H37+H40 -> 42.952112 | I42: =I37+I40 -> 14.52 | J42: =J37+J40 -> 15.903295 | ... DF42: =DF37+DF40 -> 1461.878 | DG42: =DG37*(DB44+DG45/10000) -> 1228.9152 | DH42: =DH37*(DC44+DH45/10000) -> 1790.9964 | DI42: =DI37+DI40 -> 5820.6076 | DJ42: =DJ37*(DE44+DJ45/10000) -> 1286.0202 | DK42: =DK37*(DF44+DK45/10000) -> 1288.7293 | DL42: =DL37*(DG44+DL45/10000) -> 1219.9154 | DM42: =DM37*(DH44+DM45/10000) -> 1762.7024 | DN42: =DN37+DN40 -> 5557.3673 | DO42: =DO37*(DJ44+DO45/10000) -> 1300.4816 | DP42: =DP37*(DK44+DP45/10000) -> 1301.0539 | DQ42: =DQ37*(DL44+DQ45/10000) -> 1236.8564 | DR42: =DR37*(DM44+DR45/10000) -> 1770.4858 | DS42: =DS37+DS40 -> 5608.8778
B43: % chg. Y/Y | H43: =H42/C42-1 -> 1.0164364 | I43: =I42/D42-1 -> 0.95608245 | J43: =J42/E42-1 -> 0.73125354 | K43: =K42/F42-1 -> 0.8069812 | L43: =L42/G42-1 -> 0.67906567 | M43: =M42/H42-1 -> 0.76898687 | N43: =N42/I42-1 -> 0.55722369 | O43: =O42/J42-1 -> 0.96480528 | ... DS43: =DS42/DN42-1 -> 0.0092688661
B44: % sales | C44: =C42/C$37 -> 0.52273675 | D44: =D42/D$37 -> 0.47492003 | E44: =E42/E$37 -> 0.53637744 | F44: =F42/F$37 -> 0.51896517 | G44: =G42/G$37 -> 0.50884274 | H44: =H42/H$37 -> 0.51055004 | I44: =I42/I$37 -> 0.51518592 | J44: =J42/J$37 -> 0.48906976 | ... DS44: =DS42/DS$37 -> 0.54291791
B45: Margin chg. Y/Y bps | H45: =(H44-C44)*100*100 -> -121.86712 | I45: =(I44-D44)*100*100 -> 402.65895 | J45: =(J44-E44)*100*100 -> -473.07681 | K45: =(K44-F44)*100*100 -> 20.647043 | L45: =(L44-G44)*100*100 -> 47.610809 | M45: =(M44-H44)*100*100 -> -2.1114518 | N45: =(N44-I44)*100*100 -> -103.59785 | O45: =(O44-J44)*100*100 -> 434.17894 | ... DF45: =(DF44-DA44)*100*100 -> 201.94625 | DG45: -250 | DH45: 0 | DI45: =(DI44-DD44)*100*100 -> -98.930278 | DJ45: 30 | DK45: =30-550 -> -520 | DL45: -15 | DM45: -15 | DN45: =(DN44-DI44)*100*100 -> -121.74988 | DO45: -10 | DP45: -10 | DQ45: -10 | DR45: -10 | DS45: =(DS44-DN44)*100*100 -> -10.195185
B47: Total SG&A | C47: -10.841 | D47: -3.574 | E47: -4.473 | F47: -5.338 | G47: -13.032738 | H47: =SUM(D47:G47) -> -26.417738 | I47: -8.406 | J47: -12.667215 | K47: -14.045858 | L47: -17.420925 | M47: =SUM(I47:L47) -> -52.539998 | N47: -15.762698 | O47: -21.477352 | P47: -24.050692 | Q47: -34.886606 | R47: =SUM(N47:Q47) -> -96.177348 | S47: -29.80172 | T47: -28.832643 | U47: -28.838165 | V47: -31.214 | W47: =SUM(S47:V47) -> -118.68653 | X47: -25.096 | Y47: -30.832 | Z47: -35.412 | AA47: -44.929 | AB47: =SUM(X47:AA47) -> -136.269 | AC47: -41.883 | AD47: -46.055 | AE47: -54.456 | AF47: =-71.483-0.679 -> -72.162 | AG47: =SUM(AC47:AF47) -> -214.556 | AH47: -58.04 | AI47: -62.584 | AJ47: -68.792 | AK47: -92.951 | AL47: =SUM(AH47:AK47) -> -282.367 | AM47: -84.199 | AN47: -85.567 | AO47: -94.689 | AP47: -121.932 | AQ47: =SUM(AM47:AP47) -> -386.387 | AR47: -104.836 | AS47: -106.969 | AT47: -112.27 | AU47: -124.643 | AV47: =SUM(AR47:AU47) -> -448.718 | AW47: -125.943 | AX47: -129.419 | AY47: -129.932 | AZ47: -152.853 | BA47: =SUM(AW47:AZ47) -> -538.147 | BB47: -137.841 | BC47: -145.446 | BD47: -156.619 | BE47: -188.184 | BF47: =SUM(BB47:BE47) -> -628.09 | BG47: -181.542 | BH47: -180.202 | BI47: -185.451 | BJ47: -231.27 | BK47: =SUM(BG47:BJ47) -> -778.465 | BL47: -199.141 | BM47: =-225.524-3.186+2.244+3.186-2.244 -> -225.524 | BN47: =-215.367-21.007+21.007 -> -215.367 | BO47: =-264.232-2.001+2.001 -> -264.232 | BP47: =SUM(BL47:BO47) -> -904.264 | BQ47: -240.428 | BR47: -261.986 | BS47: -270.874 | BT47: -337.163 | BU47: =SUM(BQ47:BT47) -> -1110.451 | BV47: -292.908 | BW47: -317.814 | BX47: -329.208 | BY47: -394.339 | BZ47: =SUM(BV47:BY47) -> -1334.269 | CA47: =-301.651 -> -301.651 | CB47: =-352.904-0.724-11.464+7.201+5.045-0.782 -> -353.628 | CC47: =-411.662-8.531+1.017+7.514 -> -411.662 | CD47: =-544.831-7.802+0.285+7.517 -> -544.831 | CE47: =SUM(CA47:CD47) -> -1611.772 | CF47: =-496.634-7.664+7.168+0.496 -> -496.634 | CG47: -541.317 | CH47: -545.124 | CI47: -641.959 | CJ47: =SUM(CF47:CI47) -> -2225.034 | CK47: -607.851 | CL47: =-662.253+10.18-10.18 -> -662.253 | CM47: -684.236 | CN47: -803.107 | CO47: =SUM(CK47:CN47) -> -2757.447 | CP47: -747.513 | CQ47: -817.375 | CR47: -842.795 | CS47: -989.535 | CT47: =SUM(CP47:CS47) -> -3397.218 | CU47: -842.426 | CV47: -871.959 | CW47: -909.827 | CX47: -1138.167 | CY47: =SUM(CU47:CX47) -> -3762.379 | CZ47: -942.871 | DA47: -951.658 | DB47: -988.254 | DC47: =-1183.773 -> -1183.773 | DD47: =SUM(CZ47:DC47) -> -4066.556 | DE47: -1059.988 | DF47: -1006.332 | DG47: =-DG37*(DB49+DG50/10000) -> -1077.0882 | DH47: =-DH37*(DC49+DH50/10000) -> -1159.1005 | DI47: =SUM(DE47:DH47) -> -4302.5087 | DJ47: =-DJ37*(DE49+DJ50/10000) -> -1047.994 | DK47: =-DK37*(DF49+DK50/10000) -> -1005.4785 | DL47: =-DL37*(DG49+DL50/10000) -> -1089.5194 | DM47: =-DM37*(DH49+DM50/10000) -> -1168.0737 | DN47: =SUM(DJ47:DM47) -> -4311.0656 | DO47: =-DO37*(DJ49+DO50/10000) -> -1073.6881 | DP47: =-DP37*(DK49+DP50/10000) -> -1028.7139 | DQ47: =-DQ37*(DL49+DQ50/10000) -> -1118.4488 | DR47: =-DR37*(DM49+DR50/10000) -> -1191.585 | DS47: =SUM(DO47:DR47) -> -4412.4359
B48: % chg. Y/Y | H48: =H47/C47-1 -> 1.4368359 | I48: =I47/D47-1 -> 1.3519866 | J48: =J47/E47-1 -> 1.8319282 | K48: =K47/F47-1 -> 1.631296 | L48: =L47/G47-1 -> 0.33670492 | M48: =M47/H47-1 -> 0.98881517 | N48: =N47/I47-1 -> 0.87517226 | O48: =O47/J47-1 -> 0.69550702 | ... DS48: =DS47/DN47-1 -> 0.023513958
B49: % of sales | H49: =-H47/H37 -> 0.3140143 | I49: =-I47/I37 -> 0.29825433 | J49: =-J47/J37 -> 0.38955146 | K49: =-K47/K37 -> 0.39051402 | L49: =-L47/L37 -> 0.33363333 | M49: =-M47/M37 -> 0.35289019 | N49: =-N47/N37 -> 0.35192877 | O49: =-O47/O37 -> 0.36600216 | ... DS49: =-DS47/DS37 -> 0.42710691
...

Sheet 3. Earnings Build
B1: Lululemon Athletica Inc. (LULU)
B2: Segment Build
B3: $ millions except per-share data, fiscal year ending January
C5: Jan | D5: Apr | E5: Jul | F5: Oct | G5: Jan | H5: Jan | I5: Apr | J5: Jul | K5: Oct | L5: Jan | M5: Jan | N5: Apr | O5: Jul | P5: Oct | Q5: Jan | R5: Jan | S5: Apr | T5: Jul | U5: Oct | V5: Jan | W5: Jan | X5: Apr | Y5: Jul | Z5: Oct | AA5: Jan | AB5: Jan | AC5: Apr | AD5: Jul | AE5: Oct | AF5: Jan | AG5: Jan | AH5: Apr | AI5: Jul | AJ5: Oct | AK5: Jan | AL5: Jan | AM5: Apr | AN5: Jul | AO5: Oct | AP5: Jan | AQ5: Jan | AR5: Apr | AS5: Jul | AT5: Oct | AU5: Jan | AV5: Jan | AW5: Apr | AX5: Jul | AY5: Oct | AZ5: Jan | BA5: Jan | BB5: Apr | BC5: Jul | BD5: Oct | BE5: Jan | BF5: Jan | BG5: Apr | BH5: Jul | BI5: Oct | BJ5: Jan | BK5: Jan | BL5: Apr | BM5: Jul | BN5: Oct | BO5: Jan | BP5: Jan | BQ5: Apr | BR5: Jul | BS5: Oct | BT5: Jan | BU5: Jan | BV5: Apr | BW5: Jul | BX5: Oct | BY5: Jan | BZ5: Jan | CA5: Apr | CB5: Jul | CC5: Oct | CD5: Jan | CE5: Jan | CF5: Apr | CG5: Jul | CH5: Oct | CI5: Jan | CJ5: Jan | CK5: Apr | CL5: Jul | CM5: Oct | CN5: Jan | CO5: Jan | CP5: Apr | CQ5: Jul | CR5: Oct | CS5: Jan | CT5: Jan | CU5: Apr | CV5: Jul | CW5: Oct | CX5: Jan | CY5: Jan | CZ5: Apr | DA5: Jul | DB5: Oct | DC5: Jan | DD5: Jan | DE5: Apr | DF5: Jul | DG5: Oct | DH5: Jan | DI5: Jan | DJ5: Apr | DK5: Jul | DL5: Oct | DM5: Jan | DN5: Jan | DO5: Apr | DP5: Jul | DQ5: Oct | DR5: Jan | DS5: Jan
C6: FY04 | D6: 1Q | E6: 2Q | F6: 3Q | G6: 4Q | H6: FY05 | I6: 1Q | J6: 2Q | K6: 3Q | L6: 4Q | M6: FY06 | N6: 1Q | O6: 2Q | P6: 3Q | Q6: 4Q | R6: FY07 | S6: 1Q | T6: 2Q | U6: 3Q | V6: 4Q | W6: FY08* | X6: 1Q | Y6: 2Q | Z6: 3Q | AA6: 4Q | AB6: FY09 | AC6: 1Q | AD6: 2Q | AE6: 3Q | AF6: 4Q | AG6: FY10 | AH6: 1Q | AI6: 2Q | AJ6: 3Q | AK6: 4Q | AL6: FY11 | AM6: 1Q | AN6: 2Q | AO6: 3Q | AP6: 4Q | AQ6: FY12 | AR6: 1Q | AS6: 2Q | AT6: 3Q | AU6: 4Q | AV6: FY13* | AW6: 1Q | AX6: 2Q | AY6: 3Q | AZ6: 4Q | BA6: FY14 | BB6: 1Q | BC6: 2Q | BD6: 3Q | BE6: 4Q | BF6: FY15 | BG6: 1Q | BH6: 2Q | BI6: 3Q | BJ6: 4Q | BK6: FY16 | BL6: 1Q | BM6: 2Q | BN6: 3Q | BO6: 4Q | BP6: FY17 | BQ6: 1Q | BR6: 2Q | BS6: 3Q | BT6: 4Q | BU6: FY18* | BV6: 1Q | BW6: 2Q | BX6: 3Q | BY6: 4Q | BZ6: FY19 | CA6: 1Q | CB6: 2Q | CC6: 3Q | CD6: 4Q | CE6: FY20 | CF6: 1Q | CG6: 2Q | CH6: 3Q | CI6: 4Q | CJ6: FY21 | CK6: 1Q | CL6: 2Q | CM6: 3Q | CN6: 4Q | CO6: FY22 | CP6: 1Q | CQ6: 2Q | CR6: 3Q | CS6: 4Q | CT6: FY23 | CU6: 1Q | CV6: 2Q | CW6: 3Q | CX6: 4Q | CY6: FY24 | CZ6: 1Q | DA6: 2Q | DB6: 3Q | DC6: 4Q | DD6: FY25 | DE6: 1Q | DF6: 2Q | DG6: 3QE | DH6: 4QE | DI6: FY26E | DJ6: 1QE | DK6: 2QE | DL6: 3QE | DM6: 4QE | DN6: FY27E | DO6: 1QE | DP6: 2QE | DQ6: 3QE | DR6: 4QE | DS6: FY28E
B7: Consolidated Summary
B8: Sales Summary
B10: Americas | CO10: =CO173 -> 6817.454 | CP10: =CP173 -> 1567.738 | CQ10: =CQ173 -> 1719.773 | CR10: =CR173 -> 1732.398 | CS10: =CS173 -> 2611.738 | CT10: =CT173 -> 7631.647 | CU10: =CU173 -> 1622.264 | CV10: =CV173 -> 1741.433 | ... DS10: =DS173 -> 6312.3848
B11: Mainland China | CO11: =CO236 -> 576.503 | CP11: =CP236 -> 210.068 | CQ11: =CQ236 -> 234.445 | CR11: =CR236 -> 228.595 | CS11: =CS236 -> 290.652 | CT11: =CT236 -> 963.76 | CU11: =CU236 -> 303.786 | CV11: =CV236 -> 314.189 | ... DS11: =DS236 -> 2185.8684
B12: Rest of World | CO12: =CO294 -> 716.561 | CP12: =CP294 -> 222.986 | CQ12: =CQ294 -> 254.947 | CR12: =CR294 -> 243.225 | CS12: =CS294 -> 302.713 | CT12: =CT294 -> 1023.871 | CU12: =CU294 -> 282.841 | CV12: =CV294 -> 315.456 | ... DS12: =DS294 -> 1832.7337
B13: Total sales | C13: =SUM(C28:C32) -> 40.749 | D13: =SUM(D28,D30,D32) -> 15.63 | E13: =SUM(E28,E30,E32) -> 17.126 | F13: =SUM(F28,F30,F32) -> 19.984 | G13: =SUM(G28,G30,G32) -> 31.389093 | H13: =SUM(H28,H30,H32) -> 84.129093 | I13: =SUM(I28,I30,I32) -> 28.184 | J13: =SUM(J28,J30,J32) -> 32.517437 | K13: =SUM(K28,K30,K32) -> 35.967615 | ... CN13: =SUM(CN28,CN30,CN32) -> 2771.838 | CO13: =SUM(CO10:CO12) -> 8110.518 | CP13: =SUM(CP10:CP12) -> 2000.792 | CQ13: =SUM(CQ10:CQ12) -> 2209.165 | CR13: =SUM(CR10:CR12) -> 2204.218 | CS13: =SUM(CS10:CS12) -> 3205.103 | CT13: =SUM(CT10:CT12) -> 9619.278 | CU13: =SUM(CU10:CU12) -> 2208.891 | CV13: =SUM(CV10:CV12) -> 2371.078 | ... DS13: =SUM(DS10:DS12) -> 10330.987
B14: % chg. Y/Y | H14: =H13/C13-1 -> 1.0645683 | I14: =I13/D13-1 -> 0.80319898 | J14: =J13/E13-1 -> 0.89871756 | K14: =K13/F13-1 -> 0.79982061 | L14: =L13/G13-1 -> 0.66350082 | M14: =M13/H13-1 -> 0.76971876 | N14: =N13/I13-1 -> 0.58918024 | O14: =O13/J13-1 -> 0.8045993 | ... DS14: =DS13/DN13-1 -> 0.011164122
B15: 2-yr CAGR | N15: =(N13/D13)^(1/2)-1 -> 0.69281074 | O15: =(O13/E13)^(1/2)-1 -> 0.85106034 | P15: =(P13/F13)^(1/2)-1 -> 0.8193851 | Q15: =(Q13/G13)^(1/2)-1 -> 0.82977119 | R15: =(R13/H13)^(1/2)-1 -> 0.80703582 | S15: =(S13/I13)^(1/2)-1 -> 0.665374 | T15: =(T13/J13)^(1/2)-1 -> 0.62138007 | U15: =(U13/K13)^(1/2)-1 -> 0.55568413 | ... DS15: =(DS13/DI13)^(1/2)-1 -> -0.0064996223
B16: % chg Y/Y, FX-Neutral | N16: =(1+N14)/(1+N17)-1 -> 0.53668153 | O16: =(1+O14)/(1+O17)-1 -> 0.74694139 | P16: =(1+P14)/(1+P17)-1 -> 0.72803168 | Q16: =(1+Q14)/(1+Q17)-1 -> 0.89463292 | R16: =(1+R14)/(1+R17)-1 -> 0.75550409 | S16: =(1+S14)/(1+S17)-1 -> 0.59245964 | T16: =(1+T14)/(1+T17)-1 -> 0.40068033 | U16: =(1+U14)/(1+U17)-1 -> 0.38843312 | ... BN16: =(1+BN14)/(1+BN17)-1 -> 0.12676361 | BO16: 0.16 | BP16: 0.12 | BQ16: 0.23 | BR16: =(1+BR14)/(1+BR17)-1 -> 0.2425465 | BS16: =(1+BS14)/(1+BS17)-1 -> 0.22039475 | BT16: =(1+BT14)/(1+BT17)-1 -> 0.27197347 | BU16: =(1+BU14)/(1+BU17)-1 -> 0.24512601 | BV16: 0.22 | BW16: 0.23 | BX16: 0.23 | BY16: 0.2 | BZ16: =(1+BZ14)/(1+BZ17)-1 -> 0.21924508 | CA16: -0.16 | CB16: 0.03 | CC16: 0.21 | CD16: 0.22 | CE16: =(1+CE14)/(1+CE17)-1 -> 0.10054642 | CF16: 0.83 | CG16: 0.56 | CH16: 0.28 | CI16: 0.23 | CJ16: =(1+CJ14)/(1+CJ17)-1 -> 0.39320819 | CK16: 0.32 | CL16: 0.31 | CM16: 0.31 | CN16: 0.33 | CO16: =(1+CO14)/(1+CO17)-1 -> 0.32520063 | CP16: 0.27 | CQ16: 0.2 | CR16: 0.19 | CS16: 0.16 | CT16: =(1+CT14)/(1+CT17)-1 -> 0.19870163 | CU16: 0.11 | CV16: 0.08 | CW16: 0.08 | CX16: 0.14 | CY16: =(1+CY14)/(1+CY17)-1 -> 0.10671457 | CZ16: 0.08 | DA16: 0.06 | DB16: 0.07 | DC16: 0 | DD16: =(1+DD14)/(1+DD17)-1 -> 0.044865736 | DE16: 0.02 | DF16: -0.05 | DG16: =(1+DG14)/(1+DG17)-1 -> -0.1074336 | DH16: =(1+DH14)/(1+DH17)-1 -> -0.10897737 | DI16: =(1+DI14)/(1+DI17)-1 -> -0.05540147 | DJ16: =(1+DJ14)/(1+DJ17)-1 -> -0.047900587 | DK16: =(1+DK14)/(1+DK17)-1 -> -0.037677383 | DL16: =(1+DL14)/(1+DL17)-1 -> -0.0045097354 | DM16: =(1+DM14)/(1+DM17)-1 -> -0.013100228 | DN16: =(1+DN14)/(1+DN17)-1 -> -0.025114061 | ... DS16: =(1+DS14)/(1+DS17)-1 -> 0.011164122
