Workbook
Name \0: '[1]RANDSTAD (old 4)'!#REF!
Name \0: '[1]RANDSTAD (old 4)'!#REF!
Name \a: '[1]RANDSTAD (old 4)'!#REF!
Name \a: '[1]RANDSTAD (old 4)'!#REF!
Name \b: '[2]teo model'!#REF!
Name \b: '[2]teo model'!#REF!
Name \BS: #REF!
Name \BS: #REF!
Name \BS: #REF!
Name \c: '[2]teo model'!#REF!
Name \c: '[2]teo model'!#REF!
Name \d: #REF!
Name \d: #REF!
Name \d: #REF!
Name \e: [3]Geographic!#REF!
Name \e: [3]Geographic!#REF!
Name \EP1: #REF!
Name \EP1: #REF!
Name \EP1: #REF!
Name \EP2: #REF!
Name \EP2: #REF!
Name \EP2: #REF!
Name \f: #REF!
Name \f: #REF!
Name \f: #REF!
Name \g: [3]Geographic!#REF!
Name \g: [3]Geographic!#REF!
Name \h: '[2]teo model'!#REF!
Name \h: '[2]teo model'!#REF!
Name \i: '[1]RANDSTAD (old 4)'!#REF!
Name \i: '[1]RANDSTAD (old 4)'!#REF!
Name \j: [3]Geographic!#REF!
Name \j: #REF!
Name \j: #REF!
Name \k: [4]roysuna!#REF!
Name \k: [4]roysuna!#REF!
Name \l: '[2]teo model'!#REF!
Name \l: #REF!
Name \l: #REF!
Name \m: '[2]teo model'!#REF!
Name \m: #REF!
Name \m: #REF!
Name \o: #REF!
Name \o: #REF!
Name \o: #REF!
Name \p: #REF!
Name \P: #REF!
Name \P: #REF!
Name \PL: #REF!
Name \PL: #REF!
Name \PL: #REF!
Name \q: [5]VABQORF!#REF!
Name \q: [5]VABQORF!#REF!
Name \R: #REF!
Name \R: #REF!
Name \R: #REF!
Name \s: #REF!
Name \s: #REF!
Name \s: #REF!
Name \SF: #REF!

Sheet Cover Sheet
C4: Adidas Model
C5: European General Retail
B13: Team:
B16: Richard Edwards
B17: Managing Director
B18: Richard.Edwards@gs.com
B19: +44 (20) 7051-6016
B21: Ben Williams
B22: Analyst
B23: ben.williams@gs.com
B24: +44 (20) 7051-0661
B26: Hamish Bogdan
B27: Analyst
B28: hamish.bogdan@gs.com
B29: +44 (20) 7552-2214

Sheet Sheet2

Sheet Sheet1

Sheet Profit and Loss
A1: =TODAY() -> 46294 | B1: FY 95 | C1: FY 96 | D1: FY 97 | E1: FY 98 | F1: FY 99 | G1: FY 00 | H1: FY 01 | I1: FY 02 | J1: FY 03 | K1: FY 04 | L1: FY 05 | M1: FY 06 | N1: FY 07 | O1: FY 08 | P1: FY 09 | Q1: FY 10 | R1: FY 11 | S1: FY 12 | T1: FY 13 | U1: FY 14 | V1: FY 15 | W1: FY 16 | X1: FY 17 | Y1: FY 18 | Z1: FY 19 | AA1: FY 20 | AB1: FY 21 | AC1: FY 22 | AD1: FY 23 | AE1: FY 24 | AF1: FY 25 | AG1: FY 26E | AH1: FY 27E | AI1: FY 28E | AJ1: FY 29E | AK1: FY 30E
A2: adidas - Dec YE - in EUR mn | L2: IFRS | M2: IFRS | N2: IFRS | O2: IFRS | P2: IFRS | Q2: IFRS | R2: IFRS | S2: IFRS | T2: IFRS | U2: IFRS | V2: IFRS | W2: IFRS | X2: IFRS | Y2: IFRS | Z2: IFRS | AA2: IFRS | AB2: IFRS | AC2: IFRS | AD2: IFRS | AE2: IFRS | AF2: IFRS | AG2: IFRS | AH2: IFRS | AI2: IFRS | AJ2: IFRS | AK2: IFRS
A4: Sales by segment | T4: FY 13 | U4: FY 14 | V4: FY 15 | W4: FY 16 | X4: FY 17 | Y4: FY 18 | Z4: FY 19 | AA4: FY 20 | AB4: FY 21 | AC4: FY 22 | AD4: FY 23 | AE4: =AE1 -> FY 24 | AF4: =AF1 -> FY 25 | AG4: =AG1 -> FY 26E | AH4: =AH1 -> FY 27E | AI4: =AI1 -> FY 28E | AJ4: =AJ1 -> FY 29E | AK4: =AK1 -> FY 30E | AO4: FY 12 | AP4: FY 13 | AQ4: FY 14 | AR4: FY 15 | AS4: FY 16 | AT4: FY 17E | AU4: FY 18E | AV4: FY 19E | AW4: FY 20 | AX4: FY 21 | AY4: FY 22E | AZ4: FY 23E | BA4: FY 24E | BB4: FY 25E
A5: Wholesale | M5: =M9*M$32 -> 8571.4 | N5: =N9*N32 -> 8548.17 | O5: 7758 | P5: 7164 | Q5: 8181 | R5: 8971 | S5: =+Interim!EO5 -> 9533 | T5: =Interim!EW5 -> 9100 | U5: 9376 | V5: =V32-V27-V10 -> 11227 | W5: =W32-W27-W10 -> 12812 | X5: =X32-X27-X10 -> 14617 | Y5: =Y32-Y27-Y10 -> 14596 | Z5: =Z32-Z27-Z10 -> 15222 | AA5: =AA32-AA27-AA10 -> 11237 | AB5: =AB32-AB27-AB10 -> 12796.003 | AC5: =AC32-AC27-AC10 -> 13523 | ... AK5: =AK32-AK27-AK10 -> 20822.778 | AN5: Wholesale | AO5: =S5 -> 9533 | AP5: =T5 -> 9100 | AQ5: =U5 -> 9376 | AR5: =V5 -> 11227 | AS5: =W5 -> 12812 | AT5: =X5 -> 14617 | AU5: =Y5 -> 14596 | AV5: =Z5 -> 15222 | ... BB5: =AF5 -> 14808
A6: Growth | N6: =N5/M5-1 -> -0.0027101757 | O6: =O5/N5-1 -> -0.092437329 | P6: =P5/O5-1 -> -0.076566125 | Q6: =Q5/P5-1 -> 0.1419598 | R6: =R5/Q5-1 -> 0.096565212 | S6: =+S5/R5-1 -> 0.062646305 | T6: =T5/S5-1 -> -0.045421169 | U6: =U5/T5-1 -> 0.03032967 | V6: =V5/U5-1 -> 0.19741894 | W6: =W5/V5-1 -> 0.14117752 | X6: =X5/W5-1 -> 0.14088355 | Y6: =Y5/X5-1 -> -0.0014366833 | Z6: =Z5/Y5-1 -> 0.042888463 | AA6: =AA5/Z5-1 -> -0.26179214 | ... AE6: =AE5/AD5-1 -> 0.13967096 | AF6: =Interim!IO6 -> 0.07 | AG6: =AG5/AF5-1 -> 0.10568359 | AH6: =AH5/AG5-1 -> 0.074563685 | AI6: =AI5/AH5-1 -> 0.066841687 | AJ6: =AJ5/AI5-1 -> 0.053275387 | AK6: =AK5/AJ5-1 -> 0.053264224 | AN6: Retail | AO6: =S10 -> 3373 | AP6: =T10 -> 3446 | AQ6: =U10 -> 3820.5652 | AR6: =V10 -> 4221 | AS6: =W10 -> 5003 | AT6: =X10 -> 5860 | AU6: =Y10 -> 6488 | AV6: =Z10 -> 7814 | ... BB6: =AF10 -> 9931
A7: FX & Scope impact | P7: =P6-P8 -> 0.013433875 | Q7: =Q6-Q8 -> 0.066959799 | R7: =R6-R8 -> -0.013434788 | S7: =+S6-S8 -> 0.041739266 | T7: =T6-T8 -> -0.049224274 | U7: =U6-U8 -> -0.02967033 | V7: =V6-V8 -> 0.089049577 | W7: =W6-W8 -> -0.044691725 | X7: =X6-X8 -> -0.018181918 | Y7: =Y6-Y8 -> -0.063659848 | Z7: =Z6-Z8 -> 0.034761388 | AA7: =AA6-AA8 -> -0.026607596 | ... AK7: =AK6-AK8 -> 2.4286129e-16 | AN7: Other | AO7: =S27 -> 1977 | AP7: =T27 -> 1659 | AQ7: =U27 -> 1358 | AR7: =V27 -> 1467 | AS7: =W27 -> 1475 | AT7: =X27 -> 741 | AU7: =Y27 -> 831 | AV7: =Z27 -> 605 | ... BB7: =AF27 -> 72
A8: Currency neutral | P8: -0.09 | Q8: 0.075 | R8: =Interim!EG8 -> 0.11 | S8: =+Interim!EO8 -> 0.020907039 | T8: =Interim!EW8 -> 0.003803105 | U8: 0.06 | V8: =(U32*V35-U27*V30-U10*V13)/U5 -> 0.10836937 | W8: =(V32*W35-V27*W30-V10*W13)/V5 -> 0.18586924 | X8: =(W32*X35-W27*X30-W10*X13)/W5 -> 0.15906546 | Y8: =(X32*Y35-X27*Y30-X10*Y13)/X5 -> 0.062223165 | Z8: =(Y32*Z35-Y27*Z30-Y10*Z13)/Y5 -> 0.0081270748 | AA8: =(Z32*AA35-Z27*AA30-Z10*AA13)/Z5 -> -0.23518455 | AB8: =(AA32*AB35-AA27*AB30-AA10*AB13)/AA5 -> 0.23141875 | AC8: =(AB32*AC35-AB27*AC30-AB10*AC13)/AB5 -> 0.0050181236 | ... AE8: =(AD32*AE35-AD27*AE30-AD10*AE13)/AD5 -> 0.16830868 | AF8: =Interim!IO8 -> 0.12 | AG8: =(AF32*AG35-AF27*AG30-AF10*AG13)/AF5 -> 0.11754862 | AH8: =(AG32*AH35-AG27*AH30-AG10*AH13)/AG5 -> 0.066497018 | AI8: =(AH32*AI35-AH27*AI30-AH10*AI13)/AH5 -> 0.066841687 | AJ8: =(AI32*AJ35-AI27*AJ30-AI10*AJ13)/AI5 -> 0.053275387 | AK8: =(AJ32*AK35-AJ27*AK30-AJ10*AK13)/AJ5 -> 0.053264224 | AS8: =AS6/SUM(AS5:AS7) -> 0.25935718 | AT8: =AT6/SUM(AT5:AT7) -> 0.2761806 | AU8: =AU6/SUM(AU5:AU7) -> 0.29605293 | AV8: =AV6/SUM(AV5:AV7) -> 0.33052747 | AW8: =AW6/SUM(AW5:AW7) -> 0.40974602 | AX8: =AX6/SUM(AX5:AX7) -> 0.39059984 | AY8: =AY6/SUM(AY5:AY7) -> 0.39260806 | AZ8: =AZ6/SUM(AZ5:AZ7) -> 0.42010833 | ... BB8: =BB6/SUM(BB5:BB7) -> 0.40026601
A9: % of total | M9: 0.85 | N9: 0.83 | O9: =O5/O32 -> 0.7195993 | P9: =P5/P32 -> 0.69130561 | Q9: =Q5/Q32 -> 0.6823186 | R9: =R5/R32 -> 0.67334684 | S9: =S5/S32 -> 0.64052946 | T9: =T5/T32 -> 0.6406195 | U9: =U5/U32 -> 0.64510802 | V9: =V5/V32 -> 0.66373042 | ... AK9: =AK5/AK32 -> 0.5951685
A10: Retail | M10: =M32-M5-M27 -> 656.6 | N10: =N32-N5-N27 -> 946.83 | O10: 1738 | P10: 1906 | Q10: 2389 | R10: 2793 | S10: =+Interim!EO10 -> 3373 | T10: =Interim!EW10 -> 3446 | U10: =Interim!FE10 -> 3820.5652 | V10: =Interim!FM10 -> 4221 | W10: =Interim!FU10 -> 5003 | X10: =Interim!GC10 -> 5860 | Y10: =Interim!GK10 -> 6488 | Z10: =Y10*(1+Z11) -> 7814 | AA10: =Z10*(1+AA11) -> 8131 | AB10: =AA10*(1+AB11) -> 8293.997 | AC10: =AB10*(1+AC11) -> 8838 | AD10: =AC10*(1+AD11) -> 8687 | AE10: =AD10*(1+AE11) -> 9490 | AF10: =Interim!IO10 -> 9931 | AG10: =AF10*(1+AG11) -> 10608.219 | AH10: =AG10*(1+AH11) -> 11436.57 | AI10: =AH10*(1+AI11) -> 12237.13 | AJ10: =AI10*(1+AJ11) -> 13093.729 | AK10: =AJ10*(1+AK11) -> 14010.29
A11: Growth | N11: =N10/M10-1 -> 0.44201949 | O11: =O10/N10-1 -> 0.83559879 | P11: =P10/O10-1 -> 0.096662831 | Q11: =Q10/P10-1 -> 0.25341028 | R11: =+R10/Q10-1 -> 0.16910841 | S11: =+S10/R10-1 -> 0.20766201 | T11: =T10/S10-1 -> 0.021642455 | U11: =U10/T10-1 -> 0.10869564 | V11: =V10/U10-1 -> 0.10481036 | W11: =W10/V10-1 -> 0.18526416 | X11: =X10/W10-1 -> 0.17129722 | Y11: =Y10/X10-1 -> 0.10716724 | Z11: =Z12+Z13 -> 0.20437731 | AA11: =AA12+AA13 -> 0.040568211 | AB11: =AB12+AB13 -> 0.020046362 | AC11: =AC12+AC13 -> 0.065589973 | AD11: =AD12+AD13 -> -0.017085313 | AE11: =AE12+AE13 -> 0.092436975 | AF11: =AF12+AF13 -> 0.1 | AG11: =AG12+AG13 -> 0.068192381 | ... AK11: =AK12+AK13 -> 0.07
A12: FX & Scope impact | P12: =P11-P13 -> 0.026662831 | Q12: =Q11-Q13 -> 0.075410283 | R12: =+R11-R13 -> -0.030891586 | S12: =+S11-S13 -> 0.070154314 | T12: =T11-T13 -> -0.059504002 | U12: =U11-U13 -> -0.10030436 | V12: =V11-V13 -> -0.0051896415 | W12: =W11-W13 -> -0.044735845 | X12: =X11-X13 -> -0.00060163902 | Y12: =Y11-Y13 -> -0.042525597 | Z12: =Z$34 -> 0.01823927 | AA12: =AA$34 -> -0.02612586 | AB12: =AB$34 -> -0.089953638 | AC12: 0.045589973 | AD12: -0.047085313 | AE12: -0.017563025 | AF12: =Interim!IO12 -> -0.04 | AG12: =AG$34 -> -0.011807619 | AH12: =AH$34 -> 0.0080857898 | AI12: =AI$34 -> 0 | AJ12: =AJ$34 -> 1.5265567e-16 | AK12: =AK$34 -> 0
A13: Currency neutral | P13: 0.07 | Q13: 0.178 | R13: =Interim!EG13 -> 0.2 | S13: =+Interim!EO13 -> 0.1375077 | T13: =Interim!EW13 -> 0.081146457 | U13: 0.209 | V13: =Interim!FM13 -> 0.11 | W13: =Interim!FU13 -> 0.23 | X13: =Interim!GC13 -> 0.17189886 | Y13: =Interim!GK13 -> 0.14969283 | Z13: 0.18613804 | AA13: 0.066694071 | AB13: 0.11 | AC13: 0.02 | AD13: 0.03 | AE13: 0.11 | AF13: =Interim!IO13 -> 0.14 | AG13: 0.08 | AH13: 0.07 | AI13: =AH13 -> 0.07 | AJ13: =AI13 -> 0.07 | AK13: =AJ13 -> 0.07
A14: % of total | M14: =M10/M$32 -> 0.06511305 | N14: =N10/$N$32 -> 0.091934168 | O14: =O10/O32 -> 0.16120954 | P14: =P10/P32 -> 0.18392357 | Q14: =Q10/Q32 -> 0.19924937 | R14: =R10/R32 -> 0.20963747 | S14: =S10/S32 -> 0.22663442 | T14: =T10/T32 -> 0.24259064 | U14: =U10/U32 -> 0.26287087 | V14: =V10/V32 -> 0.24954183 | ... AK14: =AK10/AK32 -> 0.40045007
A15: of which stores | O15: =O10-O21 -> 1722.0031 | P15: =P10-P21 -> 1876.4142 | Q15: =Q10-Q21 -> 2334 | R15: =R10-R21 -> 2704 | S15: =S10-S21 -> 3215 | T15: =T10-T21 -> 3196 | U15: =U10-U21 -> 3398.5652 | V15: =V10-V21 -> 3593.2489 | ... AK15: =AK10-AK21 -> 7637.409
A16: Growth | P16: =P15/O15-1 -> 0.089669444 | Q16: =Q15/P15-1 -> 0.24386183 | R16: =R15/Q15-1 -> 0.15852614 | S16: =S15/R15-1 -> 0.18897929 | T16: =T15/S15-1 -> -0.0059097978 | U16: =U15/T15-1 -> 0.063380849 | V16: =V15/U15-1 -> 0.057284099 | W16: =W15/V15-1 -> 0.11389024 | ... AK16: =AK15/AJ15-1 -> 0.061796348
A17: FX & Scope impact | P17: =P16-P18 -> 0.026729603 | Q17: =Q16-Q18 -> 0.075488994 | R17: =R16-R18 -> -0.031175955 | S17: =S16-S18 -> 0.070708627 | T17: =T16-T18 -> -0.059591602 | U17: =U16-U18 -> -0.10564731 | V17: =V16-V18 -> -0.014223186 | W17: =W16-W18 -> -0.053216706 | ... AK17: =AK16-AK18 -> -1.4571677e-16
A18: Currency neutral | P18: =(O10*P13-O21*P24)/O15 -> 0.062939841 | Q18: =(P10*Q13-P21*Q24)/P15 -> 0.16837283 | R18: =(Q10*R13-Q21*R24)/Q15 -> 0.18970209 | S18: =(R10*S13-R21*S24)/R15 -> 0.11827066 | T18: =(S10*T13-S21*T24)/S15 -> 0.053681804 | U18: =(T10*U13-T21*U24)/T15 -> 0.16902816 | V18: =(U10*V13-U21*V24)/U15 -> 0.071507285 | W18: =(V10*W13-V21*W24)/V15 -> 0.16710695 | ... AC18: =(AB10*AC13-AB21*AC24)/AB15 -> 0.003020308 | AD18: 0.12 | AE18: 0.15 | AF18: =(AE10*AF13-AE21*AF24)/AE15 -> 0.1258956 | AG18: =(AF10*AG13-AF21*AG24)/AF15 -> 0.08 | AH18: =(AG10*AH13-AG21*AH24)/AG15 -> 0.062197304 | AI18: =(AH10*AI13-AH21*AI24)/AH15 -> 0.062067516 | AJ18: =(AI10*AJ13-AI21*AJ24)/AI15 -> 0.06193358 | AK18: =(AJ10*AK13-AJ21*AK24)/AJ15 -> 0.061796348
A19: % of total | P19: =P15/P$32 -> 0.18106863 | Q19: =Q15/Q$32 -> 0.19466222 | R19: =R15/R$32 -> 0.20295729 | S19: =S15/S$32 -> 0.21601828 | T19: =T15/T$32 -> 0.2249912 | U19: =U15/U$32 -> 0.2338355 | V19: =V15/V$32 -> 0.21242973 | W19: =W15/W$32 -> 0.20749015 | ... AK19: =AK15/AK$32 -> 0.21829677
A20: % of retail | P20: =P15/P$10 -> 0.98447755 | Q20: =Q15/Q$10 -> 0.97697781 | R20: =R15/R$10 -> 0.96813462 | S20: =S15/S$10 -> 0.95315743 | T20: =T15/T$10 -> 0.92745212 | U20: =U15/U$10 -> 0.88954514 | V20: =V15/V$10 -> 0.85127907 | W20: =W15/W$10 -> 0.80001698 | ... AK20: =AK15/AK$10 -> 0.54512856
A21: of which eCommerce | O21: =P21/(1+P22) -> 15.996863 | P21: =Q21/(1+Q22) -> 29.585799 | Q21: 55 | R21: 89 | S21: 158 | T21: 250 | U21: 422 | V21: =U21*(1+V22) -> 627.75106 | W21: =V21*(1+W22) -> 1000.5151 | X21: =W21*(1+X22) -> 1510.7281 | Y21: =X21*(1+Y22) -> 1977.0021 | Z21: =Y21*(1+Z22) -> 2665.4718 | AA21: =Z21*(1+AA22) -> 4008.5342 | AB21: =AA21*(1+AB22) -> 3808.2933 | AC21: =AB21*(1+AC22) -> 4149.913 | ... AK21: =AJ21*(1+AK22) -> 6372.8806
A22: Growth | P22: =P23+P24 -> 0.849475 | Q22: 0.859 | R22: =R21/Q21-1 -> 0.61818182 | S22: =S21/R21-1 -> 0.7752809 | T22: =T21/S21-1 -> 0.58227848 | U22: =U21/T21-1 -> 0.688 | V22: =V23+V24 -> 0.48756176 | W22: =W23+W24 -> 0.59380863 | X22: =X23+X24 -> 0.50995037 | Y22: =Y23+Y24 -> 0.30864191 | Z22: =Z23+Z24 -> 0.34823927 | AA22: =AA23+AA24 -> 0.50387414 | AB22: =AB23+AB24 -> -0.049953638 | AC22: =AC23+AC24 -> 0.089704154 | ... AK22: =AK23+AK24 -> 0.08
A23: FX & Scope impact | P23: =P$34 -> 0.019475002 | Q23: =Q$34 -> 0.070418219 | R23: =R$34 -> -0.01882402 | S23: =S$34 -> 0.053313188 | T23: =T22-T24 -> -0.057721519 | U23: =U22-U24 -> -0.032 | V23: =V145 -> 0.067561756 | W23: =W145+4.5% -> 0.0038086314 | X23: =X$34 -> -0.060049627 | Y23: =Y$34 -> -0.051358092 | Z23: =Z$34 -> 0.01823927 | AA23: =AA$34 -> -0.02612586 | AB23: =AB$34 -> -0.089953638 | AC23: =AC$34 -> 0.049704154 | AD23: =AD$34 -> -0.037426858 | AE23: =AE$34 -> -0.023656533 | ... AK23: =AK$34 -> 0
A24: Currency neutral | P24: 0.83 | Q24: =Q22-Q23 -> 0.78858178 | R24: =R22-R23 -> 0.63700584 | S24: =S22-S23 -> 0.72196771 | T24: 0.64 | U24: 0.72 | V24: =Interim!FM19 -> 0.42 | W24: =Interim!FU19 -> 0.59 | X24: 0.57 | Y24: 0.36 | Z24: 0.33 | AA24: 0.53 | AB24: 0.04 | AC24: 0.04 | AD24: -0.05 | AE24: 0.06 | AF24: =Interim!IO19 -> 0.16 | AG24: 0.08 | AH24: 0.08 | AI24: 0.08 | AJ24: 0.08 | AK24: 0.08
A25: % of total | P25: =P21/P32 -> 0.0028549454 | Q25: =Q21/Q32 -> 0.004587156 | R25: =R21/R32 -> 0.0066801771 | S25: =S21/S32 -> 0.010616139 | T25: =T21/T32 -> 0.017599437 | U25: =U21/U32 -> 0.029035365 | V25: =V21/V32 -> 0.037112093 | W25: =W21/W32 -> 0.051867033 | ... AK25: =AK21/AK32 -> 0.1821533
A26: % of retail | P26: =P21/P$10 -> 0.015522455 | Q26: =Q21/Q$10 -> 0.023022185 | R26: =R21/R$10 -> 0.031865378 | S26: =S21/S$10 -> 0.046842573 | T26: =T21/T$10 -> 0.072547882 | U26: =U21/U$10 -> 0.11045486 | V26: =V21/V$10 -> 0.14872093 | W26: =W21/W$10 -> 0.19998302 | ... AK26: =AK21/AK$10 -> 0.45487144
A27: Other Businesses | M27: =M31*M$32 -> 856 | N27: =N31*N$32 -> 804 | O27: 1285 | P27: 1293 | Q27: 1420 | R27: 1580 | S27: =+Interim!EO21 -> 1977 | T27: =T32-T5-T10 -> 1659 | U27: =U137 -> 1358 | V27: =V137 -> 1467 | W27: =W137 -> 1475 | X27: =X137 -> 741 | Y27: =Y137 -> 831 | Z27: =Z137 -> 605 | AA27: =AA137 -> 476 | AB27: =AB137 -> 144 | ... AK27: =AK137 -> 153.29012
A28: Growth | N28: =N27/M27-1 -> -0.060747664 | O28: =O27/N27-1 -> 0.59825871 | P28: =P27/O27-1 -> 0.0062256809 | Q28: =Q27/P27-1 -> 0.098221191 | R28: =+R27/Q27-1 -> 0.11267606 | S28: =+S27/R27-1 -> 0.25126582 | T28: =T27/S27-1 -> -0.16084977 | U28: =U27/T27-1 -> -0.1814346 | V28: =V27/U27-1 -> 0.080265096 | W28: =W27/V27-1 -> 0.0054533061 | X28: =X27/W27-1 -> -0.49762712 | Y28: =Y27/X27-1 -> 0.12145749 | Z28: =Z27/Y27-1 -> -0.27196149 | AA28: =AA27/Z27-1 -> -0.21322314 | ... AK28: =AK27/AJ27-1 -> 0
A29: FX & Scope impact | P29: =P28-P30 -> 0.046225681 | Q29: =Q28-Q30 -> 0.082221191 | R29: =+R28-R30 -> -0.017323944 | S29: =+S28-S30 -> 0.082856962 | T29: =T28-T30 -> -0.20956247 | U29: =U28-U30 -> 0.0095654008 | V29: =V28-V30 -> 0.10685714 | W29: =W28-W30 -> -0.004204499 | X29: =X28-X30 -> -0.62535632 | Y29: =Y28-Y30 -> 0.12145749 | Z29: =Z28-Z30 -> -0.27196149 | AA29: =AA28-AA30 -> -0.014005221 | ... AK29: =AK28-AK30 -> 0
A30: Currency neutral | P30: -0.04 | Q30: 0.016 | R30: =Interim!EG24 -> 0.13 | S30: =+Interim!EO24 -> 0.16840886 | T30: =Interim!EW24 -> 0.048712696 | U30: -0.191 | V30: =V140 -> -0.026592047 | W30: =W140 -> 0.009657805 | X30: =X140 -> 0.1277292 | Y30: =Y140 -> 0 | Z30: =Z140 -> 0 | AA30: =AA140 -> -0.19921792 | AB30: =AB140 -> -0.67189603 | AC30: =AC140 -> -0.059096276 | ... AK30: =AK140 -> 0
A31: % of total | M31: 0.08488695 | N31: 0.078065832 | O31: =O27/O32 -> 0.11919117 | P31: =P27/P32 -> 0.12477082 | Q31: =Q27/Q32 -> 0.11843203 | R31: =R27/R32 -> 0.11859191 | S31: =S27/S32 -> 0.13283612 | T31: =T27/T32 -> 0.11678986 | U31: =U27/U32 -> 0.093436081 | V31: =V27/V32 -> 0.086727756 | ... AK31: =AK27/AK32 -> 0.0043814255
A32: Total sales | K32: =K325 -> 5860 | L32: 6636 | M32: 10084 | N32: 10299 | O32: =SUM(O27,O10,O5) -> 10781 | P32: =SUM(P27,P10,P5) -> 10363 | Q32: =SUM(Q27,Q10,Q5) -> 11990 | R32: =Interim!EG26 -> 13323 | S32: =+Interim!EO26 -> 14883 | T32: =T325 -> 14205 | U32: =U325 -> 14534 | V32: =V143 -> 16915 | W32: =W143 -> 19290 | X32: =X143 -> 21218 | Y32: =Y143 -> 21915 | Z32: =Z143 -> 23641 | AA32: =AA143 -> 19844 | AB32: =AB143 -> 21234 | AC32: =AC143 -> 22511 | ... AK32: =AK143 -> 34986.358 | AM32: =((AF32/AB32)^0.25)-1 -> 0.039688198
A33: Growth | L33: =L32/K32-1 -> 0.13242321 | M33: 0.14 | N33: =N32/M32-1 -> 0.021320904 | O33: =O32/N32-1 -> 0.04680066 | P33: =P32/O32-1 -> -0.038771914 | Q33: =Q32/P32-1 -> 0.15700087 | R33: =R32/Q32-1 -> 0.11117598 | S33: =S32/R32-1 -> 0.11709075 | T33: =T32/S32-1 -> -0.045555332 | U33: =U32/T32-1 -> 0.023160859 | ... AK33: =AK32/AJ32-1 -> 0.05965397
A34: FX & Scope impact | P34: =P33-P35 -> 0.019475002 | Q34: =Q33-Q35 -> 0.070418219 | R34: =R33-R35 -> -0.01882402 | S34: =S33-S35 -> 0.053313188 | T34: =T33-T35 -> -0.0749744 | U34: =U33-U35 -> -0.04153104 | V34: =V33-V35 -> 0.067481675 | W34: =W149 -> -0.043378907 | X34: =X33-X35 -> -0.060049627 | Y34: =Y33-Y35 -> -0.051358092 | Z34: =Z33-Z35 -> 0.01823927 | AA34: =AA33-AA35 -> -0.02612586 | AB34: =AB33-AB35 -> -0.089953638 | AC34: =AC33-AC35 -> 0.049704154 | AD34: =AD33-AD35 -> -0.037426858 | AE34: =AE33-AE35 -> -0.023656533 | ... AK34: =AK33-AK35 -> 0
A35: Currency neutral | P35: =(P8*$O$5+P13*$O$10+P30*$O$27)/$O$32 -> -0.058246916 | Q35: =(Q8*$P$5+Q13*$P$10+Q30*$P$27)/$P$32 -> 0.08658265 | R35: =Interim!EG29 -> 0.13 | S35: =Interim!EO29 -> 0.063777558 | T35: =Interim!EW29 -> 0.029419069 | U35: =Interim!FE29 -> 0.064691899 | V35: =V146 -> 0.096341086 | W35: =W146 -> 0.18159929 | X35: =X146 -> 0.15999779 | Y35: =Y146 -> 0.08420756 | Z35: =Z146 -> 0.060519571 | AA35: =AA146 -> -0.13448494 | AB35: =AB146 -> 0.16 | AC35: =AC146 -> 0.010435245 | ... AK35: =AK146 -> 0.05965397
A36: Check | Y36: =(Y14-X14)*25% -> 0.0049680826 | Z36: =(Z14-Y14)*25% -> 0.0086186354 | AA36: =(AA14-Z14)*25% -> 0.019804636 | AB36: =(AB14-AA14)*25% -> -0.0047865452 | AC36: =(AC14-AB14)*25% -> 0.000502055 | AD36: =(AD14-AC14)*25% -> 0.0068750674 | AE36: =(AE14-AD14)*25% -> -0.0020226969 | AF36: =(AF14-AE14)*25% -> -0.0029378823 | ... AK36: =(AK14-AJ14)*25% -> 0.00096800661
A38: Gross profit by segment
A39: Wholesale | O39: 3387 | P39: 2978 | Q39: 3379 | R39: 3585 | S39: =Interim!EO33 -> 3840 | T39: 3884 | U39: 3911 | V39: =Interim!FM33 -> 5064.752 | W39: =W5*W40 -> 5736.9077 | X39: =X5*X40 -> 6691.3136 | Y39: =Y5*Y40 -> 6725.4883 | Z39: =Z5*Z40 -> 7090.0441 | AA39: =AA5*AA40 -> 5245.1633 | AB39: =AB5*AB40 -> 5985.6647 | AC39: =AC5*AC40 -> 6339.2595 | AD39: =AD5*AD40 -> 5539.6 | ... AK39: =AK5*AK40 -> 9927.8035
A40: Gross margin % | O40: =O39/O$5 -> 0.43658159 | P40: =P39/P$5 -> 0.41568956 | Q40: =Q39/Q5 -> 0.41303019 | R40: =Interim!EG35 -> 0.39888268 | S40: =+S39/S5 -> 0.40281129 | T40: =T39/T5 -> 0.42681319 | U40: =U39/U5 -> 0.41712884 | V40: =V39/V5 -> 0.45112247 | W40: 0.44777612 | X40: =W40+0.01 -> 0.45777612 | Y40: =X40+0.3% -> 0.46077612 | Z40: =Y40+0.5% -> 0.46577612 | AA40: =Z40+0.1% -> 0.46677612 | AB40: =AA40+0.1% -> 0.46777612 | AC40: =AB40+0.1% -> 0.46877612 | AD40: =AC40+0.1% -> 0.46977612 | AE40: =AD40+0.1% -> 0.47077612 | AF40: =AE40+0.1% -> 0.47177612 | AG40: =AF40+0.1% -> 0.47277612 | AH40: =AG40+0.1% -> 0.47377612 | ... AK40: =AJ40+0.1% -> 0.47677612
A41: Retail | O41: 1069 | P41: 1116 | Q41: 1476 | R41: 1749 | S41: =Interim!EO36 -> 2055 | T41: 2143 | U41: 2281 | V41: =Interim!FM36 -> 2606.248 | W41: =W10*W42 -> 3089.0923 | X41: =X10*X42 -> 3687.5357 | Y41: =Y10*Y42 -> 4092.9165 | Z41: =Z10*Z42 -> 4953.8988 | AA41: =AA10*AA42 -> 5163.4592 | AB41: =AB10*AB42 -> 5360.9949 | AC41: =AC10*AC42 -> 5712.6224 | AD41: =AD10*AD42 -> 5615.0205 | ... AK41: =AK10*AK42 -> 9055.8378
A42: Gross margin % | O42: =O41/O$10 -> 0.6150748 | P42: =P41/P$10 -> 0.58551941 | Q42: =Q41/Q10 -> 0.61783173 | R42: =Interim!EG38 -> 0.62620838 | S42: =+S41/S10 -> 0.60924993 | T42: =T41/T10 -> 0.62188044 | U42: =U41/U10 -> 0.59703208 | V42: =V41/V10 -> 0.617448 | W42: =V42 -> 0.617448 | X42: 0.6292723 | Y42: 0.63084409 | Z42: 0.63397733 | AA42: 0.63503373 | AB42: 0.64637049 | AC42: 0.64637049 | AD42: 0.64637049 | AE42: 0.64637049 | AF42: 0.64637049 | AG42: 0.64637049 | AH42: 0.64637049 | AI42: 0.64637049 | AJ42: 0.64637049 | AK42: 0.64637049
...

Sheet Interim
A1: =TODAY() -> 46294 | B1: 1995 | J1: 1996 | R1: 1997 | Z1: 1998 | AH1: 1999 | AP1: 2000 | AX1: 2001 | BF1: 2002 | BN1: 2003 | BV1: 2004 | CD1: 2005 | CL1: 2006 | CT1: 2007 | DB1: 2008 | DJ1: 2009 | DR1: 2010 | DZ1: 2011 | EH1: 2012 | EP1: 2013 | EX1: 2014 | FF1: 2015 | FN1: 2016 | FV1: 2017 | GD1: 2018E | JD1: 2015 | JK1: 2016
A2: ADIDAS -in EURmn | B2: Q1 95 | C2: Q2 95 | D2: H1 95 | E2: Q3 95 | F2: 9M 95 | G2: Q4 95 | H2: H2 95 | I2: FY 95 | J2: Q1 96 | K2: Q2 96 | L2: H1 96 | M2: Q3 96 | N2: 9M 96 | O2: Q4 96 | P2: H2 96 | Q2: FY 96 | R2: Q1 97 | S2: Q2 97 | T2: H1 97 | U2: Q3 97 | V2: 9M 97 | W2: Q4 97 | X2: H2 97 | Y2: FY 97 | Z2: Q1 98 | AA2: Q2 98 | AB2: H1 98 | AC2: Q3 98 | AD2: 9M 97 | AE2: Q4 98 | AF2: H2 98 | AG2: FY 98 | AH2: Q1 99 | AI2: Q2 99 | AJ2: H1 99 | AK2: Q3 99 | AL2: 9M 99 | AM2: Q4 99 | AN2: H2 99 | AO2: FY 99 | AP2: Q1 00 | AQ2: Q2 00 | AR2: H1 00 | AS2: Q3 00 | AT2: 9M 00 | AU2: Q4 00 | AV2: H2 00 | AW2: FY 00 | AX2: Q1 01 | AY2: Q2 01 | AZ2: H1 01 | BA2: Q3 01 | BB2: 9M 01 | BC2: Q4 01 | BD2: H2 01 | BE2: FY 01 | BF2: Q1 02 | BG2: Q2 02 | BH2: H1 02 | BI2: Q3 02 | BJ2: 9M 02 | BK2: Q4 02 | BL2: H2 02 | BM2: FY 02 | BN2: Q1 03 | BO2: Q2 03 | BP2: H1 03 | BQ2: Q3 03 | BR2: 9M 03 | BS2: Q4 03 | BT2: H2 03 | BU2: FY 03 | BV2: Q1 04 | BW2: Q2 04 | BX2: H1 04 | BY2: Q3 04 | BZ2: 9M 04 | CA2: Q4 04 | CB2: H2 04 | CC2: FY 04 | CD2: Q1 05 | CE2: Q2 05 | CF2: H1 05 | CG2: Q3 05 | CH2: 9M 05 | CI2: Q4 05 | CJ2: H2 05 | CK2: FY 05 | CL2: Q1 06 | CM2: Q2 06 | CN2: H1 06 | CO2: Q3 06 | CP2: 9M 06 | CQ2: Q4 06 | CR2: H2 06 | CS2: FY 06 | CT2: Q1 07 | CU2: Q2 07 | CV2: H1 07 | CW2: Q3 07 | CX2: 9M 07 | CY2: Q4 07 | CZ2: H2 07 | DA2: FY 07 | DB2: Q1 08 | DC2: Q2 08 | DD2: H1 08 | DE2: Q3 08 | DF2: 9M 08 | DG2: Q4 08 | DH2: H2 08 | DI2: FY 08 | DJ2: Q1 09 | DK2: Q2 09 | DL2: H1 09 | DM2: Q3 09 | DN2: 9M 09 | DO2: Q4 09 | DP2: H2 09 | DQ2: FY 09 | DR2: Q1 10 | DS2: Q2 10 | DT2: H1 10 | DU2: Q3 10 | DV2: 9M 10 | DW2: Q4 10 | DX2: H2 10 | DY2: FY 10 | DZ2: Q1 11 | EA2: Q2 11 | EB2: H1 11 | EC2: Q3 11 | ED2: 9M 11 | EE2: Q4 11 | EF2: H2 11 | EG2: FY 11 | EH2: Q1 12 | EI2: Q2 12 | EJ2: H1 12 | EK2: Q3 12 | EL2: 9M 12 | EM2: Q4 12 | EN2: H2 12 | EO2: FY 12 | EP2: 1Q13 | EQ2: 2Q13 | ER2: 1H13 | ES2: 3Q13 | ET2: 9M13 | EU2: 4Q13 | EV2: 2H13 | EW2: FY13 | EX2: 1Q14 | EY2: 2Q14 | EZ2: 1H14 | FA2: 3Q14 | FB2: 9M14 | FC2: 4Q14 | FD2: 2H14 | FE2: FY14 | FF2: 1Q15 | FG2: 2Q15 | FH2: 1H15 | FI2: 3Q15 | FJ2: 9M15 | FK2: 4Q15 | FL2: 2H15 | FM2: FY15 | FN2: 1Q16 | FO2: 2Q16 | FP2: 1H16 | FQ2: 3Q16 | FR2: 9M16 | FS2: 4Q16 | FT2: 2H16 | FU2: FY16 | FV2: 1Q17 | FW2: 2Q17 | FX2: 1H17 | FY2: 3Q17 | FZ2: 9M17 | GA2: 4Q17 | GB2: 2H17 | GC2: FY17 | GD2: 1Q18 | GE2: 2Q18 | GF2: 1H18 | GG2: 3Q18 | GH2: 9M18 | GI2: 4Q18 | GJ2: 2H18 | GK2: FY18 | GL2: 1Q19 | GM2: 2Q19 | GN2: 1H19 | GO2: 3Q19 | GP2: 9M19 | GQ2: 4Q19 | GR2: 2H19 | GS2: FY19 | GT2: 1Q20 | GU2: 2Q20 | GV2: 1H20 | GW2: 3Q20 | GX2: 9M20 | GY2: 4Q20 | GZ2: 2H20 | HA2: FY20 | HB2: 1Q21 | HC2: 2Q21 | HD2: 1H21 | HE2: 3Q21 | HF2: 9M21 | HG2: 4Q21 | HH2: 2H21 | HI2: FY21 | HJ2: 1Q22 | HK2: 2Q22 | HL2: 1H22 | HM2: 3Q22 | HN2: 9M22E | HO2: 4Q22 | HP2: 2H22 | HQ2: FY22 | HR2: 1Q23 | HS2: 2Q23 | HT2: 1H23 | HU2: 3Q23 | HV2: 9M23E | HW2: 4Q23 | HX2: 2H23 | HY2: FY23 | HZ2: 1Q24 | IA2: 2Q24 | IB2: 1H24 | IC2: 3Q24 | ID2: 9M24E | IE2: 4Q24 | IF2: 2H24E | IG2: FY24 | IH2: 1Q25 | II2: 2Q25 | IJ2: 1H25 | IK2: 3Q25 | IL2: 9M25E | IM2: 4Q25 | IN2: 2H25E | IO2: FY25 | IP2: 1Q26 | IQ2: 2Q26 | IR2: 1H25E | IS2: 3Q26E | IT2: 9M25E | IU2: 4Q26E | IV2: 2H25E | IW2: FY26E | JB2: Q3 | JC2: Q4 | JD2: Q1 | JE2: Q2 | JF2: 1H | JG2: Q3 | JH2: 9M | JI2: Q4 | JJ2: 2H | JK2: Q1 | JL2: Q2 | JM2: 1H | JN2: Q3 | JO2: 9M | JP2: Q4
A3: Interim Results | AD3: adidas-Salomon | CE3: =CE2/2 -> #VALUE!
A4: Sales by segment | DB4: =DB$2 -> Q1 08 | DC4: =DC$2 -> Q2 08 | DD4: =DD$2 -> H1 08 | DE4: =DE$2 -> Q3 08 | DF4: =DF$2 -> 9M 08 | DG4: =DG$2 -> Q4 08 | DH4: =DH$2 -> H2 08 | DI4: =DI$2 -> FY 08 | ... GS4: =GS$2 -> FY19 | GT4: 1Q20 | GU4: 2Q20 | GV4: 1H20 | GW4: 3Q20 | GX4: 9M20 | GY4: 4Q20 | GZ4: 2H20 | HA4: FY20 | HB4: 1Q21 | HC4: 2Q21 | HD4: 1H21 | HE4: 3Q21 | HF4: 9M21 | HG4: 4Q21 | HH4: 2H21 | HI4: FY21 | HJ4: 1Q22 | HK4: 2Q22 | HL4: 1H22 | HM4: 3Q22 | HN4: 9M22E | HO4: 4Q22 | HP4: 2H22 | HQ4: FY22 | HR4: 1Q23 | HS4: 2Q23 | HT4: 1H23E | HU4: 3Q23 | HV4: 9M23E | HW4: 4Q23 | HX4: 2H23 | HY4: FY23 | HZ4: 1Q24 | IA4: 2Q24 | IB4: 1H23E | IC4: 3Q24 | ID4: 9M23E | IE4: 4Q24 | IF4: 2H23 | IG4: FY24 | IH4: =IH2 -> 1Q25 | II4: =II2 -> 2Q25 | IJ4: =IJ2 -> 1H25 | IK4: =IK2 -> 3Q25 | IL4: =IL2 -> 9M25E | IM4: =IM2 -> 4Q25 | IN4: =IN2 -> 2H25E | IO4: =IO2 -> FY25 | ... IQ4: =IQ2 -> 2Q26
A5: Wholesale | DB5: 1968 | DC5: 1755 | DD5: =DB5+DC5 -> 3723 | DE5: 2241 | DF5: =DD5+DE5 -> 5964 | DG5: 1794 | DH5: =DE5+DG5 -> 4035 | DI5: ='Profit and Loss'!O5 -> 7758 | DJ5: 1874 | DK5: 1605 | DL5: =DJ5+DK5 -> 3479 | DM5: 2036 | DN5: =DM5+DL5 -> 5515 | DO5: 1650 | DP5: =DO5+DM5 -> 3686 | DQ5: ='Profit and Loss'!P5 -> 7164 | DR5: 1898 | DS5: 1928 | DT5: =DR5+DS5 -> 3826 | DU5: 2421 | DV5: =DT5+DU5 -> 6247 | DW5: =DY5-DV5 -> 1934 | DX5: =DU5+DW5 -> 4355 | DY5: ='Profit and Loss'!Q5 -> 8181 | DZ5: 2320 | EA5: 1973 | EB5: =DZ5+EA5 -> 4293 | EC5: =ED5-EB5 -> 2576 | ED5: 6869 | EE5: 2081 | EF5: =+EG5-EB5 -> 4657 | EG5: =DZ5+EA5+EC5+EE5 -> 8950 | EH5: 2614 | EI5: =+EJ5-EH5 -> 2113 | EJ5: 4727 | EK5: =EL5-EJ5 -> 2743 | EL5: 7470 | EM5: 2063 | EN5: =EK5+EM5 -> 4806 | EO5: =EH5+EI5+EK5+EM5 -> 9533 | EP5: 2481 | EQ5: =ER5-EP5 -> 2014 | ER5: 4495 | ES5: 2553 | ET5: =ER5+ES5 -> 7048 | EU5: 2052 | EV5: =ES5+EU5 -> 4605 | EW5: =EP5+EQ5+ES5+EU5 -> 9100 | EX5: 2357 | EY5: 2085 | EZ5: =EX5+EY5 -> 4442 | FA5: 2717 | FB5: =EZ5+FA5 -> 7159 | FC5: =EU5*(1+FC6) -> 2038.2274 | FD5: =FA5+FC5 -> 4755.2274 | FE5: =EZ5+FD5 -> 9197.2274 | FF5: =FF26-FF21-FF10 -> 2811 | FG5: =FG26-FG21-FG10 -> 2485 | FH5: =FH26-FH21-FH10 -> 5296 | FI5: =FI26-FI21-FI10 -> 3311 | FJ5: =FJ26-FJ21-FJ10 -> 8607 | FK5: =FK26-FK21-FK10 -> 2620 | FL5: =FM5-FH5 -> 5931 | FM5: =FM26-FM21-FM10 -> 11227 | FN5: =FN26-FN21-FN10 -> 3339 | FO5: =FO26-FO21-FO10 -> 2869 | FP5: =FP26-FP21-FP10 -> 6208 | FQ5: =FQ26-FQ21-FQ10 -> 3716 | FR5: =FR26-FR21-FR10 -> 9924 | FS5: =FS26-FS21-FS10 -> 2888 | FT5: =FT26-FT21-FT10 -> 6604 | ... GH5: =GH26-GH21-GH10 -> 11473 | GI5: =GI26-GI10-GI21 -> 3125 | GJ5: =GJ26-GJ21-GJ10 -> 7070 | GK5: =GK26-GK10-GK21 -> 14598 | GL5: =GL26-GL21-GL10 -> 4093 | GM5: =GM26-GM21-GM10 -> 3512 | GN5: =GN26-GN21-GN10 -> 7605 | GO5: =GO26-GO21-GO10 -> 4288 | GP5: =GP26-GP21-GP10 -> 11893 | GQ5: =GQ26-GQ10-GQ21 -> 3329 | GR5: =GR26-GR21-GR10 -> 7617 | GS5: =GS26-GS10-GS21 -> 15222 | GT5: =GT26-GT21-GT10 -> 3002 | GU5: =GU26-GU21-GU10 -> 1675 | GV5: =GV26-GV21-GV10 -> 4677 | GW5: =GW26-GW21-GW10 -> 3707.232 | GY5: =HA5-GW5-GU5-GT5 -> 2852.768 | GZ5: =GZ26-GZ21-GZ10 -> 6560 | HA5: ='Profit and Loss'!AA5 -> 11237 | HB5: =HB26-HB21-HB10 -> 3420 | HC5: =HC26-HC21-HC10 -> 3139 | HD5: =HD26-HD21-HD10 -> 6559 | HE5: =HE26-HE21-HE10 -> 3694 | HG5: =HI5-HE5-HC5-HB5 -> 2543.003 | HH5: =HH26-HH21-HH10 -> 6359 | HI5: ='Profit and Loss'!AB5 -> 12796.003 | HJ5: =HJ26-HJ21-HJ10 -> 3361 | HK5: =HK26-HK21-HK10 -> 3451 | HM5: =HM26-HM21-HM10 -> 4050 | HO5: =HQ5-HM5-HK5-HJ5 -> 2661 | HP5: =HP26-HP21-HP10 -> 6828 | HQ5: ='Profit and Loss'!AC5 -> 13523 | HR5: =HR26-HR21-HR10 -> 3420 | HS5: =HS26-HS21-HS10 -> 2557 | HU5: =HU26-HU21-HU10 -> 3369 | HW5: =HY5-HU5-HS5-HR5 -> 2446 | HX5: =HX26-HX21-HX10 -> 5815 | HY5: ='Profit and Loss'!AD5 -> 11792 | HZ5: =HZ26-HZ21-HZ10 -> 3230 | IA5: =IA26-IA21-IA10 -> 3211 | IC5: =IC26-IC21-IC10 -> 3863 | IE5: =IE26-IE21-IE10 -> 3155 | IG5: =IG26-IG21-IG10 -> 13543 | IH5: =IH26-IH21-IH10 -> 3969 | II5: =II26-II21-II10 -> 3600 | IK5: =IK26-IK21-IK10 -> 4192 | IM5: =IM26-IM21-IM10 -> 3048 | IO5: =IO26-IO21-IO10 -> 14808 | IP5: =IP26-IP21-IP10 -> 4050 | IQ5: =IQ26-IQ21-IQ10 -> 3805
A6: Growth | DJ6: =DJ5/DB5-1 -> -0.047764228 | DK6: =DK5/DC5-1 -> -0.085470085 | DL6: =DL5/DD5-1 -> -0.065538544 | DM6: =DM5/DE5-1 -> -0.091477019 | DN6: =DN5/DF5-1 -> -0.075285044 | DO6: =DO5/DG5-1 -> -0.080267559 | DP6: =DP5/DH5-1 -> -0.086493185 | DQ6: =DQ5/DI5-1 -> -0.076566125 | ... FB6: =FB5/ET5-1 -> 0.015749149 | FC6: =FC7+FC8 -> -0.0067117918 | FD6: =FD5/EV5-1 -> 0.032622672 | FE6: =FE5/EW5-1 -> 0.01068433 | FF6: =FF5/EX5-1 -> 0.19261773 | FG6: =FG5/EY5-1 -> 0.19184652 | FH6: =FH5/EZ5-1 -> 0.19225574 | FI6: =FI5/FA5-1 -> 0.21862348 | FJ6: =FJ5/FB5-1 -> 0.20226289 | FK6: =FK5/FC5-1 -> 0.28543066 | ... GW6: =GW5/GO5-1 -> -0.1354403 | GY6: =GY5/GQ5-1 -> -0.14305557 | GZ6: =GZ5/GR5-1 -> -0.13876854 | HA6: =HA5/GS5-1 -> -0.26179214 | HB6: =HB5/2917-1 -> 0.17243744 | HC6: =HC5/GU5-1 -> 0.87402985 | HD6: =HD5/GV5-1 -> 0.4023947 | HE6: =HE5/GW5-1 -> -0.0035692398 | HG6: =HG5/GY5-1 -> -0.108584 | HH6: =HH5/GZ5-1 -> -0.030640244 | HI6: =HI5/HA5-1 -> 0.13873837 | HJ6: =HJ5/HB5-1 -> -0.017251462 | HK6: =HK5/HC5-1 -> 0.099394712 | HM6: =HM5/HE5-1 -> 0.096372496 | HO6: =HO5/HG5-1 -> 0.046400639 | HP6: =HP5/HH5-1 -> 0.073753735 | HQ6: =HQ5/HI5-1 -> 0.056814379 | HR6: =HR5/HJ5-1 -> 0.017554299 | HS6: =HS5/HK5-1 -> -0.25905535 | HU6: =HU5/HM5-1 -> -0.16814815 | HW6: =HW5/HO5-1 -> -0.080796693 | HX6: =HX5/HP5-1 -> -0.1483597 | HY6: =HY5/HQ5-1 -> -0.12800414 | HZ6: =HZ5/HR5-1 -> -0.055555556 | IA6: =IA5/HS5-1 -> 0.25576848 | IC6: =IC5/HU5-1 -> 0.14663105 | IH6: =IH5/HZ5-1 -> 0.22879257 | II6: =II5/IA5-1 -> 0.12114606 | IK6: =IK5/IC5-1 -> 0.085166969 | IM6: -0.06 | IO6: 0.07 | IP6: =IP5/IH5-1 -> 0.020408163 | IQ6: =IQ5/II5-1 -> 0.056944444
A7: FX & Scope impact | DJ7: =DJ6-DJ8 -> 0.032235772 | DK7: =DK6-DK8 -> 0.044529915 | DL7: =DL6-DL8 -> 0.038031158 | DM7: =DM6-DM8 -> -0.0014770192 | DN7: =DN6-DN8 -> 0.023185781 | DO7: =DO6-DO8 -> -0.040267559 | DP7: =DP6-DP8 -> -0.018723668 | DQ7: =DQ6-DQ8 -> 0.013433875 | ... DW7: =DW6-DW8 -> 0.096121212 | DX7: =((DW7*DO5)+(DU7*DM5))/DP5 -> 0.094450353 | DY7: ='Profit and Loss'!Q7 -> 0.066959799 | DZ7: =DZ6-DZ8 -> 0.042339305 | EA7: =EA6-EA8 -> -0.036659751 | EB7: =EB6-EB8 -> -0.0079404077 | EC7: =EC6-EC8 -> -0.035976869 | ED7: =ED6-ED8 -> -0.020432207 | EE7: =+EE6-EE8 -> -0.013991727 | EF7: =+EF6-EF8 -> -0.023083812 | EG7: =EG6-EG8 -> -0.016001711 | EH7: =+EH6-EH8 -> 0.026724138 | EI7: =+EI6-EI8 -> 0.060957932 | EJ7: =+EJ6-EJ8 -> 0.041094805 | EK7: =EK6-EK8 -> 0.060829193 | EL7: =EL6-EL8 -> 0.048494541 | EM7: =EM6-EM8 -> 0.027350312 | EN7: =+EN6-EN8 -> 0.045869014 | EO7: =+EO6-EO8 -> 0.044232626 | EP7: =EP6-EP8 -> -0.018879878 | EQ7: =EQ6-EQ8 -> -0.036852816 | ER7: =ER6-ER8 -> -0.027079755 | ES7: =ES6-ES8 -> -0.061267226 | ET7: =ET6-ET8 -> -0.039528514 | EU7: =EU6-EU8 -> -0.084332041 | EV7: =EV6-EV8 -> -0.071167915 | EW7: =EW6-EW8 -> -0.049224274 | ... FB7: =FB6-FB8 -> -0.046013763 | FC7: =((EU95*(0.1*FC492)+EU100*FC102+EU105*FC483+EU110*FC112+EU115*FC117+EU120*FC122)/EU127)-(FE842/EW5) -> -0.056711792 | FD7: =FD6-FD8 -> -0.036781237 | FE7: =FE6-FE8 -> -0.04842611 | FF7: =FF6-FF8 -> 0.10728978 | FG7: =FG6-FG8 -> 0.1217689 | FH7: =FH6-FH8 -> 0.11504369 | FI7: =FI6-FI8 -> 0.078377003 | FJ7: =FJ6-FJ8 -> 0.099814275 | FK7: =FK6-FK8 -> 0.14314646 | ... GH7: =GH6-GH8 -> -0.068441891 | GI7: =GI12 -> -0.010189798 | GJ7: =GJ6-GJ8 -> -0.035242553 | GK7: =GK12 -> -0.051358092 | GL7: =GL6-GL8 -> 0.014795133 | GM7: =GM6-GM8 -> 0.0050951157 | GN7: =GN6-GN8 -> 0.010567295 | GO7: =GO6-GO8 -> 0.027649937 | GP7: =GP6-GP8 -> 0.016441175 | GQ7: =GQ12 -> 0.02595339 | GR7: =GR6-GR8 -> 0.018627864 | GS7: =GS12 -> 0.01823927 | GT7: =GT6-GT8 -> -0.0013542634 | GU7: =GU6-GU8 -> -0.0018962642 | GV7: =GV6-GV8 -> -0.0016045602 | GW7: =GW6-GW8 -> -0.038094216 | GY7: =GY6-GY8 -> -0.047954575 | GZ7: =GZ6-GZ8 -> -0.042403673 | HA7: =HA6-HA8 -> -0.025149222 | HB7: =HB6-HB8 -> -0.26695235 | HC7: =HC6-HC8 -> -0.10308095 | HD7: =HD6-HD8 -> -0.2338473 | HE7: =HE6-HE8 -> -0.037240921 | HG7: =HG6-HG8 -> -0.059263094 | HH7: =HH6-HH8 -> -0.028220675 | HI7: =HI6-HI8 -> -0.062311503 | HJ7: =HJ6-HJ8 -> 0.032522358 | HK7: =HK6-HK8 -> 0.064249124 | HM7: =HM6-HM8 -> 0.060837033 | HO7: =HO6-HO8 -> 0.061403374 | HP7: =HP6-HP8 -> 0.059110552 | HQ7: =HQ6-HQ8 -> 0.052578603 | HR7: =HR6-HR8 -> 0.0072691432 | HS7: =HS6-HS8 -> -0.031002318 | HU7: =HU6-HU8 -> -0.01906929 | HW7: =HW6-HW8 -> 0.10403871 | HX7: =HX6-HX8 -> 0.012099645 | HY7: =HY6-HY8 -> 0.032619417 | HZ7: =HZ6-HZ8 -> -0.090091687 | IA7: =IA6-IA8 -> 0.067359406 | IC7: =IC6-IC8 -> 0.016841793 | IH7: =IH6-IH8 -> 0.033613136 | II7: =II6-II8 -> -0.066645905 | IK7: =IK6-IK8 -> -0.021878007 | IM7: =IM6-IM8 -> -0.08 | IO7: =IO6-IO8 -> -0.05 | IP7: =IP6-IP8 -> -0.059591837 | IQ7: =IQ6-IQ8 -> -0.0035027778 | JA7: 2 year | JB7: =(EK5*(1+ES8)*(1+FA8))/EK5-1 -> 0.07632 | JC7: =(EM5*(1+EU8)*(1+FC8))/EM5-1 -> 0.13295 | JD7: =(EP5*(1+EX8)*(1+FF8))/EP5-1 -> 0.091839927 | JE7: =(EQ5*(1+EY8)*(1+FG8))/EQ5-1 -> 0.17815546 | JF7: =(EJ5*(1+ER8)*(1+EZ8))/EJ5-1 -> 0.025496641 | JG7: =(ES5*(1+FA8)*(1+FI8))/ES5-1 -> 0.23716743 | JH7: =(EL5*(1+ET8)*(1+FB8))/EL5-1 -> 0.043751035 | JI7: =(EU5*(1+FC8)*(1+FK8))/EU5-1 -> 0.19939842 | JJ7: =(EN5*(1+EV8)*(1+FD8))/EN5-1 -> 0.10078577 | JK7: =(EX5*(1+FF8)*(1+FN8))/EX5-1 -> 0.33761671 | JL7: =(EY5*(1+FG8)*(1+FO8))/EY5-1 -> 0.31380125 | JM7: =(EZ5*(1+FH8)*(1+FP8))/EZ5-1 -> 0.32524297 | JN7: =(FA5*(1+FI8)*(1+FQ8))/FA5-1 -> 0.32360438 | JO7: =(FB5*(1+FJ8)*(1+FR8))/FB5-1 -> 0.32683795 | JP7: =(FC5*(1+FK8)*(1+FS8))/FC5-1 -> 0.28829995
A8: Currency neutral | DJ8: -0.08 | DK8: -0.13 | DL8: =(DJ8*DB5+DK8*DC5)/DD5 -> -0.1035697 | DM8: -0.09 | DN8: =(DJ8*DB5+DK8*DC5+DM8*DE5)/DF5 -> -0.098470825 | DO8: -0.04 | DP8: =(DM8*DE5+DO8*DG5)/DH5 -> -0.067769517 | DQ8: ='Profit and Loss'!P8 -> -0.09 | DR8: 0.01 | DS8: 0.121 | DT8: 0.06 | DU8: 0.096 | DV8: 0.075 | DW8: 0.076 | DX8: =DX6-DX7 -> 0.087047206 | DY8: =DY6-DY7 -> 0.075 | DZ8: 0.18 | EA8: 0.06 | EB8: 0.13 | EC8: 0.1 | ED8: 0.12 | EE8: 0.09 | EF8: =(-EB8*DT5+EG8*DY5)/DX5 -> 0.092429392 | EG8: 0.11 | EH8: 0.1 | EI8: 0.01 | EJ8: 0.06 | EK8: 0.004 | EL8: 0.039 | EM8: -0.036 | EN8: =+(EK8*EC5+EM8*EE5)/EF5 -> -0.013874168 | EO8: =(EH8*DZ5+EI8*EA5+EK8*EC5+EM8*EE5)/EG5 -> 0.020907039 | EP8: -0.032 | EQ8: -0.01 | ER8: -0.022 | ES8: -0.008 | ET8: =(EH5*EP8+EI5*EQ8+EK5*ES8)/EL5 -> -0.016964123 | EU8: 0.079 | EV8: =(EK5*ES8+EM5*EU8)/EN5 -> 0.029345194 | EW8: =(EH5*EP8+EI5*EQ8+EK5*ES8+EM5*EU8)/EO5 -> 0.003803105 | EX8: 0.006 | EY8: 0.101 | EZ8: =(EP5*EX8+EQ5*EY8)/ER5 -> 0.048565072 | FA8: 0.085 | FB8: =(EP5*EX8+EQ5*EY8+ES5*FA8)/ET5 -> 0.061762911 | FC8: 0.05 | FD8: =(ES5*FA8+EU5*FC8)/EV5 -> 0.069403909 | FE8: =(EP5*EX8+EQ5*EY8+ES5*FA8+EU5*FC8)/EW5 -> 0.05911044 | FF8: =(EX26*FF29-EX10*FF13-EX21*FF24)/EX5 -> 0.085327959 | FG8: =(EY26*FG29-EY10*FG13-EY21*FG24)/EY5 -> 0.070077618 | FH8: =(EZ26*FH29-EZ10*FH13-EZ21*FH24)/EZ5 -> 0.077212051 | FI8: =(FA26*FI29-FA10*FI13-FA21*FI24)/FA5 -> 0.14024648 | FJ8: =(FB26*FJ29-FB10*FJ13-FB21*FJ24)/FB5 -> 0.10244861 | FK8: =(FC26*FK29-FC10*FK13-FC21*FK24)/FC5 -> 0.14228421 | FL8: =(FE5*FM8-EZ5*FH8)/FD5 -> 0.14100559 | FM8: =(FE26*FM29-FE10*FM13-FE21*FM24)/FE5 -> 0.11019512 | FN8: =(FF26*FN29-FF21*FN24-FF10*FN13)/FF5 -> 0.23245393 | FO8: =(FG26*FO29-FG21*FO24-FG10*FO13)/FG5 -> 0.22776258 | FP8: =(FH26*FP29-FH21*FP24-FH10*FP13)/FH5 -> 0.23025264 | FQ8: =(FI26*FQ29-FI21*FQ24-FI10*FQ13)/FI5 -> 0.1608055 | FR8: =(FJ26*FR29-FJ21*FR24-FJ10*FR13)/FJ5 -> 0.20353724 | FS8: =(FK26*FS29-FK21*FS24-FK10*FS13)/FK5 -> 0.12782786 | FT8: =(FL26*FT29-FL21*FT24-FL10*FT13)/FL5 -> 0.14623773 | FU8: =(FM26*FU29-FM21*FU24-FM10*FU13)/FM5 -> 0.18586924 | ... GH8: =(FZ26*GH29-FZ21*GH24-FZ10*GH13)/FZ5 -> 0.074757127 | GI8: =GI6-GI7 -> -0.018106222 | GJ8: =(GB26*GJ29-GB21*GJ24-GB10*GJ13)/GB5 -> 0.0057298559 | GK8: =GK6-GK7 -> 0.050058236 | GL8: =(GD26*GL29-GD21*GL24-GD10*GL13)/GD5 -> 0.0015942389 | GM8: =(GE26*GM29-GE21*GM24-GE10*GM13)/GE5 -> -0.0019531562 | GN8: =(GF26*GN29-GF21*GN24-GF10*GN13)/GF5 -> -0.00033881509 | GO8: =(GG26*GO29-GG21*GO24-GG10*GO13)/GG5 -> 0.059295564 | GP8: =(GH26*GP29-GH21*GP24-GH10*GP13)/GH5 -> 0.020166513 | GQ8: =GQ6-GQ7 -> 0.03932661 | GR8: =(GJ26*GR29-GJ21*GR24-GJ10*GR13)/GJ5 -> 0.058741301 | GS8: =GS6-GS7 -> 0.024506312 | GT8: =(GL26*GT29-GL21*GT24-GL10*GT13)/GL5 -> -0.26519839 | GU8: =(GM26*GU29-GM21*GU24-GM10*GU13)/GM5 -> -0.52116752 | GV8: =(GN26*GV29-GN21*GV24-GN10*GV13)/GN5 -> -0.3834053 | GW8: =(GO26*GW29-GO21*GW24-GO10*GW13)/GO5 -> -0.097346082 | GY8: =(GQ26*GY29-GQ21*GY24-GQ10*GY13)/GQ5 -> -0.095100997 | GZ8: =(GR26*GZ29-GR21*GZ24-GR10*GZ13)/GR5 -> -0.096364871 | HA8: =(GS26*HA29-GS21*HA24-GS10*HA13)/GS5 -> -0.23664292 | HB8: =(4381*HB29-47*HB24-1464*HB13)/2917 -> 0.43938978 | HC8: =(GU26*HC29-GU21*HC24-GU10*HC13)/GU5 -> 0.9771108 | HD8: =(GV26*HD29-GV21*HD24-GV10*HD13)/GV5 -> 0.636242 | HE8: =(GW26*HE29-GW21*HE24-GW10*HE13)/GW5 -> 0.033671681 | HG8: =(GY26*HG29-GY21*HG24-GY10*HG13)/GY5 -> -0.049320908 | HH8: =(GZ26*HH29-GZ21*HH24-GZ10*HH13)/GZ5 -> -0.0024195694 | HI8: =(HA26*HI29-HA21*HI24-HA10*HI13)/HA5 -> 0.20104987 | HJ8: =(4381*HJ29-47*HJ24-1464*HJ13)/2917 -> -0.04977382 | HK8: =(HC26*HK29-HC21*HK24-HC10*HK13)/HC5 -> 0.035145588 | HM8: =(HE26*HM29-HE21*HM24-HE10*HM13)/HE5 -> 0.035535463 | HO8: =(HG26*HO29-HG21*HO24-HG10*HO13)/HG5 -> -0.015002735 | HP8: =(HH26*HP29-HH21*HP24-HH10*HP13)/HH5 -> 0.014643183 | HQ8: =(HI26*HQ29-HI21*HQ24-HI10*HQ13)/HI5 -> 0.0042357758 | HR8: =(4381*HR29-47*HR24-1464*HR13)/2917 -> 0.010285156 | HS8: =(HK26*HS29-HK21*HS24-HK10*HS13)/HK5 -> -0.22805303 | HU8: =(HM26*HU29-HM21*HU24-HM10*HU13)/HM5 -> -0.14907886 | HW8: =(HO26*HW29-HO21*HW24-HO10*HW13)/HO5 -> -0.1848354 | HX8: =(HP26*HX29-HP21*HX24-HP10*HX13)/HP5 -> -0.16045934 | HY8: =(HQ26*HY29-HQ21*HY24-HQ10*HY13)/HQ5 -> -0.16062356 | HZ8: =(4381*HZ29-47*HZ24-1464*HZ13)/2917 -> 0.034536131 | IA8: =(HS26*IA29-HS21*IA24-HS10*IA13)/HS5 -> 0.18840907 | IC8: =(HU26*IC29-HU21*IC24-HU10*IC13)/HU5 -> 0.12978925 | IH8: =(4381*IH29-47*IH24-1464*IH13)/2917 -> 0.19517943 | II8: =(IA26*II29-IA21*II24-IA10*II13)/IA5 -> 0.18779197 | IK8: =(IC26*IK29-IC21*IK24-IC10*IK13)/IC5 -> 0.10704498 | IM8: 0.02 | IO8: 0.12 | IP8: 0.08 | IQ8: =(II26*IQ29-II21*IQ24-II10*IQ13)/II5 -> 0.060447222 | JA8: 3 year | JB8: =(EC5*(1+EK8)*(1+ES8)*(1+FA8))/EC5-1 -> 0.08062528 | JC8: =(EE5*(1+EM8)*(1+EU8)*(1+FC8))/EE5-1 -> 0.0921638 | JD8: =(EH5*(1+EP8)*(1+EX8)*(1+FF8))/EH5-1 -> 0.056901049 | JE8: =(EI5*(1+EQ8)*(1+EY8)*(1+FG8))/EI5-1 -> 0.1663739 | JF8: =(EB5*(1+EJ8)*(1+ER8)*(1+EZ8))/EB5-1 -> 0.087026439 | JG8: =(EK5*(1+ES8)*(1+FA8)*(1+FI8))/EK5-1 -> 0.22727009 | JH8: =(ED5*(1+EL8)*(1+ET8)*(1+FB8))/ED5-1 -> 0.084457325 | JI8: =(EM5*(1+EU8)*(1+FC8)*(1+FK8))/EM5-1 -> 0.29415089 | JJ8: =(EF5*(1+EN8)*(1+EV8)*(1+FD8))/EF5-1 -> 0.085513287 | JK8: =(EP5*(1+EX8)*(1+FF8)*(1+FN8))/EP5-1 -> 0.34564241 | JL8: =(EQ5*(1+EY8)*(1+FG8)*(1+FO8))/EQ5-1 -> 0.44649518 | JM8: =(ER5*(1+EZ8)*(1+FH8)*(1+FP8))/ER5-1 -> 0.38960349 | JN8: =(ES5*(1+FA8)*(1+FI8)*(1+FQ8))/ES5-1 -> 0.43611075 | JO8: =(ET5*(1+FB8)*(1+FJ8)*(1+FR8))/ET5-1 -> 0.40878733 | JP8: =(EU5*(1+FC8)*(1+FK8)*(1+FS8))/EU5-1 -> 0.35271495
A9: % of total | DB9: =DB5/DB$26 -> 0.75315729 | DC9: =DC5/DC$26 -> 0.69809069 | DD9: =DD5/DD$26 -> 0.72615565 | DE9: =DE5/DE$26 -> 0.72783371 | DF9: =DF5/DF$26 -> 0.72678528 | DG9: =DG5/DG$26 -> 0.69642857 | DH9: =DH5/DH$26 -> 0.71352785 | DI9: =DI5/DI$26 -> 0.81560161 | ... GW9: =GW5/GW$26 -> 0.62156805 | GY9: =GY5/GY$26 -> 0.51419468 | GZ9: =GZ5/GZ$26 -> 0.56982269 | HA9: =HA5/HA$26 -> 0.56626688 | HB9: =HB5/HB$26 -> 0.64920273 | HC9: =HC5/HC$26 -> 0.61827851 | HD9: =HD5/HD$26 -> 0.6340261 | HE9: =HE5/HE$26 -> 0.6422114 | HG9: =HG5/HG$26 -> 0.4950366 | HH9: =HH5/HH$26 -> 0.58398384 | HI9: =HI5/HI$26 -> 0.60261858 | HJ9: =HJ5/HJ$26 -> 0.63391173 | HK9: =HK5/HK$26 -> 0.61658031 | HM9: =HM5/HM$26 -> 0.63202247 | HO9: =HO5/HO$26 -> 0.51133743 | HP9: =HP5/HP$26 -> 0.58214682 | HQ9: =HQ5/HQ$26 -> 0.60072853 | HR9: =HR5/HR$26 -> 0.64846416 | HS9: =HS5/HS$26 -> 0.51729719 | HU9: =HU5/HU$26 -> 0.59638874 | HW9: =HW5/HW$26 -> 0.50831255 | HX9: =HX5/HX$26 -> 0.5558742 | HY9: =HY5/HY$26 -> 0.57026792 | HZ9: =HZ5/HZ$26 -> 0.60851545 | IA9: =IA5/IA$26 -> 0.57114906 | IC9: =IC5/IC$26 -> 0.619269 | IH9: =IH5/IH$26 -> 0.64505119 | II9: =II5/II$26 -> 0.60483871 | IK9: =IK5/IK$26 -> 0.63227753 | IM9: =IM5/IM$26 -> 0.50164582 | IO9: =IO5/IO$26 -> 0.59683205 | IP9: =IP5/IP$26 -> 0.61438107 | IQ9: =IQ5/IQ$26 -> 0.56428889
A10: Retail | DB10: 360 | DC10: 423 | DD10: =DB10+DC10 -> 783 | DE10: 491 | DF10: =DD10+DE10 -> 1274 | DG10: 464 | DH10: =DE10+DG10 -> 955 | DI10: ='Profit and Loss'!O10 -> 1738 | DJ10: 400 | DK10: 486 | DL10: =DJ10+DK10 -> 886 | DM10: 524 | DN10: =DM10+DL10 -> 1410 | DO10: 497 | DP10: =DO10+DM10 -> 1021 | DQ10: ='Profit and Loss'!P10 -> 1906 | DR10: 459 | DS10: 602 | DT10: =DR10+DS10 -> 1061 | DU10: 665 | DV10: =DT10+DU10 -> 1726 | DW10: =DY10-DV10 -> 663 | DX10: =DU10+DW10 -> 1328 | DY10: ='Profit and Loss'!Q10 -> 2389 | DZ10: 577 | EA10: 681 | EB10: =DZ10+EA10 -> 1258 | EC10: =ED10-EB10 -> 757 | ED10: 2015 | EE10: =+EF10-EC10 -> 778 | EF10: =+EG10-EB10 -> 1535 | EG10: 2793 | EH10: 693 | EI10: =+EJ10-EH10 -> 854 | EJ10: 1547 | EK10: =EL10-EJ10 -> 944 | EL10: 2491 | EM10: 882 | EN10: =EK10+EM10 -> 1826 | EO10: =EH10+EI10+EK10+EM10 -> 3373 | EP10: 722 | EQ10: =ER10-EP10 -> 867 | ER10: 1589 | ES10: 923 | ET10: =ER10+ES10 -> 2512 | EU10: 934 | EV10: =ES10+EU10 -> 1857 | EW10: =EP10+EQ10+ES10+EU10 -> 3446 | EX10: 794 | EY10: 958 | EZ10: =EX10+EY10 -> 1752 | FA10: 1047 | FB10: =EZ10+FA10 -> 2799 | FC10: =EU10*(1+FC11) -> 1021.5652 | FD10: =FA10+FC10 -> 2068.5652 | FE10: =EZ10+FD10 -> 3820.5652 | FF10: 895 | FG10: =FH10-FF10 -> 1057 | FH10: 1952 | FI10: =FJ10-FH10 -> 1104 | FJ10: 3056 | FK10: =FM10-FJ10 -> 1165 | FL10: =FM10-FH10 -> 2269 | FM10: 4221 | FN10: 1034 | FO10: =FP10-FN10 -> 1177 | FP10: 2211 | FQ10: 1330 | FR10: =FN10+FO10+FQ10 -> 3541 | FS10: =FU10-FN10-FO10-FQ10 -> 1462 | FT10: =FQ10+FS10 -> 2792 | FU10: 5003 | FV10: 1290 | FW10: 1467 | FX10: =FV10+FW10 -> 2757 | FY10: 1417 | FZ10: =FV10+FW10+FY10 -> 4174 | GA10: =GC10-FV10-FW10-FY10 -> 1686 | GB10: =FY10+GA10 -> 3103 | GC10: 5860 | GD10: 1331 | GE10: 1571 | GF10: =GD10+GE10 -> 2902 | GG10: 1698 | GH10: =GD10+GE10+GG10 -> 4600 | GI10: =GK10-GD10-GE10-GG10 -> 1888 | GJ10: =GG10+GI10 -> 3586 | GK10: 6488 | GL10: 1595 | GM10: 1850 | GN10: =GL10+GM10 -> 3445 | GO10: 1960 | GP10: =GL10+GM10+GO10 -> 5405 | GQ10: =GS10-GL10-GM10-GO10 -> 2409 | GR10: =GO10+GQ10 -> 4369 | GS10: 7814 | GT10: 1595 | GU10: 1830 | GV10: =GT10+GU10 -> 3425 | GW10: 2104 | GY10: =HA10-GW10-GU10-GT10 -> 2602 | GZ10: =GW10+GY10 -> 4706 | HA10: ='Profit and Loss'!AA10 -> 8131 | HB10: 1809 | HC10: 1904 | HD10: =HB10+HC10 -> 3713 | HE10: 2014 | HG10: =HI10-HE10-HC10-HB10 -> 2445 | HH10: =HE10+HG10 -> 4459 | HI10: 8172 | HJ10: 1905 | HK10: 2117 | HM10: 2312 | HO10: =HQ10-HM10-HK10-HJ10 -> 2504 | HP10: =HM10+HO10 -> 4816 | HQ10: 8838 | HR10: 1774 | HS10: 2338 | HU10: 2242 | HW10: =HY10-HU10-HS10-HR10 -> 2333 | HX10: =HU10+HW10 -> 4575 | HY10: 8687 | HZ10: 2046 | IA10: 2388 | IC10: 2346 | IE10: =IG10-IC10-IA10-HZ10 -> 2710 | IG10: 9490 | IH10: 2163 | II10: 2338 | IK10: 2417 | IM10: 3012 | IO10: 9931 | IP10: 2480 | IQ10: 2909
A11: Growth | DJ11: =DJ10/DB10-1 -> 0.11111111 | DK11: =DK10/DC10-1 -> 0.14893617 | DL11: =DL10/DD10-1 -> 0.13154534 | DM11: =DM10/DE10-1 -> 0.067209776 | DN11: =DN10/DF10-1 -> 0.10675039 | DO11: =DO10/DG10-1 -> 0.07112069 | DP11: =DP10/DH10-1 -> 0.069109948 | DQ11: =DQ10/DI10-1 -> 0.096662831 | ... EG11: =EG10/DY10-1 -> 0.16910841 | EH11: =+EH10/DZ10-1 -> 0.20103986 | EI11: =EI10/EA10-1 -> 0.25403818 | EJ11: =EJ10/EB10-1 -> 0.22972973 | EK11: =EK10/EC10-1 -> 0.24702774 | EL11: =EL10/ED10-1 -> 0.23622829 | EM11: =EM10/EE10-1 -> 0.13367609 | EN11: =EN10/EF10-1 -> 0.18957655 | EO11: =EO10/EG10-1 -> 0.20766201 | EP11: =EP10/EH10-1 -> 0.041847042 | ... FB11: =FB10/ET10-1 -> 0.11425159 | FC11: =FC12+FC13 -> 0.093752883 | FD11: =FD10/EV10-1 -> 0.11392848 | FE11: =FE10/EW10-1 -> 0.10869564 | FF11: =FF10/EX10-1 -> 0.12720403 | FG11: =FG10/EY10-1 -> 0.10334029 | FH11: =FH10/EZ10-1 -> 0.11415525 | FI11: =FI10/FA10-1 -> 0.054441261 | FJ11: =FJ10/FB10-1 -> 0.091818507 | FK11: =FK10/FC10-1 -> 0.14040691 | ... GC11: =GC10/FU10-1 -> 0.17129722 | GD11: =GD10/1311-1 -> 0.01525553 | GE11: =GE10/1496-1 -> 0.05013369 | GF11: =GF10/(1496+1311)-1 -> 0.033843962 | GG11: =GG10/1444-1 -> 0.17590028 | GH11: =GH10/FZ10-1 -> 0.10206037 | GI11: =GI10/GA10-1 -> 0.1198102 | GJ11: =GJ10/GB10-1 -> 0.15565582 | GK11: =GK12+GK13 -> 0.098334741 | GL11: =GL10/GD10-1 -> 0.19834711 | GM11: =GM10/1496-1 -> 0.23663102 | GN11: =GN10/(1496+1311)-1 -> 0.22728892 | GO11: =GO10/1444-1 -> 0.35734072 | GP11: =GP10/GH10-1 -> 0.175 | GQ11: =GQ10/GI10-1 -> 0.27595339 | GR11: =GR10/GJ10-1 -> 0.21834914 | GS11: =GS12+GS13 -> 0.19510933 | GT11: =GT10/GL10-1 -> 0 | GU11: =GU10/1850-1 -> -0.010810811 | GV11: =GV10/(1595+1850)-1 -> -0.0058055152 | GW11: =GW10/1960-1 -> 0.073469388 | GY11: =GY10/2409-1 -> 0.080116231 | GZ11: =GZ10/GR10-1 -> 0.077134356 | HA11: =HA10/7814-1 -> 0.040568211 | HB11: =HB10/1464-1 -> 0.23565574 | HC11: =HC10/1683-1 -> 0.13131313 | HD11: =HD10/(1464+1683)-1 -> 0.17985383 | HE11: =HE10/1927-1 -> 0.045147898 | HG11: =HG10/2396-1 -> 0.020450751 | HH11: =HH10/GZ10-1 -> -0.052486188 | HI11: =HI10/7471-1 -> 0.093829474 | HJ11: =HJ10/HB10-1 -> 0.053067993 | HK11: =HK10/1683-1 -> 0.25787285 | HM11: =HM10/1927-1 -> 0.19979242 | HO11: =HO10/2396-1 -> 0.045075125 | HP11: =HP10/HH10-1 -> 0.080062794 | HQ11: =HQ10/7471-1 -> 0.18297417 | HR11: =HR10/HJ10-1 -> -0.068766404 | HS11: =HS10/1683-1 -> 0.38918598 | HU11: =HU10/1927-1 -> 0.16346653 | HW11: =HW10/2396-1 -> -0.026293823 | HX11: =HX10/HP10-1 -> -0.050041528 | HY11: =HY10/7471-1 -> 0.16276268 | HZ11: =HZ10/HR10-1 -> 0.15332582 | IA11: =IA10/1683-1 -> 0.41889483 | IC11: =IC10/1927-1 -> 0.21743643 | IH11: =IH10/HZ10-1 -> 0.057184751 | II11: =II10/IA10-1 -> -0.020938023 | IK11: =IK10/IC10-1 -> 0.03026428 | IM11: 0.12 | IO11: 0.1 | IP11: =IP10/IH10-1 -> 0.14655571 | IQ11: =IQ10/II10-1 -> 0.24422583
A12: FX & Scope impact | DJ12: =DJ11-DJ13 -> 0.071111111 | DK12: =DK11-DK13 -> 0.07893617 | DL12: =DL11-DL13 -> 0.075338442 | DM12: =DM11-DM13 -> 0.027209776 | DN12: =DN11-DN13 -> 0.056789639 | DO12: =DO11-DO13 -> -0.06887931 | DP12: =DP11-DP13 -> -0.01947644 | DQ12: =DQ11-DQ13 -> 0.026662831 | ... DW12: =DW11-DW13 -> 0.10800402 | DX12: =((DW12*DO10)+(DU12*DM10))/DP10 -> 0.11112439 | DY12: ='Profit and Loss'!Q12 -> 0.075410283 | DZ12: =DZ11-DZ13 -> 0.03708061 | EA12: =EA11-EA13 -> -0.068770764 | EB12: =EB11-EB13 -> -0.024326107 | EC12: =EC11-EC13 -> -0.071654135 | ED12: =ED11-ED13 -> -0.042560834 | EE12: =+EE11-EE13 -> -0.006546003 | EF12: =+EF11-EF13 -> -0.036137048 | EG12: =EG11-EG13 -> -0.030891586 | EH12: =+EH11-EH13 -> 0.041039861 | EI12: =+EI11-EI13 -> 0.093038179 | EJ12: =+EJ11-EJ13 -> 0.06772973 | EK12: =EK11-EK13 -> 0.10102774 | EL12: =EL11-EL13 -> 0.080228288 | EM12: =EM11-EM13 -> 0.041676093 | EN12: =+EN11-EN13 -> 0.070945928 | EO12: =+EO11-EO13 -> 0.070154314 | EP12: =EP11-EP13 -> -0.023152958 | EQ12: =EQ11-EQ13 -> -0.037777518 | ER12: =ER11-ER13 -> -0.030850679 | ES12: =ES11-ES13 -> -0.078245763 | ET12: =ET11-ET13 -> -0.049044962 | EU12: =EU11-EU13 -> -0.089043084 | EV12: =EV11-EV13 -> -0.083461117 | EW12: =EW11-EW13 -> -0.059504002 | ... FB12: =FB11-FB13 -> -0.096860271 | FC12: =((EU95*(0.1*FC492)+EU100*FC102+EU105*FC483+EU110*FC112+EU115*FC117+EU120*FC122)/EU127)*1.2 -> -0.031247117 | FD12: =FD11-FD13 -> -0.047355308 | FE12: =FE11-FE13 -> -0.079076555 | FF12: =FF11-FF13 -> -0.01279597 | FG12: =FG11-FG13 -> 0.018204593 | FH12: =FH11-FH13 -> 0.0041552511 | FI12: =FI11-FI13 -> -0.035558739 | FJ12: =FJ11-FJ13 -> -0.0081814934 | FK12: =FK11-FK13 -> 0.0030077731 | ... GJ12: =GJ11-GJ13 -> -0.024576217 | GK12: =GK218 -> -0.051358092 | GL12: =GL11-GL13 -> 0.018347107 | GM12: =GM11-GM13 -> 0.076631016 | GN12: =GN11-GN13 -> 0.058115936 | GO12: =GO11-GO13 -> 0.24734072 | GP12: =GP11-GP13 -> 0.027669565 | GQ12: =GQ11-GQ13 -> 0.02595339 | GR12: =GR11-GR13 -> 0.034640268 | GS12: =GS218 -> 0.01823927 | GT12: =GT11-GT13 -> 0.01 | GU12: =GU11-GU13 -> -0.020810811 | GV12: =GV11-GV13 -> -0.0065457184 | GW12: =GW11-GW13 -> -0.056530612 | GY12: =GY11-GY13 -> -0.059883769 | GZ12: =GZ11-GZ13 -> -0.058379492 | HA12: =HA11-HA13 -> -0.029431789 | HB12: =HB11-HB13 -> 0.30965574 | HC12: =HC11-HC13 -> -0.038686869 | HD12: =HD11-HD13 -> 0.12348303 | HE12: =HE11-HE13 -> -0.0048521017 | HG12: =HG11-HG13 -> 0.020450751 | HH12: =HH11-HH13 -> -0.074840629 | HI12: =HI11-HI13 -> -0.016170526 | HJ12: =HJ11-HJ13 -> 0.043067993 | HK12: =HK11-HK13 -> 0.21787285 | HM12: =HM11-HM13 -> 0.13979242 | HO12: =HO11-HO13 -> 0.055075125 | HP12: =HP11-HP13 -> 0.05844584 | HQ12: =HQ11-HQ13 -> 0.16297417 | HR12: =HR11-HR13 -> 0.0012335958 | HS12: =HS11-HS13 -> 0.19918598 | HU12: =HU11-HU13 -> 0.063466528 | HW12: =HW11-HW13 -> -0.11629382 | HX12: =HX11-HX13 -> -0.14484219 | HY12: =HY11-HY13 -> 0.042762682 | HZ12: =HZ11-HZ13 -> 0.043325817 | IA12: =IA11-IA13 -> 0.26889483 | IC12: =IC11-IC13 -> 0.04743643 | IH12: =IH11-IH13 -> -0.072815249 | II12: =II11-II13 -> -0.050938023 | IK12: =IK11-IK13 -> -0.10973572 | IM12: =IM11-IM13 -> -0.07 | IO12: =IO11-IO13 -> -0.04 | IP12: =IP11-IP13 -> -0.07344429 | IQ12: =IQ11-IQ13 -> -0.005774166 | JA12: 2 year | JB12: =(EK10*(1+ES13)*(1+FA13))/EK10-1 -> 0.265088 | JC12: =(EM10*(1+EU13)*(1+FC13))/EM10-1 -> 0.2915 | JD12: =(EP10*(1+EX13)*(1+FF13))/EP10-1 -> 0.38624 | JE12: =(EQ10*(1+EY13)*(1+FG13))/EQ10-1 -> 0.32495069 | JF12: =(EJ10*(1+ER13)*(1+EZ13))/EJ10-1 -> 0.28941436 | JG12: =(ES10*(1+FA13)*(1+FI13))/ES10-1 -> 0.30582 | JH12: =(EL10*(1+ET13)*(1+FB13))/EL10-1 -> 0.28072089 | JI12: =(EU10*(1+FC13)*(1+FK13))/EU10-1 -> 0.27957402 | JJ12: =(EN10*(1+EV13)*(1+FD13))/EN10-1 -> 0.27792095 | JK12: =(EX10*(1+FF13)*(1+FN13))/EX10-1 -> 0.3908 | JL12: =(EY10*(1+FG13)*(1+FO13))/EY10-1 -> 0.30382596 | JM12: =(EZ10*(1+FH13)*(1+FP13))/EZ10-1 -> 0.3431 | JN12: =(FA10*(1+FI13)*(1+FQ13))/FA10-1 -> 0.34907246 | JO12: =(FB10*(1+FJ13)*(1+FR13))/FB10-1 -> 0.342 | JP12: =(FC10*(1+FK13)*(1+FS13))/FC10-1 -> 0.42883691
A13: Currency neutral | DJ13: 0.04 | DK13: 0.07 | DL13: =(DJ13*DB10+DK13*DC10)/DD10 -> 0.056206897 | DM13: 0.04 | DN13: =(DJ13*DB10+DK13*DC10+DM13*DE10)/DF10 -> 0.049960754 | DO13: 0.14 | DP13: =(DM13*DE10+DO13*DG10)/DH10 -> 0.088586387 | DQ13: ='Profit and Loss'!P13 -> 0.07 | DR13: 0.16 | DS13: 0.167 | DT13: 0.16 | DU13: 0.155 | DV13: 0.161 | DW13: 0.226 | DX13: =DX11-DX12 -> 0.18956121 | DY13: =DY11-DY12 -> 0.178 | DZ13: 0.22 | EA13: 0.2 | EB13: 0.21 | EC13: 0.21 | ED13: 0.21 | EE13: 0.18 | EF13: =(-EB13*DT10+EG13*DY10)/DX10 -> 0.19201054 | EG13: 0.2 | EH13: 0.16 | EI13: 0.161 | EJ13: 0.162 | EK13: 0.146 | EL13: 0.156 | EM13: 0.092 | EN13: =+(EK13*EC10+EM13*EE10)/EF10 -> 0.11863062 | EO13: =(EH13*DZ10+EI13*EA10+EK13*EC10+EM13*EE10)/EG10 -> 0.1375077 | EP13: 0.065 | EQ13: 0.053 | ER13: 0.058 | ES13: 0.056 | ET13: =(EH10*EP13+EI10*EQ13+EK10*ES13)/EL10 -> 0.057475311 | EU13: 0.148 | EV13: =(EK10*ES13+EM10*EU13)/EN10 -> 0.10043812 | EW13: =(EH10*EP13+EI10*EQ13+EK10*ES13+EM10*EU13)/EO10 -> 0.081146457 | EX13: 0.216 | EY13: 0.221 | EZ13: =(EP10*EX13+EQ10*EY13)/ER10 -> 0.21872813 | FA13: 0.198 | FB13: =(EP10*EX13+EQ10*EY13+ES10*FA13)/ET10 -> 0.21111186 | FC13: 0.125 | FD13: =(ES10*FA13+EU10*FC13)/EV10 -> 0.16128379 | FE13: =(EP10*EX13+EQ10*EY13+ES10*FA13+EU10*FC13)/EW10 -> 0.1877722 | FF13: 0.14 | FG13: =(EZ10*FH13-EX10*FF13)/EY10 -> 0.085135699 | FH13: 0.11 | FI13: 0.09 | FJ13: 0.1 | FK13: =(FE10*FM13-FB10*FJ13)/FC10 -> 0.13739913 | FL13: =(FE10*FM13-EZ10*FH13)/FD10 -> 0.11 | FM13: 0.11 | FN13: 0.22 | FO13: =(FH10*FP13-FF10*FN13)/FG10 -> 0.20153264 | FP13: 0.21 | FQ13: =(FJ10*FR13-FH10*FP13)/FI10 -> 0.23768116 | FR13: 0.22 | FS13: =(FM10*FU13-FJ10*FR13)/FK10 -> 0.25623176 | FT13: =(FI10*FQ13+FK10*FS13)/FL10 -> 0.24720582 | FU13: 0.23 | FV13: 0.18 | FW13: 0.21 | FX13: =(FN10*FV13+FO10*FW13)/FP10 -> 0.19597015 | FY13: =(FR10*FZ13-FP10*FX13)/FQ10 -> 0.09 | FZ13: 0.15616775 | GA13: 0.21 | GB13: =(FQ10*FY13+FS10*GA13)/FT10 -> 0.15283668 | GC13: =(FN10*FV13+FO10*FW13+FQ10*FY13+FS10*GA13)/FU10 -> 0.17189886 | GD13: 0.11 | GE13: 0.12 | GF13: =(FV10*GD13+FW10*GE13)/FX10 -> 0.115321 | GG13: 0.24 | GH13: =(FX10*GF13+FY10*GG13)/FZ10 -> 0.15764734 | GI13: 0.13 | GJ13: =(FY10*GG13+GA10*GI13)/GB10 -> 0.18023203 | GK13: =((GJ13*$GB$10)+(GF13*$FX$10))/$GC$10 -> 0.14969283 | GL13: 0.18 | GM13: 0.16 | GN13: =(GD10*GL13+GE10*GM13)/GF10 -> 0.16917298 | GO13: 0.11 | GP13: =(GF10*GN13+GG10*GO13)/GH10 -> 0.14733043 | GQ13: 0.25 | GR13: =(GG10*GO13+GI10*GQ13)/GJ10 -> 0.18370887 | GS13: =((GR13*$GB$10)+(GN13*$FX$10))/$GC$10 -> 0.17687006 | GT13: -0.01 | GU13: 0.01 | GV13: =(GL10*GT13+GM10*GU13)/GN10 -> 0.00074020319 | GW13: 0.13 | GY13: 0.14 | GZ13: =(GO10*GW13+GQ10*GY13)/GR10 -> 0.13551385 | HA13: 0.07 | HB13: -0.074 | HC13: 0.17 | HD13: =(GT10*HB13+GU10*HC13)/GV10 -> 0.056370803 | HE13: 0.05 | HG13: 0 | HH13: =(GW10*HE13+GY10*HG13)/GZ10 -> 0.022354441 | HI13: 0.11 | HJ13: 0.01 | HK13: 0.04 | HM13: 0.06 | HO13: -0.01 | HP13: =(HE10*HM13+HG10*HO13)/HH10 -> 0.021616954 | HQ13: 0.02 | HR13: -0.07 | HS13: 0.19 | HU13: 0.1 | HW13: 0.09 | HX13: =(HM10*HU13+HO10*HW13)/HP10 -> 0.094800664 | HY13: 0.12 | HZ13: 0.11 | IA13: 0.15 | IC13: 0.17 | IH13: 0.13 | II13: 0.03 | IK13: 0.14 | IM13: 0.19 | IO13: 0.14 | IP13: 0.22 | IQ13: 0.25 | JA13: 3 year | JB13: =(EC10*(1+EK13)*(1+ES13)*(1+FA13))/EC10-1 -> 0.44979085 | JC13: =(EE10*(1+EM13)*(1+EU13)*(1+FC13))/EE10-1 -> 0.410318 | JD13: =(EH10*(1+EP13)*(1+EX13)*(1+FF13))/EH10-1 -> 0.4763456 | JE13: =(EI10*(1+EQ13)*(1+EY13)*(1+FG13))/EI10-1 -> 0.39517308 | JF13: =(EB10*(1+EJ13)*(1+ER13)*(1+EZ13))/EB10-1 -> 0.49829949 | JG13: =(EK10*(1+ES13)*(1+FA13)*(1+FI13))/EK10-1 -> 0.37894592 | JH13: =(ED10*(1+EL13)*(1+ET13)*(1+FB13))/ED10-1 -> 0.48051335 | JI13: =(EM10*(1+EU13)*(1+FC13)*(1+FK13))/EM10-1 -> 0.46895098 | JJ13: =(EF10*(1+EN13)*(1+EV13)*(1+FD13))/EF10-1 -> 0.4295215 | JK13: =(EP10*(1+EX13)*(1+FF13)*(1+FN13))/EP10-1 -> 0.6912128 | JL13: =(EQ10*(1+EY13)*(1+FG13)*(1+FO13))/EQ10-1 -> 0.5919715 | JM13: =(ER10*(1+EZ13)*(1+FH13)*(1+FP13))/ER10-1 -> 0.63687375 | JN13: =(ES10*(1+FA13)*(1+FI13)*(1+FQ13))/ES10-1 -> 0.61618881 | JO13: =(ET10*(1+FB13)*(1+FJ13)*(1+FR13))/ET10-1 -> 0.62531212 | JP13: =(EU10*(1+FC13)*(1+FK13)*(1+FS13))/EU10-1 -> 0.60744153
A14: Store contribution implied | DR14: =DR13-DR16-DR15 -> 0.09 | DS14: =DS13-DS16-DS15 -> 0.078769547 | DT14: =DT13-DT16-DT15 -> 0.08 | DU14: =DU13-DU16-DU15 -> 0.048091603 | DV14: =DV13-DV16-DV15 -> 0.071 | DW14: =DW13-DW16-DW15 -> 0.076 | DX14: =DX13-DX16-DX15 -> 0.053635651 | DY14: =DY13-DY16-DY15 -> 0.068 | ... GJ14: =GJ13-GJ16-GJ15 -> 0.040181487 | GK14: =((GJ14*$GB$10)+(GF14*$FX$10))/$GC$10 -> 0.019905945 | GL14: =GL13-GL16-GL15 -> -0.0018866884 | GM14: =GM13-GM16-GM15 -> -0.0027451868 | GN14: =GN13-GN16-GN15 -> -0.0023514372 | GO14: =GO13-GO16-GO15 -> 0.0073396591 | GP14: =GP13-GP16-GP15 -> -0.0099400392 | GQ14: =GQ13-GQ16-GQ15 -> 0.059830308 | GR14: =GR13-GR16-GR15 -> 0.034975561 | GS14: =((GR14*$GB$10)+(GN14*$FX$10))/$GC$10 -> 0.017414037 | GT14: =GT13-GT16-GT15 -> 0.19060978 | GU14: =GU13-GU16-GU15 -> -0.11723686 | GV14: =GV13-GV16-GV15 -> 0.049369165 | GW14: =GW13-GW16-GW15 -> 0.0960314 | GY14: =GY13-GY16-GY15 -> 0.043320592 | GZ14: =GZ13-GZ16-GZ15 -> 0.083924984 | HA14: =HA13-HA16-HA15 -> 0.099209102 | HB14: =HB13-HB16-HB15 -> -0.56598742 | HC14: =HC13-HC16-HC15 -> 0.40901916 | HD14: =HD13-HD16-HD15 -> -0.021416508 | HE14: =HE13-HE16-HE15 -> 0.01056048 | HG14: =HG13-HG16-HG15 -> 0.0098598799 | HH14: =HH13-HH16-HH15 -> 0.014825232 | HI14: =HI13-HI16-HI15 -> 0.09028024 | HJ14: =HJ13-HJ16-HJ15 -> 0.00081674775 | HK14: =HK13-HK16-HK15 -> -0.01969114 | HM14: =HM13-HM16-HM15 -> 0.02056048 | HO14: =HO13-HO16-HO15 -> 0.0097197599 | HP14: =HP13-HP16-HP15 -> 0.017289827 | HQ14: =HQ13-HQ16-HQ15 -> 0.00028024015 | HR14: =HR13-HR16-HR15 -> 0.035607401 | HS14: =HS13-HS16-HS15 -> 0.12571723 | HU14: =HU13-HU16-HU15 -> 0.09507006 | HW14: =HW13-HW16-HW15 -> 0.14915928 | HX14: =HX13-HX16-HX15 -> 0.11234972 | HY14: =HY13-HY16-HY15 -> 0.1446497 | HZ14: =HZ13-HZ16-HZ15 -> -0.046115288 | IA14: =IA13-IA16-IA15 -> 0.17754976 | IC14: =IC13-IC16-IC15 -> 0.18478982 | IH14: =IH13-IH16-IH15 -> 0.04735073 | II14: =II13-II16-II15 -> 0.043774878 | IK14: =IK13-IK16-IK15 -> 0.066050901 | IM14: =IM13-IM16-IM15 -> 0.086471261 | IO14: =IO13-IO16-IO15 -> 0.061120961 | IP14: =IP13-IP16-IP15 -> 0.10520935 | IQ14: =IQ13-IQ16-IQ15 -> 0.12602609
