Workbook
Name A_ALL_KEYWORDS_TYPE_ScalarContributed_EQTY_200021488: #REF!,#REF!,#REF!
Name A_ALL_ONON: #REF!
Name A_ALL_SECTION_KEYWORDS_EQTY_200021488_13A: #REF!
Name A_ALL_YOUG.DE: [1]YOUG.DE_Annotation_Sheet!$A$1:$U$346
Name E_ALL_GFG.DE: [2]GFG.DE_Exchange_Sheet!$A$1:$U$346
Name E_ALL_ONON: #REF!
Name E_ALL_YOUG.DE: [1]YOUG.DE_Exchange_Sheet!$A$1:$U$346
Name IQ_CH: 110000
Name IQ_CQ: 5000
Name IQ_CY: 10000
Name IQ_DAILY: 500000
Name IQ_FH: 100000
Name IQ_FQ: 500
Name IQ_FY: 1000
Name IQ_LTM: 2000
Name IQ_MONTH: 15000
Name IQ_NTM: 6000
Name IQ_WEEK: 50000
Name IQ_YTD: 3000
Name L_ALL_GFG.DE: [2]GFG.DE_Live_Sheet!$A$1:$U$346
Name L_ALL_KEYWORDS_TYPE_ScalarContributed_EQTY_200021488: #REF!,#REF!,#REF!
Name L_ALL_ONON: #REF!
Name L_ALL_SECTION_KEYWORDS_EQTY_200021488_13A: #REF!
Name L_ALL_YOUG.DE: [1]YOUG.DE_Live_Sheet!$A$1:$U$346
Name V_ALL_GFG.DE: [2]GFG.DE_Validation_Sheet!$A$1:$U$346
Name V_ALL_KEYWORDS_TYPE_ScalarContributed_EQTY_200021488: #REF!,#REF!,#REF!
Name V_ALL_KEYWORDS_TYPE_ScalarContributed_ISSR_208001535: ITX.MC_Validation_Sheet!$9:$9,ITX.MC_Validation_Sheet!$42:$42
Name V_ALL_KEYWORDS_TYPE_ScalarReference_ISSR_208001535: ITX.MC_Validation_Sheet!$6:$7
Name V_ALL_ONON: #REF!
Name V_ALL_PERIODS_ITX.MC: ITX.MC_Validation_Sheet!$F$1:$DL$1
Name V_ALL_SECTION_KEYWORDS_EQTY_200021488_13A: #REF!
Name V_ALL_SECTION_KEYWORDS_ISSR_208001535_1314: ITX.MC_Validation_Sheet!$C$44:$C$73
Name V_ALL_SECTION_KEYWORDS_ISSR_208001535_13168: ITX.MC_Validation_Sheet!$C$131:$C$188
Name V_ALL_SECTION_KEYWORDS_ISSR_208001535_1316S: ITX.MC_Validation_Sheet!$C$190:$C$198
Name V_ALL_SECTION_KEYWORDS_ISSR_208001535_1316T: ITX.MC_Validation_Sheet!$C$200:$C$225
Name V_ALL_SECTION_KEYWORDS_ISSR_208001535_1319: ITX.MC_Validation_Sheet!$C$75:$C$92
Name V_ALL_SECTION_KEYWORDS_ISSR_208001535_131E: ITX.MC_Validation_Sheet!$C$94:$C$111
Name V_ALL_SECTION_KEYWORDS_ISSR_208001535_131J: ITX.MC_Validation_Sheet!$C$113:$C$125
Name V_ALL_SECTION_KEYWORDS_ISSR_208001535_131O: ITX.MC_Validation_Sheet!$C$127
Name V_ALL_SECTION_KEYWORDS_ISSR_208001535_131P: ITX.MC_Validation_Sheet!$C$129
Name V_ALL_SECTION_KEYWORDS_ISSR_208001535_13A: ITX.MC_Validation_Sheet!$C$9
Name V_ALL_SECTION_KEYWORDS_ISSR_208001535_13U: ITX.MC_Validation_Sheet!$C$11:$C$29
Name V_ALL_SECTION_KEYWORDS_ISSR_208001535_13V: ITX.MC_Validation_Sheet!$C$31:$C$42
Name V_ALL_SECTION_KEYWORDS_ISSR_208001535_Reference_Data: ITX.MC_Validation_Sheet!$C$6:$C$7
Name V_ALL_YOUG.DE: [1]YOUG.DE_Validation_Sheet!$A$1:$U$346
Name V_CURRENCY_ISSR_208001535_REP: ITX.MC_Validation_Sheet!$E$7
Name V_ENTITY_DATA_ISSR_208001535: ITX.MC_Validation_Sheet!$E$5:$DL$284
Name V_KEYWORD_ISSR_208001535_ACC_AMORT: ITX.MC_Validation_Sheet!$53:$53
Name V_KEYWORD_ISSR_208001535_ACC_DDA: ITX.MC_Validation_Sheet!$50:$50
Name V_KEYWORD_ISSR_208001535_ACC_END_DATE: ITX.MC_Validation_Sheet!$3:$3
Name V_KEYWORD_ISSR_208001535_ACC_PAY_GQ: ITX.MC_Validation_Sheet!$59:$59
Name V_KEYWORD_ISSR_208001535_ACQ: ITX.MC_Validation_Sheet!$100:$100
Name V_KEYWORD_ISSR_208001535_ADJ_UNF_PENS_GOOD: ITX.MC_Validation_Sheet!$88:$88
Name V_KEYWORD_ISSR_208001535_ASSOC_JV_ADDBK: ITX.MC_Validation_Sheet!$113:$113
Name V_KEYWORD_ISSR_208001535_ASSOCIATE: ITX.MC_Validation_Sheet!$26:$26
Name V_KEYWORD_ISSR_208001535_ASSOCIATE_OP: ITX.MC_Validation_Sheet!$37:$37
Name V_KEYWORD_ISSR_208001535_BAL_MINO_INT: ITX.MC_Validation_Sheet!$91:$91
Name V_KEYWORD_ISSR_208001535_CAP_LEASES: ITX.MC_Validation_Sheet!$80:$80
Name V_KEYWORD_ISSR_208001535_CAPEX: ITX.MC_Validation_Sheet!$99:$99
Name V_KEYWORD_ISSR_208001535_CAPEX_EXPANSION: ITX.MC_Validation_Sheet!$123:$123

Sheet Cover Sheet
D4: On Holding Model
D5: European General Retail
B13: Team:
B15: Richard Edwards
B16: Managing Director
B17: Richard.Edwards@gs.com
B18: +44 (20) 7051-6016
B20: Ben Williams
B21: Analyst
B22: ben.williams@gs.com
B23: +44 (20) 7051-0661
B25: Hamish Bogdan
B26: Analyst
B27: hamish.bogdan@gs.com
B28: +44 (20) 7552-2214

Sheet ITX.MC_Validation_Sheet

Sheet MODEL
AT1: =AT153/MODEL!AT153-1 -> 0 | AU1: =AU153/MODEL!AU153-1 -> 0 | AV1: =AV153/MODEL!AV153-1 -> 0 | AW1: =AW153/MODEL!AW153-1 -> 0 | AX1: =AX153/MODEL!AX153-1 -> 0 | AY1: =AY153/MODEL!AY153-1 -> 0
B2: Dec year end (CHFmn) | C2: 1Q19 | D2: 2Q19 | E2: 3Q19 | F2: 4Q19 | G2: 2019 | H2: 1Q20 | I2: 2Q20 | J2: 1H20 | K2: 3Q20 | L2: 4Q20 | M2: 2H20 | N2: 2020 | O2: 1Q21 | P2: 2Q21 | Q2: 1H21 | R2: 3Q21 | S2: 4Q21 | T2: 2H21 | U2: =Valuation!C48 -> 2021 | V2: 1Q22 | W2: 2Q22 | X2: 3Q22 | Y2: 4Q22 | Z2: =Valuation!D48 -> 2022 | AA2: 1Q23 | AB2: 2Q23 | AC2: 3Q23 | AD2: 4Q23 | AE2: =Valuation!E48 -> 2023 | AF2: 1Q24 | AG2: 2Q24 | AH2: 3Q24 | AI2: 4Q24 | AJ2: =Valuation!F48 -> 2024 | AK2: 1Q25 | AL2: 2Q25 | AM2: 3Q25 | AN2: 4Q25 | AO2: =Valuation!G48 -> 2025 | AP2: 1Q26 | AQ2: 2Q26 | AR2: 3Q26E | AS2: 4Q26E | AT2: =Valuation!H48 -> 2026E | AU2: =Valuation!I48 -> 2027E | AV2: =Valuation!J48 -> 2028E | AW2: =Valuation!K48 -> 2029E | AX2: =Valuation!L48 -> 2030E | AY2: =Valuation!M48 -> 2031E
B3: Sales by region
B4: Europe | C4: 24.409314 | D4: 36.582871 | E4: 32.461653 | F4: 34.890102 | G4: 128.34394 | H4: 33.749016 | I4: 47.995953 | J4: =I4+H4 -> 81.74497 | K4: 58.767857 | L4: 46.997419 | M4: =L4+K4 -> 105.76528 | N4: 187.51024 | O4: =H4*(1+O7) -> 57.1 | P4: =I4*(1+P7) -> 70.8 | Q4: =P4+O4 -> 127.9 | R4: =K4*(1+R7) -> 88.3 | S4: =L4*(1+S7) -> 44.2 | T4: =S4+R4 -> 132.5 | U4: =T4+Q4 -> 260.4 | V4: =O4*(1+V7) -> 74.9 | W4: =P4*(1+W7) -> 83.293 | X4: =R4*(1+X7) -> 116.468 | Y4: =S4*(1+Y7) -> 79.639 | Z4: =SUM(V4:Y4) -> 354.3 | AA4: =V4*(1+AA7) -> 118.9 | AB4: =W4*(1+AB7) -> 113.6 | AC4: =X4*(1+AC7) -> 144 | AD4: =AE4-SUM(AA4:AC4) -> 112.2 | AE4: =Z4*(1+AE7) -> 488.7 | AF4: =AA4*(1+AF7) -> 126.2 | AG4: =AB4*(1+AG7) -> 138.4 | AH4: =AC4*(1+AH7) -> 165.8 | AI4: 147.4 | AJ4: =AE4*(1+AJ7) -> 577.8 | AK4: =AF4*(1+AK7) -> 168.6032 | AL4: =AG4*(1+AL7) -> 197.7736 | AM4: =AH4*(1+AM7) -> 213.3 | AN4: =AO4-SUM(AK4:AM4) -> 183.0232 | AO4: =AJ4*(1+AO7) -> 762.7 | AP4: =AK4*(1+AP7) -> 207.1 | AQ4: =AL4*(1+AQ7) -> 228.2 | AR4: =AM4*(1+AR7) -> 240.75012 | AS4: =AT4-SUM(AP4:AR4) -> 221.22491 | AT4: =AO4*(1+AT7) -> 897.27503 | AU4: =AT4*(1+AU7) -> 1054.132 | AV4: =AU4*(1+AV7) -> 1191.1691 | AW4: =AV4*(1+AW7) -> 1334.1094 | AX4: =AW4*(1+AX7) -> 1467.5204 | AY4: =AX4*(1+AY7) -> 1584.922
B5: - cFX growth | O5: =((1+O7)/(1+O6))-1 -> 0.79553474 | P5: =((1+P7)/(1+P6))-1 -> 0.55104458 | Q5: =((1+Q7)/(1+Q6))-1 -> 0.65143558 | R5: =((1+R7)/(1+R6))-1 -> 0.5259871 | S5: =((1+S7)/(1+S6))-1 -> -0.10047028 | T5: =((1+T7)/(1+T6))-1 -> 0.23830651 | U5: =((1+U7)/(1+U6))-1 -> 0.41177435 | V5: =((1+V7)/(1+V6))-1 -> 0.24073235 | ... AB5: =((1+AB7)/(1+AB6))-1 -> 0.35788118 | AC5: 0.24 | AD5: =((1+AD7)/(1+AD6))-1 -> 0.26001273 | AE5: =((1+AE7)/(1+AE6))-1 -> 0.35032983 | AF5: =((1+AF7)/(1+AF6))-1 -> 0.10396081 | AG5: =((1+AG7)/(1+AG6))-1 -> 0.22197579 | AH5: =((1+AH7)/(1+AH6))-1 -> 0.15196487 | AI5: =((1+AI7)/(1+AI6))-1 -> 0.33105282 | AJ5: =((1+AJ7)/(1+AJ6))-1 -> 0.19939817 | AK5: =((1+AK7)/(1+AK6))-1 -> 0.33000156 | ... AO5: =((1+AO7)/(1+AO6))-1 -> 0.34728225 | AP5: 0.256 | AQ5: 0.205 | AR5: 0.13 | AS5: =((1+AS7)/(1+AS6))-1 -> 0.19489595 | AT5: 0.19 | AU5: 0.17 | AV5: 0.16 | AW5: 0.15 | AX5: 0.12 | AY5: 0.1
B6: - ccy/other | O6: =FX!M8*0.9 -> -0.057717391 | P6: =FX!N8*0.9 -> -0.0489478 | Q6: =((O6*H4)+(P6*I4))/J4 -> -0.052568391 | R6: =FX!O8*0.9 -> -0.015376966 | S6: =FX!P8*0.9 -> 0.045520972 | T6: =((R6*K4)+(S6*L4))/M4 -> 0.011683389 | U6: =((O6*H4)+(P6*I4)+(R6*K4)+(S6*L4))/N4 -> -0.016327133 | V6: =FX!R8*0.9 -> 0.057225434 | W6: =FX!S8*0.9 -> 0.061957157 | X6: =FX!T8*0.9 -> 0.068651489 | Y6: =FX!U8*0.9 -> 0.032566372 | Z6: =((V6*O4)+(W6*P4)+(X6*R4)+(Y6*S4))/U4 -> 0.058200841 | AA6: =FX!W8*0.9 -> 0.0342 | AB6: =FX!X8*0.9 -> 0.0044031311 | AC6: =(((1+0.199)-(1+AC5))) -> -0.041 | AD6: 0.11812956 | AE6: 0.021483425 | AF6: -0.038556333 | AG6: -0.003 | AH6: -0.0005 | AI6: -0.013017761 | AJ6: -0.014238579 | AK6: 0.0045100995 | AL6: -0.022169349 | AM6: -0.032696436 | AN6: -0.026 | AO6: -0.020244702 | AP6: -0.022031996 | AQ6: -0.042452616 | AR6: =FX!AN8 -> -0.0013074337 | AS6: =FX!AO8 -> 0.011574292 | AT6: =AVERAGE(AP6:AS6) -> -0.013554438 | AU6: =FX!AQ8/3 -> 0.00481478 | AV6: =FX!AR8/3 -> 0 | AW6: =FX!AS8/3 -> 0 | AX6: =FX!AT8/3 -> 0 | AY6: =FX!AU8/3 -> 0
B7: - total growth | H7: =H4/C4-1 -> 0.38262863 | I7: =I4/D4-1 -> 0.31197885 | K7: =K4/E4-1 -> 0.81037784 | L7: =L4/F4-1 -> 0.34701295 | N7: =N4/G4-1 -> 0.46099805 | O7: 0.69190116 | P7: 0.47512436 | Q7: =Q4/J4-1 -> 0.56462227 | R7: 0.50252205 | S7: -0.059522815 | T7: =T4/M4-1 -> 0.25277412 | U7: =U4/N4-1 -> 0.38872412 | V7: 0.3117338 | W7: 0.1764548 | X7: 0.3190034 | Y7: 0.80178733 | Z7: =Z4/U4-1 -> 0.36059908 | AA7: 0.58744993 | AB7: 0.36386011 | AC7: 0.23639111 | AD7: =AD4/Y4-1 -> 0.40885747 | AE7: 0.37933954 | AF7: 0.061396131 | AG7: 0.21830986 | AH7: 0.15138889 | AI7: =AI4/AD4-1 -> 0.31372549 | AJ7: 0.18232044 | AK7: 0.336 | AL7: 0.429 | AM7: 0.28648975 | AN7: =AN4/AI4-1 -> 0.24167707 | AO7: 0.32000692 | AP7: =((1+AP6)*(1+AP5))-1 -> 0.22832781 | AQ7: =((1+AQ6)*(1+AQ5))-1 -> 0.1538446 | AR7: =AR6+AR5 -> 0.12869257 | AS7: =AS4/AN4-1 -> 0.20872603 | AT7: =AT6+AT5 -> 0.17644556 | AU7: =AU6+AU5 -> 0.17481478 | AV7: 0.13 | AW7: 0.12 | AX7: 0.1 | AY7: 0.08
B8: Group sales mix | C8: =C4/C$31 -> 0.49241786 | D8: =D4/D$31 -> 0.52502893 | E8: =E4/E$31 -> 0.49886749 | F8: =F4/F$31 -> 0.42137244 | G8: =G4/G$31 -> 0.48047308 | H8: =H4/H$31 -> 0.47340569 | I8: =I4/I$31 -> 0.48175237 | J8: =J4/J$31 -> 0.47827097 | ... AY8: =AY4/AY$31 -> 0.22126781
B9: Europe DTC % | N9: =(N4-N94)/N4 -> 0.3258395 | U9: =(U4-U94)/U4 -> 0.31696742 | Z9: =(Z4-Z94)/Z4 -> 0.36746903 | AE9: =(AE4-AE94)/AE4 -> 0.47034559 | AJ9: =(AJ4-AJ94)/AJ4 -> 0.48938733 | AO9: =(AO4-AO94)/AO4 -> 0.55321626 | AT9: =(AT4-AT94)/AT4 -> 0.57753911 | AU9: =(AU4-AU94)/AU4 -> 0.59998334 | AV9: =(AV4-AV94)/AV4 -> 0.61715219 | AW9: =(AW4-AW94)/AW4 -> 0.63031259 | AX9: =(AX4-AX94)/AX4 -> 0.64345329 | AY9: =(AY4-AY94)/AY4 -> 0.64975889
B10: - total growth yo2y | O10: =(1*(1+H7)*(1+O7))-1 -> 1.339271 | P10: =(1*(1+I7)*(1+P7))-1 -> 0.93533197 | R10: =(1*(1+K7)*(1+R7))-1 -> 1.7201326 | S10: =(1*(1+L7)*(1+S7))-1 -> 0.26683494 | U10: =(1*(1+N7)*(1+U7))-1 -> 1.0289232 | V10: =(1*(1+O7)*(1+V7))-1 -> 1.2193239 | W10: =(1*(1+P7)*(1+W7))-1 -> 0.73541714 | X10: =(1*(1+R7)*(1+X7))-1 -> 0.98183168 | Y10: =(1*(1+S7)*(1+Y7))-1 -> 0.69453988 | Z10: =(1*(1+U7)*(1+Z7))-1 -> 0.88949676 | AA10: =(1*(1+T7)*(1+AA7))-1 -> 0.9887162 | AB10: =(1*(1+U7)*(1+AB7))-1 -> 0.89402543 | AC10: =(1*(1+W7)*(1+AC7))-1 -> 0.45455826 | AD10: =(1*(1+X7)*(1+AD7))-1 -> 0.85828779 | AE10: =(1*(1+Z7)*(1+AE7))-1 -> 0.87672811 | AF10: =(1*(1+Y7)*(1+AF7))-1 -> 0.9124101 | AG10: =(1*(1+Z7)*(1+AG7))-1 -> 0.65763127 | AH10: =(1*(1+AB7)*(1+AH7))-1 -> 0.57033337 | AI10: =(1*(1+AC7)*(1+AI7))-1 -> 0.62427852 | AJ10: =(1*(1+AE7)*(1+AJ7))-1 -> 0.63082134 | AK10: =(1*(1+AD7)*(1+AK7))-1 -> 0.88223358 | AL10: =(1*(1+AE7)*(1+AL7))-1 -> 0.97107621 | AM10: =(1*(1+AG7)*(1+AM7))-1 -> 0.56734314 | AN10: =(1*(1+AH7)*(1+AN7))-1 -> 0.42965318 | AO10: =(1*(1+AJ7)*(1+AO7))-1 -> 0.56067117 | AP10: =(1*(1+AI7)*(1+AP7))-1 -> 0.61368556 | AQ10: =(1*(1+AJ7)*(1+AQ7))-1 -> 0.36421406 | AR10: =(1*(1+AL7)*(1+AR7))-1 -> 0.61290168 | AS10: =(1*(1+AM7)*(1+AS7))-1 -> 0.55501364 | AT10: =(1*(1+AO7)*(1+AT7))-1 -> 0.55291629 | AU10: =(1*(1+AT7)*(1+AU7))-1 -> 0.38210563 | AV10: =(1*(1+AU7)*(1+AV7))-1 -> 0.3275407 | AW10: =(1*(1+AV7)*(1+AW7))-1 -> 0.2656 | AX10: =(1*(1+AW7)*(1+AX7))-1 -> 0.232 | AY10: =(1*(1+AX7)*(1+AY7))-1 -> 0.188
B11: North America/Americas (from FY22) | C11: ='[3]Net Sales Breakdown'!C28/1000000 -> 20.919437 | D11: ='[3]Net Sales Breakdown'!D28/1000000 -> 26.762032 | E11: ='[3]Net Sales Breakdown'!E28/1000000 -> 26.174527 | F11: ='[3]Net Sales Breakdown'!F28/1000000 -> 37.905004 | G11: =SUM(C11:F11) -> 111.761 | H11: ='[3]Net Sales Breakdown'!H28/1000000 -> 33.124064 | I11: ='[3]Net Sales Breakdown'!I28/1000000 -> 46.872629 | J11: =I11+H11 -> 79.996693 | K11: ='[3]Net Sales Breakdown'!J28/1000000 -> 61.427927 | L11: ='[3]Net Sales Breakdown'!K28/1000000 -> 66.66438 | M11: =L11+K11 -> 128.09231 | N11: =M11+J11 -> 208.089 | O11: =H11*(1+O14) -> 74.2 | P11: =I11*(1+P14) -> 89.7 | Q11: =P11+O11 -> 163.9 | R11: =K11*(1+R14) -> 112.2 | S11: =L11*(1+S14) -> 133.4 | T11: =S11+R11 -> 245.6 | U11: =T11+Q11 -> 409.5 | V11: =O11*(1+V14) -> 138.4 | W11: =P11*(1+W14) -> 181.673 | X11: =R11*(1+X14) -> 176.26 | Y11: =S11*(1+Y14) -> 242.167 | Z11: =SUM(V11:Y11) -> 738.5 | AA11: =V11*(1+AA14) -> 270.2 | AB11: =W11*(1+AB14) -> 296.6 | AC11: =X11*(1+AC14) -> 294.9 | AD11: =AE11-SUM(AA11:AC11) -> 300.6 | AE11: =Z11*(1+AE14) -> 1162.3 | AF11: =AA11*(1+AF14) -> 329.6 | AG11: =AB11*(1+AG14) -> 370.1 | AH11: =AC11*(1+AH14) -> 395.5 | AI11: 385.1 | AJ11: =AE11*(1+AJ14) -> 1480.3 | AK11: =AF11*(1+AK14) -> 437.3792 | AL11: =AG11*(1+AL14) -> 432.2768 | AM11: =AH11*(1+AM14) -> 436.2 | AN11: =AO11-SUM(AK11:AM11) -> 434.344 | AO11: =AJ11*(1+AO14)+0.1 -> 1740.2 | AP11: =AK11*(1+AP14) -> 450.8 | AQ11: =AL11*(1+AQ14) -> 451.6 | AR11: =AM11*(1+AR14) -> 451.71351 | AS11: =AT11-SUM(AP11:AR11) -> 473.99707 | AT11: =AO11*(1+AT14) -> 1828.1106 | AU11: =AT11*(1+AU14) -> 1999.9317 | AV11: =AU11*(1+AV14) -> 2159.9262 | AW11: =AV11*(1+AW14) -> 2332.7203 | AX11: =AW11*(1+AX14) -> 2519.3379 | AY11: =AX11*(1+AY14) -> 2670.4982
B12: - cFX growth | O12: =((1+O14)/(1+O13))-1 -> 1.3963821 | P12: =((1+P14)/(1+P13))-1 -> 1.0243151 | Q12: =((1+Q14)/(1+Q13))-1 -> 1.1773605 | R12: =((1+R14)/(1+R13))-1 -> 0.82955457 | S12: =((1+S14)/(1+S13))-1 -> 0.96058094 | T12: =((1+T14)/(1+T13))-1 -> 0.89846813 | U12: =((1+U14)/(1+U13))-1 -> 1.0010547 | V12: =((1+V14)/(1+V13))-1 -> 0.82658463 | ... AB12: =((1+AB14)/(1+AB13))-1 -> 0.75326886 | AC12: 0.75 | AD12: =((1+AD14)/(1+AD13))-1 -> 0.29038576 | AE12: =((1+AE14)/(1+AE13))-1 -> 0.61047066 | AF12: =((1+AF14)/(1+AF13))-1 -> 0.30369422 | AG12: =((1+AG14)/(1+AG13))-1 -> 0.25800184 | AH12: =((1+AH14)/(1+AH13))-1 -> 0.34516809 | AI12: =((1+AI14)/(1+AI13))-1 -> 0.33892697 | AJ12: =((1+AJ14)/(1+AJ13))-1 -> 0.31234783 | AK12: =((1+AK14)/(1+AK13))-1 -> 0.28684312 | ... AO12: =((1+AO14)/(1+AO13))-1 -> 0.23390534 | AP12: 0.171 | AQ12: 0.13 | AR12: 0.08 | AS12: =((1+AS14)/(1+AS13))-1 -> 0.089315885 | AT12: 0.11 | AU12: 0.09 | AV12: =((1+AV14)/(1+AV13))-1 -> 0.08 | AW12: =((1+AW14)/(1+AW13))-1 -> 0.08 | AX12: =((1+AX14)/(1+AX13))-1 -> 0.08 | AY12: =((1+AY14)/(1+AY13))-1 -> 0.06
B13: - ccy/other | O13: =FX!M9 -> -0.065231159 | P13: =FX!N9 -> -0.054644809 | Q13: =((O13*H11)+(P13*I11))/J11 -> -0.059028277 | R13: =FX!O9 -> -0.0016527408 | S13: =FX!P9 -> 0.020650871 | T13: =((R13*K11)+(S13*L11))/M11 -> 0.0099549544 | U13: =((O13*H11)+(P13*I11)+(R13*K11)+(S13*L11))/N11 -> -0.016564614 | V13: =FX!R9 -> 0.021156689 | W13: =FX!S9 -> 0.059436511 | X13: =FX!T9 -> 0.052880897 | Y13: =FX!U9 -> 0.043984601 | Z13: =((V13*O11)+(W13*P11)+(X13*R11)+(Y13*S11))/U11 -> 0.045670485 | AA13: =FX!W9 -> -0.00018474044 | AB13: =FX!X9 -> -0.068823001 | AC13: =(((1+0.605)-(1+AC12))) -> -0.145 | AD13: -0.038045674 | AE13: -0.022729201 | AF13: -0.064322647 | AG13: -0.0081028025 | AH13: -0.003 | AI13: -0.043185713 | AJ13: -0.029529042 | AK13: 0.031205727 | AL13: -0.054891334 | AM13: -0.087849468 | AN13: -0.070095643 | AO13: -0.047329704 | AP13: -0.11982529 | AQ13: -0.075485851 | AR13: =FX!AN9-(FX!$AM$9-MODEL!$AQ$13) -> -0.044434869 | AS13: =FX!AO9-(FX!$AM$9-MODEL!$AQ$13) -> 0.0018160639 | AT13: =AVERAGE(AP13:AS13) -> -0.059482486 | AU13: =FX!AQ9-(FX!$AM$9-MODEL!$AQ$13) -> 0.0039883579 | AV13: =FX!AR9 -> 0 | AW13: =FX!AS9 -> 0 | AX13: =FX!AT9 -> 0 | AY13: =FX!AU9 -> 0
B14: - total growth | H14: =H11/C11-1 -> 0.58341085 | I14: =I11/D11-1 -> 0.75146004 | K14: =K11/E11-1 -> 1.3468591 | L14: =L11/F11-1 -> 0.7587224 | N14: =N11/G11-1 -> 0.86191068 | O14: 1.2400633 | P14: 0.9136968 | Q14: =Q11/J11-1 -> 1.0488347 | R14: 0.82653079 | S14: 1.0010686 | T14: =T11/M11-1 -> 0.9173673 | U14: =U11/N11-1 -> 0.96790796 | V14: 0.86522911 | W14: 1.02534 | X14: 0.57094474 | Y14: 0.81534483 | Z14: =Z11/U11-1 -> 0.8034188 | AA14: 0.95231214 | AB14: 0.63260363 | AC14: 0.67309656 | AD14: =AD11/Y11-1 -> 0.24129217 | AE14: 0.57386594 | AF14: 0.21983716 | AG14: 0.2478085 | AH14: 0.34113259 | AI14: =AI11/AD11-1 -> 0.28110446 | AJ14: 0.27359546 | AK14: 0.327 | AL14: 0.168 | AM14: 0.10290771 | AN14: =AN11/AI11-1 -> 0.12787328 | AO14: 0.17550497 | AP14: =((1+AP13)*(1+AP12))-1 -> 0.030684587 | AQ14: =((1+AQ13)*(1+AQ12))-1 -> 0.044700988 | AR14: =AR13+AR12 -> 0.035565131 | AS14: =AS11/AN11-1 -> 0.091294152 | AT14: =AT13+AT12 -> 0.050517514 | AU14: =AU13+AU12 -> 0.093988358 | AV14: 0.08 | AW14: 0.08 | AX14: 0.08 | AY14: 0.06
B15: Group sales mix | C15: =C11/C$31 -> 0.42201532 | D15: =D11/D$31 -> 0.38408251 | E15: =E11/E$31 -> 0.40224756 | F15: =F11/F$31 -> 0.45778382 | G15: =G11/G$31 -> 0.41839258 | H15: =H11/H$31 -> 0.46463933 | I15: =I11/I$31 -> 0.47047717 | J15: =J11/J$31 -> 0.4680422 | ... AY15: =AY11/AY$31 -> 0.37282295
B16: North America DTC % | N16: =(N11-N99)/N11 -> 0.44595822 | U16: =(U11-U99)/U11 -> 0.39467139 | Z16: =(Z11-Z99)/Z11 -> 0.29878688 | AE16: =(AE11-AE99)/AE11 -> 0.30153199 | AJ16: =(AJ11-AJ99)/AJ11 -> 0.31457002 | AO16: =(AO11-AO99)/AO11 -> 0.23820069 | AT16: =(AT11-AT99)/AT11 -> 0.22257124 | AU16: =(AU11-AU99)/AU11 -> 0.18812305 | AV16: =(AV11-AV99)/AV11 -> 0.15684509 | AW16: =(AW11-AW99)/AW11 -> 0.12296712 | AX16: =(AX11-AX99)/AX11 -> 0.074206711 | AY16: =(AY11-AY99)/AY11 -> 0.037982343
B17: - total growth yo2y | O17: =(1*(1+H14)*(1+O14))-1 -> 2.5469405 | P17: =(1*(1+I14)*(1+P14))-1 -> 2.3517635 | R17: =(1*(1+K14)*(1+R14))-1 -> 3.2866104 | S17: =(1*(1+L14)*(1+S14))-1 -> 2.5193242 | U17: =(1*(1+N14)*(1+U14))-1 -> 2.6640689 | V17: =(1*(1+O14)*(1+V14))-1 -> 3.1782313 | W17: =(1*(1+P14)*(1+W14))-1 -> 2.8758867 | X17: =(1*(1+R14)*(1+X14))-1 -> 1.8693789 | Y17: =(1*(1+S14)*(1+Y14))-1 -> 2.6326296 | Z17: =(1*(1+U14)*(1+Z14))-1 -> 2.5489622 | AA17: =(1*(1+T14)*(1+AA14))-1 -> 2.7432994 | AB17: =(1*(1+U14)*(1+AB14))-1 -> 2.2128137 | AC17: =(1*(1+W14)*(1+AC14))-1 -> 2.3885894 | AD17: =(1*(1+X14)*(1+AD14))-1 -> 0.9500014 | AE17: =(1*(1+Z14)*(1+AE14))-1 -> 1.8383394 | AF17: =(1*(1+Y14)*(1+AF14))-1 -> 1.2144251 | AG17: =(1*(1+Z14)*(1+AG14))-1 -> 1.2503213 | AH17: =(1*(1+AB14)*(1+AH14))-1 -> 1.1895379 | AI17: =(1*(1+AC14)*(1+AI14))-1 -> 1.1434115 | AJ17: =(1*(1+AE14)*(1+AJ14))-1 -> 1.0044685 | AK17: =(1*(1+AD14)*(1+AK14))-1 -> 0.6471947 | AL17: =(1*(1+AE14)*(1+AL14))-1 -> 0.83827542 | AM17: =(1*(1+AG14)*(1+AM14))-1 -> 0.37621761 | AN17: =(1*(1+AH14)*(1+AN14))-1 -> 0.51262761 | AO17: =(1*(1+AJ14)*(1+AO14))-1 -> 0.49711778 | AP17: =(1*(1+AI14)*(1+AP14))-1 -> 0.32041462 | AQ17: =(1*(1+AJ14)*(1+AQ14))-1 -> 0.33052643 | AR17: =(1*(1+AL14)*(1+AR14))-1 -> 0.20954007 | AS17: =(1*(1+AM14)*(1+AS14))-1 -> 0.20359674 | AT17: =(1*(1+AO14)*(1+AT14))-1 -> 0.23488855 | AU17: =(1*(1+AT14)*(1+AU14))-1 -> 0.14925393 | AV17: =(1*(1+AU14)*(1+AV14))-1 -> 0.18150743 | AW17: =(1*(1+AV14)*(1+AW14))-1 -> 0.1664 | AX17: =(1*(1+AW14)*(1+AX14))-1 -> 0.1664 | AY17: =(1*(1+AX14)*(1+AY14))-1 -> 0.1448
B18: APAC | C18: 2.8521384 | D18: 4.164982 | E18: 4.3005595 | F18: 6.54932 | G18: 17.867 | H18: 3.3503464 | I18: 4.1559842 | J18: =I18+H18 -> 7.5063307 | K18: 7.6383264 | L18: 7.8543429 | M18: =L18+K18 -> 15.492669 | N18: 22.999 | O18: =H18*(1+O21) -> 7.3 | P18: =I18*(1+P21) -> 11.7 | Q18: =P18+O18 -> 19 | R18: =K18*(1+R21) -> 13.1 | S18: =L18*(1+S21) -> 10.6 | T18: =S18+R18 -> 23.7 | U18: =T18+Q18 -> 42.7 | V18: =O18*(1+V21) -> 16.4 | W18: =P18*(1+W21) -> 17.916 | X18: =R18*(1+X21) -> 24.246 | Y18: =S18*(1+Y21) -> 21.638 | Z18: =SUM(V18:Y18) -> 80.2 | AA18: =V18*(1+AA21) -> 31.1 | AB18: =W18*(1+AB21) -> 34.1 | AC18: =X18*(1+AC21) -> 41.6 | AD18: =AE18-SUM(AA18:AC18) -> 34.3 | AE18: =Z18*(1+AE21) -> 141.1 | AF18: =AA18*(1+AF21) -> 52.4 | AG18: =AB18*(1+AG21) -> 59.2 | AH18: =AC18*(1+AH21) -> 74.5 | AI18: 74.1 | AJ18: =AE18*(1+AJ21) -> 260.2 | AK18: =AF18*(1+AK21) -> 120.5724 | AL18: =AG18*(1+AL21) -> 119.1696 | AM18: =AH18*(1+AM21) -> 144.9 | AN18: =AO18-SUM(AK18:AM18) -> 126.458 | AO18: =AJ18*(1+AO21) -> 511.1 | AP18: =AK18*(1+AP21) -> 174 | AQ18: =AL18*(1+AQ21) -> 170.5 | AR18: =AM18*(1+AR21) -> 224.595 | AS18: =AT18-SUM(AP18:AR18) -> 207.64518 | AT18: =AO18*(1+AT21) -> 776.74018 | AU18: =AT18*(1+AU21) -> 1104.4606 | AV18: =AU18*(1+AV21) -> 1491.0218 | AW18: =AV18*(1+AW21) -> 1938.3283 | AX18: =AW18*(1+AX21) -> 2422.9104 | AY18: =AX18*(1+AY21) -> 2907.4925
B19: - cFX growth | O19: =((1+O21)/(1+O20))-1 -> 1.1589669 | P19: =((1+P21)/(1+P20))-1 -> 1.711177 | Q19: =((1+Q21)/(1+Q20))-1 -> 1.4685854 | R19: =((1+R21)/(1+R20))-1 -> 0.60670534 | S19: =((1+S21)/(1+S20))-1 -> 0.27957491 | T19: =((1+T21)/(1+T20))-1 -> 0.44183985 | U19: =((1+U21)/(1+U20))-1 -> 0.76928465 | V19: =((1+V21)/(1+V20))-1 -> 1.1594562 | ... AB19: =((1+AB21)/(1+AB20))-1 -> 1.1660207 | AC19: 0.96 | AD19: =((1+AD21)/(1+AD20))-1 -> 0.75997911 | AE19: =((1+AE21)/(1+AE20))-1 -> 0.95998543 | AF19: =((1+AF21)/(1+AF20))-1 -> 0.90698767 | AG19: =((1+AG21)/(1+AG20))-1 -> 0.84702112 | AH19: 0.857 | AI19: =((1+AI21)/(1+AI20))-1 -> 1.2459238 | AJ19: =((1+AJ21)/(1+AJ20))-1 -> 0.95473813 | AK19: =((1+AK21)/(1+AK20))-1 -> 1.2889435 | AL19: =((1+AL21)/(1+AL20))-1 -> 1.1088607 | AM19: =((1+AM21)/(1+AM20))-1 -> 1.0915192 | AN19: =((1+AN21)/(1+AN20))-1 -> 0.8505592 | AO19: =((1+AO21)/(1+AO20))-1 -> 1.0668113 | AP19: 0.614 | AQ19: 0.547 | AR19: 0.5 | AS19: =((1+AS21)/(1+AS20))-1 -> 0.56381814 | AT19: 0.54 | AU19: 0.4 | AV19: 0.35 | AW19: 0.3 | AX19: 0.25 | AY19: 0.2
B20: - ccy/other | O20: =FX!M10 -> 0.0092230296 | P20: =FX!N10 -> 0.038374718 | Q20: =((O20*H18)+(P20*I18))/J18 -> 0.025363267 | R20: =FX!O10 -> 0.067423705 | S20: =FX!P10 -> 0.05470327 | T20: =((R20*K18)+(S20*L18))/M18 -> 0.060974806 | U20: =((O20*H18)+(P20*I18)+(R20*K18)+(S20*L18))/N18 -> 0.04935204 | V20: =FX!R10 -> 0.040343098 | W20: =FX!S10 -> 0.032152842 | X20: =FX!T10 -> -0.0074389247 | Y20: =FX!U10 -> -0.061488498 | Z20: =((V20*O18)+(W20*P18)+(X20*R18)+(Y20*S18))/U18 -> -0.00183923 | AA20: =FX!W10 -> -0.07547043 | AB20: =FX!X10 -> -0.12127959 | AC20: =(((1+0.715)-(1+AC19))) -> -0.245 | AD20: -0.099322134 | AE20: -0.10236495 | AF20: -0.11646652 | AG20: -0.060070097 | AH20: -0.034549929 | AI20: -0.0381019 | AJ20: -0.056609076 | AK20: 0.0052672751 | AL20: -0.045456168 | AM20: -0.07007 | AN20: -0.0778 | AO20: -0.049618951 | AP20: -0.10587588 | AQ20: -0.075155777 | AR20: 0.05 | AS20: 0.05 | AT20: =AVERAGE(AP20:AS20) -> -0.020257913 | AU20: =FX!AQ10/2 -> 0.021917665 | AV20: =FX!AR10 -> 0 | AW20: =FX!AS10 -> 0 | AX20: =FX!AT10 -> 0 | AY20: =FX!AU10 -> 0
B21: - total growth | H21: =H18/C18-1 -> 0.17467876 | I21: =I18/D18-1 -> -0.0021603479 | K21: =K18/E18-1 -> 0.77612387 | L21: =L18/F18-1 -> 0.19926082 | N21: =N18/G18-1 -> 0.28723345 | O21: 1.1788791 | P21: 1.8152176 | Q21: =Q18/J18-1 -> 1.5311968 | R21: 0.71503537 | S21: 0.34957184 | T21: =T18/M18-1 -> 0.52975575 | U21: =U18/N18-1 -> 0.85660246 | V21: 1.2465753 | W21: 0.53128205 | X21: 0.85083969 | Y21: 1.0413208 | Z21: =Z18/U18-1 -> 0.87822014 | AA21: 0.89634146 | AB21: 0.90332664 | AC21: 0.71574693 | AD21: =AD18/Y18-1 -> 0.58517423 | AE21: 0.75935162 | AF21: 0.68488746 | AG21: 0.73607038 | AH21: 0.79086538 | AI21: =AI18/AD18-1 -> 1.1603499 | AJ21: 0.84408221 | AK21: 1.301 | AL21: 1.013 | AM21: 0.94496644 | AN21: =AN18/AI18-1 -> 0.7065857 | AO21: 0.96425826 | AP21: =((1+AP20)*(1+AP19))-1 -> 0.44311634 | AQ21: =((1+AQ20)*(1+AQ19))-1 -> 0.43073401 | AR21: =AR20+AR19 -> 0.55 | AS21: =AS18/AN18-1 -> 0.64200905 | AT21: =AT20+AT19 -> 0.51974209 | AU21: =AU20+AU19 -> 0.42191766 | AV21: =AV20+AV19 -> 0.35 | AW21: =AW20+AW19 -> 0.3 | AX21: =AX20+AX19 -> 0.25 | AY21: =AY20+AY19 -> 0.2
B22: Group sales mix | C22: =C18/C$31 -> 0.057537213 | D22: =D18/D$31 -> 0.059774862 | E22: =E18/E$31 -> 0.066090576 | F22: =F18/F$31 -> 0.079097016 | G22: =G18/G$31 -> 0.066887556 | H22: =H18/H$31 -> 0.046996127 | I22: =I18/I$31 -> 0.041715085 | J22: =J18/J$31 -> 0.04391781 | ... AD22: =AD18/AD$31 -> 0.076716618 | AE22: 0.05 | AF22: =AF18/AF$31 -> 0.10310901 | AG22: =AG18/AG$31 -> 0.10428043 | AH22: =AH18/AH$31 -> 0.11717521 | AI22: =AI18/AI$31 -> 0.12215628 | AJ22: =AJ18/AJ$31 -> 0.11223742 | AK22: =AK18/AK$31 -> 0.16595087 | AL22: =AL18/AL$31 -> 0.15905822 | AM22: =AM18/AM$31 -> 0.18240181 | ... AY22: =AY18/AY$31 -> 0.40590925
B23: APAC DTC % | N23: =(N18-N104)/N18 -> 0.3500587 | U23: =(U18-U104)/U18 -> 0.45301522 | Z23: =(Z18-Z104)/Z18 -> 0.56298767 | AE23: =(AE18-AE104)/AE18 -> 0.64827414 | AJ23: =(AJ18-AJ104)/AJ18 -> 0.74701768 | AO23: =(AO18-AO104)/AO18 -> 0.82967152 | AT23: =(AT18-AT104)/AT18 -> 0.85177787 | AU23: =(AU18-AU104)/AU18 -> 0.86813512 | AV23: =(AV18-AV104)/AV18 -> 0.87643773 | AW23: =(AW18-AW104)/AW18 -> 0.8797644 | AX23: =(AX18-AX104)/AX18 -> 0.88361194 | AY23: =(AY18-AY104)/AY18 -> 0.88264204
B24: - total growth yo2y | O24: =(1*(1+H21)*(1+O21))-1 -> 1.559483 | P24: =(1*(1+I21)*(1+P21))-1 -> 1.8091358 | R24: =(1*(1+K21)*(1+R21))-1 -> 2.0461153 | S24: =(1*(1+L21)*(1+S21))-1 -> 0.61848864 | U24: =(1*(1+N21)*(1+U21))-1 -> 1.3898808 | V24: =(1*(1+O21)*(1+V21))-1 -> 3.8950162 | W24: =(1*(1+P21)*(1+W21))-1 -> 3.3108922 | X24: =(1*(1+R21)*(1+X21))-1 -> 2.1742555 | Y24: =(1*(1+S21)*(1+Y21))-1 -> 1.754909 | Z24: =(1*(1+U21)*(1+Z21))-1 -> 2.4871081 | AA24: =(1*(1+T21)*(1+AA21))-1 -> 1.9009393 | AB24: =(1*(1+U21)*(1+AB21))-1 -> 2.5337209 | AC24: =(1*(1+W21)*(1+AC21))-1 -> 1.6272925 | AD24: =(1*(1+X21)*(1+AD21))-1 -> 1.9339034 | AE24: =(1*(1+Z21)*(1+AE21))-1 -> 2.3044496 | AJ24: =(1*(1+AE21)*(1+AJ21))-1 -> 2.244389 | AO24: =(1*(1+AJ21)*(1+AO21))-1 -> 2.6222537 | AT24: =(1*(1+AO21)*(1+AT21))-1 -> 1.985166 | AU24: =(1*(1+AT21)*(1+AU21))-1 -> 1.1609481 | AV24: =(1*(1+AU21)*(1+AV21))-1 -> 0.91958885 | AW24: =(1*(1+AV21)*(1+AW21))-1 -> 0.755 | AX24: =(1*(1+AW21)*(1+AX21))-1 -> 0.625 | AY24: =(1*(1+AX21)*(1+AY21))-1 -> 0.5
B25: Rest of the World | C25: 1.3894368 | D25: 2.1679348 | E25: 2.133953 | F25: 3.4566754 | G25: 9.148 | H25: 1.0664144 | I25: 0.6032842 | J25: =I25+H25 -> 1.6696986 | K25: 2.2432334 | L25: 2.784068 | M25: =L25+K25 -> 5.0273014 | N25: 6.697 | O25: =H25*(1+O28) -> 1.8 | P25: =I25*(1+P28) -> 2.9 | Q25: =P25+O25 -> 4.7 | R25: =K25*(1+R28) -> 4.4 | S25: =L25*(1+S28) -> 2.9 | T25: =S25+R25 -> 7.3 | U25: =T25+Q25 -> 12 | V25: =O25*(1+V28) -> 6 | W25: =P25*(1+W28) -> 8.78 | X25: =R25*(1+X28) -> 11.039 | Y25: =S25*(1+Y28) -> 23.281 | Z25: =SUM(V25:Y25) -> 49.1
B26: - cFX growth | AO26: =AO18-AJ18 -> 250.9 | AT26: =AT18-AO18 -> 265.64018 | AU26: =AU18-AT18 -> 327.7204 | AV26: =AV18-AU18 -> 386.5612 | AW26: =AW18-AV18 -> 447.30654 | AX26: =AX18-AW18 -> 484.58208 | AY26: =AY18-AX18 -> 484.58208
B27: - ccy
B28: - total growth | H28: =H25/C25-1 -> -0.23248439 | I28: =I25/D25-1 -> -0.72172402 | K28: =K25/E25-1 -> 0.051210313 | L28: =L25/F25-1 -> -0.19458217 | N28: =N25/G25-1 -> -0.26792742 | O28: 0.68789912 | P28: 3.8070213 | Q28: =Q25/J25-1 -> 1.8148792 | R28: 0.9614544 | S28: 0.041641232 | T28: =T25/M25-1 -> 0.45207129 | U28: =U25/N25-1 -> 0.7918471 | V28: 2.3333333 | W28: 2.0275862 | X28: 1.5088636 | Y28: 7.027931 | Z28: =Z25/U25-1 -> 3.0916667
B29: Sales mix | C29: =C25/C$31 -> 0.028029608 | D29: =D25/D$31 -> 0.031113701 | E29: =E25/E$31 -> 0.03279438 | F29: =F25/F$31 -> 0.041746732 | G29: =G25/G$31 -> 0.034246788 | H29: =H25/H$31 -> 0.014958856 | I29: =I25/I$31 -> 0.006055377 | J29: =J25/J$31 -> 0.0097690217 | ... Z29: =Z25/Z$31 -> 0.040176745
B30: - total growth yo2y | O30: =(1*(1+H28)*(1+O28))-1 -> 0.29548893 | P30: =(1*(1+I28)*(1+P28))-1 -> 0.33767858 | R30: =(1*(1+K28)*(1+R28))-1 -> 1.0619011 | S30: =(1*(1+L28)*(1+S28))-1 -> -0.16104358 | U30: =(1*(1+N28)*(1+U28))-1 -> 0.31176213 | V30: =(1*(1+O28)*(1+V28))-1 -> 4.6263304 | W30: =(1*(1+P28)*(1+W28))-1 -> 13.553671 | X30: =(1*(1+R28)*(1+X28))-1 -> 3.9210216 | Y30: =(1*(1+S28)*(1+Y28))-1 -> 7.362224 | Z30: =(1*(1+U28)*(1+Z28))-1 -> 6.331641
B31: Total | C31: =C25+C18+C11+C4 -> 49.570327 | D31: =D25+D18+D11+D4 -> 69.67782 | E31: =E25+E18+E11+E4 -> 65.070692 | F31: =F25+F18+F11+F4 -> 82.801101 | G31: =G25+G18+G11+G4 -> 267.11994 | H31: =H25+H18+H11+H4 -> 71.289841 | I31: =I25+I18+I11+I4 -> 99.627851 | J31: =I31+H31 -> 170.91769 | K31: =K25+K18+K11+K4 -> 130.07734 | L31: =L25+L18+L11+L4 -> 124.30021 | M31: =L31+K31 -> 254.37755 | N31: =N25+N18+N11+N4 -> 425.29524 | O31: =O25+O18+O11+O4 -> 140.4 | P31: =P25+P18+P11+P4 -> 175.1 | Q31: =P31+O31 -> 315.5 | R31: =R25+R18+R11+R4 -> 218 | S31: =S25+S18+S11+S4 -> 191.1 | T31: =S31+R31 -> 409.1 | U31: =U25+U18+U11+U4 -> 724.6 | V31: =V25+V18+V11+V4 -> 235.7 | W31: =W25+W18+W11+W4 -> 291.662 | X31: =X25+X18+X11+X4 -> 328.013 | Y31: =Y25+Y18+Y11+Y4 -> 366.725 | Z31: =Z25+Z18+Z11+Z4 -> 1222.1 | AA31: =AA25+AA18+AA11+AA4 -> 420.2 | AB31: =AB25+AB18+AB11+AB4 -> 444.3 | AC31: =AC25+AC18+AC11+AC4 -> 480.5 | AD31: =AE31-SUM(AA31:AC31) -> 447.1 | AE31: =AE25+AE18+AE11+AE4 -> 1792.1 | AF31: =AF25+AF18+AF11+AF4 -> 508.2 | AG31: =AG25+AG18+AG11+AG4 -> 567.7 | AH31: =AH25+AH18+AH11+AH4 -> 635.8 | AI31: =AJ31-SUM(AF31:AH31) -> 606.6 | AJ31: =AJ25+AJ18+AJ11+AJ4 -> 2318.3 | AK31: =AK25+AK18+AK11+AK4 -> 726.5548 | AL31: =AL25+AL18+AL11+AL4 -> 749.22 | AM31: =AM25+AM18+AM11+AM4 -> 794.4 | AN31: =AO31-SUM(AK31:AM31) -> 743.8252 | AO31: =AO25+AO18+AO11+AO4 -> 3014 | AP31: =AP25+AP18+AP11+AP4 -> 831.9 | AQ31: =AQ25+AQ18+AQ11+AQ4 -> 850.3 | AR31: =AR25+AR18+AR11+AR4 -> 917.05863 | AS31: =AT31-SUM(AP31:AR31) -> 902.86715 | AT31: =AT25+AT18+AT11+AT4 -> 3502.1258 | AU31: =AU25+AU18+AU11+AU4 -> 4158.5242 | AV31: =AV25+AV18+AV11+AV4 -> 4842.1171 | AW31: =AW25+AW18+AW11+AW4 -> 5605.1581 | AX31: =AX25+AX18+AX11+AX4 -> 6409.7687 | AY31: =AY25+AY18+AY11+AY4 -> 7162.9127
B32: - cFX growth | O32: =((1+O34)/(1+O33))-1 -> 1.0908354 | P32: =((1+P34)/(1+P33))-1 -> 0.84611658 | Q32: =((1+Q34)/(1+Q33))-1 -> 0.94755564 | R32: =((1+R34)/(1+R33))-1 -> 0.68237721 | S32: =((1+S34)/(1+S33))-1 -> 0.48905633 | T32: =((1+T34)/(1+T33))-1 -> 0.58618233 | U32: =((1+U34)/(1+U33))-1 -> 0.7259124 | V32: =((1+V34)/(1+V33))-1 -> 0.61883479 | ... AC32: =((1+AC34)/(1+AC33))-1 -> 0.65417808 | AD32: 0.31 | AE32: 0.55 | AF32: =((1+AF34)/(1+AF33))-1 -> 0.29170745 | AG32: =((1+AG34)/(1+AG33))-1 -> 0.29404278 | AH32: =((1+AH34)/(1+AH33))-1 -> 0.3317938 | AI32: =((1+AI34)/(1+AI33))-1 -> 0.40627971 | AJ32: 0.332 | AK32: =((1+AK34)/(1+AK33))-1 -> 0.40031831 | AL32: =((1+AL34)/(1+AL33))-1 -> 0.38204002 | AM32: =((1+AM34)/(1+AM33))-1 -> 0.34549598 | AN32: =((1+AN34)/(1+AN33))-1 -> 0.30493637 | AO32: =((1+AO34)/(1+AO33))-1 -> 0.35544157 | AP32: =((AP5*AK4)+(AP12*AK11)+(AP19*AK18))/(AK4+AK11+AK18) -> 0.26424121 | AQ32: =((AQ5*AL4)+(AQ12*AL11)+(AQ19*AL18))/(AL4+AL11+AL18) -> 0.21612523 | AR32: =((AR5*AM4)+(AR12*AM11)+(AR19*AM18))/(AM4+AM11+AM18) -> 0.17003399 | AS32: =((AS5*AN4)+(AS12*AN11)+(AS19*AN18))/(AN4+AN11+AN18) -> 0.19596488 | AT32: =((AT5*AO4)+(AT12*AO11)+(AT19*AO18))/(AO4+AO11+AO18) -> 0.20316158 | AU32: =((AU5*AT4)+(AU12*AT11)+(AU19*AT18))/(AT4+AT11+AT18) -> 0.17925192 | AV32: =((AV5*AU4)+(AV12*AU11)+(AV19*AU18))/(AU4+AU11+AU18) -> 0.17198814 | AW32: =((AW5*AV4)+(AW12*AV11)+(AW19*AV18))/(AV4+AV11+AV18) -> 0.1649642 | AX32: =((AX5*AW4)+(AX12*AW11)+(AX19*AW18))/(AW4+AW11+AW18) -> 0.14830855 | AY32: =((AY5*AX4)+(AY12*AX11)+(AY19*AX18))/(AX4+AX11+AX18) -> 0.12207841
B33: - ccy | O33: =((O6*H4)+(O13*H11)+(O20*H18))/(H4+H11+H18) -> -0.058067886 | P33: =((P6*I4)+(P13*I11)+(P20*I18))/(I4+I11+I18) -> -0.047979583 | Q33: =Q133 -> -0.052187419 | R33: =((R6*K4)+(R13*K11)+(R20*K18))/(K4+K11+K18) -> -0.0038345909 | S33: =((S6*L4)+(S13*L11)+(S20*L18))/(L4+L11+L18) -> 0.032470616 | T33: =T133 -> 0.013905751 | U33: =((U6*N4)+(U13*N11)+(U20*N18))/(N4+N11+N18) -> -0.012836583 | V33: =((V6*O4)+(V13*O11)+(V20*O18))/(O4+O11+O18) -> 0.037026718 | W33: =((W6*P4)+(W13*P11)+(W20*P18))/(P4+P11+P18) -> 0.058619106 | X33: =((X6*R4)+(X13*R11)+(X20*R18))/(R4+R11+R18) -> 0.055700904 | Y33: =((Y6*S4)+(Y13*S11)+(Y20*S18))/(S4+S11+S18) -> 0.035362387 | Z33: =((Z6*U4)+(Z13*U11)+(Z20*U18))/(U4+U11+U18) -> 0.047402509 | AA33: =((AA6*V4)+(AA13*V11)+(AA20*V18))/(V4+V11+V18) -> 0.0056521414 | AB33: =((AB6*W4)+(AB13*W11)+(AB20*W18))/(W4+W11+W18) -> -0.050584258 | AC33: =((AC6*X4)+(AC13*X11)+(AC20*X18))/(X4+X11+X18) -> -0.11443575 | AD33: =((AD34+1)/(1+AD32))-1 -> -0.069336124 | AE33: =((AE34+1)/(1+AE32))-1 -> -0.053928853 | AF33: -0.063701241 | AG33: -0.012598129 | AH33: -0.00644905 | AI33: =((AI6*AD4)+(AI13*AD11)+(AI20*AD18))/(AD4+AD11+AD18) -> -0.035225036 | AJ33: =((AJ34+1)/(1+AJ32))-1 -> -0.028812307 | AK33: 0.020955815 | AL33: -0.045073716 | AM33: =((AM6*AH4)+(AM13*AH11)+(AM20*AH18))/(AH4+AH11+AH18) -> -0.071383688 | AN33: =((AN6*AI4)+(AN13*AI11)+(AN20*AI18))/(AI4+AI11+AI18) -> -0.060321813 | AO33: =((AO6*AJ4)+(AO13*AJ11)+(AO20*AJ18))/(AJ4+AJ11+AJ18) -> -0.04083613 | AP33: =AP34-AP32 -> -0.11924843 | AQ33: =AQ34-AQ32 -> -0.081211584 | AR33: =AR34-AR32 -> -0.015629866 | AS33: =AS34-AS32 -> 0.017851424 | AT33: =AT34-AT32 -> -0.041208763 | AU33: =AU34-AU32 -> 0.0081766543 | AV33: =AV34-AV32 -> -0.007604611 | AW33: =AW34-AW32 -> -0.0073800515 | ... AY33: =AY34-AY32 -> -0.0045790119
B34: - total growth | H34: =H31/C31-1 -> 0.43815557 | I34: =I31/D31-1 -> 0.42983594 | K34: =K31/E31-1 -> 0.99901583 | L34: =L31/F31-1 -> 0.50119029 | N34: =N31/G31-1 -> 0.59215087 | O34: =O31/H31-1 -> 0.96942506 | P34: =P31/I31-1 -> 0.75754068 | Q34: =Q31/J31-1 -> 0.84591774 | R34: =R31/K31-1 -> 0.67592599 | S34: =S31/L31-1 -> 0.5374069 | T34: =T31/M31-1 -> 0.60823939 | U34: =U31/N31-1 -> 0.70375759 | ... W34: =W31/P31-1 -> 0.66568818 | X34: =X31/R31-1 -> 0.50464679 | Y34: =Y31/S31-1 -> 0.91902145 | Z34: =Z31/U31-1 -> 0.6865857 | AA34: =AA31/V31-1 -> 0.78277471 | AB34: =AB31/W31-1 -> 0.52333866 | AC34: =AC31/X31-1 -> 0.46488097 | AD34: =AD31/Y31-1 -> 0.21916968 | AE34: =AE31/Z31-1 -> 0.46641028 | AF34: =AF31/AA31-1 -> 0.20942408 | AG34: =AG31/AB31-1 -> 0.27774027 | ... AT34: =AT31/AO31-1 -> 0.16195282 | AU34: =AU31/AT31-1 -> 0.18742858 | AV34: =AV31/AU31-1 -> 0.16438353 | AW34: =AW31/AV31-1 -> 0.15758415 | AX34: =AX31/AW31-1 -> 0.14354825 | AY34: =AY31/AX31-1 -> 0.1174994
B35: - total growth yo2y | O35: =(1*(1+H34)*(1+O34))-1 -> 1.8323396 | P35: =(1*(1+I34)*(1+P34))-1 -> 1.5129948 | R35: =(1*(1+K34)*(1+R34))-1 -> 2.3502026 | S35: =(1*(1+L34)*(1+S34))-1 -> 1.3079403 | U35: =(1*(1+N34)*(1+U34))-1 -> 1.7126391 | V35: =(1*(1+O34)*(1+V34))-1 -> 2.3062214 | W35: =(1*(1+P34)*(1+W34))-1 -> 1.9275147 | X35: =(1*(1+R34)*(1+X34))-1 -> 1.5216767 | Y35: =(1*(1+S34)*(1+Y34))-1 -> 1.9503168 | Z35: =(1*(1+U34)*(1+Z34))-1 -> 1.8735332 | AA35: =(1*(1+T34)*(1+AA34))-1 -> 1.8671285 | AB35: =(1*(1+U34)*(1+AB34))-1 -> 1.5953998 | AC35: =(1*(1+W34)*(1+AC34))-1 -> 1.4400349 | AD35: =(1*(1+X34)*(1+AD34))-1 -> 0.83441974 | AE35: =(1*(1+Z34)*(1+AE34))-1 -> 1.4732266 | AJ35: =(1*(1+AE34)*(1+AJ34))-1 -> 0.89698061 | AO35: =(1*(1+AJ34)*(1+AO34))-1 -> 0.68182579 | AT35: =(1*(1+AO34)*(1+AT34))-1 -> 0.51064391 | AU35: =(1*(1+AT34)*(1+AU34))-1 -> 0.37973598 | AV35: =(1*(1+AU34)*(1+AV34))-1 -> 0.38262228 | AW35: =(1*(1+AV34)*(1+AW34))-1 -> 0.34787192 | AX35: =(1*(1+AW34)*(1+AX34))-1 -> 0.32375334 | AY35: =(1*(1+AX34)*(1+AY34))-1 -> 0.27791449
B37: Sales by Product
B38: Shoes | C38: 46.347513 | D38: 67.031732 | E38: 61.496701 | F38: 80.735853 | G38: 255.6118 | H38: 66.729297 | I38: 94.970091 | J38: =I38+H38 -> 161.69939 | K38: 124.07351 | L38: 120.6174 | M38: =L38+K38 -> 244.69091 | N38: 406.3903 | O38: =H38*(1+O41) -> 131.7 | P38: =P53-P43-P48 -> 165.3 | Q38: =P38+O38 -> 297 | R38: =K38*(1+R41) -> 205 | S38: =L38*(1+S41) -> 181.3 | T38: =S38+R38 -> 386.3 | U38: =T38+Q38 -> 683.3 | V38: =O38*(1+V41) -> 222.5 | W38: =P38*(1+W41) -> 280.621 | X38: =R38*(1+X41) -> 310.892 | Y38: =S38*(1+Y41) -> 353.487 | Z38: =SUM(V38:Y38) -> 1167.5 | AA38: =V38*(1+AA41) -> 400.5 | AB38: =W38*(1+AB41) -> 428.2 | AC38: =X38*(1+AC41) -> 456.9 | AD38: =Y38*(1+AD41) -> 425.8 | AE38: =SUM(AA38:AD38) -> 1711.4 | AF38: =AA38*(1+AF41) -> 484.7 | AG38: 542.5 | AH38: 603.7 | AI38: =AJ38-AH38-AG38-AF38 -> 568.7 | AJ38: =AE38*(1+AJ41) -> 2199.6 | AK38: 680.9 | AL38: 704.9 | AM38: 731.3 | AN38: =AO38-AM38-AL38-AK38 -> 687.3 | AO38: =AJ38*(1+AO41) -> 2804.4 | AP38: =AK38*(1+AP41) -> 763.7 | AQ38: =AL38*(1+AQ41) -> 781.6 | AR38: =AM38*(1+AR41) -> 871.04255 | AS38: =AT38-AR38-AQ38-AP38 -> 765.19116 | AT38: =AT42*AT31 -> 3181.5337 | AU38: =AU42*AU31 -> 3694.6736 | AV38: =AV42*AV31 -> 4205.1747 | AW38: =AW42*AW31 -> 4755.7404 | AX38: =AX42*AX31 -> 5310.2233 | AY38: =AY42*AY31 -> 5790.9131
B39: - cFX growth | AG39: 0.282 | AH39: 0.329 | AI39: 0.385 | AJ39: 0.323 | AK39: =((1+AK41)/(1+AK40))-1 -> 0.3753329 | AL39: =((1+AL41)/(1+AL40))-1 -> 0.36004126 | AM39: =((1+AM41)/(1+AM40))-1 -> 0.30440926 | AN39: 0.288 | AO39: 0.329 | AP39: 0.24 | AQ39: 0.189 | AR39: 0.21 | AS39: =AS41-AS55 -> 0.095477772
B40: - ccy | AG40: =AG41-AG39 -> -0.01506866 | AH40: =AH41-AH39 -> -0.0077043117 | AI40: =AI41-AI39 -> -0.04939643 | AJ40: =AJ41-AJ39 -> -0.037736473 | AK40: 0.02141559 | AL40: -0.044621014 | AM40: -0.071331909 | AN40: =AN41-AN39 -> -0.079454194 | AO40: =AO41-AO39 -> -0.054040917 | AP40: -0.095480839 | AQ40: -0.067443431 | AR40: =AR133 -> -0.015629866 | AS40: =AS41-AS39 -> 0.017851424
B41: - total growth | H41: =H38/C38-1 -> 0.43976003 | I41: =I38/D38-1 -> 0.41679304 | K41: =K38/E38-1 -> 1.0175636 | L41: =L38/F38-1 -> 0.4939757 | N41: =N38/G38-1 -> 0.58987299 | O41: 0.97364585 | P41: =P38/I38-1 -> 0.74054797 | Q41: =Q38/J38-1 -> 0.83674164 | R41: 0.65224637 | S41: 0.50309985 | T41: 0.445 | U41: =U38/N38-1 -> 0.68138857 | V41: 0.68944571 | W41: 0.6976467 | X41: 0.51654634 | Y41: 0.94973525 | Z41: =Z38/U38-1 -> 0.70861993 | AA41: 0.8 | AB41: 0.52590148 | AC41: 0.46964219 | AD41: 0.20457047 | AE41: =AE38/Z38-1 -> 0.46586724 | AF41: 0.2102372 | AG41: =AG38/AB38-1 -> 0.26693134 | AH41: =AH38/AC38-1 -> 0.32129569 | AI41: =AI38/AD38-1 -> 0.33560357 | AJ41: 0.28526353 | AK41: =AK38/AF38-1 -> 0.40478647 | AL41: =AL38/AG38-1 -> 0.29935484 | AM41: =AM38/AH38-1 -> 0.21136326 | AN41: =AN38/AI38-1 -> 0.20854581 | AO41: 0.27495908 | AP41: =((1+AP40)*(1+AP39))-1 -> 0.12160376 | AQ41: =((1+AQ40)*(1+AQ39))-1 -> 0.10880976 | AR41: =((1+AR40)*(1+AR39))-1 -> 0.19108786 | AS41: =AS38/AN38-1 -> 0.1133292 | AT41: =AT38/AO38-1 -> 0.13447929 | AU41: =AU38/AT38-1 -> 0.16128694 | AV41: =AV38/AU38-1 -> 0.13817219 | AW41: =AW38/AV38-1 -> 0.13092577 | AX41: =AX38/AW38-1 -> 0.11659233 | AY41: =AY38/AX38-1 -> 0.09052158
...

Sheet GSe vs Cons
B2: Source: FactSet
B3: ONON | C3: VA Keyword | D3: 2Q25E | F3: GSe vs. Consensus
B4: CHF, mn | D4: GSe | E4: Consensus
B5: Net Sales | D5: =MODEL!$AL$131 -> 749.22 | E5: 703.1 | F5: =D5/E5-1 -> 0.065595221
B6: -∆ yoy % | D6: =MODEL!$AL$134 -> 0.31974634 | E6: =E5/MODEL!AG131-1 -> 0.23850625 | F6: =(D6-E6)*10000 -> 812.40092
B7: -∆ cFX yoy % | D7: =MODEL!$AL$132 -> 0.38204002
B8: By Channel
B9: -Wholesale | D9: =MODEL!$AL$118 -> 0.23058889 | E9: =428.5/MODEL!AG115-1 -> 0.1959252 | F9: =(D9-E9)*10000 -> 346.6369
B10: -DTC | D10: =MODEL!$AL$81 -> 0.47230181 | E10: =278.5/MODEL!AG78-1 -> 0.32999045 | F10: =(D10-E10)*10000 -> 1423.1137
B11: By Region
B12: -EMEA cFX | D12: =MODEL!$AL$5 -> 0.46139825
B13: -Americas cFX | D13: =MODEL!$AL$12 -> 0.23583673
B14: -APAC cFX | D14: =MODEL!$AL$19 -> 1.1088607
B15: Gross Margin | D15: =MODEL!$AL$136 -> 0.61503964 | E15: 0.599 | F15: =(D15-E15)*10000 -> 160.39641
B16: -∆ bps | D16: =MODEL!$AL$137 -> 157.21163 | E16: =(E15-MODEL!AG136)*10000 -> -3.1847851 | F16: -
B17: adj. EBITDA | D17: =MODEL!$AL$153 -> 136.1 | E17: 114.6 | F17: =D17/E17-1 -> 0.18760908
B18: adj. EBITDA margin | D18: =MODEL!$AL$155 -> 0.18165559 | E18: =E17/E5 -> 0.16299246 | F18: =(D18-E18)*10000 -> 186.63127
B20: Source: Visible Alpha
A21: Ticker | B21: ONON | C21: VA Keyword | D21: 3Q26E | F21: GSe vs. | G21: FY26E | I21: GSe vs. | J21: FY27E | L21: GSe vs. | M21: FY28E | O21: GSe vs. | P21: FY29E | R21: GSe vs.
B22: CHF, mn | D22: GSe | E22: Consensus | F22: Consensus | G22: GSe | H22: Consensus | I22: Consensus | J22: GSe | K22: Consensus | L22: Consensus | M22: GSe | N22: Consensus | O22: Consensus | P22: GSe | Q22: Consensus | R22: Consensus
A23: ONON_CH | B23: =B5 -> Net Sales | C23: Total Revenue | D23: =MODEL!$AR$131 -> 917.05863 | E23: =_xll.VisibleAlpha.UDF.VAData($A23,D$21,$C23,E$22,"CD") -> #NAME? | F23: =D23/E23-1 -> #NAME? | G23: =MODEL!$AT$131 -> 3502.1258 | H23: =_xll.VisibleAlpha.UDF.VAData($A23,G$21,$C23,H$22,"CD") -> #NAME? | I23: =G23/H23-1 -> #NAME? | J23: =MODEL!$AU$131 -> 4158.5242 | K23: =_xll.VisibleAlpha.UDF.VAData($A23,J$21,$C23,K$22,"CD") -> #NAME? | L23: =J23/K23-1 -> #NAME? | M23: =MODEL!$AV$131 -> 4842.1171 | N23: =_xll.VisibleAlpha.UDF.VAData($A23,M$21,$C23,N$22,"CD") -> #NAME? | O23: =M23/N23-1 -> #NAME? | P23: =MODEL!$AW$131 -> 5605.1581 | Q23: =_xll.VisibleAlpha.UDF.VAData($A23,P$21,$C23,Q$22,"CD") -> 5736.8116 | R23: =P23/Q23-1 -> -0.02294891
A24: ONON_CH | B24: =B6 -> -∆ yoy % | C24: Total Revenue | D24: =MODEL!$AR$134 -> 0.15440412 | E24: =_xll.VisibleAlpha.UDF.VAData($A24,D$21,$C24,E$22,"CD",,,"YoY%") -> #NAME? | F24: =(D24-E24)*10000 -> #NAME? | G24: =MODEL!$AT$134 -> 0.16195282 | H24: =_xll.VisibleAlpha.UDF.VAData($A24,G$21,$C24,H$22,"CD",,,"YoY%") -> #NAME? | I24: =(G24-H24)*10000 -> #NAME? | J24: =MODEL!$AU$134 -> 0.18742858 | K24: =_xll.VisibleAlpha.UDF.VAData($A24,J$21,$C24,K$22,"CD",,,"YoY%") -> #NAME? | L24: =(J24-K24)*10000 -> #NAME? | M24: =MODEL!$AV$134 -> 0.16438353 | N24: =_xll.VisibleAlpha.UDF.VAData($A24,M$21,$C24,N$22,"CD",,,"YoY%") -> #NAME? | O24: =(M24-N24)*10000 -> #NAME? | P24: =MODEL!$AW$134 -> 0.15758415 | Q24: =_xll.VisibleAlpha.UDF.VAData($A24,P$21,$C24,Q$22,"CD",,,"YoY%") -> 0.15150472 | R24: =(P24-Q24)*10000 -> 60.794343
A25: ONON_CH | B25: =B7 -> -∆ cFX yoy % | C25: Constant currency impact | D25: =MODEL!$AR$132 -> 0.17003399 | E25: =_xll.VisibleAlpha.UDF.VAData($A25,D$21,$C25,E$22,"CD")/100 -> #NAME? | F25: =(D25-E25)*10000 -> #NAME? | G25: =MODEL!$AT$132 -> 0.20316158 | H25: =_xll.VisibleAlpha.UDF.VAData($A25,G$21,$C25,H$22,"CD")/100 -> #NAME? | I25: =(G25-H25)*10000 -> #NAME? | J25: =MODEL!$AU$132 -> 0.17779813 | K25: =_xll.VisibleAlpha.UDF.VAData($A25,J$21,$C25,K$22,"CD")/100 -> #NAME? | L25: =(J25-K25)*10000 -> #NAME? | M25: =MODEL!$AV$132 -> 0.17330607 | N25: =_xll.VisibleAlpha.UDF.VAData($A25,M$21,$C25,N$22,"CD")/100 -> #NAME? | O25: =(M25-N25)*10000 -> #NAME? | P25: =MODEL!$AW$132 -> 0.1661907 | Q25: =_xll.VisibleAlpha.UDF.VAData($A25,P$21,$C25,Q$22,"CD")/100 -> 0.14635192 | R25: =(P25-Q25)*10000 -> 198.3878
A26: ONON_CH | B26: =B8 -> By Channel
A27: ONON_CH | B27: =B9 -> -Wholesale | C27: Total revenue - Wholesale | D27: =MODEL!$AR$118 -> 0.082262567 | E27: =_xll.VisibleAlpha.UDF.VAData($A27,D$21,$C27,E$22,"CD",,,"YoY%") -> #NAME? | F27: =(D27-E27)*10000 -> #NAME? | G27: =MODEL!$AT$118 -> 0.092340709 | H27: =_xll.VisibleAlpha.UDF.VAData($A27,G$21,$C27,H$22,"CD",,,"YoY%") -> #NAME? | I27: =(G27-H27)*10000 -> #NAME? | J27: =MODEL!$AU$118 -> 0.14387915 | K27: =_xll.VisibleAlpha.UDF.VAData($A27,J$21,$C27,K$22,"CD",,,"YoY%") -> #NAME? | L27: =(J27-K27)*10000 -> #NAME? | M27: =MODEL!$AV$118 -> 0.12342014 | N27: =_xll.VisibleAlpha.UDF.VAData($A27,M$21,$C27,N$22,"CD",,,"YoY%") -> #NAME? | O27: =(M27-N27)*10000 -> #NAME? | P27: =MODEL!$AW$118 -> 0.12623147 | Q27: =_xll.VisibleAlpha.UDF.VAData($A27,P$21,$C27,Q$22,"CD",,,"YoY%") -> 0.12521792 | R27: =(P27-Q27)*10000 -> 10.13543
A28: ONON_CH | B28: =B10 -> -DTC | C28: Total revenue - DTC | D28: =MODEL!$AR$81 -> 0.26437013 | E28: =_xll.VisibleAlpha.UDF.VAData($A28,D$21,$C28,E$22,"CD",,,"YoY%") -> #NAME? | F28: =(D28-E28)*10000 -> #NAME? | G28: =MODEL!$AT$81 -> 0.25879124 | H28: =_xll.VisibleAlpha.UDF.VAData($A28,G$21,$C28,H$22,"CD",,,"YoY%") -> #NAME? | I28: =(G28-H28)*10000 -> #NAME? | J28: =MODEL!$AU$81 -> 0.24 | K28: =_xll.VisibleAlpha.UDF.VAData($A28,J$21,$C28,K$22,"CD",,,"YoY%") -> #NAME? | L28: =(J28-K28)*10000 -> #NAME? | M28: =MODEL!$AV$81 -> 0.21 | N28: =_xll.VisibleAlpha.UDF.VAData($A28,M$21,$C28,N$22,"CD",,,"YoY%") -> #NAME? | O28: =(M28-N28)*10000 -> #NAME? | P28: =MODEL!$AW$81 -> 0.19 | Q28: =_xll.VisibleAlpha.UDF.VAData($A28,P$21,$C28,Q$22,"CD",,,"YoY%") -> 0.17993633 | R28: =(P28-Q28)*10000 -> 100.63669
A29: ONON_CH | B29: =B11 -> By Region
A30: ONON_CH | B30: =B12 -> -EMEA cFX | C30: EMEA - Constant currency impact | D30: =MODEL!$AR$5 -> 0.13 | E30: =_xll.VisibleAlpha.UDF.VAData($A30,D$21,$C30,E$22,"CD")/100 -> #NAME? | F30: =(D30-E30)*10000 -> #NAME? | G30: =MODEL!$AT$5 -> 0.19 | H30: =_xll.VisibleAlpha.UDF.VAData($A30,G$21,$C30,H$22,"CD")/100 -> #NAME? | I30: =(G30-H30)*10000 -> #NAME? | J30: =MODEL!$AU$5 -> 0.17 | K30: =_xll.VisibleAlpha.UDF.VAData($A30,J$21,$C30,K$22,"CD")/100 -> #NAME? | L30: =(J30-K30)*10000 -> #NAME? | M30: =MODEL!$AV$5 -> 0.16 | N30: =_xll.VisibleAlpha.UDF.VAData($A30,M$21,$C30,N$22,"CD")/100 -> #NAME? | O30: =(M30-N30)*10000 -> #NAME? | P30: =MODEL!$AW$5 -> 0.15 | Q30: =_xll.VisibleAlpha.UDF.VAData($A30,P$21,$C30,Q$22,"CD")/100 -> 0.14099101 | R30: =(P30-Q30)*10000 -> 90.089872
A31: ONON_CH | B31: =B13 -> -Americas cFX | C31: Americas - constant currency impact | D31: =MODEL!$AR$12 -> 0.08 | E31: =_xll.VisibleAlpha.UDF.VAData($A31,D$21,$C31,E$22,"CD")/100 -> #NAME? | F31: =(D31-E31)*10000 -> #NAME? | G31: =MODEL!$AT$12 -> 0.11 | H31: =_xll.VisibleAlpha.UDF.VAData($A31,G$21,$C31,H$22,"CD")/100 -> #NAME? | I31: =(G31-H31)*10000 -> #NAME? | J31: =MODEL!$AU$12 -> 0.09 | K31: =_xll.VisibleAlpha.UDF.VAData($A31,J$21,$C31,K$22,"CD")/100 -> #NAME? | L31: =(J31-K31)*10000 -> #NAME? | M31: =MODEL!$AV$12 -> 0.08 | N31: =_xll.VisibleAlpha.UDF.VAData($A31,M$21,$C31,N$22,"CD")/100 -> #NAME? | O31: =(M31-N31)*10000 -> #NAME? | P31: =MODEL!$AW$12 -> 0.08 | Q31: =_xll.VisibleAlpha.UDF.VAData($A31,P$21,$C31,Q$22,"CD")/100 -> 0.10711495 | R31: =(P31-Q31)*10000 -> -271.14954
A32: ONON_CH | B32: =B14 -> -APAC cFX | C32: Asia Pacific - constant currency impact | D32: =MODEL!$AR$19 -> 0.5 | E32: =_xll.VisibleAlpha.UDF.VAData($A32,D$21,$C32,E$22,"CD")/100 -> #NAME? | F32: =(D32-E32)*10000 -> #NAME? | G32: =MODEL!$AT$19 -> 0.54 | H32: =_xll.VisibleAlpha.UDF.VAData($A32,G$21,$C32,H$22,"CD")/100 -> #NAME? | I32: =(G32-H32)*10000 -> #NAME? | J32: =MODEL!$AU$19 -> 0.4 | K32: =_xll.VisibleAlpha.UDF.VAData($A32,J$21,$C32,K$22,"CD")/100 -> #NAME? | L32: =(J32-K32)*10000 -> #NAME? | M32: =MODEL!$AV$19 -> 0.35 | N32: =_xll.VisibleAlpha.UDF.VAData($A32,M$21,$C32,N$22,"CD")/100 -> #NAME? | O32: =(M32-N32)*10000 -> #NAME? | P32: =MODEL!$AW$19 -> 0.3 | Q32: =_xll.VisibleAlpha.UDF.VAData($A32,P$21,$C32,Q$22,"CD")/100 -> 0.22503711 | R32: =(P32-Q32)*10000 -> 749.62887
A33: ONON_CH | B33: =B15 -> Gross Margin | C33: Gross profit/(loss) | D33: =MODEL!$AR$136 -> 0.65 | E33: =_xll.VisibleAlpha.UDF.VAData($A33,D$21,$C33,E$22,"CD")/E23 -> #NAME? | F33: =(D33-E33)*10000 -> #NAME? | G33: =MODEL!$AT$136 -> 0.65 | H33: =_xll.VisibleAlpha.UDF.VAData($A33,G$21,$C33,H$22,"CD")/H23 -> #NAME? | I33: =(G33-H33)*10000 -> #NAME? | J33: =MODEL!$AU$136 -> 0.652 | K33: =_xll.VisibleAlpha.UDF.VAData($A33,J$21,$C33,K$22,"CD")/K23 -> #NAME? | L33: =(J33-K33)*10000 -> #NAME? | M33: =MODEL!$AV$136 -> 0.654 | N33: =_xll.VisibleAlpha.UDF.VAData($A33,M$21,$C33,N$22,"CD")/N23 -> #NAME? | O33: =(M33-N33)*10000 -> #NAME? | P33: =MODEL!$AW$136 -> 0.656 | Q33: =_xll.VisibleAlpha.UDF.VAData($A33,P$21,$C33,Q$22,"CD")/Q23 -> 0.65675047 | R33: =(P33-Q33)*10000 -> -7.5047277
A34: ONON_CH | B34: =B16 -> -∆ bps | D34: =MODEL!$AR$137 -> -73.514602 | E34: =(E33-MODEL!$AM$136)*10000 -> #NAME? | F34: - | G34: =(G33-MODEL!$AO$136)*10000 -> 217.31918 | H34: =(H33-MODEL!$AO$136)*10000 -> #NAME? | I34: - | J34: =(J33-G33)*10000 -> 20 | K34: =(K33-H33)*10000 -> #NAME? | L34: - | M34: =(M33-J33)*10000 -> 20 | N34: =(N33-K33)*10000 -> #NAME? | O34: - | P34: =(P33-M33)*10000 -> 20 | Q34: =(Q33-N33)*10000 -> #NAME? | R34: -
A35: ONON_CH | B35: =B17 -> adj. EBITDA | C35: EBITDA - Operating | D35: =MODEL!$AR$153 -> 197.52286 | E35: =_xll.VisibleAlpha.UDF.VAData($A35,D$21,$C35,E$22,"CD") -> #NAME? | F35: =D35/E35-1 -> #NAME? | G35: =MODEL!$AT$153 -> 699.98963 | H35: =_xll.VisibleAlpha.UDF.VAData($A35,G$21,$C35,H$22,"CD") -> #NAME? | I35: =G35/H35-1 -> #NAME? | J35: =MODEL!$AU$153 -> 855 | K35: =_xll.VisibleAlpha.UDF.VAData($A35,J$21,$C35,K$22,"CD") -> #NAME? | L35: =J35/K35-1 -> #NAME? | M35: =MODEL!$AV$153 -> 1030 | N35: =_xll.VisibleAlpha.UDF.VAData($A35,M$21,$C35,N$22,"CD") -> #NAME? | O35: =M35/N35-1 -> #NAME? | P35: =MODEL!$AW$153 -> 1233 | Q35: =_xll.VisibleAlpha.UDF.VAData($A35,P$21,$C35,Q$22,"CD") -> 1239.7723 | R35: =P35/Q35-1 -> -0.0054625058
A36: ONON_CH | B36: =B18 -> adj. EBITDA margin | D36: =MODEL!$AR$155 -> 0.21538738 | E36: =E35/E23 -> #NAME? | F36: =(D36-E36)*10000 -> #NAME? | G36: =MODEL!$AT$155 -> 0.19987564 | H36: =H35/H23 -> #NAME? | I36: =(G36-H36)*10000 -> #NAME? | J36: =MODEL!$AU$155 -> 0.20560178 | K36: =K35/K23 -> #NAME? | L36: =(J36-K36)*10000 -> #NAME? | M36: =MODEL!$AV$155 -> 0.21271687 | N36: =N35/N23 -> #NAME? | O36: =(M36-N36)*10000 -> #NAME? | P36: =MODEL!$AW$155 -> 0.21997596 | Q36: =Q35/Q23 -> 0.21610824 | R36: =(P36-Q36)*10000 -> 38.677159
P37: =P36*P34 -> 4.3995191
P38: =P37/H35-1 -> #NAME?
B42: ONON | C42: VA Keyword | D42: Beat/Miss | E42: 1Q26
B43: CHF, mn | E43: Actual | F43: GSe | G43: Consensus
B44: =B23 -> Net Sales | D44: =IF(E44>G44,"Beat", "Miss") -> #NAME? | F44: =D23 -> 917.05863 | G44: =E23 -> #NAME?
B45: =B24 -> -∆ yoy % | D45: =IF(E45>G45,"Beat", "Miss") -> #NAME? | F45: =D24 -> 0.15440412 | G45: =E24 -> #NAME?
...

Sheet FX
B2: Dec year end (CHFmn) | C2: 1Q19 | D2: 2Q19 | E2: 3Q19 | F2: 4Q19 | G2: FY19 | H2: 1Q20 | I2: 2Q20 | J2: 3Q20 | K2: 4Q20 | L2: FY20 | M2: 1Q21 | N2: 2Q21 | O2: 3Q21 | P2: 4Q21 | Q2: =Valuation!C48 -> 2021 | R2: 1Q22 | S2: 2Q22 | T2: 3Q22 | U2: 4Q22E | V2: =Valuation!D48 -> 2022 | W2: 1Q23 | X2: 2Q23 | Y2: 3Q23 | Z2: 4Q23E | AA2: =Valuation!E48 -> 2023 | AB2: 1Q24 | AC2: 2Q24 | AD2: 3Q24 | AE2: 4Q24 | AF2: =Valuation!F48 -> 2024 | AG2: 1Q25 | AH2: 2Q25 | AI2: 3Q25 | AJ2: 4Q25E | AK2: =Valuation!G48 -> 2025 | AL2: 1Q26 | AM2: 2Q26 | AN2: 3Q26E | AO2: 4Q26E | AP2: =Valuation!H48 -> 2026E | AQ2: =Valuation!I48 -> 2027E | AR2: =Valuation!J48 -> 2028E | AS2: =Valuation!K48 -> 2029E | AT2: =Valuation!L48 -> 2030E | AU2: =Valuation!M48 -> 2031E
B3: FX
B4: CHF/Euro | G4: 1.0065 | H4: 1.0332 | I4: 1.038 | J4: 1.0873 | K4: 1.1071 | L4: 1.0137 | M4: 1.104 | N4: 1.0977 | O4: 1.1062 | P4: 1.0538 | Q4: =AVERAGE(M4:P4) -> 1.090425 | R4: 1.038 | S4: 1.027 | T4: 1.0278 | U4: 1.017 | V4: =AVERAGE(R4:U4) -> 1.02745 | W4: 1 | X4: 1.022 | Y4: 1.045 | Z4: 1.03 | AA4: =AVERAGE(W4:Z4) -> 1.02425 | AB4: 1.027 | AC4: 1.055 | AD4: 1.051 | AE4: 1.0684 | AF4: =AVERAGE(AB4:AE4) -> 1.05035 | AG4: 1.061 | AH4: 1.068 | AI4: 1.0694 | AJ4: 1.075 | AK4: =AVERAGE(AG4:AJ4) -> 1.06835 | AL4: 1.0905 | AM4: 1.0882 | AN4: 1.0708 | AO4: 1.0627 | AP4: =AVERAGE(AL4:AO4) -> 1.07805 | AQ4: =AO4 -> 1.0627 | AR4: =AQ4 -> 1.0627 | AS4: =AR4 -> 1.0627 | AT4: =AS4 -> 1.0627 | AU4: =AT4 -> 1.0627
B5: US$/CHF | G5: 1.0065 | H5: 1.0332 | I5: 1.038 | J5: 1.0873 | K5: 1.1071 | L5: =AVERAGE(H5:K5) -> 1.0664 | M5: 1.1053 | N5: 1.098 | O5: 1.0891 | P5: 1.0847 | Q5: =AVERAGE(M5:P5) -> 1.094275 | R5: 1.0824 | S5: 1.0364 | T5: 1.0344 | U5: 1.039 | V5: =AVERAGE(R5:U5) -> 1.04805 | W5: 1.0826 | X5: 1.113 | Y5: 1.137 | Z5: 1.12 | AA5: =AVERAGE(W5:Z5) -> 1.11315 | AB5: 1.1058 | AC5: 1.15 | AD5: 1.1553 | AE5: 1.139 | AF5: =AVERAGE(AB5:AE5) -> 1.137525 | AG5: 1.115 | AH5: 1.212 | AI5: 1.25 | AJ5: 1.251 | AK5: =AVERAGE(AG5:AJ5) -> 1.207 | AL5: 1.277 | AM5: 1.2652 | AN5: 1.2639 | AO5: 1.2084 | AP5: =AVERAGE(AL5:AO5) -> 1.253625 | AQ5: =AO5 -> 1.2084 | AR5: =AQ5 -> 1.2084 | AS5: =AR5 -> 1.2084 | AT5: =AS5 -> 1.2084 | AU5: =AT5 -> 1.2084
B6: Yuan/CHF | G6: 6.76 | H6: 7.222 | I6: 7.36 | J6: 7.52 | K6: 7.315 | L6: =AVERAGE(H6:K6) -> 7.35425 | M6: 7.156 | N6: 7.088 | O6: 7.045 | P6: 6.9356 | Q6: =AVERAGE(M6:P6) -> 7.05615 | R6: 6.8785 | S6: 6.8672 | T6: 7.0978 | U6: 7.39 | V6: =AVERAGE(R6:U6) -> 7.058375 | W6: 7.44 | X6: 7.815 | Y6: 8.338 | Z6: 8.13 | AA6: =AVERAGE(W6:Z6) -> 7.93075 | AB6: 8.023 | AC6: 8.27 | AD6: 8.2727 | AE6: 8.188 | AF6: =AVERAGE(AB6:AE6) -> 8.188425 | AG6: 8.1237 | AH6: 8.764 | AI6: 8.946 | AJ6: 8.87 | AK6: =AVERAGE(AG6:AJ6) -> 8.675925 | AL6: 8.839 | AM6: 8.6138 | AN6: 8.317 | AO6: 8.1156 | AP6: =AVERAGE(AL6:AO6) -> 8.47135 | AQ6: =AO6 -> 8.1156 | AR6: =AQ6 -> 8.1156 | AS6: =AR6 -> 8.1156 | AT6: =AS6 -> 8.1156 | AU6: =AT6 -> 8.1156
AN7: \
B8: CHF/Euro growth | L8: =G4/L4-1 -> -0.0071026931 | M8: =H4/M4-1 -> -0.064130435 | N8: =I4/N4-1 -> -0.054386444 | O8: =J4/O4-1 -> -0.017085518 | P8: =K4/P4-1 -> 0.050578857 | Q8: =L4/Q4-1 -> -0.070362473 | R8: =M4/R4-1 -> 0.063583815 | S8: =N4/S4-1 -> 0.068841285 | ... AP8: =AK4/AP4-1 -> -0.0089977274 | AQ8: =AP4/AQ4-1 -> 0.01444434 | AR8: =AQ4/AR4-1 -> 0 | AS8: =AR4/AS4-1 -> 0 | AT8: =AS4/AT4-1 -> 0 | AU8: =AT4/AU4-1 -> 0
B9: US$/CHF growth | L9: =G5/L5-1 -> -0.056170293 | M9: =H5/M5-1 -> -0.065231159 | N9: =I5/N5-1 -> -0.054644809 | O9: =J5/O5-1 -> -0.0016527408 | P9: =K5/P5-1 -> 0.020650871 | Q9: =L5/Q5-1 -> -0.025473487 | R9: =M5/R5-1 -> 0.021156689 | S9: =N5/S5-1 -> 0.059436511 | ... AP9: =AK5/AP5-1 -> -0.037192143 | AQ9: =AP5/AQ5-1 -> 0.037425521 | AR9: =AQ5/AR5-1 -> 0 | AS9: =AR5/AS5-1 -> 0 | AT9: =AS5/AT5-1 -> 0 | AU9: =AT5/AU5-1 -> 0
B10: Yuan/CHF growth | L10: =G6/L6-1 -> -0.080803617 | M10: =H6/M6-1 -> 0.0092230296 | N10: =I6/N6-1 -> 0.038374718 | O10: =J6/O6-1 -> 0.067423705 | P10: =K6/P6-1 -> 0.05470327 | Q10: =L6/Q6-1 -> 0.042246834 | R10: =M6/R6-1 -> 0.040343098 | S10: =N6/S6-1 -> 0.032152842 | ... AP10: =AK6/AP6-1 -> 0.024149044 | AQ10: =AP6/AQ6-1 -> 0.043835329 | AR10: =AQ6/AR6-1 -> 0 | AS10: =AR6/AS6-1 -> 0 | AT10: =AS6/AT6-1 -> 0 | AU10: =AT6/AU6-1 -> 0

Sheet Worksheet
C5: DTC | D5: Wholesale
B6: Retail Price | C6: 140 | D6: 140
B7: Wholesale Price | D7: 70
B8: COGS | C8: =C6-C9 -> 56.629652 | D8: =C8 -> 56.629652
B9: Gross Profit | C9: =C6*C10 -> 83.370348 | D9: =D7*D10 -> 0
B10: GM | C10: =MODEL!AE136 -> 0.59550248 | D10: =MODEL!$AE$122 -> 0
B11: Selling and Dist | C11: =MODEL!$AE$87 -> 0 | D11: =MODEL!$AE$124 -> 0
B12: Admin and D&A | C12: =MODEL!$AE$152+MODEL!$AE$159 -> 0.15992411 | D12: =MODEL!$AE$152+MODEL!$AE$159 -> 0.15992411
C13: =C10-SUM(C11:C12) -> 0.43557837 | D13: =D10-SUM(D11:D12) -> -0.15992411
C16: DTC | D16: Wholesale
B17: =B6 -> Retail Price | C17: =C6 -> 140 | D17: =D6 -> 140
B18: Retailer Commision | D18: =D6-D7 -> 70
B19: COGS | C19: =C8 -> 56.629652 | D19: =D8 -> 56.629652
B20: Selling and Distribution | C20: =C11*C6 -> 0 | D20: =D11*D7 -> 0
B21: Admin and D&A | C21: =C12*C6 -> 22.389376 | D21: =D12*D7 -> 11.194688
B22: EBIT | C22: =C17-SUM(C18:C21) -> 60.980972 | D22: =D17-SUM(D18:D21) -> 2.1756598
B31: Gross Margins | C31: 2019 | D31: 2020 | E31: 2021 | F31: 2022E | G31: 2023E | H31: 2024E | I31: 2025E | J31: 2026E | K31: 2027E | L31: 2028E
B32: On | C32: =MODEL!G136 -> 0.53577889 | D32: =MODEL!N136 -> 0.54339968 | E32: =MODEL!U136 -> 0.59384488 | F32: =MODEL!Z136 -> 0.56042877 | G32: =MODEL!AE136 -> 0.59550248 | H32: =MODEL!AJ136 -> 0.60633821 | I32: =MODEL!AO136 -> 0.62826808 | J32: =MODEL!AT136 -> 0.65 | K32: =MODEL!AU136 -> 0.652 | L32: =MODEL!AV136 -> 0.654
B33: Puma | C33: =Comps!BA7 -> #DIV/0! | D33: =Comps!BB7 -> #DIV/0! | E33: =Comps!BC7 -> #DIV/0! | F33: =Comps!BD7 -> #DIV/0! | G33: =Comps!BE7 -> #DIV/0! | H33: =Comps!BF7 -> #DIV/0! | I33: =Comps!BG7 -> #DIV/0! | J33: =Comps!BH7 -> #DIV/0! | K33: =Comps!BI7 -> #DIV/0!
B34: Adidas | C34: =Comps!BA6 -> #DIV/0! | D34: =Comps!BB6 -> #DIV/0! | E34: =Comps!BC6 -> #DIV/0! | F34: =Comps!BD6 -> #DIV/0! | G34: =Comps!BE6 -> #DIV/0! | H34: =Comps!BF6 -> #DIV/0! | I34: =Comps!BG6 -> #DIV/0! | J34: =Comps!BH6 -> #DIV/0! | K34: =Comps!BI6 -> #DIV/0!
B35: Nike | C35: =Comps!BA4 -> #DIV/0! | D35: =Comps!BB4 -> #DIV/0! | E35: =Comps!BC4 -> #DIV/0! | F35: =Comps!BD4 -> #DIV/0! | G35: =Comps!BE4 -> #DIV/0! | H35: =Comps!BF4 -> #DIV/0! | I35: =Comps!BG4 -> #DIV/0!
B36: Lululemon | C36: =Comps!BA5 -> #DIV/0! | D36: =Comps!BB5 -> #DIV/0! | E36: =Comps!BC5 -> #DIV/0! | F36: =Comps!BD5 -> #DIV/0! | G36: =Comps!BE5 -> #DIV/0! | H36: =Comps!BF5 -> #DIV/0! | I36: =Comps!BG5 -> #DIV/0!
D46: N | E46: U | F46: Z | G46: AA
D47: 2020 | E47: 2021 | F47: 2022E | G47: 2023E | H47: 2024E | I47: 2025E | J47: 2026E | K47: 2027E | L47: 2028E
B48: Wholesale contribution margin | D48: =MODEL!N127 -> 0.195 | E48: =MODEL!U127 -> 0.14473391 | F48: =MODEL!Z127 -> 0.226 | G48: =MODEL!AE127 -> 0 | H48: =MODEL!AJ127 -> 0 | I48: =MODEL!AO127 -> 0 | J48: =MODEL!AT127 -> 0 | K48: =MODEL!AU127 -> 0 | L48: =MODEL!AV127 -> 0
B49: DTC contribution margin | D49: =MODEL!N90 -> 0.29372724 | E49: =MODEL!U90 -> 0.42032668 | F49: =MODEL!Z90 -> 0.32037295 | G49: =MODEL!AE90 -> 0 | H49: =MODEL!AJ90 -> 0 | I49: =MODEL!AO90 -> 0 | J49: =MODEL!AT90 -> 0 | K49: =MODEL!AU90 -> 0 | L49: =MODEL!AV90 -> 0
B50: contribution margin = EBITDA before central admin costs
C64: G | D64: N | E64: U | F64: Z
B65: Opex breakdown | C65: =C31 -> 2019 | D65: =D31 -> 2020 | E65: =E31 -> 2021 | F65: =F31 -> 2022E | G65: =G31 -> 2023E | H65: =H31 -> 2024E | I65: =I31 -> 2025E | J65: =J31 -> 2026E | ... L65: =L31 -> 2028E
B66: G&A | C66: =MODEL!G152 -> 0.12220892 | D66: =MODEL!N152 -> 0.11524261 | E66: =MODEL!U152 -> 0.11649738 | F66: =MODEL!Z152 -> 0.12511251 | G66: =MODEL!AE152 -> 0.12370961 | H66: =MODEL!AJ152 -> 0.12290243 | I66: =MODEL!AO152 -> 0.12179827 | J66: =MODEL!AT152 -> 0.12012436 | K66: =MODEL!AU152 -> 0.11839822 | L66: =MODEL!AV152 -> 0.11528313
B67: Marketing | C67: =MODEL!G146 -> 0.10689213 | D67: =MODEL!N146 -> 0.1072796 | E67: =MODEL!U146 -> 0.13869721 | F67: =MODEL!Z146 -> 0.10653793 | G67: =MODEL!AE146 -> 0.1092573 | H67: =MODEL!AJ146 -> 0.1193266 | I67: =MODEL!AO146 -> 0.12491705 | J67: =MODEL!AT146 -> 0.135 | K67: =MODEL!AU146 -> 0.134 | L67: =MODEL!AV146 -> 0.133
B68: Selling | C68: =MODEL!G143 -> 0.087926236 | D68: =MODEL!N143 -> 0.083740699 | E68: =MODEL!U143 -> 0.072591775 | F68: =MODEL!Z143 -> 0.069961542 | G68: =MODEL!AE143 -> 0.07438201 | H68: =MODEL!AJ143 -> 0.072551815 | I68: =MODEL!AO143 -> 0.086297279 | J68: =MODEL!AT143 -> 0.095 | K68: =MODEL!AU143 -> 0.097 | L68: =MODEL!AV143 -> 0.099
B69: Distribution | C69: =MODEL!G140 -> 0.10693217 | D69: =MODEL!N140 -> 0.12012678 | E69: =MODEL!U140 -> 0.13303892 | F69: =MODEL!Z155 -> 0.13525898 | G69: =MODEL!AE155 -> 0.15451147 | H69: =MODEL!AJ155 -> 0.16720131 | I69: =MODEL!AO155 -> 0.1881221 | J69: =MODEL!AT155 -> 0.19987564 | K69: =MODEL!AU155 -> 0.20560178 | L69: =MODEL!AV155 -> 0.21271687
C70: =SUM(C66:C69) -> 0.42395946 | D70: =SUM(D66:D69) -> 0.42638969 | E70: =SUM(E66:E69) -> 0.46082528 | F70: =SUM(F66:F69) -> 0.43687096 | G70: =SUM(G66:G69) -> 0.46186039 | H70: =SUM(H66:H69) -> 0.48198215 | I70: =SUM(I66:I69) -> 0.5211347 | J70: =SUM(J66:J69) -> 0.55 | ... L70: =SUM(L66:L69) -> 0.56
C89: 2021 | D89: 2022 | E89: 2023 | F89: 2024E
B90: DTC | C90: =MODEL!$U$82 -> 0.38020977 | D90: =MODEL!Z82 -> 0.36420915 | E90: =MODEL!AE82 -> 0.37486747 | F90: =MODEL!AJ82 -> 0.40667731
B91: Wholesale | C91: =1-C90 -> 0.61979023 | D91: =1-D90 -> 0.63579085 | E91: =1-E90 -> 0.62513253 | F91: =1-F90 -> 0.59332269
C93: =C89 -> 2021 | D93: =D89 -> 2022 | E93: =E89 -> 2023 | F93: =F89 -> 2024E
B94: Europe | C94: =MODEL!U8 -> 0.35937069
B95: North America | C95: =MODEL!U15 -> 0.56513939
...

Sheet Vs consensus
C1: 2021E | F1: 2022E | I1: 2023E | L1: 2024E
C2: GSe | D2: Guidance | E2: GSe/Guidance | F2: GSe | G2: Guidance | H2: GSe/Guidance | I2: GSe | J2: Guidance | K2: GSe/Guidance | L2: GSe | M2: Guidance | N2: GSe/Guidance | Q2: GSe vs VA Consensus | R2: 2022E | U2: 2023E | X2: 2024E | AA2: 2025E
