Workbook
Name \q: #REF!
Name \S: #REF!
Name __eps96: #REF!
Name __inc90: #REF!
Name __int94: #REF!
Name __int95: #REF!
Name __int96: #REF!
Name __qtr1: #REF!
Name __qtr2: #REF!
Name __qtr4: #REF!
Name __sga87: #REF!
Name __sga88: #REF!
Name __sga89: #REF!
Name __sga90: #REF!
Name __sga91: #REF!
Name __sga93: #REF!
Name __sls87: #REF!
Name __sls88: #REF!
Name __sls89: #REF!
Name __sls93: #REF!
Name __sls95: #REF!
Name __sls96: #REF!
Name __tax91: #REF!
Name __tax92: #REF!
Name __tax94: #REF!
Name __tax95: #REF!
Name __tax96: #REF!
Name _107_._0Restructuring_char: #REF!
Name _108_._0Restructuring_char: #REF!
Name _116_._0SGA_gro: #REF!
Name _117_._0SGA_gro: #REF!
Name _125_._0Shares_repurchase_liabil: #REF!
Name _126_._0Shares_repurchase_liabil: #REF!
Name _134_0FAMERangeSheet: #REF!
Name _135_0FAMERangeSheet: #REF!
Name _143_0FAMERangeSheet: #REF!
Name _144_0FAMERangeSheet: #REF!
Name _152_0FAMERangeSheet: #REF!
Name _153_0FAMERangeSheet: #REF!
Name _161_0FAMERangeSheet: #REF!
Name _162_0FAMERangeSheet: #REF!
Name _17_0UniqueRang: #REF!
Name _170_0FAMERangeSheet: #REF!
Name _171_0FAMERangeSheet: #REF!
Name _179_0FAMERangeSheet: #REF!
Name _18_0UniqueRang: #REF!
Name _180_0FAMERangeSheet: #REF!
Name _188_0FAMERangeSheet: #REF!
Name _189_0FAMERangeSheet: #REF!
Name _197_0FAMERangeSheet: #REF!
Name _198_0FAMERangeSheet: #REF!
Name _206_0UniqueRang: #REF!
Name _207_0UniqueRang: #REF!
Name _215_0UniqueRang: #REF!
Name _216_0UniqueRang: #REF!
Name _224_0UniqueRang: #REF!
Name _225_0UniqueRang: #REF!
Name _233_0UniqueRange: #REF!
Name _234_0UniqueRange: #REF!
Name _242_0UniqueRange: #REF!

Sheet 1. Cover
F3: Nike Inc. (NKE)
F4: COMPANY MODEL
B9: Sources: Company data, Goldman Sachs Global Investment Research
B11: Date: October 1st, 2026
B13: Brooke Roach, CFA
B14: Managing Director
B15: tel: 212-357-2421
B16: brooke.roach@gs.com
B18: Mentesnot Adamu
B19: Analyst
B20: tel: 801-744-0630
B21: mentesnot.adamu@gs.com
B23: Carly Chasen
B24: Analyst
... B26: carly.chasen@gs.com

Sheet 2. Consolidated
B1: Nike (NKE)
B2: Consolidated Financial Results
B3: $ millions except per share data, FY ending May
C5: 35216 | D5: 35581 | E5: 35946 | F5: 36311 | G5: 36677 | H5: 37042 | I5: 37407 | J5: 37772 | K5: 38138 | L5: 38503 | M5: 38868 | N5: 39233 | O5: 39599 | P5: 39964 | Q5: 40329 | R5: 40421 | S5: 40512 | T5: 40602 | U5: 40694 | V5: 40694 | W5: 40786 | X5: 40877 | Y5: 40968 | Z5: 41060 | AA5: 41060 | AB5: 41060 | AC5: 41152 | AD5: 41243 | AE5: 41333 | AF5: 41425 | AG5: 41425 | AH5: 41517 | AI5: 41608 | AJ5: 41698 | AK5: 41790 | AL5: 41790 | AM5: 41882 | AN5: 41973 | AO5: 42063 | AP5: 42155 | AQ5: 42155 | AR5: 42247 | AS5: 42338 | AT5: 42429 | AU5: 42521 | AV5: 42521 | AW5: 42613 | AX5: 42704 | AY5: 42794 | AZ5: 42886 | BA5: 42886 | BB5: 42978 | BC5: 43069 | BD5: 43159 | BE5: 43251 | BF5: 43251 | BG5: 43343 | BH5: 43434 | BI5: 43524 | BJ5: 43616 | BK5: 43616 | BL5: 43708 | BM5: 43799 | BN5: 43890 | BO5: 43982 | BP5: 43982 | BQ5: 44074 | BR5: 44165 | BS5: 44255 | BT5: 44347 | BU5: 44347 | BV5: 44439 | BW5: 44530 | BX5: 44620 | BY5: 44712 | BZ5: 44712 | CA5: 44804 | CB5: 44895 | CC5: 44985 | CD5: 45077 | CE5: 45077 | CF5: 45169 | CG5: 45260 | CH5: 45350 | CI5: 45443 | CJ5: 45443 | CK5: 45535 | CL5: 45626 | CM5: 45716 | CN5: 45808 | CO5: 45808 | CP5: 45900 | CQ5: 45991 | CR5: 46081 | CS5: 46173 | CT5: 46173 | CU5: 46265 | CV5: 46356 | CW5: 46446 | CX5: 46538 | CY5: 46538 | CZ5: 46630 | DA5: 46721 | DB5: 46811 | DC5: 46904 | DD5: 46904 | DE5: =DD5+91 -> 46995 | DF5: =DE5+91 -> 47086 | DG5: =DF5+91 -> 47177 | DH5: =DG5+91 -> 47268 | DI5: 46904
C6: 1996 | D6: 1997 | E6: 1998 | F6: 1999 | G6: 2000 | H6: 2001 | I6: 2002 | J6: 2003 | K6: 2004 | L6: 2005 | M6: 2006 | N6: 2007 | O6: 2008 | P6: 2009 | Q6: 2010 | R6: 1Q | S6: 2Q | T6: 3Q | U6: 4Q | V6: 2011 | W6: 1Q | X6: 2Q | Y6: 3Q | Z6: 4Q | AA6: 2012 | AB6: 2012R | AC6: 1Q | AD6: 2Q | AE6: 3Q | AF6: 4Q | AG6: 2013 | AH6: 1Q | AI6: 2Q | AJ6: 3Q | AK6: 4Q | AL6: 2014 | AM6: 1Q | AN6: 2Q | AO6: 3Q | AP6: 4Q | AQ6: 2015 | AR6: 1Q | AS6: 2Q | AT6: 3Q | AU6: 4Q | AV6: 2016 | AW6: 1Q | AX6: 2Q | AY6: 3Q | AZ6: 4Q | BA6: 2017 | BB6: 1Q | BC6: 2Q | BD6: 3Q | BE6: 4Q | BF6: 2018 | BG6: 1Q | BH6: 2Q | BI6: 3Q | BJ6: 4Q | BK6: 2019 | BL6: 1Q | BM6: 2Q | BN6: 3Q | BO6: 4Q | BP6: 2020 | BQ6: 1Q | BR6: 2Q | BS6: 3Q | BT6: 4Q | BU6: 2021 | BV6: 1Q | BW6: 2Q | BX6: 3Q | BY6: 4Q | BZ6: 2022 | CA6: 1Q | CB6: 2Q | CC6: 3Q | CD6: 4Q | CE6: 2023 | CF6: 1Q | CG6: 2Q | CH6: 3Q | CI6: 4Q | CJ6: 2024 | CK6: 1Q | CL6: 2Q | CM6: 3Q | CN6: 4Q | CO6: 2025 | CP6: 1Q | CQ6: 2Q | CR6: 3Q | CS6: 4Q | CT6: 2026 | CU6: 1Q | CV6: 2QE | CW6: 3QE | CX6: 4QE | CY6: 2027E | CZ6: 1QE | DA6: 2QE | DB6: 3QE | DC6: 4QE | DD6: 2028E | DE6: 1QE | DF6: 2QE | DG6: 3QE | DH6: 4QE | DI6: 2029E
B7: DIVISIONAL SUMMARY
B8: Net Sales
B9: North America | C9: 3615.062 | D9: 5201.624 | E9: 5139.412 | F9: 4750.711 | G9: 4732.073 | H9: 4819 | I9: 4669.6 | J9: 4658.5 | K9: 4786.3 | L9: 5129.3 | M9: 5722.5 | N9: 6107.1 | O9: 6414.5 | P9: =P31 -> 6778.3 | Q9: =Q31 -> 6696 | R9: =+'3. Segment Analysis'!R9 -> 1903 | S9: =+'3. Segment Analysis'!S9 -> 1701 | T9: =+'3. Segment Analysis'!T9 -> 1836 | U9: =+'3. Segment Analysis'!U9 -> 2139 | V9: =+'3. Segment Analysis'!V9 -> 7579 | W9: =+'3. Segment Analysis'!W9 -> 2200 | X9: =+'3. Segment Analysis'!X9 -> 2066 | Y9: =+'3. Segment Analysis'!Y9 -> 2149 | ... AA9: =+'3. Segment Analysis'!AA9 -> 8839 | AB9: =AA9 -> 8839 | AC9: =+'3. Segment Analysis'!AC9 -> 2866 | AD9: =+'3. Segment Analysis'!AD9 -> 2564 | AE9: =+'3. Segment Analysis'!AE9 -> 2737 | AF9: =+'3. Segment Analysis'!AF9 -> 2991 | AG9: =+'3. Segment Analysis'!AG9 -> 11158 | AH9: =+'3. Segment Analysis'!AH9 -> 3135 | AI9: =+'3. Segment Analysis'!AI9 -> 2801 | AJ9: =+'3. Segment Analysis'!AJ9 -> 3069 | ... DI9: =+'3. Segment Analysis'!DI9 -> 18673.44
B10: EMEA | C10: -- | D10: -- | E10: -- | F10: -- | G10: -- | H10: -- | I10: -- | J10: -- | K10: -- | L10: -- | M10: -- | N10: -- | O10: -- | P10: =P32+P33 -> 5512.3 | Q10: =Q32+Q33 -> 5041.9 | R10: =+'3. Segment Analysis'!R10 -> 1335 | S10: =+'3. Segment Analysis'!S10 -> 1077 | T10: =+'3. Segment Analysis'!T10 -> 1175 | U10: =+'3. Segment Analysis'!U10 -> 1311 | V10: =+'3. Segment Analysis'!V10 -> 4898 | W10: =+'3. Segment Analysis'!W10 -> 1562 | X10: =+'3. Segment Analysis'!X10 -> 1176 | Y10: =+'3. Segment Analysis'!Y10 -> 1237 | ... AA10: =+'3. Segment Analysis'!AA10 -> 5344 | AB10: =AA10 -> 5344 | AC10: =+'3. Segment Analysis'!AC10 -> 1503 | AD10: =+'3. Segment Analysis'!AD10 -> 1160 | AE10: =+'3. Segment Analysis'!AE10 -> 1360 | AF10: =+'3. Segment Analysis'!AF10 -> 1399 | AG10: =+'3. Segment Analysis'!AG10 -> 5422 | AH10: =+'3. Segment Analysis'!AH10 -> 1667 | AI10: =+'3. Segment Analysis'!AI10 -> 1369 | AJ10: =+'3. Segment Analysis'!AJ10 -> 1648 | ... DI10: =+'3. Segment Analysis'!DI10 -> 11085.17
B11: Greater China | C11: -- | D11: -- | E11: -- | F11: -- | G11: -- | H11: -- | I11: -- | J11: -- | K11: -- | L11: -- | M11: -- | N11: =O11/1.5 -> 902.66667 | O11: 1354 | P11: =P34 -> 1743.3 | Q11: =Q34 -> 1741.8 | R11: =+'3. Segment Analysis'!R11 -> 460 | S11: =+'3. Segment Analysis'!S11 -> 482 | T11: =+'3. Segment Analysis'!T11 -> 554 | U11: =+'3. Segment Analysis'!U11 -> 564 | V11: =+'3. Segment Analysis'!V11 -> 2060 | W11: =+'3. Segment Analysis'!W11 -> 528 | X11: =+'3. Segment Analysis'!X11 -> 650 | Y11: =+'3. Segment Analysis'!Y11 -> 694 | ... AA11: =+'3. Segment Analysis'!AA11 -> 2539 | AB11: =AA11 -> 2539 | AC11: =+'3. Segment Analysis'!AC11 -> 577 | AD11: =+'3. Segment Analysis'!AD11 -> 582 | AE11: =+'3. Segment Analysis'!AE11 -> 641 | AF11: =+'3. Segment Analysis'!AF11 -> 678 | AG11: =+'3. Segment Analysis'!AG11 -> 2478 | AH11: =+'3. Segment Analysis'!AH11 -> 574 | AI11: =+'3. Segment Analysis'!AI11 -> 629 | AJ11: =+'3. Segment Analysis'!AJ11 -> 697 | ... DI11: =+'3. Segment Analysis'!DI11 -> 3624.0423
B12: APAC & Latam | C12: -- | D12: -- | E12: -- | F12: -- | G12: -- | H12: -- | I12: -- | J12: -- | K12: -- | L12: -- | M12: -- | N12: -- | O12: -- | P12: =P36+P35 -> 2627.9 | Q12: =Q36+Q35 -> 2923.6 | R12: =+'3. Segment Analysis'!R12 -> 754 | S12: =+'3. Segment Analysis'!S12 -> 947 | T12: =+'3. Segment Analysis'!T12 -> 838 | U12: =+'3. Segment Analysis'!U12 -> 963 | V12: =+'3. Segment Analysis'!V12 -> 3502 | W12: =+'3. Segment Analysis'!W12 -> 990 | X12: =+'3. Segment Analysis'!X12 -> 1145 | Y12: =+'3. Segment Analysis'!Y12 -> 994 | ... AA12: =+'3. Segment Analysis'!AA12 -> 4239 | AB12: =AA12 -> 4239 | AC12: =+'3. Segment Analysis'!AC12 -> 1094 | AD12: =+'3. Segment Analysis'!AD12 -> 1314 | AE12: =+'3. Segment Analysis'!AE12 -> 1062 | AF12: =+'3. Segment Analysis'!AF12 -> 1238 | AG12: =+'3. Segment Analysis'!AG12 -> 4708 | AH12: =+'3. Segment Analysis'!AH12 -> 1060 | AI12: =+'3. Segment Analysis'!AI12 -> 1240 | AJ12: =+'3. Segment Analysis'!AJ12 -> 1114 | ... DI12: =+'3. Segment Analysis'!DI12 -> 6214.6093
B13: Global Brand | C13: -- | D13: -- | E13: -- | F13: -- | G13: -- | H13: -- | I13: -- | J13: -- | K13: -- | L13: -- | M13: -- | N13: -- | O13: -- | P13: =+P37 -> 95.3 | Q13: =+Q37 -> 105.3 | R13: =+'3. Segment Analysis'!R13 -> 31 | S13: =+'3. Segment Analysis'!S13 -> 24 | T13: =+'3. Segment Analysis'!T13 -> 22 | U13: =+'3. Segment Analysis'!U13 -> 29 | V13: =+'3. Segment Analysis'!V13 -> 106 | W13: =+'3. Segment Analysis'!W13 -> 33 | X13: =+'3. Segment Analysis'!X13 -> 25 | Y13: =+'3. Segment Analysis'!Y13 -> 27 | ... AA13: =+'3. Segment Analysis'!AA13 -> 111 | AB13: =AA13 -> 111 | AC13: =+'3. Segment Analysis'!AC13 -> 27 | AD13: =+'3. Segment Analysis'!AD13 -> 28 | AE13: =+'3. Segment Analysis'!AE13 -> 29 | AF13: =+'3. Segment Analysis'!AF13 -> 31 | AG13: =+'3. Segment Analysis'!AG13 -> 115 | AH13: =+'3. Segment Analysis'!AH13 -> 32 | AI13: =+'3. Segment Analysis'!AI13 -> 31 | AJ13: =+'3. Segment Analysis'!AJ13 -> 26 | ... DI13: =+'3. Segment Analysis'!DI13 -> 46
B14: Total Nike Brand | C14: -- | D14: -- | E14: -- | F14: -- | G14: -- | H14: -- | I14: -- | J14: -- | K14: -- | L14: -- | M14: -- | N14: -- | O14: -- | P14: =SUM(P9:P13) -> 16757.1 | Q14: =SUM(Q9:Q13) -> 16508.6 | R14: =SUM(R9:R13) -> 4483 | S14: =SUM(S9:S13) -> 4231 | T14: =SUM(T9:T13) -> 4425 | U14: =SUM(U9:U13) -> 5006 | V14: =SUM(V9:V13) -> 18145 | W14: =SUM(W9:W13) -> 5313 | ... DI14: =SUM(DI9:DI13) -> 39643.261
B15: Converse | C15: -- | D15: -- | E15: -- | F15: -- | G15: -- | H15: -- | I15: -- | J15: -- | K15: -- | L15: -- | M15: -- | N15: -- | O15: -- | P15: =P39 -> 2419 | Q15: =Q39 -> 2529.5 | R15: =+'3. Segment Analysis'!R18 -> 694 | S15: =+'3. Segment Analysis'!S18 -> 639 | T15: =+'3. Segment Analysis'!T18 -> 680 | U15: =+'3. Segment Analysis'!U18 -> 773 | V15: =+'3. Segment Analysis'!V18 -> 2786 | W15: =+'3. Segment Analysis'!W18 -> 773 | X15: =+'3. Segment Analysis'!X18 -> 673 | Y15: =+'3. Segment Analysis'!Y18 -> 753 | ... AA15: =+'3. Segment Analysis'!AA18 -> 3095 | AB15: =+AA15 -> 3095 | AC15: =+'3. Segment Analysis'!AC18 -> 418 | AD15: =+'3. Segment Analysis'!AD18 -> 316 | AE15: =+'3. Segment Analysis'!AE18 -> 361 | AF15: =+'3. Segment Analysis'!AF18 -> 354 | AG15: =+'3. Segment Analysis'!AG18 -> 1449 | AH15: =+'3. Segment Analysis'!AH18 -> 494 | AI15: =+'3. Segment Analysis'!AI18 -> 360 | AJ15: =+'3. Segment Analysis'!AJ18 -> 420 | ... DI15: =+'3. Segment Analysis'!DI18 -> 861.872
B16: Corporate | C16: -- | D16: -- | E16: -- | F16: -- | G16: -- | H16: -- | I16: -- | J16: -- | K16: -- | L16: -- | M16: -- | N16: -- | O16: -- | P16: =P40 -> 0 | Q16: =Q40 -> -24.1 | R16: =+'3. Segment Analysis'!R19 -> -2 | S16: =+'3. Segment Analysis'!S19 -> -28 | T16: =+'3. Segment Analysis'!T19 -> -26 | U16: =+'3. Segment Analysis'!U19 -> -13 | V16: =+'3. Segment Analysis'!V19 -> -69 | W16: =+'3. Segment Analysis'!W19 -> -5 | X16: =+'3. Segment Analysis'!X19 -> -4 | Y16: =+'3. Segment Analysis'!Y19 -> -8 | ... AA16: =+'3. Segment Analysis'!AA19 -> -39 | AB16: =+AA16 -> -39 | AC16: =+'3. Segment Analysis'!AC19 -> -11 | AD16: =+'3. Segment Analysis'!AD19 -> -9 | AE16: =+'3. Segment Analysis'!AE19 -> -3 | AF16: =+'3. Segment Analysis'!AF19 -> 6 | AG16: =+'3. Segment Analysis'!AG19 -> -17 | AH16: =+'3. Segment Analysis'!AH19 -> 9 | AI16: =+'3. Segment Analysis'!AI19 -> 1 | AJ16: =+'3. Segment Analysis'!AJ19 -> -2 | ... DI16: =+'3. Segment Analysis'!DI19 -> 0
B17: Net Sales | C17: =C57 -> 6470.625 | D17: =D57 -> 9186.539 | E17: =E57 -> 9553.1 | F17: =F57 -> 8776.9 | G17: =G57 -> 8995.1 | H17: =H57 -> 9488.8 | I17: =I57 -> 9893 | J17: =J57 -> 10697 | ... O17: =O57 -> 18627 | P17: =+P14+P15+P16 -> 19176.1 | Q17: =+Q14+Q15+Q16 -> 19014 | R17: =+R14+R15+R16 -> 5175 | S17: =+S14+S15+S16 -> 4842 | T17: =+T14+T15+T16 -> 5079 | U17: =+U14+U15+U16 -> 5766 | V17: =+V14+V15+V16 -> 20862 | W17: =+W14+W15+W16 -> 6081 | ... DI17: =+DI14+DI15+DI16 -> 40505.133
B19: Operating Profit
B20: North America | C20: -- | D20: -- | E20: -- | F20: -- | G20: -- | H20: -- | I20: -- | J20: -- | K20: -- | L20: -- | M20: -- | N20: -- | O20: -- | P20: =P44 -> 1429.3 | Q20: =Q44 -> 1538.1 | R20: =+'3. Segment Analysis'!R163 -> 443 | S20: =+'3. Segment Analysis'!S163 -> 356 | T20: =+'3. Segment Analysis'!T163 -> 419 | U20: =+'3. Segment Analysis'!U163 -> 518 | V20: =+'3. Segment Analysis'!V163 -> 1736 | W20: =+'3. Segment Analysis'!W163 -> 534 | X20: =+'3. Segment Analysis'!X163 -> 418 | Y20: =+'3. Segment Analysis'!Y163 -> 496 | ... AA20: =+'3. Segment Analysis'!AA163 -> 2007 | AC20: =+'3. Segment Analysis'!AC163 -> 645 | AD20: =+'3. Segment Analysis'!AD163 -> 565 | AE20: =+'3. Segment Analysis'!AE163 -> 653 | AF20: =+'3. Segment Analysis'!AF163 -> 778 | AG20: =AG44 -> 2641 | AH20: =+'3. Segment Analysis'!AH163 -> 813 | AI20: =+'3. Segment Analysis'!AI163 -> 649 | AJ20: =+'3. Segment Analysis'!AJ163 -> 729 | AK20: =+'3. Segment Analysis'!AK163 -> 888 | AL20: =+'3. Segment Analysis'!AL163 -> 3079 | AM20: =+'3. Segment Analysis'!AM163 -> 970 | AN20: =+'3. Segment Analysis'!AN163 -> 785 | AO20: =+'3. Segment Analysis'!AO163 -> 830 | ... DI20: =+'3. Segment Analysis'!DI163 -> 5228.2873
B21: EMEA | C21: -- | D21: -- | E21: -- | F21: -- | G21: -- | H21: -- | I21: -- | J21: -- | K21: -- | L21: -- | M21: -- | N21: -- | O21: -- | P21: =P45+P46 -> 1354.2 | Q21: =Q45+Q46 -> 1136.9 | R21: =+'3. Segment Analysis'!R164 -> 353 | S21: =+'3. Segment Analysis'!S164 -> 190 | T21: =+'3. Segment Analysis'!T164 -> 222 | U21: =+'3. Segment Analysis'!U164 -> 209 | V21: =+'3. Segment Analysis'!V164 -> 974 | W21: =+'3. Segment Analysis'!W164 -> 293 | X21: =+'3. Segment Analysis'!X164 -> 125 | Y21: =+'3. Segment Analysis'!Y164 -> 209 | ... AA21: =+'3. Segment Analysis'!AA164 -> 831 | AC21: =+'3. Segment Analysis'!AC164 -> 266 | AD21: =+'3. Segment Analysis'!AD164 -> 147 | AE21: =+'3. Segment Analysis'!AE164 -> 243 | AF21: =+'3. Segment Analysis'!AF164 -> 221 | AG21: =AG45+AG46 -> 877 | AH21: =+'3. Segment Analysis'!AH164 -> 346 | AI21: =+'3. Segment Analysis'!AI164 -> 171 | AJ21: =+'3. Segment Analysis'!AJ164 -> 354 | AK21: =+'3. Segment Analysis'!AK164 -> 263 | AL21: =+'3. Segment Analysis'!AL164 -> 1134 | AM21: =+'3. Segment Analysis'!AM164 -> 472 | AN21: =+'3. Segment Analysis'!AN164 -> 318 | AO21: =+'3. Segment Analysis'!AO164 -> 385 | ... DI21: =+'3. Segment Analysis'!DI164 -> 2569.6072
B22: Greater China | C22: -- | D22: -- | E22: -- | F22: -- | G22: -- | H22: -- | I22: -- | J22: -- | K22: -- | L22: -- | M22: -- | N22: -- | O22: -- | P22: =P47 -> 575.2 | Q22: =Q47 -> 637.1 | R22: =+'3. Segment Analysis'!R165 -> 164 | S22: =+'3. Segment Analysis'!S165 -> 174 | T22: =+'3. Segment Analysis'!T165 -> 213 | U22: =+'3. Segment Analysis'!U165 -> 226 | V22: =+'3. Segment Analysis'!V165 -> 777 | W22: =+'3. Segment Analysis'!W165 -> 171 | X22: =+'3. Segment Analysis'!X165 -> 220 | Y22: =+'3. Segment Analysis'!Y165 -> 273 | ... AA22: =+'3. Segment Analysis'!AA165 -> 911 | AC22: =+'3. Segment Analysis'!AC165 -> 165 | AD22: =+'3. Segment Analysis'!AD165 -> 187 | AE22: =+'3. Segment Analysis'!AE165 -> 218 | AF22: =+'3. Segment Analysis'!AF165 -> 243 | AG22: =AG47 -> 813 | AH22: =+'3. Segment Analysis'!AH165 -> 170 | AI22: =+'3. Segment Analysis'!AI165 -> 197 | AJ22: =+'3. Segment Analysis'!AJ165 -> 234 | AK22: =+'3. Segment Analysis'!AK165 -> 223 | AL22: =+'3. Segment Analysis'!AL165 -> 824 | AM22: =+'3. Segment Analysis'!AM165 -> 218 | AN22: =+'3. Segment Analysis'!AN165 -> 258 | AO22: =+'3. Segment Analysis'!AO165 -> 251 | ... DI22: =+'3. Segment Analysis'!DI165 -> 906.40022
B23: APAC & Latam | C23: -- | D23: -- | E23: -- | F23: -- | G23: -- | H23: -- | I23: -- | J23: -- | K23: -- | L23: -- | M23: -- | N23: -- | O23: -- | P23: =P48+P49 -> 548 | Q23: =Q48+Q49 -> 672.9 | R23: =+'3. Segment Analysis'!R166 -> 151 | S23: =+'3. Segment Analysis'!S166 -> 230 | T23: =+'3. Segment Analysis'!T166 -> 204 | U23: =+'3. Segment Analysis'!U166 -> 217 | V23: =+'3. Segment Analysis'!V166 -> 802 | W23: =+'3. Segment Analysis'!W166 -> 224 | X23: =+'3. Segment Analysis'!X166 -> 282 | Y23: =+'3. Segment Analysis'!Y166 -> 239 | ... AA23: =+'3. Segment Analysis'!AA166 -> 989 | AC23: =+'3. Segment Analysis'!AC166 -> 244 | AD23: =+'3. Segment Analysis'!AD166 -> 343 | AE23: =+'3. Segment Analysis'!AE166 -> 240 | AF23: =+'3. Segment Analysis'!AF166 -> 300 | AG23: =AG48+AG49 -> 1127 | AH23: =+'3. Segment Analysis'!AH166 -> 234 | AI23: =+'3. Segment Analysis'!AI166 -> 290 | AJ23: =+'3. Segment Analysis'!AJ166 -> 249 | AK23: =+'3. Segment Analysis'!AK166 -> 310 | AL23: =+'3. Segment Analysis'!AL166 -> 1083 | AM23: =+'3. Segment Analysis'!AM166 -> 167 | AN23: =+'3. Segment Analysis'!AN166 -> 265 | AO23: =+'3. Segment Analysis'!AO166 -> 256 | ... DI23: =+'3. Segment Analysis'!DI166 -> 1680.3031
B24: Global Brand | C24: -- | D24: -- | E24: -- | F24: -- | G24: -- | H24: -- | I24: -- | J24: -- | K24: -- | L24: -- | M24: -- | N24: -- | O24: -- | P24: =P50 -> -811.5 | Q24: =Q50 -> -866.8 | R24: =+'3. Segment Analysis'!R167 -> -245 | S24: =+'3. Segment Analysis'!S167 -> -221 | T24: =+'3. Segment Analysis'!T167 -> -237 | U24: =+'3. Segment Analysis'!U167 -> -268 | V24: =+'3. Segment Analysis'!V167 -> -971 | W24: =+'3. Segment Analysis'!W167 -> -261 | X24: =+'3. Segment Analysis'!X167 -> -273 | Y24: =+'3. Segment Analysis'!Y167 -> -292 | ... AA24: =+'3. Segment Analysis'!AA167 -> -1177 | AC24: =+'3. Segment Analysis'!AC167 -> -456 | AD24: =+'3. Segment Analysis'!AD167 -> -410 | AE24: =+'3. Segment Analysis'!AE167 -> -414 | AF24: =+'3. Segment Analysis'!AF167 -> -466 | AG24: =AG50 -> -1746 | AH24: =+'3. Segment Analysis'!AH167 -> -466 | AI24: =+'3. Segment Analysis'!AI167 -> -462 | AJ24: =+'3. Segment Analysis'!AJ167 -> -528 | AK24: =+'3. Segment Analysis'!AK167 -> -549 | AL24: =+'3. Segment Analysis'!AL167 -> -2005 | AM24: =+'3. Segment Analysis'!AM167 -> -533 | AN24: =+'3. Segment Analysis'!AN167 -> -554 | AO24: =+'3. Segment Analysis'!AO167 -> -552 | ... DI24: =+'3. Segment Analysis'!DI167 -> -5047.1868
B25: Total Nike Brand | C25: -- | D25: -- | E25: -- | F25: -- | G25: -- | H25: -- | I25: -- | J25: -- | K25: -- | L25: -- | M25: -- | N25: -- | O25: -- | P25: =SUM(P20:P24) -> 3095.2 | Q25: =SUM(Q20:Q24) -> 3118.2 | R25: =SUM(R20:R24) -> 866 | S25: =SUM(S20:S24) -> 729 | T25: =SUM(T20:T24) -> 821 | U25: =SUM(U20:U24) -> 902 | V25: =SUM(V20:V24) -> 3318 | W25: =SUM(W20:W24) -> 961 | ... AA25: =SUM(AA20:AA24) -> 3561 | AC25: =SUM(AC20:AC24) -> 864 | AD25: =SUM(AD20:AD24) -> 832 | AE25: =SUM(AE20:AE24) -> 940 | AF25: =SUM(AF20:AF24) -> 1076 | AG25: =SUM(AG20:AG24) -> 3712 | AH25: =SUM(AH20:AH24) -> 1097 | AI25: =SUM(AI20:AI24) -> 845 | AJ25: =SUM(AJ20:AJ24) -> 1038 | ... DI25: =SUM(DI20:DI24) -> 5337.4111
B26: Converse | C26: -- | D26: -- | E26: -- | F26: -- | G26: -- | H26: -- | I26: -- | J26: -- | K26: -- | L26: -- | M26: -- | N26: -- | O26: -- | P26: =P52 -> 208.7 | Q26: =Q52 -> 299.4 | R26: =+'3. Segment Analysis'!R173 -> 109 | S26: =+'3. Segment Analysis'!S173 -> 59 | T26: =+'3. Segment Analysis'!T173 -> 85 | U26: =+'3. Segment Analysis'!U173 -> 82 | V26: =+'3. Segment Analysis'!V173 -> 335 | W26: =+'3. Segment Analysis'!W173 -> 86 | X26: =+'3. Segment Analysis'!X173 -> 57 | Y26: =+'3. Segment Analysis'!Y173 -> 87 | ... AA26: =+'3. Segment Analysis'!AA173 -> 341 | AC26: =+'3. Segment Analysis'!AC173 -> 124 | AD26: =+'3. Segment Analysis'!AD173 -> 91 | AE26: =+'3. Segment Analysis'!AE173 -> 121 | AF26: =+'3. Segment Analysis'!AF173 -> 89 | AG26: =AG52 -> 425 | AH26: =+'3. Segment Analysis'!AH173 -> 169 | AI26: =+'3. Segment Analysis'!AI173 -> 100 | AJ26: =+'3. Segment Analysis'!AJ173 -> 133 | AK26: =+'3. Segment Analysis'!AK173 -> 94 | AL26: =+'3. Segment Analysis'!AL173 -> 496 | AM26: =+'3. Segment Analysis'!AM173 -> 186 | AN26: =+'3. Segment Analysis'!AN173 -> 88 | AO26: =+'3. Segment Analysis'!AO173 -> 163 | ... DI26: =+'3. Segment Analysis'!DI173 -> 4.51189
B27: Corporate | C27: -- | D27: -- | E27: -- | F27: -- | G27: -- | H27: -- | I27: -- | J27: -- | K27: -- | L27: -- | M27: -- | N27: -- | O27: -- | P27: =P53 -> -760.6 | Q27: =Q53 -> -894.4 | R27: =+'3. Segment Analysis'!R174 -> -221 | S27: =+'3. Segment Analysis'!S174 -> -178 | T27: =+'3. Segment Analysis'!T174 -> -199 | U27: =+'3. Segment Analysis'!U174 -> -207 | V27: =+'3. Segment Analysis'!V174 -> -805 | W27: =+'3. Segment Analysis'!W174 -> -195 | X27: =+'3. Segment Analysis'!X174 -> -208 | Y27: =+'3. Segment Analysis'!Y174 -> -242 | ... AA27: =+'3. Segment Analysis'!AA174 -> -916 | AC27: =+'3. Segment Analysis'!AC174 -> -196 | AD27: =+'3. Segment Analysis'!AD174 -> -214 | AE27: =+'3. Segment Analysis'!AE174 -> -207 | AF27: =+'3. Segment Analysis'!AF174 -> -267 | AG27: =AG53 -> -884 | AH27: =+'3. Segment Analysis'!AH174 -> -218 | AI27: =+'3. Segment Analysis'!AI174 -> -220 | AJ27: =+'3. Segment Analysis'!AJ174 -> -282 | AK27: =+'3. Segment Analysis'!AK174 -> -301 | AL27: =+'3. Segment Analysis'!AL174 -> -1021 | AM27: =+'3. Segment Analysis'!AM174 -> -242 | AN27: =+'3. Segment Analysis'!AN174 -> -273 | AO27: =+'3. Segment Analysis'!AO174 -> -281 | ... DI27: =+'3. Segment Analysis'!DI174 -> -2852.9313
B28: EBIT | C28: -- | D28: -- | E28: -- | F28: -- | G28: -- | H28: -- | I28: -- | J28: -- | K28: -- | L28: -- | M28: -- | N28: -- | O28: -- | P28: =SUM(P25:P27) -> 2543.3 | Q28: =SUM(Q25:Q27) -> 2523.2 | R28: =+R25+R26+R27 -> 754 | S28: =+S25+S26+S27 -> 610 | T28: =+T25+T26+T27 -> 707 | U28: =+U25+U26+U27 -> 777 | V28: =+V25+V26+V27 -> 2848 | W28: =+W25+W26+W27 -> 852 | X28: =+X25+X26+X27 -> 621 | Y28: =+Y25+Y26+Y27 -> 770 | ... AA28: =+AA25+AA26+AA27 -> 2986 | AC28: =+AC25+AC26+AC27 -> 792 | AD28: =+AD25+AD26+AD27 -> 709 | AE28: =+AE25+AE26+AE27 -> 854 | AF28: =+AF25+AF26+AF27 -> 898 | AG28: =SUM(AG25:AG27) -> 3253 | AH28: =+AH25+AH26+AH27 -> 1048 | AI28: =+AI25+AI26+AI27 -> 725 | AJ28: =+AJ25+AJ26+AJ27 -> 889 | AK28: =+AK25+AK26+AK27 -> 928 | AL28: =+AL25+AL26+AL27 -> 3590 | AM28: =+AM25+AM26+AM27 -> 1238 | AN28: =+AN25+AN26+AN27 -> 887 | AO28: =+AO25+AO26+AO27 -> 1052 | ... DI28: =+DI25+DI26+DI27 -> 2488.9917
B30: Net Sales - OLD SEGMENTS
B31: North America | C31: 3615.062 | D31: 5201.624 | E31: 5139.412 | F31: 4750.711 | G31: 4732.073 | H31: 4819 | I31: 4669.6 | J31: 4658.5 | K31: 4786.3 | L31: 5129.3 | M31: 5722.5 | N31: 6107.1 | O31: 6414.5 | P31: 6778.3 | Q31: 6696 | R31: 1903 | S31: 1701 | T31: 1836 | U31: 2139 | V31: =SUM(R31:U31) -> 7579 | W31: 2200 | X31: 2066 | Y31: 2149 | Z31: 2424 | AA31: =SUM(W31:Z31) -> 8839 | AC31: 2866 | AD31: 2564 | AE31: 2737 | AF31: 2991 | AG31: =SUM(AC31:AF31) -> 11158 | AH31: 3135 | AI31: 2801 | AJ31: 3069 | AK31: 3294 | AL31: =SUM(AH31:AK31) -> 12299 | AM31: 3513 | AN31: 3241 | AO31: 3254 | AP31: 3732 | AQ31: =SUM(AM31:AP31) -> 13740 | AR31: 3799 | AS31: 3547 | AT31: 3683 | AU31: 3735 | AV31: =SUM(AR31:AU31) -> 14764 | AW31: 4031 | AX31: 3650 | AY31: 3782 | AZ31: 3753 | BA31: =SUM(AW31:AZ31) -> 15216 | BB31: -- | BC31: -- | BD31: -- | BE31: -- | BF31: -- | BG31: -- | BH31: -- | BI31: -- | BJ31: -- | BK31: -- | BL31: -- | BM31: -- | BN31: -- | BO31: -- | BP31: -- | BQ31: -- | BR31: -- | BS31: -- | BT31: -- | BU31: -- | BV31: -- | BW31: -- | BX31: -- | BY31: -- | BZ31: -- | CA31: -- | CB31: -- | CC31: -- | CD31: -- | CE31: -- | CF31: -- | CG31: -- | CH31: -- | CI31: -- | CJ31: -- | CK31: -- | CL31: -- | CM31: -- | CN31: -- | CO31: -- | CP31: -- | CQ31: -- | CR31: -- | CS31: -- | CT31: -- | CU31: -- | CV31: -- | CW31: -- | CX31: -- | CY31: -- | CZ31: -- | DA31: -- | DB31: -- | DC31: -- | DD31: -- | DE31: -- | DF31: -- | DG31: -- | DH31: -- | DI31: --
B32: Western Europe | C32: -- | D32: -- | E32: -- | F32: -- | G32: -- | H32: -- | I32: -- | J32: -- | K32: -- | L32: -- | M32: -- | N32: -- | O32: -- | P32: 4139.1 | Q32: 3892 | R32: 1066 | S32: 853 | T32: 922 | U32: 1017 | V32: =SUM(R32:U32) -> 3858 | W32: 1228 | X32: 915 | Y32: 962 | Z32: 1039 | AA32: =SUM(W32:Z32) -> 4144 | AC32: 1176 | AD32: 908 | AE32: 1057 | AF32: 1052 | AG32: =SUM(AC32:AF32) -> 4193 | AH32: 1301 | AI32: 1074 | AJ32: 1292 | AK32: 1312 | AL32: =SUM(AH32:AK32) -> 4979 | AM32: 1714 | AN32: 1312 | AO32: 1413 | AP32: 1267 | AQ32: =SUM(AM32:AP32) -> 5706 | AR32: 1641 | AS32: 1299 | AT32: 1442 | AU32: 1502 | AV32: =SUM(AR32:AU32) -> 5884 | AW32: 1763 | AX32: 1385 | AY32: 1499 | AZ32: 1564 | BA32: =SUM(AW32:AZ32) -> 6211 | BB32: -- | BC32: -- | BD32: -- | BE32: -- | BF32: -- | BG32: -- | BH32: -- | BI32: -- | BJ32: -- | BK32: -- | BL32: -- | BM32: -- | BN32: -- | BO32: -- | BP32: -- | BQ32: -- | BR32: -- | BS32: -- | BT32: -- | BU32: -- | BV32: -- | BW32: -- | BX32: -- | BY32: -- | BZ32: -- | CA32: -- | CB32: -- | CC32: -- | CD32: -- | CE32: -- | CF32: -- | CG32: -- | CH32: -- | CI32: -- | CJ32: -- | CK32: -- | CL32: -- | CM32: -- | CN32: -- | CO32: -- | CP32: -- | CQ32: -- | CR32: -- | CS32: -- | CT32: -- | CU32: -- | CV32: -- | CW32: -- | CX32: -- | CY32: -- | CZ32: -- | DA32: -- | DB32: -- | DC32: -- | DD32: -- | DE32: -- | DF32: -- | DG32: -- | DH32: -- | DI32: --
B33: Central & Eastern Europe | C33: -- | D33: -- | E33: -- | F33: -- | G33: -- | H33: -- | I33: -- | J33: -- | K33: -- | L33: -- | M33: -- | N33: -- | O33: -- | P33: 1373.2 | Q33: 1149.9 | R33: 269 | S33: 224 | T33: 253 | U33: 294 | V33: =SUM(R33:U33) -> 1040 | W33: 334 | X33: 261 | Y33: 275 | Z33: 330 | AA33: =SUM(W33:Z33) -> 1200 | AC33: 327 | AD33: 252 | AE33: 303 | AF33: 347 | AG33: =SUM(AC33:AF33) -> 1229 | AH33: 366 | AI33: 295 | AJ33: 356 | AK33: 370 | AL33: =SUM(AH33:AK33) -> 1387 | AM33: 392 | AN33: 347 | AO33: 321 | AP33: 360 | AQ33: =SUM(AM33:AP33) -> 1420 | AR33: 401 | AS33: 326 | AT33: 359 | AU33: 345 | AV33: =SUM(AR33:AU33) -> 1431 | AW33: 440 | AX33: 328 | AY33: 362 | AZ33: 357 | BA33: =SUM(AW33:AZ33) -> 1487 | BB33: -- | BC33: -- | BD33: -- | BE33: -- | BF33: -- | BG33: -- | BH33: -- | BI33: -- | BJ33: -- | BK33: -- | BL33: -- | BM33: -- | BN33: -- | BO33: -- | BP33: -- | BQ33: -- | BR33: -- | BS33: -- | BT33: -- | BU33: -- | BV33: -- | BW33: -- | BX33: -- | BY33: -- | BZ33: -- | CA33: -- | CB33: -- | CC33: -- | CD33: -- | CE33: -- | CF33: -- | CG33: -- | CH33: -- | CI33: -- | CJ33: -- | CK33: -- | CL33: -- | CM33: -- | CN33: -- | CO33: -- | CP33: -- | CQ33: -- | CR33: -- | CS33: -- | CT33: -- | CU33: -- | CV33: -- | CW33: -- | CX33: -- | CY33: -- | CZ33: -- | DA33: -- | DB33: -- | DC33: -- | DD33: -- | DE33: -- | DF33: -- | DG33: -- | DH33: -- | DI33: --
B34: Greater China | C34: -- | D34: -- | E34: -- | F34: -- | G34: -- | H34: -- | I34: -- | J34: -- | K34: -- | L34: -- | M34: -- | N34: =O34/1.5 -> 902.66667 | O34: 1354 | P34: 1743.3 | Q34: 1741.8 | R34: 460 | S34: 482 | T34: 554 | U34: 564 | V34: =SUM(R34:U34) -> 2060 | W34: 528 | X34: 650 | Y34: 694 | Z34: 667 | AA34: =SUM(W34:Z34) -> 2539 | AC34: 577 | AD34: 582 | AE34: 641 | AF34: 678 | AG34: =SUM(AC34:AF34) -> 2478 | AH34: 574 | AI34: 629 | AJ34: 697 | AK34: 702 | AL34: =SUM(AH34:AK34) -> 2602 | AM34: 679 | AN34: 758 | AO34: 801 | AP34: 829 | AQ34: =SUM(AM34:AP34) -> 3067 | AR34: 886 | AS34: 938 | AT34: 982 | AU34: 979 | AV34: =SUM(AR34:AU34) -> 3785 | AW34: 1020 | AX34: 1055 | AY34: 1075 | AZ34: 1087 | BA34: =SUM(AW34:AZ34) -> 4237 | BB34: -- | BC34: -- | BD34: -- | BE34: -- | BF34: -- | BG34: -- | BH34: -- | BI34: -- | BJ34: -- | BK34: -- | BL34: -- | BM34: -- | BN34: -- | BO34: -- | BP34: -- | BQ34: -- | BR34: -- | BS34: -- | BT34: -- | BU34: -- | BV34: -- | BW34: -- | BX34: -- | BY34: -- | BZ34: -- | CA34: -- | CB34: -- | CC34: -- | CD34: -- | CE34: -- | CF34: -- | CG34: -- | CH34: -- | CI34: -- | CJ34: -- | CK34: -- | CL34: -- | CM34: -- | CN34: -- | CO34: -- | CP34: -- | CQ34: -- | CR34: -- | CS34: -- | CT34: -- | CU34: -- | CV34: -- | CW34: -- | CX34: -- | CY34: -- | CZ34: -- | DA34: -- | DB34: -- | DC34: -- | DD34: -- | DE34: -- | DF34: -- | DG34: -- | DH34: -- | DI34: --
B35: Japan | C35: -- | D35: -- | E35: -- | F35: -- | G35: -- | H35: -- | I35: -- | J35: -- | K35: -- | L35: -- | M35: -- | N35: -- | O35: -- | P35: 925.9 | Q35: 882 | R35: 163 | S35: 192 | T35: 195 | U35: 216 | V35: =SUM(R35:U35) -> 766 | W35: 191 | X35: 197 | Y35: 201 | Z35: 240 | AA35: =SUM(W35:Z35) -> 829 | AC35: 197 | AD35: 240 | AE35: 195 | AF35: 244 | AG35: =SUM(AC35:AF35) -> 876 | AH35: 158 | AI35: 210 | AJ35: 177 | AK35: 226 | AL35: =SUM(AH35:AK35) -> 771 | AM35: 160 | AN35: 199 | AO35: 166 | AP35: 230 | AQ35: =SUM(AM35:AP35) -> 755 | AR35: 179 | AS35: 205 | AT35: 205 | AU35: 280 | AV35: =SUM(AR35:AU35) -> 869 | AW35: 245 | AX35: 238 | AY35: 236 | AZ35: 295 | BA35: =SUM(AW35:AZ35) -> 1014 | BB35: -- | BC35: -- | BD35: -- | BE35: -- | BF35: -- | BG35: -- | BH35: -- | BI35: -- | BJ35: -- | BK35: -- | BL35: -- | BM35: -- | BN35: -- | BO35: -- | BP35: -- | BQ35: -- | BR35: -- | BS35: -- | BT35: -- | BU35: -- | BV35: -- | BW35: -- | BX35: -- | BY35: -- | BZ35: -- | CA35: -- | CB35: -- | CC35: -- | CD35: -- | CE35: -- | CF35: -- | CG35: -- | CH35: -- | CI35: -- | CJ35: -- | CK35: -- | CL35: -- | CM35: -- | CN35: -- | CO35: -- | CP35: -- | CQ35: -- | CR35: -- | CS35: -- | CT35: -- | CU35: -- | CV35: -- | CW35: -- | CX35: -- | CY35: -- | CZ35: -- | DA35: -- | DB35: -- | DC35: -- | DD35: -- | DE35: -- | DF35: -- | DG35: -- | DH35: -- | DI35: --
B36: Emerging Markets | C36: -- | D36: -- | E36: -- | F36: -- | G36: -- | H36: -- | I36: -- | J36: -- | K36: -- | L36: -- | M36: -- | N36: -- | O36: -- | P36: 1702 | Q36: 2041.6 | R36: 591 | S36: 755 | T36: 643 | U36: 747 | V36: =SUM(R36:U36) -> 2736 | W36: 799 | X36: 948 | Y36: 793 | Z36: 870 | AA36: =SUM(W36:Z36) -> 3410 | AC36: 897 | AD36: 1074 | AE36: 867 | AF36: 994 | AG36: =SUM(AC36:AF36) -> 3832 | AH36: 902 | AI36: 1030 | AJ36: 937 | AK36: 1080 | AL36: =SUM(AH36:AK36) -> 3949 | AM36: 934 | AN36: 1075 | AO36: 955 | AP36: 934 | AQ36: =SUM(AM36:AP36) -> 3898 | AR36: 966 | AS36: 984 | AT36: 879 | AU36: 872 | AV36: =SUM(AR36:AU36) -> 3701 | AW36: 945 | AX36: 1047 | AY36: 950 | AZ36: 1053 | BA36: =SUM(AW36:AZ36) -> 3995 | BB36: -- | BC36: -- | BD36: -- | BE36: -- | BF36: -- | BG36: -- | BH36: -- | BI36: -- | BJ36: -- | BK36: -- | BL36: -- | BM36: -- | BN36: -- | BO36: -- | BP36: -- | BQ36: -- | BR36: -- | BS36: -- | BT36: -- | BU36: -- | BV36: -- | BW36: -- | BX36: -- | BY36: -- | BZ36: -- | CA36: -- | CB36: -- | CC36: -- | CD36: -- | CE36: -- | CF36: -- | CG36: -- | CH36: -- | CI36: -- | CJ36: -- | CK36: -- | CL36: -- | CM36: -- | CN36: -- | CO36: -- | CP36: -- | CQ36: -- | CR36: -- | CS36: -- | CT36: -- | CU36: -- | CV36: -- | CW36: -- | CX36: -- | CY36: -- | CZ36: -- | DA36: -- | DB36: -- | DC36: -- | DD36: -- | DE36: -- | DF36: -- | DG36: -- | DH36: -- | DI36: --
B37: Global Brands | C37: -- | D37: -- | E37: -- | F37: -- | G37: -- | H37: -- | I37: -- | J37: -- | K37: -- | L37: -- | M37: -- | N37: -- | O37: -- | P37: 95.3 | Q37: 105.3 | R37: 31 | S37: 24 | T37: 22 | U37: 29 | V37: =SUM(R37:U37) -> 106 | W37: 33 | X37: 25 | Y37: 27 | Z37: 26 | AA37: =SUM(W37:Z37) -> 111 | AC37: 27 | AD37: 28 | AE37: 29 | AF37: 31 | AG37: =SUM(AC37:AF37) -> 115 | AH37: 32 | AI37: 31 | AJ37: 26 | AK37: 36 | AL37: =SUM(AH37:AK37) -> 125 | AM37: 29 | AN37: 27 | AO37: 29 | AP37: 30 | AQ37: =SUM(AM37:AP37) -> 115 | AR37: 26 | AS37: 18 | AT37: 17 | AU37: 12 | AV37: =SUM(AR37:AU37) -> 73 | AW37: 15 | AX37: 21 | AY37: 19 | AZ37: 18 | BA37: =SUM(AW37:AZ37) -> 73 | BB37: -- | BC37: -- | BD37: -- | BE37: -- | BF37: -- | BG37: -- | BH37: -- | BI37: -- | BJ37: -- | BK37: -- | BL37: -- | BM37: -- | BN37: -- | BO37: -- | BP37: -- | BQ37: -- | BR37: -- | BS37: -- | BT37: -- | BU37: -- | BV37: -- | BW37: -- | BX37: -- | BY37: -- | BZ37: -- | CA37: -- | CB37: -- | CC37: -- | CD37: -- | CE37: -- | CF37: -- | CG37: -- | CH37: -- | CI37: -- | CJ37: -- | CK37: -- | CL37: -- | CM37: -- | CN37: -- | CO37: -- | CP37: -- | CQ37: -- | CR37: -- | CS37: -- | CT37: -- | CU37: -- | CV37: -- | CW37: -- | CX37: -- | CY37: -- | CZ37: -- | DA37: -- | DB37: -- | DC37: -- | DD37: -- | DE37: -- | DF37: -- | DG37: -- | DH37: -- | DI37: --
B38: Total Nike Brand | C38: -- | D38: -- | E38: -- | F38: -- | G38: -- | H38: -- | I38: -- | J38: -- | K38: -- | L38: -- | M38: -- | N38: -- | O38: -- | P38: =SUM(P31:P37) -> 16757.1 | Q38: =SUM(Q31:Q37) -> 16508.6 | R38: =SUM(R31:R37) -> 4483 | S38: =SUM(S31:S37) -> 4231 | T38: =SUM(T31:T37) -> 4425 | U38: =SUM(U31:U37) -> 5006 | V38: =SUM(R38:U38) -> 18145 | W38: =SUM(W31:W37) -> 5313 | X38: =SUM(X31:X37) -> 5062 | Y38: =SUM(Y31:Y37) -> 5101 | Z38: =SUM(Z31:Z37) -> 5596 | AA38: =SUM(W38:Z38) -> 21072 | AC38: =SUM(AC31:AC37) -> 6067 | AD38: =SUM(AD31:AD37) -> 5648 | AE38: =SUM(AE31:AE37) -> 5829 | AF38: =SUM(AF31:AF37) -> 6337 | AG38: =SUM(AC38:AF38) -> 23881 | AH38: =SUM(AH31:AH37) -> 6468 | AI38: =SUM(AI31:AI37) -> 6070 | AJ38: =SUM(AJ31:AJ37) -> 6554 | AK38: =SUM(AK31:AK37) -> 7020 | AL38: =SUM(AH38:AK38) -> 26112 | AM38: =SUM(AM31:AM37) -> 7421 | AN38: =SUM(AN31:AN37) -> 6959 | AO38: =SUM(AO31:AO37) -> 6939 | AP38: =SUM(AP31:AP37) -> 7382 | AQ38: =SUM(AM38:AP38) -> 28701 | AR38: =SUM(AR31:AR37) -> 7898 | AS38: =SUM(AS31:AS37) -> 7317 | AT38: =SUM(AT31:AT37) -> 7567 | AU38: =SUM(AU31:AU37) -> 7725 | AV38: =SUM(AR38:AU38) -> 30507 | AW38: =SUM(AW31:AW37) -> 8459 | AX38: =SUM(AX31:AX37) -> 7724 | AY38: =SUM(AY31:AY37) -> 7923 | AZ38: =SUM(AZ31:AZ37) -> 8127 | BA38: =SUM(AW38:AZ38) -> 32233 | BB38: -- | BC38: -- | BD38: -- | BE38: -- | BF38: -- | BG38: -- | BH38: -- | BI38: -- | BJ38: -- | BK38: -- | BL38: -- | BM38: -- | BN38: -- | BO38: -- | BP38: -- | BQ38: -- | BR38: -- | BS38: -- | BT38: -- | BU38: -- | BV38: -- | BW38: -- | BX38: -- | BY38: -- | BZ38: -- | CA38: -- | CB38: -- | CC38: -- | CD38: -- | CE38: -- | CF38: -- | CG38: -- | CH38: -- | CI38: -- | CJ38: -- | CK38: -- | CL38: -- | CM38: -- | CN38: -- | CO38: -- | CP38: -- | CQ38: -- | CR38: -- | CS38: -- | CT38: -- | CU38: -- | CV38: -- | CW38: -- | CX38: -- | CY38: -- | CZ38: -- | DA38: -- | DB38: -- | DC38: -- | DD38: -- | DE38: -- | DF38: -- | DG38: -- | DH38: -- | DI38: --
B39: Other Businesses | C39: -- | D39: -- | E39: -- | F39: -- | G39: -- | H39: -- | I39: -- | J39: -- | K39: -- | L39: -- | M39: -- | N39: -- | O39: -- | P39: 2419 | Q39: 2529.5 | R39: 694 | S39: 639 | T39: 680 | U39: 773 | V39: =SUM(R39:U39) -> 2786 | W39: =585+188 -> 773 | X39: 673 | Y39: 753 | Z39: 896 | AA39: =SUM(W39:Z39) -> 3095 | AC39: 418 | AD39: 316 | AE39: 361 | AF39: 354 | AG39: =SUM(AC39:AF39) -> 1449 | AH39: 494 | AI39: 360 | AJ39: 420 | AK39: 410 | AL39: =SUM(AH39:AK39) -> 1684 | AM39: 575 | AN39: 434 | AO39: 538 | AP39: 435 | AQ39: =SUM(AM39:AP39) -> 1982 | AR39: 555 | AS39: 398 | AT39: 489 | AU39: 513 | AV39: =SUM(AR39:AU39) -> 1955 | AW39: 574 | AX39: 416 | AY39: 498 | AZ39: 554 | BA39: =SUM(AW39:AZ39) -> 2042 | BB39: -- | BC39: -- | BD39: -- | BE39: -- | BF39: -- | BG39: -- | BH39: -- | BI39: -- | BJ39: -- | BK39: -- | BL39: -- | BM39: -- | BN39: -- | BO39: -- | BP39: -- | BQ39: -- | BR39: -- | BS39: -- | BT39: -- | BU39: -- | BV39: -- | BW39: -- | BX39: -- | BY39: -- | BZ39: -- | CA39: -- | CB39: -- | CC39: -- | CD39: -- | CE39: -- | CF39: -- | CG39: -- | CH39: -- | CI39: -- | CJ39: -- | CK39: -- | CL39: -- | CM39: -- | CN39: -- | CO39: -- | CP39: -- | CQ39: -- | CR39: -- | CS39: -- | CT39: -- | CU39: -- | CV39: -- | CW39: -- | CX39: -- | CY39: -- | CZ39: -- | DA39: -- | DB39: -- | DC39: -- | DD39: -- | DE39: -- | DF39: -- | DG39: -- | DH39: -- | DI39: --
B40: Corporate | C40: -- | D40: -- | E40: -- | F40: -- | G40: -- | H40: -- | I40: -- | J40: -- | K40: -- | L40: -- | M40: -- | N40: -- | O40: -- | P40: 0 | Q40: -24.1 | R40: -2 | S40: -28 | T40: -26 | U40: -13 | V40: =SUM(R40:U40) -> -69 | W40: -5 | X40: -4 | Y40: -8 | Z40: -22 | AA40: =SUM(W40:Z40) -> -39 | AC40: -11 | AD40: -9 | AE40: -3 | AF40: 6 | AG40: =SUM(AC40:AF40) -> -17 | AH40: 9 | AI40: 1 | AJ40: -2 | AK40: -5 | AL40: =SUM(AH40:AK40) -> 3 | AM40: -14 | AN40: -13 | AO40: -17 | AP40: -38 | AQ40: =SUM(AM40:AP40) -> -82 | AR40: -39 | AS40: -29 | AT40: -24 | AU40: 6 | AV40: =SUM(AR40:AU40) -> -86 | AW40: 28 | AX40: 40 | AY40: 11 | AZ40: -4 | BA40: =SUM(AW40:AZ40) -> 75 | BB40: -- | BC40: -- | BD40: -- | BE40: -- | BF40: -- | BG40: -- | BH40: -- | BI40: -- | BJ40: -- | BK40: -- | BL40: -- | BM40: -- | BN40: -- | BO40: -- | BP40: -- | BQ40: -- | BR40: -- | BS40: -- | BT40: -- | BU40: -- | BV40: -- | BW40: -- | BX40: -- | BY40: -- | BZ40: -- | CA40: -- | CB40: -- | CC40: -- | CD40: -- | CE40: -- | CF40: -- | CG40: -- | CH40: -- | CI40: -- | CJ40: -- | CK40: -- | CL40: -- | CM40: -- | CN40: -- | CO40: -- | CP40: -- | CQ40: -- | CR40: -- | CS40: -- | CT40: -- | CU40: -- | CV40: -- | CW40: -- | CX40: -- | CY40: -- | CZ40: -- | DA40: -- | DB40: -- | DC40: -- | DD40: -- | DE40: -- | DF40: -- | DG40: -- | DH40: -- | DI40: --
B41: Net Sales | C41: =C57 -> 6470.625 | D41: =D57 -> 9186.539 | E41: =E57 -> 9553.1 | F41: =F57 -> 8776.9 | G41: =G57 -> 8995.1 | H41: =H57 -> 9488.8 | I41: =I57 -> 9893 | J41: =J57 -> 10697 | ... O41: =O57 -> 18627 | P41: =SUM(P38:P40) -> 19176.1 | Q41: =SUM(Q38:Q40) -> 19014 | R41: =SUM(R38:R40) -> 5175 | S41: =SUM(S38:S40) -> 4842 | T41: =SUM(T38:T40) -> 5079 | U41: =SUM(U38:U40) -> 5766 | V41: =SUM(R41:U41) -> 20862 | W41: =SUM(W38:W40) -> 6081 | X41: =SUM(X38:X40) -> 5731 | Y41: =SUM(Y38:Y40) -> 5846 | Z41: =SUM(Z38:Z40) -> 6470 | AA41: =SUM(W41:Z41) -> 24128 | AC41: =SUM(AC38:AC40) -> 6474 | AD41: =SUM(AD38:AD40) -> 5955 | AE41: =SUM(AE38:AE40) -> 6187 | AF41: =SUM(AF38:AF40) -> 6697 | AG41: =SUM(AC41:AF41) -> 25313 | AH41: =SUM(AH38:AH40) -> 6971 | AI41: =SUM(AI38:AI40) -> 6431 | AJ41: =SUM(AJ38:AJ40) -> 6972 | AK41: =SUM(AK38:AK40) -> 7425 | AL41: =SUM(AH41:AK41) -> 27799 | AM41: =SUM(AM38:AM40) -> 7982 | AN41: =SUM(AN38:AN40) -> 7380 | AO41: =SUM(AO38:AO40) -> 7460 | AP41: =SUM(AP38:AP40) -> 7779 | AQ41: =SUM(AM41:AP41) -> 30601 | AR41: =SUM(AR38:AR40) -> 8414 | AS41: =SUM(AS38:AS40) -> 7686 | AT41: =SUM(AT38:AT40) -> 8032 | AU41: =SUM(AU38:AU40) -> 8244 | AV41: =SUM(AR41:AU41) -> 32376 | AW41: =SUM(AW38:AW40) -> 9061 | AX41: =SUM(AX38:AX40) -> 8180 | AY41: =SUM(AY38:AY40) -> 8432 | AZ41: =SUM(AZ38:AZ40) -> 8677 | BA41: =SUM(AW41:AZ41) -> 34350 | BB41: -- | BC41: -- | BD41: -- | BE41: -- | BF41: -- | BG41: -- | BH41: -- | BI41: -- | BJ41: -- | BK41: -- | BL41: -- | BM41: -- | BN41: -- | BO41: -- | BP41: -- | BQ41: -- | BR41: -- | BS41: -- | BT41: -- | BU41: -- | BV41: -- | BW41: -- | BX41: -- | BY41: -- | BZ41: -- | CA41: -- | CB41: -- | CC41: -- | CD41: -- | CE41: -- | CF41: -- | CG41: -- | CH41: -- | CI41: -- | CJ41: -- | CK41: -- | CL41: -- | CM41: -- | CN41: -- | CO41: -- | CP41: -- | CQ41: -- | CR41: -- | CS41: -- | CT41: -- | CU41: -- | CV41: -- | CW41: -- | CX41: -- | CY41: -- | CZ41: -- | DA41: -- | DB41: -- | DC41: -- | DD41: -- | DE41: -- | DF41: -- | DG41: -- | DH41: -- | DI41: --
B43: EBIT - OLD SEGMENTS
B44: North America | C44: -- | D44: -- | E44: -- | F44: -- | G44: -- | H44: -- | I44: -- | J44: -- | K44: -- | L44: -- | M44: -- | N44: -- | O44: -- | P44: 1429.3 | Q44: 1538.1 | R44: 443 | S44: 356 | T44: 419 | U44: 518 | V44: =SUM(R44:U44) -> 1736 | W44: 534 | X44: 418 | Y44: 496 | Z44: 559 | AA44: =SUM(W44:Z44) -> 2007 | AC44: 645 | AD44: 565 | AE44: 653 | AF44: 778 | AG44: =SUM(AC44:AF44) -> 2641 | AH44: 813 | AI44: 649 | AJ44: 729 | AK44: 888 | AL44: =SUM(AH44:AK44) -> 3079 | AM44: 970 | AN44: 785 | AO44: 830 | AP44: 1060 | AQ44: =SUM(AM44:AP44) -> 3645 | AR44: 1042 | AS44: 882 | AT44: 903 | AU44: 936 | AV44: =SUM(AR44:AU44) -> 3763 | AW44: 1004 | AX44: 912 | AY44: 980 | AZ44: 979 | BA44: =SUM(AW44:AZ44) -> 3875 | BB44: -- | BC44: -- | BD44: -- | BE44: -- | BF44: -- | BG44: -- | BH44: -- | BI44: -- | BJ44: -- | BK44: -- | BL44: -- | BM44: -- | BN44: -- | BO44: -- | BP44: -- | BQ44: -- | BR44: -- | BS44: -- | BT44: -- | BU44: -- | BV44: -- | BW44: -- | BX44: -- | BY44: -- | BZ44: -- | CA44: -- | CB44: -- | CC44: -- | CD44: -- | CE44: -- | CF44: -- | CG44: -- | CH44: -- | CI44: -- | CJ44: -- | CK44: -- | CL44: -- | CM44: -- | CN44: -- | CO44: -- | CP44: -- | CQ44: -- | CR44: -- | CS44: -- | CT44: -- | CU44: -- | CV44: -- | CW44: -- | CX44: -- | CY44: -- | CZ44: -- | DA44: -- | DB44: -- | DC44: -- | DD44: -- | DE44: -- | DF44: -- | DG44: -- | DH44: -- | DI44: --
...

Sheet 3. Segment Analysis
B1: Nike (NKE)
B2: Quarterly Segment Sales Build
B3: $ millions except per share data, FY ending May
C5: =+'2. Consolidated'!C5 -> 35216 | D5: =+'2. Consolidated'!D5 -> 35581 | E5: =+'2. Consolidated'!E5 -> 35946 | F5: =+'2. Consolidated'!F5 -> 36311 | G5: =+'2. Consolidated'!G5 -> 36677 | H5: =+'2. Consolidated'!H5 -> 37042 | I5: =+'2. Consolidated'!I5 -> 37407 | J5: =+'2. Consolidated'!J5 -> 37772 | ... DI5: =+'2. Consolidated'!DI5 -> 46904
C6: =+'2. Consolidated'!C6 -> 1996 | D6: =+'2. Consolidated'!D6 -> 1997 | E6: =+'2. Consolidated'!E6 -> 1998 | F6: =+'2. Consolidated'!F6 -> 1999 | G6: =+'2. Consolidated'!G6 -> 2000 | H6: =+'2. Consolidated'!H6 -> 2001 | I6: =+'2. Consolidated'!I6 -> 2002 | J6: =+'2. Consolidated'!J6 -> 2003 | ... DI6: =+'2. Consolidated'!DI6 -> 2029E
A7: =IF(ISBLANK(B7),"Scrap", " ") | B7: CONSOLIDATED SALES / EBIT SUMMARY
A8: =IF(ISBLANK(B8),"Scrap", " ") | B8: Total Nike Sales Model
A9: =IF(ISBLANK(B9),"Scrap", " ") | B9: North America | C9: =+'2. Consolidated'!C9 -> 3615.062 | D9: =+'2. Consolidated'!D9 -> 5201.624 | E9: =+'2. Consolidated'!E9 -> 5139.412 | F9: =+'2. Consolidated'!F9 -> 4750.711 | G9: =+'2. Consolidated'!G9 -> 4732.073 | H9: =+'2. Consolidated'!H9 -> 4819 | I9: =+'2. Consolidated'!I9 -> 4669.6 | J9: =+'2. Consolidated'!J9 -> 4658.5 | ... Q9: =+'2. Consolidated'!Q9 -> 6696 | R9: =+R182 -> 1903 | S9: =+S182 -> 1701 | T9: =+T182 -> 1836 | U9: =+U182 -> 2139 | V9: =SUM(R9:U9) -> 7579 | W9: =+W182 -> 2200 | X9: =+X182 -> 2066 | Y9: =+Y182 -> 2149 | Z9: =+Z182 -> 2424 | AA9: =SUM(W9:Z9) -> 8839 | AC9: =+AC182 -> 2866 | AD9: =+AD182 -> 2564 | AE9: =+AE182 -> 2737 | AF9: =+AF182 -> 2991 | AG9: =SUM(AC9:AF9) -> 11158 | AH9: =+AH182 -> 3135 | AI9: =+AI182 -> 2801 | AJ9: =+AJ182 -> 3069 | AK9: =+AK182 -> 3294 | AL9: =SUM(AH9:AK9) -> 12299 | AM9: =+AM182 -> 3513 | AN9: =+AN182 -> 3241 | AO9: =+AO182 -> 3254 | AP9: =+AP182 -> 3732 | AQ9: =SUM(AM9:AP9) -> 13740 | AR9: =+AR182 -> 3799 | AS9: =+AS182 -> 3547 | AT9: =+AT182 -> 3683 | AU9: =+AU182 -> 3735 | AV9: =SUM(AR9:AU9) -> 14764 | AW9: =+AW182 -> 4031 | AX9: =+AX182 -> 3650 | AY9: =+AY182 -> 3782 | AZ9: =+AZ182 -> 3753 | BA9: =SUM(AW9:AZ9) -> 15216 | BB9: =+BB182 -> 3924 | BC9: =+BC182 -> 3485 | BD9: =+BD182 -> 3571 | BE9: =+BE182 -> 3875 | BF9: =SUM(BB9:BE9) -> 14855 | BG9: =+BG182 -> 4145 | BH9: =+BH182 -> 3782 | BI9: =+BI182 -> 3810 | BJ9: =+BJ182 -> 4165 | BK9: =SUM(BG9:BJ9) -> 15902 | BL9: =+BL182 -> 4293 | BM9: =+BM182 -> 3982 | BN9: =+BN182 -> 3979 | BO9: =+BO182 -> 2230 | BP9: =SUM(BL9:BO9) -> 14484 | BQ9: =+BQ182 -> 4225 | BR9: =+BR182 -> 4006 | BS9: =+BS182 -> 3564 | BT9: =+BT182 -> 5384 | BU9: =SUM(BQ9:BT9) -> 17179 | BV9: =+BV182 -> 4879 | BW9: =+BW182 -> 4477 | BX9: =+BX182 -> 3882 | BY9: =+BY182 -> 5115 | BZ9: =SUM(BV9:BY9) -> 18353 | CA9: =+CA182 -> 5510 | CB9: =+CB182 -> 5830 | CC9: =+CC182 -> 4913 | CD9: =+CD182 -> 5355 | CE9: =SUM(CA9:CD9) -> 21608 | CF9: =+CF182 -> 5423 | CG9: =+CG182 -> 5625 | CH9: =+CH182 -> 5070 | CI9: =+CI182 -> 5278 | CJ9: =SUM(CF9:CI9) -> 21396 | CK9: =+CK182 -> 4826 | CL9: =+CL182 -> 5179 | CM9: =+CM182 -> 4864 | CN9: =+CN182 -> 4703 | CO9: =SUM(CK9:CN9) -> 19572 | CP9: =+CP182 -> 5020 | CQ9: =+CQ182 -> 5633 | CR9: =+CR182 -> 5026 | CS9: =+CS182 -> 4832 | CT9: =SUM(CP9:CS9) -> 20511 | CU9: =+CU182 -> 5127 | CV9: =+CV182 -> 5050.934 | CW9: =+CW182 -> 4799.0826 | CX9: =+CX182 -> 4509.5029 | CY9: =SUM(CU9:CX9) -> 19486.52 | CZ9: =+CZ182 -> 4775.4098 | DA9: =+DA182 -> 4837.1291 | DB9: =+DB182 -> 4671.5671 | DC9: =+DC182 -> 4389.3339 | DD9: =SUM(CZ9:DC9) -> 18673.44 | DE9: =+DE182 -> 4775.4098 | DF9: =+DF182 -> 4837.1291 | DG9: =+DG182 -> 4671.5671 | DH9: =+DH182 -> 4389.3339 | DI9: =SUM(DE9:DH9) -> 18673.44
A10: =IF(ISBLANK(B10),"Scrap", " ") | B10: EMEA | C10: =+'2. Consolidated'!C10 -> -- | D10: =+'2. Consolidated'!D10 -> -- | E10: =+'2. Consolidated'!E10 -> -- | F10: =+'2. Consolidated'!F10 -> -- | G10: =+'2. Consolidated'!G10 -> -- | H10: =+'2. Consolidated'!H10 -> -- | I10: =+'2. Consolidated'!I10 -> -- | J10: =+'2. Consolidated'!J10 -> -- | ... Q10: =+'2. Consolidated'!Q10 -> 5041.9 | R10: =+R251 -> 1335 | S10: =+S251 -> 1077 | T10: =+T251 -> 1175 | U10: =+U251 -> 1311 | V10: =SUM(R10:U10) -> 4898 | W10: =+W251 -> 1562 | X10: =+X251 -> 1176 | Y10: =+Y251 -> 1237 | Z10: =+Z251 -> 1369 | AA10: =SUM(W10:Z10) -> 5344 | AC10: =+AC251 -> 1503 | AD10: =+AD251 -> 1160 | AE10: =+AE251 -> 1360 | AF10: =+AF251 -> 1399 | AG10: =SUM(AC10:AF10) -> 5422 | AH10: =+AH251 -> 1667 | AI10: =+AI251 -> 1369 | AJ10: =+AJ251 -> 1648 | AK10: =+AK251 -> 1682 | AL10: =SUM(AH10:AK10) -> 6366 | AM10: =+AM251 -> 2106 | AN10: =+AN251 -> 1658 | AO10: =+AO251 -> 1735 | AP10: =+AP251 -> 1627 | AQ10: =SUM(AM10:AP10) -> 7126 | AR10: =+AR251 -> 2104 | AS10: =+AS251 -> 1707 | AT10: =+AT251 -> 1853 | AU10: =+AU251 -> 1904 | AV10: =SUM(AR10:AU10) -> 7568 | AW10: =+AW251 -> 2262 | AX10: =+AX251 -> 1792 | AY10: =+AY251 -> 1925 | AZ10: =+AZ251 -> 1991 | BA10: =SUM(AW10:AZ10) -> 7970 | BB10: =+BB251 -> 2344 | BC10: =+BC251 -> 2133 | BD10: =+BD251 -> 2299 | BE10: =+BE251 -> 2466 | BF10: =SUM(BB10:BE10) -> 9242 | BG10: =+BG251 -> 2607 | BH10: =+BH251 -> 2313 | BI10: =+BI251 -> 2435 | BJ10: =+BJ251 -> 2457 | BK10: =SUM(BG10:BJ10) -> 9812 | BL10: =+BL251 -> 2773 | BM10: =+BM251 -> 2537 | BN10: =+BN251 -> 2709 | BO10: =+BO251 -> 1328 | BP10: =SUM(BL10:BO10) -> 9347 | BQ10: =+BQ251 -> 2910 | BR10: =+BR251 -> 2958 | BS10: =+BS251 -> 2609 | BT10: =+BT251 -> 2979 | BU10: =SUM(BQ10:BT10) -> 11456 | BV10: =+BV251 -> 3307 | BW10: =+BW251 -> 3142 | BX10: =+BX251 -> 2779 | BY10: =+BY251 -> 3251 | BZ10: =SUM(BV10:BY10) -> 12479 | CA10: =+CA251 -> 3333 | CB10: =+CB251 -> 3489 | CC10: =+CC251 -> 3246 | CD10: =+CD251 -> 3350 | CE10: =SUM(CA10:CD10) -> 13418 | CF10: =+CF251 -> 3610 | CG10: =+CG251 -> 3567 | CH10: =+CH251 -> 3138 | CI10: =+CI251 -> 3292 | CJ10: =SUM(CF10:CI10) -> 13607 | CK10: =+CK251 -> 3143 | CL10: =+CL251 -> 3303 | CM10: =+CM251 -> 2811 | CN10: =+CN251 -> 3000 | CO10: =SUM(CK10:CN10) -> 12257 | CP10: =+CP251 -> 3331 | CQ10: =+CQ251 -> 3392 | CR10: =+CR251 -> 2874 | CS10: =+CS251 -> 2975 | CT10: =SUM(CP10:CS10) -> 12572 | CU10: =+CU251 -> 3176 | CV10: =+CV251 -> 2888.6764 | CW10: =+CW251 -> 2687.4199 | CX10: =+CX251 -> 2732.7586 | CY10: =SUM(CU10:CX10) -> 11484.855 | CZ10: =+CZ251 -> 2958.4672 | DA10: =+DA251 -> 2795.5104 | DB10: =+DB251 -> 2616.9429 | DC10: =+DC251 -> 2661.4653 | DD10: =SUM(CZ10:DC10) -> 11032.386 | DE10: =+DE251 -> 2958.4672 | DF10: =+DF251 -> 2795.5104 | DG10: =+DG251 -> 2643.1124 | DH10: =+DH251 -> 2688.0799 | DI10: =SUM(DE10:DH10) -> 11085.17
A11: =IF(ISBLANK(B11),"Scrap", " ") | B11: GC | C11: =+'2. Consolidated'!C11 -> -- | D11: =+'2. Consolidated'!D11 -> -- | E11: =+'2. Consolidated'!E11 -> -- | F11: =+'2. Consolidated'!F11 -> -- | G11: =+'2. Consolidated'!G11 -> -- | H11: =+'2. Consolidated'!H11 -> -- | I11: =+'2. Consolidated'!I11 -> -- | J11: =+'2. Consolidated'!J11 -> -- | ... Q11: =+'2. Consolidated'!Q11 -> 1741.8 | R11: =+R320 -> 460 | S11: =+S320 -> 482 | T11: =+T320 -> 554 | U11: =+U320 -> 564 | V11: =SUM(R11:U11) -> 2060 | W11: =+W320 -> 528 | X11: =+X320 -> 650 | Y11: =+Y320 -> 694 | Z11: =+Z320 -> 667 | AA11: =SUM(W11:Z11) -> 2539 | AC11: =+AC320 -> 577 | AD11: =+AD320 -> 582 | AE11: =+AE320 -> 641 | AF11: =+AF320 -> 678 | AG11: =SUM(AC11:AF11) -> 2478 | AH11: =+AH320 -> 574 | AI11: =+AI320 -> 629 | AJ11: =+AJ320 -> 697 | AK11: =+AK320 -> 702 | AL11: =SUM(AH11:AK11) -> 2602 | AM11: =+AM320 -> 679 | AN11: =+AN320 -> 758 | AO11: =+AO320 -> 801 | AP11: =+AP320 -> 829 | AQ11: =SUM(AM11:AP11) -> 3067 | AR11: =+AR320 -> 886 | AS11: =+AS320 -> 938 | AT11: =+AT320 -> 982 | AU11: =+AU320 -> 979 | AV11: =SUM(AR11:AU11) -> 3785 | AW11: =+AW320 -> 1020 | AX11: =+AX320 -> 1055 | AY11: =+AY320 -> 1075 | AZ11: =+AZ320 -> 1087 | BA11: =SUM(AW11:AZ11) -> 4237 | BB11: =+BB320 -> 1108 | BC11: =+BC320 -> 1222 | BD11: =+BD320 -> 1336 | BE11: =+BE320 -> 1468 | BF11: =SUM(BB11:BE11) -> 5134 | BG11: =+BG320 -> 1379 | BH11: =+BH320 -> 1544 | BI11: =+BI320 -> 1588 | BJ11: =+BJ320 -> 1697 | BK11: =SUM(BG11:BJ11) -> 6208 | BL11: =+BL320 -> 1679 | BM11: =+BM320 -> 1847 | BN11: =+BN320 -> 1506 | BO11: =+BO320 -> 1647 | BP11: =SUM(BL11:BO11) -> 6679 | BQ11: =+BQ320 -> 1780 | BR11: =+BR320 -> 2298 | BS11: =+BS320 -> 2279 | BT11: =+BT320 -> 1933 | BU11: =SUM(BQ11:BT11) -> 8290 | BV11: =+BV320 -> 1982 | BW11: =+BW320 -> 1844 | BX11: =+BX320 -> 2160 | BY11: =+BY320 -> 1561 | BZ11: =SUM(BV11:BY11) -> 7547 | CA11: =+CA320 -> 1656 | CB11: =+CB320 -> 1788 | CC11: =+CC320 -> 1994 | CD11: =+CD320 -> 1810 | CE11: =SUM(CA11:CD11) -> 7248 | CF11: =+CF320 -> 1735 | CG11: =+CG320 -> 1863 | CH11: =+CH320 -> 2084 | CI11: =+CI320 -> 1863 | CJ11: =SUM(CF11:CI11) -> 7545 | CK11: =+CK320 -> 1666 | CL11: =+CL320 -> 1711 | CM11: =+CM320 -> 1733 | CN11: =+CN320 -> 1476 | CO11: =SUM(CK11:CN11) -> 6586 | CP11: =+CP320 -> 1512 | CQ11: =+CQ320 -> 1423 | CR11: =+CR320 -> 1615 | CS11: =+CS320 -> 1297 | CT11: =SUM(CP11:CS11) -> 5847 | CU11: =+CU320 -> 1180 | CV11: =+CV320 -> 1077.7956 | CW11: =+CW320 -> 1150.708 | CX11: =+CX320 -> 907.55669 | CY11: =SUM(CU11:CX11) -> 4316.0603 | CZ11: =+CZ320 -> 892.965 | DA11: =+DA320 -> 862.2365 | DB11: =+DB320 -> 1058.6514 | DC11: =+DC320 -> 834.95215 | DD11: =SUM(CZ11:DC11) -> 3648.805 | DE11: =+DE320 -> 866.70577 | DF11: =+DF320 -> 845.16366 | DG11: =+DG320 -> 1069.0332 | DH11: =+DH320 -> 843.13964 | DI11: =SUM(DE11:DH11) -> 3624.0423
A12: =IF(ISBLANK(B12),"Scrap", " ") | B12: APLA | C12: =+'2. Consolidated'!C12 -> -- | D12: =+'2. Consolidated'!D12 -> -- | E12: =+'2. Consolidated'!E12 -> -- | F12: =+'2. Consolidated'!F12 -> -- | G12: =+'2. Consolidated'!G12 -> -- | H12: =+'2. Consolidated'!H12 -> -- | I12: =+'2. Consolidated'!I12 -> -- | J12: =+'2. Consolidated'!J12 -> -- | ... Q12: =+'2. Consolidated'!Q12 -> 2923.6 | R12: =+R389 -> 754 | S12: =+S389 -> 947 | T12: =+T389 -> 838 | U12: =+U389 -> 963 | V12: =SUM(R12:U12) -> 3502 | W12: =+W389 -> 990 | X12: =+X389 -> 1145 | Y12: =+Y389 -> 994 | Z12: =+Z389 -> 1110 | AA12: =SUM(W12:Z12) -> 4239 | AC12: =+AC389 -> 1094 | AD12: =+AD389 -> 1314 | AE12: =+AE389 -> 1062 | AF12: =+AF389 -> 1238 | AG12: =SUM(AC12:AF12) -> 4708 | AH12: =+AH389 -> 1060 | AI12: =+AI389 -> 1240 | AJ12: =+AJ389 -> 1114 | AK12: =+AK389 -> 1306 | AL12: =SUM(AH12:AK12) -> 4720 | AM12: =+AM389 -> 1094 | AN12: =+AN389 -> 1274 | AO12: =+AO389 -> 1121 | AP12: =+AP389 -> 1164 | AQ12: =SUM(AM12:AP12) -> 4653 | AR12: =+AR389 -> 1083 | AS12: =+AS389 -> 1107 | AT12: =+AT389 -> 1032 | AU12: =+AU389 -> 1095 | AV12: =SUM(AR12:AU12) -> 4317 | AW12: =+AW389 -> 1131 | AX12: =+AX389 -> 1206 | AY12: =+AY389 -> 1122 | AZ12: =+AZ389 -> 1278 | BA12: =SUM(AW12:AZ12) -> 4737 | BB12: =+BB389 -> 1189 | BC12: =+BC389 -> 1273 | BD12: =+BD389 -> 1268 | BE12: =+BE389 -> 1436 | BF12: =SUM(BB12:BE12) -> 5166 | BG12: =+BG389 -> 1270 | BH12: =+BH389 -> 1298 | BI12: =+BI389 -> 1307 | BJ12: =+BJ389 -> 1379 | BK12: =SUM(BG12:BJ12) -> 5254 | BL12: =+BL389 -> 1345 | BM12: =+BM389 -> 1468 | BN12: =+BN389 -> 1414 | BO12: =+BO389 -> 801 | BP12: =SUM(BL12:BO12) -> 5028 | BQ12: =+BQ389 -> 1099 | BR12: =+BR389 -> 1471 | BS12: =+BS389 -> 1315 | BT12: =+BT389 -> 1458 | BU12: =SUM(BQ12:BT12) -> 5343 | BV12: =+BV389 -> 1465 | BW12: =+BW389 -> 1347 | BX12: =+BX389 -> 1461 | BY12: =+BY389 -> 1682 | BZ12: =SUM(BV12:BY12) -> 5955 | CA12: =+CA389 -> 1535 | CB12: =+CB389 -> 1599 | CC12: =+CC389 -> 1601 | CD12: =+CD389 -> 1696 | CE12: =SUM(CA12:CD12) -> 6431 | CF12: =+CF389 -> 1572 | CG12: =+CG389 -> 1805 | CH12: =+CH389 -> 1647 | CI12: =+CI389 -> 1705 | CJ12: =SUM(CF12:CI12) -> 6729 | CK12: =+CK389 -> 1462 | CL12: =+CL389 -> 1744 | CM12: =+CM389 -> 1470 | CN12: =+CN389 -> 1575 | CO12: =SUM(CK12:CN12) -> 6251 | CP12: =+CP389 -> 1490 | CQ12: =+CQ389 -> 1667 | CR12: =+CR389 -> 1490 | CS12: =+CS389 -> 1596 | CT12: =SUM(CP12:CS12) -> 6243 | CU12: =+CU389 -> 1463 | CV12: =+CV389 -> 1626.6919 | CW12: =+CW389 -> 1450.5727 | CX12: =+CX389 -> 1512.3252 | CY12: =SUM(CU12:CX12) -> 6052.5898 | CZ12: =+CZ389 -> 1445.5408 | DA12: =+DA389 -> 1642.3831 | DB12: =+DB389 -> 1464.5096 | DC12: =+DC389 -> 1526.8446 | DD12: =SUM(CZ12:DC12) -> 6079.2782 | DE12: =+DE389 -> 1477.6216 | DF12: =+DF389 -> 1679.1591 | DG12: =+DG389 -> 1497.0047 | DH12: =+DH389 -> 1560.8238 | DI12: =SUM(DE12:DH12) -> 6214.6093
A13: =IF(ISBLANK(B13),"Scrap", " ") | B13: Global Brand | C13: =+'2. Consolidated'!C13 -> -- | D13: =+'2. Consolidated'!D13 -> -- | E13: =+'2. Consolidated'!E13 -> -- | F13: =+'2. Consolidated'!F13 -> -- | G13: =+'2. Consolidated'!G13 -> -- | H13: =+'2. Consolidated'!H13 -> -- | I13: =+'2. Consolidated'!I13 -> -- | J13: =+'2. Consolidated'!J13 -> -- | ... Q13: =+'2. Consolidated'!Q13 -> 105.3 | R13: =+R458 -> 31 | S13: =+S458 -> 24 | T13: =+T458 -> 22 | U13: =+U458 -> 29 | V13: =SUM(R13:U13) -> 106 | W13: =+W458 -> 33 | X13: =+X458 -> 25 | Y13: =+Y458 -> 27 | Z13: =+Z458 -> 26 | AA13: =SUM(W13:Z13) -> 111 | AC13: =+AC458 -> 27 | AD13: =+AD458 -> 28 | AE13: =+AE458 -> 29 | AF13: =+AF458 -> 31 | AG13: =SUM(AC13:AF13) -> 115 | AH13: =+AH458 -> 32 | AI13: =+AI458 -> 31 | AJ13: =+AJ458 -> 26 | AK13: =+AK458 -> 36 | AL13: =SUM(AH13:AK13) -> 125 | AM13: =+AM458 -> 29 | AN13: =+AN458 -> 28 | AO13: =+AO458 -> 28 | AP13: =+AP458 -> 30 | AQ13: =SUM(AM13:AP13) -> 115 | AR13: =+AR458 -> 26 | AS13: =+AS458 -> 18 | AT13: =+AT458 -> 17 | AU13: =+AU458 -> 12 | AV13: =SUM(AR13:AU13) -> 73 | AW13: =+AW458 -> 15 | AX13: =+AX458 -> 21 | AY13: =+AY458 -> 19 | AZ13: =+AZ458 -> 18 | BA13: =SUM(AW13:AZ13) -> 73 | BB13: =+BB458 -> 20 | BC13: =+BC458 -> 23 | BD13: =+BD458 -> 21 | BE13: =+BE458 -> 24 | BF13: =SUM(BB13:BE13) -> 88 | BG13: =+BG458 -> 16 | BH13: =+BH458 -> 9 | BI13: =+BI458 -> 8 | BJ13: =+BJ458 -> 9 | BK13: =SUM(BG13:BJ13) -> 42 | BL13: =+BL458 -> 6 | BM13: =+BM458 -> 10 | BN13: =+BN458 -> 8 | BO13: =+BO458 -> 6 | BP13: =SUM(BL13:BO13) -> 30 | BQ13: =+BQ458 -> 4 | BR13: =+BR458 -> 8 | BS13: =+BS458 -> 6 | BT13: =+BT458 -> 7 | BU13: =SUM(BQ13:BT13) -> 25 | BV13: =+BV458 -> 7 | BW13: =+BW458 -> 6 | BX13: =+BX458 -> 41 | BY13: =+BY458 -> 48 | BZ13: =SUM(BV13:BY13) -> 102 | CA13: =+CA458 -> 14 | CB13: =+CB458 -> 18 | CC13: =+CC458 -> 12 | CD13: =+CD458 -> 14 | CE13: =SUM(CA13:CD13) -> 58 | CF13: =+CF458 -> 13 | CG13: =+CG458 -> 12 | CH13: =+CH458 -> 9 | CI13: =+CI458 -> 11 | CJ13: =SUM(CF13:CI13) -> 45 | CK13: =+CK458 -> 14 | CL13: =+CL458 -> 13 | CM13: =+CM458 -> 12 | CN13: =+CN458 -> 9 | CO13: =SUM(CK13:CN13) -> 48 | CP13: =+CP458 -> 9 | CQ13: =+CQ458 -> 9 | CR13: =+CR458 -> 7 | CS13: =+CS458 -> 24 | CT13: =SUM(CP13:CS13) -> 49 | CU13: =+CU458 -> 6 | CV13: =+CV458 -> 9 | CW13: =+CW458 -> 7 | CX13: =+CX458 -> 24 | CY13: =SUM(CU13:CX13) -> 46 | CZ13: =+CZ458 -> 6 | DA13: =+DA458 -> 9 | DB13: =+DB458 -> 7 | DC13: =+DC458 -> 24 | DD13: =SUM(CZ13:DC13) -> 46 | DE13: =+DE458 -> 6 | DF13: =+DF458 -> 9 | DG13: =+DG458 -> 7 | DH13: =+DH458 -> 24 | DI13: =SUM(DE13:DH13) -> 46
A14: =IF(ISBLANK(B14),"Scrap", " ") | B14: Total Nike Brand | C14: =+'2. Consolidated'!C14 -> -- | D14: =+'2. Consolidated'!D14 -> -- | E14: =+'2. Consolidated'!E14 -> -- | F14: =+'2. Consolidated'!F14 -> -- | G14: =+'2. Consolidated'!G14 -> -- | H14: =+'2. Consolidated'!H14 -> -- | I14: =+'2. Consolidated'!I14 -> -- | J14: =+'2. Consolidated'!J14 -> -- | ... Q14: =+'2. Consolidated'!Q14 -> 16508.6 | R14: =SUM(R9:R13) -> 4483 | S14: =SUM(S9:S13) -> 4231 | T14: =SUM(T9:T13) -> 4425 | U14: =SUM(U9:U13) -> 5006 | V14: =SUM(R14:U14) -> 18145 | W14: =SUM(W9:W13) -> 5313 | X14: =SUM(X9:X13) -> 5062 | Y14: =SUM(Y9:Y13) -> 5101 | Z14: =SUM(Z9:Z13) -> 5596 | AA14: =SUM(W14:Z14) -> 21072 | AC14: =SUM(AC9:AC13) -> 6067 | AD14: =SUM(AD9:AD13) -> 5648 | AE14: =SUM(AE9:AE13) -> 5829 | AF14: =SUM(AF9:AF13) -> 6337 | AG14: =SUM(AC14:AF14) -> 23881 | AH14: =SUM(AH9:AH13) -> 6468 | AI14: =SUM(AI9:AI13) -> 6070 | AJ14: =SUM(AJ9:AJ13) -> 6554 | AK14: =SUM(AK9:AK13) -> 7020 | AL14: =SUM(AH14:AK14) -> 26112 | AM14: =SUM(AM9:AM13) -> 7421 | AN14: =SUM(AN9:AN13) -> 6959 | AO14: =SUM(AO9:AO13) -> 6939 | AP14: =SUM(AP9:AP13) -> 7382 | AQ14: =SUM(AM14:AP14) -> 28701 | AR14: =SUM(AR9:AR13) -> 7898 | AS14: =SUM(AS9:AS13) -> 7317 | AT14: =SUM(AT9:AT13) -> 7567 | AU14: =SUM(AU9:AU13) -> 7725 | AV14: =SUM(AR14:AU14) -> 30507 | AW14: =SUM(AW9:AW13) -> 8459 | AX14: =SUM(AX9:AX13) -> 7724 | AY14: =SUM(AY9:AY13) -> 7923 | AZ14: =SUM(AZ9:AZ13) -> 8127 | BA14: =SUM(AW14:AZ14) -> 32233 | BB14: =SUM(BB9:BB13) -> 8585 | BC14: =SUM(BC9:BC13) -> 8136 | BD14: =SUM(BD9:BD13) -> 8495 | BE14: =SUM(BE9:BE13) -> 9269 | BF14: =SUM(BB14:BE14) -> 34485 | BG14: =SUM(BG9:BG13) -> 9417 | BH14: =SUM(BH9:BH13) -> 8946 | BI14: =SUM(BI9:BI13) -> 9148 | BJ14: =SUM(BJ9:BJ13) -> 9707 | BK14: =SUM(BG14:BJ14) -> 37218 | BL14: =SUM(BL9:BL13) -> 10096 | BM14: =SUM(BM9:BM13) -> 9844 | BN14: =SUM(BN9:BN13) -> 9616 | BO14: =SUM(BO9:BO13) -> 6012 | BP14: =SUM(BL14:BO14) -> 35568 | BQ14: =SUM(BQ9:BQ13) -> 10018 | BR14: =SUM(BR9:BR13) -> 10741 | BS14: =SUM(BS9:BS13) -> 9773 | BT14: =SUM(BT9:BT13) -> 11761 | BU14: =SUM(BQ14:BT14) -> 42293 | BV14: =SUM(BV9:BV13) -> 11640 | BW14: =SUM(BW9:BW13) -> 10816 | BX14: =SUM(BX9:BX13) -> 10323 | BY14: =SUM(BY9:BY13) -> 11657 | BZ14: =SUM(BV14:BY14) -> 44436 | CA14: =SUM(CA9:CA13) -> 12048 | CB14: =SUM(CB9:CB13) -> 12724 | CC14: =SUM(CC9:CC13) -> 11766 | CD14: =SUM(CD9:CD13) -> 12225 | CE14: =SUM(CA14:CD14) -> 48763 | CF14: =SUM(CF9:CF13) -> 12353 | CG14: =SUM(CG9:CG13) -> 12872 | CH14: =SUM(CH9:CH13) -> 11948 | CI14: =SUM(CI9:CI13) -> 12149 | CJ14: =SUM(CF14:CI14) -> 49322 | CK14: =SUM(CK9:CK13) -> 11111 | CL14: =SUM(CL9:CL13) -> 11950 | CM14: =SUM(CM9:CM13) -> 10890 | CN14: =SUM(CN9:CN13) -> 10763 | CO14: =SUM(CK14:CN14) -> 44714 | CP14: =SUM(CP9:CP13) -> 11362 | CQ14: =SUM(CQ9:CQ13) -> 12124 | CR14: =SUM(CR9:CR13) -> 11012 | CS14: =SUM(CS9:CS13) -> 10724 | CT14: =SUM(CP14:CS14) -> 45222 | CU14: =SUM(CU9:CU13) -> 10952 | CV14: =SUM(CV9:CV13) -> 10653.098 | CW14: =SUM(CW9:CW13) -> 10094.783 | CX14: =SUM(CX9:CX13) -> 9686.1434 | CY14: =SUM(CU14:CX14) -> 41386.025 | CZ14: =SUM(CZ9:CZ13) -> 10078.383 | DA14: =SUM(DA9:DA13) -> 10146.259 | DB14: =SUM(DB9:DB13) -> 9818.6711 | DC14: =SUM(DC9:DC13) -> 9436.596 | DD14: =SUM(CZ14:DC14) -> 39479.909 | DE14: =SUM(DE9:DE13) -> 10084.204 | DF14: =SUM(DF9:DF13) -> 10165.962 | DG14: =SUM(DG9:DG13) -> 9887.7175 | DH14: =SUM(DH9:DH13) -> 9505.3773 | DI14: =SUM(DE14:DH14) -> 39643.261
